Workbook

Sheet Dashboard
G1: ="DASHBOARD · INDICADORES OPERACIONAIS"&IF(calculos!$E$2="",""," · "&calculos!$E$2) -> DASHBOARD · INDICADORES OPERACIONAIS · TPC
B3: CLIENTE ▸ | D3: Todos | L3: PERÍODO ▸ | Q3: 46296 | T3: até | V3: 46326
B4: ="Período "&TEXT(calculos!$F$7,"dd/mm")&"/"&YEAR(calculos!$F$7)&" a "&TEXT(calculos!$G$7,"dd/mm")&"/"&YEAR(calculos!$G$7)&" · ▲▼ comparado a "&TEXT(calculos!$F$8,"dd/mm")&"–"&TEXT(calculos!$G$8,"dd/mm")&" (mesmo número de dias) · gráficos diários: "&calculos!$B$7 -> Período 01/10/2026 a 31/10/2026 · ▲▼ comparado a 31/08–30/09 (mesmo número de dias) · gráficos diários: Outubro/2026
C6: =Config!$D$60&"" -> RECEBIMENTO (IN) | H6: =Config!$D$62&"" -> EXPEDIÇÃO (OUT) | M6: =Config!$D$64&"" -> NC OPERACIONAL | R6: =Config!$D$69&"" -> ÍNDICE DE OCUPAÇÃO (P.P) | W6: =Config!$D$75&"" -> GENTE
B7: =IF(calculos!$AX$384="Não se aplica","—",calculos!$B$342) -> 0 | G7: =IF(calculos!$AY$384="Não se aplica","—",calculos!$B$345) -> 0 | L7: =calculos!$B$348 -> 0 | Q7: =IF(calculos!$AZ$384="Só ocupadas","CONTRATO",IF(OR(calculos!$AZ$384="Completo",calculos!$AZ$384=""),calculos!$BA$384&"","")) -> ARMAZÉM | S7: =IF(calculos!$AZ$384="Só ocupadas",IF(calculos!$BC$384="","—",UPPER(calculos!$BC$384)),IF(OR(calculos!$AZ$384="Completo",calculos!$AZ$384=""),calculos!$B$353,"")) | V7: =Config!$D$76&"" -> EFETIVO | X7: =calculos!$B$356
Q8: =IF(calculos!$AZ$384="Não se aplica","",Config!$D$72&"") -> OCUPADA | S8: =IF(calculos!$AZ$384="Não se aplica","",calculos!$B$352) | V8: =Config!$D$77&"" -> ABSENTEÍSMO (H/H) | X8: =calculos!$B$359 -> 0
L9: =Config!$D$65&"" -> incidentes no período | Q9: =IF(OR(calculos!$AZ$384="Completo",calculos!$AZ$384=""),Config!$D$73&"","") -> TX OCUPAÇÃO | S9: =IF(OR(calculos!$AZ$384="Completo",calculos!$AZ$384=""),calculos!$B$354,"") | V9: =Config!$D$78&"" -> FÉRIAS | X9: =calculos!$B$362 -> 0
B10: =IF(calculos!$AX$384="Não se aplica","não se aplica a este cliente",Config!$D$61&"") -> veículos recebidos | G10: =IF(calculos!$AY$384="Não se aplica","não se aplica a este cliente",Config!$D$63&"") -> veículos expedidos | L10: =Config!$D$66&"" -> NO SHOW | N10: =calculos!$B$349 -> 0 | Q10: =IF(OR(calculos!$AZ$384="Completo",calculos!$AZ$384=""),Config!$D$74&"","") -> OCIOSIDADE | S10: =IF(OR(calculos!$AZ$384="Completo",calculos!$AZ$384=""),calculos!$B$355,"") | V10: =Config!$D$79&"" -> TURNOVER | X10: =calculos!$B$364
B11: =IF(calculos!$AX$384="Não se aplica","",calculos!$B$382) -> 0 pallets movimentados | G11: =IF(calculos!$AY$384="Não se aplica","",calculos!$F$382) -> 0 pallets movimentados | L11: =Config!$D$67&"" -> BACKLOG INTRALOG | N11: =calculos!$B$350 | Q11: =IF(calculos!$AZ$384="Não se aplica","não se aplica a este cliente",IF(calculos!$AZ$384="Só ocupadas","posições ocupadas · contrato "&IF(calculos!$BC$384="","não informado",calculos!$BC$384),IF(ISNUMBER(calculos!$B$354),"taxa de ocupação · "&IF(calculos!$B$354>1,"excede o contratado",IF(calculos!$B$354>=calculos!$B$6,"ocupação alta",IF(calculos!$B$354>=calculos!$B$5,"ocupação média","ociosidade alta"))),""))) | V11: =Config!$D$80&"" -> DESVIOS COMPORTAM. | X11: =calculos!$B$365 -> 0
B12: =IF(calculos!$AX$384="Não se aplica","",calculos!$D$382) -> 0,0 t movimentadas | G12: =IF(calculos!$AY$384="Não se aplica","",calculos!$H$382) -> 0,0 t movimentadas | L12: =Config!$D$68&"" -> BACKLOG CLIENTE | N12: =calculos!$B$351 | V12: =Config!$D$81&"" -> ACIDENTES (CAF/SAF) | X12: =N(calculos!$B$366)&" / "&N(calculos!$B$367) -> 0 / 0
B13: =IF(calculos!$AX$384="Não se aplica","",calculos!$D$342) | G13: =IF(calculos!$AY$384="Não se aplica","",calculos!$D$345) | L13: =calculos!$D$348 | Q13: =IF(AND(calculos!$AZ$384<>"Completo",calculos!$AZ$384<>""),"",calculos!$D$354) | V13: =calculos!$D$356
B65: Cards: período digitado (dia inicial e final). Gráficos: mês do dia inicial. Absenteísmo (H/H) = horas de ausência lançadas na BD (soma do período) · Turnover = desligamentos ÷ efetivo · CAF/SAF = acidentes com / sem afastamento. Metas: aba BD.

Sheet Monitoramento
G1: MONITORAMENTO DIÁRIO DE PERFORMANCE · TPC | AE1: OUTUBRO · 2026
A2: CLIENTE | B2: INDICADORES | D2: META | F2: REALIZADO P/DIA | AK2: MÊS
F3: =IF(ISNUMBER($AE$1),DATE(YEAR($AE$1),MONTH($AE$1),1),IFERROR(DATE(VALUE(RIGHT(TRIM($AE$1),4)),MATCH(TRIM(LEFT($AE$1,FIND("·",$AE$1)-1)),{"JANEIRO","FEVEREIRO","MARÇO","ABRIL","MAIO","JUNHO","JULHO","AGOSTO","SETEMBRO","OUTUBRO","NOVEMBRO","DEZEMBRO"},0),1),DATE(2026,10,1))) -> 46296 | G3: =IF(F3="","",IF(MONTH(F3+1)=MONTH($F$3),F3+1,"")) -> 46297 | H3: =IF(G3="","",IF(MONTH(G3+1)=MONTH($F$3),G3+1,"")) -> 46298 | I3: =IF(H3="","",IF(MONTH(H3+1)=MONTH($F$3),H3+1,"")) -> 46299 | J3: =IF(I3="","",IF(MONTH(I3+1)=MONTH($F$3),I3+1,"")) -> 46300 | K3: =IF(J3="","",IF(MONTH(J3+1)=MONTH($F$3),J3+1,"")) -> 46301 | L3: =IF(K3="","",IF(MONTH(K3+1)=MONTH($F$3),K3+1,"")) -> 46302 | M3: =IF(L3="","",IF(MONTH(L3+1)=MONTH($F$3),L3+1,"")) -> 46303 | N3: =IF(M3="","",IF(MONTH(M3+1)=MONTH($F$3),M3+1,"")) -> 46304 | ... AJ3: =IF(AI3="","",IF(MONTH(AI3+1)=MONTH($F$3),AI3+1,"")) -> 46326
A5: Alpargatas | B5: IN | C5: Veículos Recebidos | D5: =IFERROR(1/(1/INDEX(BD!$AL$23:$BF$23,MATCH($A$5,BD!$AL$22:$BF$22,0))),"") | F5: =IF(F$3="","",IF(COUNTIFS(BD!$A$3:$A$5001,F$3,BD!$B$3:$B$5001,$A$5,BD!$C$3:$C$5001,"<>")=0,"",SUMIFS(BD!$C$3:$C$5001,BD!$A$3:$A$5001,F$3,BD!$B$3:$B$5001,$A$5))) | G5: =IF(G$3="","",IF(COUNTIFS(BD!$A$3:$A$5001,G$3,BD!$B$3:$B$5001,$A$5,BD!$C$3:$C$5001,"<>")=0,"",SUMIFS(BD!$C$3:$C$5001,BD!$A$3:$A$5001,G$3,BD!$B$3:$B$5001,$A$5))) | H5: =IF(H$3="","",IF(COUNTIFS(BD!$A$3:$A$5001,H$3,BD!$B$3:$B$5001,$A$5,BD!$C$3:$C$5001,"<>")=0,"",SUMIFS(BD!$C$3:$C$5001,BD!$A$3:$A$5001,H$3,BD!$B$3:$B$5001,$A$5))) | I5: =IF(I$3="","",IF(COUNTIFS(BD!$A$3:$A$5001,I$3,BD!$B$3:$B$5001,$A$5,BD!$C$3:$C$5001,"<>")=0,"",SUMIFS(BD!$C$3:$C$5001,BD!$A$3:$A$5001,I$3,BD!$B$3:$B$5001,$A$5))) | J5: =IF(J$3="","",IF(COUNTIFS(BD!$A$3:$A$5001,J$3,BD!$B$3:$B$5001,$A$5,BD!$C$3:$C$5001,"<>")=0,"",SUMIFS(BD!$C$3:$C$5001,BD!$A$3:$A$5001,J$3,BD!$B$3:$B$5001,$A$5))) | K5: =IF(K$3="","",IF(COUNTIFS(BD!$A$3:$A$5001,K$3,BD!$B$3:$B$5001,$A$5,BD!$C$3:$C$5001,"<>")=0,"",SUMIFS(BD!$C$3:$C$5001,BD!$A$3:$A$5001,K$3,BD!$B$3:$B$5001,$A$5))) | L5: =IF(L$3="","",IF(COUNTIFS(BD!$A$3:$A$5001,L$3,BD!$B$3:$B$5001,$A$5,BD!$C$3:$C$5001,"<>")=0,"",SUMIFS(BD!$C$3:$C$5001,BD!$A$3:$A$5001,L$3,BD!$B$3:$B$5001,$A$5))) | M5: =IF(M$3="","",IF(COUNTIFS(BD!$A$3:$A$5001,M$3,BD!$B$3:$B$5001,$A$5,BD!$C$3:$C$5001,"<>")=0,"",SUMIFS(BD!$C$3:$C$5001,BD!$A$3:$A$5001,M$3,BD!$B$3:$B$5001,$A$5))) | ... AJ5: =IF(AJ$3="","",IF(COUNTIFS(BD!$A$3:$A$5001,AJ$3,BD!$B$3:$B$5001,$A$5,BD!$C$3:$C$5001,"<>")=0,"",SUMIFS(BD!$C$3:$C$5001,BD!$A$3:$A$5001,AJ$3,BD!$B$3:$B$5001,$A$5))) | AK5: =IF(COUNT(F5:AJ5)=0,"",SUM(F5:AJ5))
C6: Caixas Movimentadas | D6: =IFERROR(1/(1/INDEX(BD!$AL$27:$BF$27,MATCH($A$5,BD!$AL$22:$BF$22,0))),"") | F6: =IF(F$3="","",IF(COUNTIFS(BD!$A$3:$A$5001,F$3,BD!$B$3:$B$5001,$A$5,BD!$G$3:$G$5001,"<>")=0,"",SUMIFS(BD!$G$3:$G$5001,BD!$A$3:$A$5001,F$3,BD!$B$3:$B$5001,$A$5))) | G6: =IF(G$3="","",IF(COUNTIFS(BD!$A$3:$A$5001,G$3,BD!$B$3:$B$5001,$A$5,BD!$G$3:$G$5001,"<>")=0,"",SUMIFS(BD!$G$3:$G$5001,BD!$A$3:$A$5001,G$3,BD!$B$3:$B$5001,$A$5))) | H6: =IF(H$3="","",IF(COUNTIFS(BD!$A$3:$A$5001,H$3,BD!$B$3:$B$5001,$A$5,BD!$G$3:$G$5001,"<>")=0,"",SUMIFS(BD!$G$3:$G$5001,BD!$A$3:$A$5001,H$3,BD!$B$3:$B$5001,$A$5))) | I6: =IF(I$3="","",IF(COUNTIFS(BD!$A$3:$A$5001,I$3,BD!$B$3:$B$5001,$A$5,BD!$G$3:$G$5001,"<>")=0,"",SUMIFS(BD!$G$3:$G$5001,BD!$A$3:$A$5001,I$3,BD!$B$3:$B$5001,$A$5))) | J6: =IF(J$3="","",IF(COUNTIFS(BD!$A$3:$A$5001,J$3,BD!$B$3:$B$5001,$A$5,BD!$G$3:$G$5001,"<>")=0,"",SUMIFS(BD!$G$3:$G$5001,BD!$A$3:$A$5001,J$3,BD!$B$3:$B$5001,$A$5))) | K6: =IF(K$3="","",IF(COUNTIFS(BD!$A$3:$A$5001,K$3,BD!$B$3:$B$5001,$A$5,BD!$G$3:$G$5001,"<>")=0,"",SUMIFS(BD!$G$3:$G$5001,BD!$A$3:$A$5001,K$3,BD!$B$3:$B$5001,$A$5))) | L6: =IF(L$3="","",IF(COUNTIFS(BD!$A$3:$A$5001,L$3,BD!$B$3:$B$5001,$A$5,BD!$G$3:$G$5001,"<>")=0,"",SUMIFS(BD!$G$3:$G$5001,BD!$A$3:$A$5001,L$3,BD!$B$3:$B$5001,$A$5))) | M6: =IF(M$3="","",IF(COUNTIFS(BD!$A$3:$A$5001,M$3,BD!$B$3:$B$5001,$A$5,BD!$G$3:$G$5001,"<>")=0,"",SUMIFS(BD!$G$3:$G$5001,BD!$A$3:$A$5001,M$3,BD!$B$3:$B$5001,$A$5))) | ... AJ6: =IF(AJ$3="","",IF(COUNTIFS(BD!$A$3:$A$5001,AJ$3,BD!$B$3:$B$5001,$A$5,BD!$G$3:$G$5001,"<>")=0,"",SUMIFS(BD!$G$3:$G$5001,BD!$A$3:$A$5001,AJ$3,BD!$B$3:$B$5001,$A$5))) | AK6: =IF(COUNT(F6:AJ6)=0,"",SUM(F6:AJ6))
B7: OUT | C7: Veículos Expedidos | D7: =IFERROR(1/(1/INDEX(BD!$AL$32:$BF$32,MATCH($A$5,BD!$AL$22:$BF$22,0))),"") | F7: =IF(F$3="","",IF(COUNTIFS(BD!$A$3:$A$5001,F$3,BD!$B$3:$B$5001,$A$5,BD!$L$3:$L$5001,"<>")=0,"",SUMIFS(BD!$L$3:$L$5001,BD!$A$3:$A$5001,F$3,BD!$B$3:$B$5001,$A$5))) | G7: =IF(G$3="","",IF(COUNTIFS(BD!$A$3:$A$5001,G$3,BD!$B$3:$B$5001,$A$5,BD!$L$3:$L$5001,"<>")=0,"",SUMIFS(BD!$L$3:$L$5001,BD!$A$3:$A$5001,G$3,BD!$B$3:$B$5001,$A$5))) | H7: =IF(H$3="","",IF(COUNTIFS(BD!$A$3:$A$5001,H$3,BD!$B$3:$B$5001,$A$5,BD!$L$3:$L$5001,"<>")=0,"",SUMIFS(BD!$L$3:$L$5001,BD!$A$3:$A$5001,H$3,BD!$B$3:$B$5001,$A$5))) | I7: =IF(I$3="","",IF(COUNTIFS(BD!$A$3:$A$5001,I$3,BD!$B$3:$B$5001,$A$5,BD!$L$3:$L$5001,"<>")=0,"",SUMIFS(BD!$L$3:$L$5001,BD!$A$3:$A$5001,I$3,BD!$B$3:$B$5001,$A$5))) | J7: =IF(J$3="","",IF(COUNTIFS(BD!$A$3:$A$5001,J$3,BD!$B$3:$B$5001,$A$5,BD!$L$3:$L$5001,"<>")=0,"",SUMIFS(BD!$L$3:$L$5001,BD!$A$3:$A$5001,J$3,BD!$B$3:$B$5001,$A$5))) | K7: =IF(K$3="","",IF(COUNTIFS(BD!$A$3:$A$5001,K$3,BD!$B$3:$B$5001,$A$5,BD!$L$3:$L$5001,"<>")=0,"",SUMIFS(BD!$L$3:$L$5001,BD!$A$3:$A$5001,K$3,BD!$B$3:$B$5001,$A$5))) | L7: =IF(L$3="","",IF(COUNTIFS(BD!$A$3:$A$5001,L$3,BD!$B$3:$B$5001,$A$5,BD!$L$3:$L$5001,"<>")=0,"",SUMIFS(BD!$L$3:$L$5001,BD!$A$3:$A$5001,L$3,BD!$B$3:$B$5001,$A$5))) | M7: =IF(M$3="","",IF(COUNTIFS(BD!$A$3:$A$5001,M$3,BD!$B$3:$B$5001,$A$5,BD!$L$3:$L$5001,"<>")=0,"",SUMIFS(BD!$L$3:$L$5001,BD!$A$3:$A$5001,M$3,BD!$B$3:$B$5001,$A$5))) | ... AJ7: =IF(AJ$3="","",IF(COUNTIFS(BD!$A$3:$A$5001,AJ$3,BD!$B$3:$B$5001,$A$5,BD!$L$3:$L$5001,"<>")=0,"",SUMIFS(BD!$L$3:$L$5001,BD!$A$3:$A$5001,AJ$3,BD!$B$3:$B$5001,$A$5))) | AK7: =IF(COUNT(F7:AJ7)=0,"",SUM(F7:AJ7))
C8: Caixas Expedidas | D8: =IFERROR(1/(1/INDEX(BD!$AL$37:$BF$37,MATCH($A$5,BD!$AL$22:$BF$22,0))),"") | F8: =IF(F$3="","",IF(COUNTIFS(BD!$A$3:$A$5001,F$3,BD!$B$3:$B$5001,$A$5,BD!$Q$3:$Q$5001,"<>")=0,"",SUMIFS(BD!$Q$3:$Q$5001,BD!$A$3:$A$5001,F$3,BD!$B$3:$B$5001,$A$5))) | G8: =IF(G$3="","",IF(COUNTIFS(BD!$A$3:$A$5001,G$3,BD!$B$3:$B$5001,$A$5,BD!$Q$3:$Q$5001,"<>")=0,"",SUMIFS(BD!$Q$3:$Q$5001,BD!$A$3:$A$5001,G$3,BD!$B$3:$B$5001,$A$5))) | H8: =IF(H$3="","",IF(COUNTIFS(BD!$A$3:$A$5001,H$3,BD!$B$3:$B$5001,$A$5,BD!$Q$3:$Q$5001,"<>")=0,"",SUMIFS(BD!$Q$3:$Q$5001,BD!$A$3:$A$5001,H$3,BD!$B$3:$B$5001,$A$5))) | I8: =IF(I$3="","",IF(COUNTIFS(BD!$A$3:$A$5001,I$3,BD!$B$3:$B$5001,$A$5,BD!$Q$3:$Q$5001,"<>")=0,"",SUMIFS(BD!$Q$3:$Q$5001,BD!$A$3:$A$5001,I$3,BD!$B$3:$B$5001,$A$5))) | J8: =IF(J$3="","",IF(COUNTIFS(BD!$A$3:$A$5001,J$3,BD!$B$3:$B$5001,$A$5,BD!$Q$3:$Q$5001,"<>")=0,"",SUMIFS(BD!$Q$3:$Q$5001,BD!$A$3:$A$5001,J$3,BD!$B$3:$B$5001,$A$5))) | K8: =IF(K$3="","",IF(COUNTIFS(BD!$A$3:$A$5001,K$3,BD!$B$3:$B$5001,$A$5,BD!$Q$3:$Q$5001,"<>")=0,"",SUMIFS(BD!$Q$3:$Q$5001,BD!$A$3:$A$5001,K$3,BD!$B$3:$B$5001,$A$5))) | L8: =IF(L$3="","",IF(COUNTIFS(BD!$A$3:$A$5001,L$3,BD!$B$3:$B$5001,$A$5,BD!$Q$3:$Q$5001,"<>")=0,"",SUMIFS(BD!$Q$3:$Q$5001,BD!$A$3:$A$5001,L$3,BD!$B$3:$B$5001,$A$5))) | M8: =IF(M$3="","",IF(COUNTIFS(BD!$A$3:$A$5001,M$3,BD!$B$3:$B$5001,$A$5,BD!$Q$3:$Q$5001,"<>")=0,"",SUMIFS(BD!$Q$3:$Q$5001,BD!$A$3:$A$5001,M$3,BD!$B$3:$B$5001,$A$5))) | ... AJ8: =IF(AJ$3="","",IF(COUNTIFS(BD!$A$3:$A$5001,AJ$3,BD!$B$3:$B$5001,$A$5,BD!$Q$3:$Q$5001,"<>")=0,"",SUMIFS(BD!$Q$3:$Q$5001,BD!$A$3:$A$5001,AJ$3,BD!$B$3:$B$5001,$A$5))) | AK8: =IF(COUNT(F8:AJ8)=0,"",SUM(F8:AJ8))
B9: NC | C9: Incidentes | D9: =IFERROR(1/(1/INDEX(BD!$AL$40:$BF$40,MATCH($A$5,BD!$AL$22:$BF$22,0))),"") | F9: =IF(F$3="","",IF(COUNTIFS(BD!$A$3:$A$5001,F$3,BD!$B$3:$B$5001,$A$5,BD!$T$3:$T$5001,"<>")=0,"",SUMIFS(BD!$T$3:$T$5001,BD!$A$3:$A$5001,F$3,BD!$B$3:$B$5001,$A$5))) | G9: =IF(G$3="","",IF(COUNTIFS(BD!$A$3:$A$5001,G$3,BD!$B$3:$B$5001,$A$5,BD!$T$3:$T$5001,"<>")=0,"",SUMIFS(BD!$T$3:$T$5001,BD!$A$3:$A$5001,G$3,BD!$B$3:$B$5001,$A$5))) | H9: =IF(H$3="","",IF(COUNTIFS(BD!$A$3:$A$5001,H$3,BD!$B$3:$B$5001,$A$5,BD!$T$3:$T$5001,"<>")=0,"",SUMIFS(BD!$T$3:$T$5001,BD!$A$3:$A$5001,H$3,BD!$B$3:$B$5001,$A$5))) | I9: =IF(I$3="","",IF(COUNTIFS(BD!$A$3:$A$5001,I$3,BD!$B$3:$B$5001,$A$5,BD!$T$3:$T$5001,"<>")=0,"",SUMIFS(BD!$T$3:$T$5001,BD!$A$3:$A$5001,I$3,BD!$B$3:$B$5001,$A$5))) | J9: =IF(J$3="","",IF(COUNTIFS(BD!$A$3:$A$5001,J$3,BD!$B$3:$B$5001,$A$5,BD!$T$3:$T$5001,"<>")=0,"",SUMIFS(BD!$T$3:$T$5001,BD!$A$3:$A$5001,J$3,BD!$B$3:$B$5001,$A$5))) | K9: =IF(K$3="","",IF(COUNTIFS(BD!$A$3:$A$5001,K$3,BD!$B$3:$B$5001,$A$5,BD!$T$3:$T$5001,"<>")=0,"",SUMIFS(BD!$T$3:$T$5001,BD!$A$3:$A$5001,K$3,BD!$B$3:$B$5001,$A$5))) | L9: =IF(L$3="","",IF(COUNTIFS(BD!$A$3:$A$5001,L$3,BD!$B$3:$B$5001,$A$5,BD!$T$3:$T$5001,"<>")=0,"",SUMIFS(BD!$T$3:$T$5001,BD!$A$3:$A$5001,L$3,BD!$B$3:$B$5001,$A$5))) | M9: =IF(M$3="","",IF(COUNTIFS(BD!$A$3:$A$5001,M$3,BD!$B$3:$B$5001,$A$5,BD!$T$3:$T$5001,"<>")=0,"",SUMIFS(BD!$T$3:$T$5001,BD!$A$3:$A$5001,M$3,BD!$B$3:$B$5001,$A$5))) | ... AJ9: =IF(AJ$3="","",IF(COUNTIFS(BD!$A$3:$A$5001,AJ$3,BD!$B$3:$B$5001,$A$5,BD!$T$3:$T$5001,"<>")=0,"",SUMIFS(BD!$T$3:$T$5001,BD!$A$3:$A$5001,AJ$3,BD!$B$3:$B$5001,$A$5))) | AK9: =IF(COUNT(F9:AJ9)=0,"",SUM(F9:AJ9))
C10: No show | D10: =IFERROR(1/(1/INDEX(BD!$AL$41:$BF$41,MATCH($A$5,BD!$AL$22:$BF$22,0))),"") | F10: =IF(F$3="","",IF(COUNTIFS(BD!$A$3:$A$5001,F$3,BD!$B$3:$B$5001,$A$5,BD!$U$3:$U$5001,"<>")=0,"",SUMIFS(BD!$U$3:$U$5001,BD!$A$3:$A$5001,F$3,BD!$B$3:$B$5001,$A$5))) | G10: =IF(G$3="","",IF(COUNTIFS(BD!$A$3:$A$5001,G$3,BD!$B$3:$B$5001,$A$5,BD!$U$3:$U$5001,"<>")=0,"",SUMIFS(BD!$U$3:$U$5001,BD!$A$3:$A$5001,G$3,BD!$B$3:$B$5001,$A$5))) | H10: =IF(H$3="","",IF(COUNTIFS(BD!$A$3:$A$5001,H$3,BD!$B$3:$B$5001,$A$5,BD!$U$3:$U$5001,"<>")=0,"",SUMIFS(BD!$U$3:$U$5001,BD!$A$3:$A$5001,H$3,BD!$B$3:$B$5001,$A$5))) | I10: =IF(I$3="","",IF(COUNTIFS(BD!$A$3:$A$5001,I$3,BD!$B$3:$B$5001,$A$5,BD!$U$3:$U$5001,"<>")=0,"",SUMIFS(BD!$U$3:$U$5001,BD!$A$3:$A$5001,I$3,BD!$B$3:$B$5001,$A$5))) | J10: =IF(J$3="","",IF(COUNTIFS(BD!$A$3:$A$5001,J$3,BD!$B$3:$B$5001,$A$5,BD!$U$3:$U$5001,"<>")=0,"",SUMIFS(BD!$U$3:$U$5001,BD!$A$3:$A$5001,J$3,BD!$B$3:$B$5001,$A$5))) | K10: =IF(K$3="","",IF(COUNTIFS(BD!$A$3:$A$5001,K$3,BD!$B$3:$B$5001,$A$5,BD!$U$3:$U$5001,"<>")=0,"",SUMIFS(BD!$U$3:$U$5001,BD!$A$3:$A$5001,K$3,BD!$B$3:$B$5001,$A$5))) | L10: =IF(L$3="","",IF(COUNTIFS(BD!$A$3:$A$5001,L$3,BD!$B$3:$B$5001,$A$5,BD!$U$3:$U$5001,"<>")=0,"",SUMIFS(BD!$U$3:$U$5001,BD!$A$3:$A$5001,L$3,BD!$B$3:$B$5001,$A$5))) | M10: =IF(M$3="","",IF(COUNTIFS(BD!$A$3:$A$5001,M$3,BD!$B$3:$B$5001,$A$5,BD!$U$3:$U$5001,"<>")=0,"",SUMIFS(BD!$U$3:$U$5001,BD!$A$3:$A$5001,M$3,BD!$B$3:$B$5001,$A$5))) | ... AJ10: =IF(AJ$3="","",IF(COUNTIFS(BD!$A$3:$A$5001,AJ$3,BD!$B$3:$B$5001,$A$5,BD!$U$3:$U$5001,"<>")=0,"",SUMIFS(BD!$U$3:$U$5001,BD!$A$3:$A$5001,AJ$3,BD!$B$3:$B$5001,$A$5))) | AK10: =IF(COUNT(F10:AJ10)=0,"",SUM(F10:AJ10))
C11: Backlog Intralog | D11: =IFERROR(1/(1/INDEX(BD!$AL$42:$BF$42,MATCH($A$5,BD!$AL$22:$BF$22,0))),"") | F11: =IF(F$3="","",IF(COUNTIFS(BD!$A$3:$A$5001,F$3,BD!$B$3:$B$5001,$A$5,BD!$V$3:$V$5001,"<>")=0,"",SUMIFS(BD!$V$3:$V$5001,BD!$A$3:$A$5001,F$3,BD!$B$3:$B$5001,$A$5))) | G11: =IF(G$3="","",IF(COUNTIFS(BD!$A$3:$A$5001,G$3,BD!$B$3:$B$5001,$A$5,BD!$V$3:$V$5001,"<>")=0,"",SUMIFS(BD!$V$3:$V$5001,BD!$A$3:$A$5001,G$3,BD!$B$3:$B$5001,$A$5))) | H11: =IF(H$3="","",IF(COUNTIFS(BD!$A$3:$A$5001,H$3,BD!$B$3:$B$5001,$A$5,BD!$V$3:$V$5001,"<>")=0,"",SUMIFS(BD!$V$3:$V$5001,BD!$A$3:$A$5001,H$3,BD!$B$3:$B$5001,$A$5))) | I11: =IF(I$3="","",IF(COUNTIFS(BD!$A$3:$A$5001,I$3,BD!$B$3:$B$5001,$A$5,BD!$V$3:$V$5001,"<>")=0,"",SUMIFS(BD!$V$3:$V$5001,BD!$A$3:$A$5001,I$3,BD!$B$3:$B$5001,$A$5))) | J11: =IF(J$3="","",IF(COUNTIFS(BD!$A$3:$A$5001,J$3,BD!$B$3:$B$5001,$A$5,BD!$V$3:$V$5001,"<>")=0,"",SUMIFS(BD!$V$3:$V$5001,BD!$A$3:$A$5001,J$3,BD!$B$3:$B$5001,$A$5))) | K11: =IF(K$3="","",IF(COUNTIFS(BD!$A$3:$A$5001,K$3,BD!$B$3:$B$5001,$A$5,BD!$V$3:$V$5001,"<>")=0,"",SUMIFS(BD!$V$3:$V$5001,BD!$A$3:$A$5001,K$3,BD!$B$3:$B$5001,$A$5))) | L11: =IF(L$3="","",IF(COUNTIFS(BD!$A$3:$A$5001,L$3,BD!$B$3:$B$5001,$A$5,BD!$V$3:$V$5001,"<>")=0,"",SUMIFS(BD!$V$3:$V$5001,BD!$A$3:$A$5001,L$3,BD!$B$3:$B$5001,$A$5))) | M11: =IF(M$3="","",IF(COUNTIFS(BD!$A$3:$A$5001,M$3,BD!$B$3:$B$5001,$A$5,BD!$V$3:$V$5001,"<>")=0,"",SUMIFS(BD!$V$3:$V$5001,BD!$A$3:$A$5001,M$3,BD!$B$3:$B$5001,$A$5))) | ... AJ11: =IF(AJ$3="","",IF(COUNTIFS(BD!$A$3:$A$5001,AJ$3,BD!$B$3:$B$5001,$A$5,BD!$V$3:$V$5001,"<>")=0,"",SUMIFS(BD!$V$3:$V$5001,BD!$A$3:$A$5001,AJ$3,BD!$B$3:$B$5001,$A$5))) | AK11: =IFERROR(LOOKUP(9.99E+307,F11:AJ11),"")
C12: Backlog Cliente | D12: =IFERROR(1/(1/INDEX(BD!$AL$43:$BF$43,MATCH($A$5,BD!$AL$22:$BF$22,0))),"") | F12: =IF(F$3="","",IF(COUNTIFS(BD!$A$3:$A$5001,F$3,BD!$B$3:$B$5001,$A$5,BD!$W$3:$W$5001,"<>")=0,"",SUMIFS(BD!$W$3:$W$5001,BD!$A$3:$A$5001,F$3,BD!$B$3:$B$5001,$A$5))) | G12: =IF(G$3="","",IF(COUNTIFS(BD!$A$3:$A$5001,G$3,BD!$B$3:$B$5001,$A$5,BD!$W$3:$W$5001,"<>")=0,"",SUMIFS(BD!$W$3:$W$5001,BD!$A$3:$A$5001,G$3,BD!$B$3:$B$5001,$A$5))) | H12: =IF(H$3="","",IF(COUNTIFS(BD!$A$3:$A$5001,H$3,BD!$B$3:$B$5001,$A$5,BD!$W$3:$W$5001,"<>")=0,"",SUMIFS(BD!$W$3:$W$5001,BD!$A$3:$A$5001,H$3,BD!$B$3:$B$5001,$A$5))) | I12: =IF(I$3="","",IF(COUNTIFS(BD!$A$3:$A$5001,I$3,BD!$B$3:$B$5001,$A$5,BD!$W$3:$W$5001,"<>")=0,"",SUMIFS(BD!$W$3:$W$5001,BD!$A$3:$A$5001,I$3,BD!$B$3:$B$5001,$A$5))) | J12: =IF(J$3="","",IF(COUNTIFS(BD!$A$3:$A$5001,J$3,BD!$B$3:$B$5001,$A$5,BD!$W$3:$W$5001,"<>")=0,"",SUMIFS(BD!$W$3:$W$5001,BD!$A$3:$A$5001,J$3,BD!$B$3:$B$5001,$A$5))) | K12: =IF(K$3="","",IF(COUNTIFS(BD!$A$3:$A$5001,K$3,BD!$B$3:$B$5001,$A$5,BD!$W$3:$W$5001,"<>")=0,"",SUMIFS(BD!$W$3:$W$5001,BD!$A$3:$A$5001,K$3,BD!$B$3:$B$5001,$A$5))) | L12: =IF(L$3="","",IF(COUNTIFS(BD!$A$3:$A$5001,L$3,BD!$B$3:$B$5001,$A$5,BD!$W$3:$W$5001,"<>")=0,"",SUMIFS(BD!$W$3:$W$5001,BD!$A$3:$A$5001,L$3,BD!$B$3:$B$5001,$A$5))) | M12: =IF(M$3="","",IF(COUNTIFS(BD!$A$3:$A$5001,M$3,BD!$B$3:$B$5001,$A$5,BD!$W$3:$W$5001,"<>")=0,"",SUMIFS(BD!$W$3:$W$5001,BD!$A$3:$A$5001,M$3,BD!$B$3:$B$5001,$A$5))) | ... AJ12: =IF(AJ$3="","",IF(COUNTIFS(BD!$A$3:$A$5001,AJ$3,BD!$B$3:$B$5001,$A$5,BD!$W$3:$W$5001,"<>")=0,"",SUMIFS(BD!$W$3:$W$5001,BD!$A$3:$A$5001,AJ$3,BD!$B$3:$B$5001,$A$5))) | AK12: =IFERROR(LOOKUP(9.99E+307,F12:AJ12),"")
B13: OCUPAÇÃO (P.P) | C13: Posições Disponíveis | D13: =IFERROR(1/(1/INDEX(BD!$AL$44:$BF$44,MATCH($A$5,BD!$AL$22:$BF$22,0))),"") | F13: =IF(F$3="","",IF(COUNTIFS(BD!$A$3:$A$5001,F$3,BD!$B$3:$B$5001,$A$5,BD!$X$3:$X$5001,"<>")=0,"",SUMIFS(BD!$X$3:$X$5001,BD!$A$3:$A$5001,F$3,BD!$B$3:$B$5001,$A$5))) | G13: =IF(G$3="","",IF(COUNTIFS(BD!$A$3:$A$5001,G$3,BD!$B$3:$B$5001,$A$5,BD!$X$3:$X$5001,"<>")=0,"",SUMIFS(BD!$X$3:$X$5001,BD!$A$3:$A$5001,G$3,BD!$B$3:$B$5001,$A$5))) | H13: =IF(H$3="","",IF(COUNTIFS(BD!$A$3:$A$5001,H$3,BD!$B$3:$B$5001,$A$5,BD!$X$3:$X$5001,"<>")=0,"",SUMIFS(BD!$X$3:$X$5001,BD!$A$3:$A$5001,H$3,BD!$B$3:$B$5001,$A$5))) | I13: =IF(I$3="","",IF(COUNTIFS(BD!$A$3:$A$5001,I$3,BD!$B$3:$B$5001,$A$5,BD!$X$3:$X$5001,"<>")=0,"",SUMIFS(BD!$X$3:$X$5001,BD!$A$3:$A$5001,I$3,BD!$B$3:$B$5001,$A$5))) | J13: =IF(J$3="","",IF(COUNTIFS(BD!$A$3:$A$5001,J$3,BD!$B$3:$B$5001,$A$5,BD!$X$3:$X$5001,"<>")=0,"",SUMIFS(BD!$X$3:$X$5001,BD!$A$3:$A$5001,J$3,BD!$B$3:$B$5001,$A$5))) | K13: =IF(K$3="","",IF(COUNTIFS(BD!$A$3:$A$5001,K$3,BD!$B$3:$B$5001,$A$5,BD!$X$3:$X$5001,"<>")=0,"",SUMIFS(BD!$X$3:$X$5001,BD!$A$3:$A$5001,K$3,BD!$B$3:$B$5001,$A$5))) | L13: =IF(L$3="","",IF(COUNTIFS(BD!$A$3:$A$5001,L$3,BD!$B$3:$B$5001,$A$5,BD!$X$3:$X$5001,"<>")=0,"",SUMIFS(BD!$X$3:$X$5001,BD!$A$3:$A$5001,L$3,BD!$B$3:$B$5001,$A$5))) | M13: =IF(M$3="","",IF(COUNTIFS(BD!$A$3:$A$5001,M$3,BD!$B$3:$B$5001,$A$5,BD!$X$3:$X$5001,"<>")=0,"",SUMIFS(BD!$X$3:$X$5001,BD!$A$3:$A$5001,M$3,BD!$B$3:$B$5001,$A$5))) | ... AJ13: =IF(AJ$3="","",IF(COUNTIFS(BD!$A$3:$A$5001,AJ$3,BD!$B$3:$B$5001,$A$5,BD!$X$3:$X$5001,"<>")=0,"",SUMIFS(BD!$X$3:$X$5001,BD!$A$3:$A$5001,AJ$3,BD!$B$3:$B$5001,$A$5))) | AK13: =IF(COUNT(F13:AJ13)>0,LOOKUP(9.99E+307,F13:AJ13),IFERROR(IF(INDEX(BD!$AI$3:$AI$5001,MATCH($A$5,BD!$B$3:$B$5001,0))&""="Contrato","",INDEX(BD!$AI$3:$AI$5001,MATCH($A$5,BD!$B$3:$B$5001,0))&""),""))
C14: Posições Ocupadas | D14: =IFERROR(1/(1/INDEX(BD!$AL$45:$BF$45,MATCH($A$5,BD!$AL$22:$BF$22,0))),"") | F14: =IF(F$3="","",IF(COUNTIFS(BD!$A$3:$A$5001,F$3,BD!$B$3:$B$5001,$A$5,BD!$Y$3:$Y$5001,"<>")=0,"",SUMIFS(BD!$Y$3:$Y$5001,BD!$A$3:$A$5001,F$3,BD!$B$3:$B$5001,$A$5))) | G14: =IF(G$3="","",IF(COUNTIFS(BD!$A$3:$A$5001,G$3,BD!$B$3:$B$5001,$A$5,BD!$Y$3:$Y$5001,"<>")=0,"",SUMIFS(BD!$Y$3:$Y$5001,BD!$A$3:$A$5001,G$3,BD!$B$3:$B$5001,$A$5))) | H14: =IF(H$3="","",IF(COUNTIFS(BD!$A$3:$A$5001,H$3,BD!$B$3:$B$5001,$A$5,BD!$Y$3:$Y$5001,"<>")=0,"",SUMIFS(BD!$Y$3:$Y$5001,BD!$A$3:$A$5001,H$3,BD!$B$3:$B$5001,$A$5))) | I14: =IF(I$3="","",IF(COUNTIFS(BD!$A$3:$A$5001,I$3,BD!$B$3:$B$5001,$A$5,BD!$Y$3:$Y$5001,"<>")=0,"",SUMIFS(BD!$Y$3:$Y$5001,BD!$A$3:$A$5001,I$3,BD!$B$3:$B$5001,$A$5))) | J14: =IF(J$3="","",IF(COUNTIFS(BD!$A$3:$A$5001,J$3,BD!$B$3:$B$5001,$A$5,BD!$Y$3:$Y$5001,"<>")=0,"",SUMIFS(BD!$Y$3:$Y$5001,BD!$A$3:$A$5001,J$3,BD!$B$3:$B$5001,$A$5))) | K14: =IF(K$3="","",IF(COUNTIFS(BD!$A$3:$A$5001,K$3,BD!$B$3:$B$5001,$A$5,BD!$Y$3:$Y$5001,"<>")=0,"",SUMIFS(BD!$Y$3:$Y$5001,BD!$A$3:$A$5001,K$3,BD!$B$3:$B$5001,$A$5))) | L14: =IF(L$3="","",IF(COUNTIFS(BD!$A$3:$A$5001,L$3,BD!$B$3:$B$5001,$A$5,BD!$Y$3:$Y$5001,"<>")=0,"",SUMIFS(BD!$Y$3:$Y$5001,BD!$A$3:$A$5001,L$3,BD!$B$3:$B$5001,$A$5))) | M14: =IF(M$3="","",IF(COUNTIFS(BD!$A$3:$A$5001,M$3,BD!$B$3:$B$5001,$A$5,BD!$Y$3:$Y$5001,"<>")=0,"",SUMIFS(BD!$Y$3:$Y$5001,BD!$A$3:$A$5001,M$3,BD!$B$3:$B$5001,$A$5))) | ... AJ14: =IF(AJ$3="","",IF(COUNTIFS(BD!$A$3:$A$5001,AJ$3,BD!$B$3:$B$5001,$A$5,BD!$Y$3:$Y$5001,"<>")=0,"",SUMIFS(BD!$Y$3:$Y$5001,BD!$A$3:$A$5001,AJ$3,BD!$B$3:$B$5001,$A$5))) | AK14: =IFERROR(LOOKUP(9.99E+307,F14:AJ14),"")
C15: Taxa de Ocupação | D15: =IFERROR(1/(1/INDEX(BD!$AL$46:$BF$46,MATCH($A$5,BD!$AL$22:$BF$22,0))),"") | F15: =IF(AND(ISNUMBER(F13),ISNUMBER(F14)),IF(F13>0,F14/F13,""),"") | G15: =IF(AND(ISNUMBER(G13),ISNUMBER(G14)),IF(G13>0,G14/G13,""),"") | H15: =IF(AND(ISNUMBER(H13),ISNUMBER(H14)),IF(H13>0,H14/H13,""),"") | I15: =IF(AND(ISNUMBER(I13),ISNUMBER(I14)),IF(I13>0,I14/I13,""),"") | J15: =IF(AND(ISNUMBER(J13),ISNUMBER(J14)),IF(J13>0,J14/J13,""),"") | K15: =IF(AND(ISNUMBER(K13),ISNUMBER(K14)),IF(K13>0,K14/K13,""),"") | L15: =IF(AND(ISNUMBER(L13),ISNUMBER(L14)),IF(L13>0,L14/L13,""),"") | M15: =IF(AND(ISNUMBER(M13),ISNUMBER(M14)),IF(M13>0,M14/M13,""),"") | ... AK15: =IF(AND(ISNUMBER(AK13),ISNUMBER(AK14)),IF(AK13>0,AK14/AK13,""),"")
B16: GENTE | C16: Efetivo Op. | D16: =IFERROR(1/(1/INDEX(BD!$AL$47:$BF$47,MATCH($A$5,BD!$AL$22:$BF$22,0))),"") | F16: =IF(F$3="","",IF(COUNTIFS(BD!$A$3:$A$5001,F$3,BD!$B$3:$B$5001,$A$5,BD!$Z$3:$Z$5001,"<>")=0,"",SUMIFS(BD!$Z$3:$Z$5001,BD!$A$3:$A$5001,F$3,BD!$B$3:$B$5001,$A$5))) | G16: =IF(G$3="","",IF(COUNTIFS(BD!$A$3:$A$5001,G$3,BD!$B$3:$B$5001,$A$5,BD!$Z$3:$Z$5001,"<>")=0,"",SUMIFS(BD!$Z$3:$Z$5001,BD!$A$3:$A$5001,G$3,BD!$B$3:$B$5001,$A$5))) | H16: =IF(H$3="","",IF(COUNTIFS(BD!$A$3:$A$5001,H$3,BD!$B$3:$B$5001,$A$5,BD!$Z$3:$Z$5001,"<>")=0,"",SUMIFS(BD!$Z$3:$Z$5001,BD!$A$3:$A$5001,H$3,BD!$B$3:$B$5001,$A$5))) | I16: =IF(I$3="","",IF(COUNTIFS(BD!$A$3:$A$5001,I$3,BD!$B$3:$B$5001,$A$5,BD!$Z$3:$Z$5001,"<>")=0,"",SUMIFS(BD!$Z$3:$Z$5001,BD!$A$3:$A$5001,I$3,BD!$B$3:$B$5001,$A$5))) | J16: =IF(J$3="","",IF(COUNTIFS(BD!$A$3:$A$5001,J$3,BD!$B$3:$B$5001,$A$5,BD!$Z$3:$Z$5001,"<>")=0,"",SUMIFS(BD!$Z$3:$Z$5001,BD!$A$3:$A$5001,J$3,BD!$B$3:$B$5001,$A$5))) | K16: =IF(K$3="","",IF(COUNTIFS(BD!$A$3:$A$5001,K$3,BD!$B$3:$B$5001,$A$5,BD!$Z$3:$Z$5001,"<>")=0,"",SUMIFS(BD!$Z$3:$Z$5001,BD!$A$3:$A$5001,K$3,BD!$B$3:$B$5001,$A$5))) | L16: =IF(L$3="","",IF(COUNTIFS(BD!$A$3:$A$5001,L$3,BD!$B$3:$B$5001,$A$5,BD!$Z$3:$Z$5001,"<>")=0,"",SUMIFS(BD!$Z$3:$Z$5001,BD!$A$3:$A$5001,L$3,BD!$B$3:$B$5001,$A$5))) | M16: =IF(M$3="","",IF(COUNTIFS(BD!$A$3:$A$5001,M$3,BD!$B$3:$B$5001,$A$5,BD!$Z$3:$Z$5001,"<>")=0,"",SUMIFS(BD!$Z$3:$Z$5001,BD!$A$3:$A$5001,M$3,BD!$B$3:$B$5001,$A$5))) | ... AJ16: =IF(AJ$3="","",IF(COUNTIFS(BD!$A$3:$A$5001,AJ$3,BD!$B$3:$B$5001,$A$5,BD!$Z$3:$Z$5001,"<>")=0,"",SUMIFS(BD!$Z$3:$Z$5001,BD!$A$3:$A$5001,AJ$3,BD!$B$3:$B$5001,$A$5))) | AK16: =IFERROR(LOOKUP(9.99E+307,F16:AJ16),"")
C17: Falta | D17: =IFERROR(1/(1/INDEX(BD!$AL$48:$BF$48,MATCH($A$5,BD!$AL$22:$BF$22,0))),"") | F17: =IF(F$3="","",IF(COUNTIFS(BD!$A$3:$A$5001,F$3,BD!$B$3:$B$5001,$A$5,BD!$AA$3:$AA$5001,"<>")=0,"",SUMIFS(BD!$AA$3:$AA$5001,BD!$A$3:$A$5001,F$3,BD!$B$3:$B$5001,$A$5))) | G17: =IF(G$3="","",IF(COUNTIFS(BD!$A$3:$A$5001,G$3,BD!$B$3:$B$5001,$A$5,BD!$AA$3:$AA$5001,"<>")=0,"",SUMIFS(BD!$AA$3:$AA$5001,BD!$A$3:$A$5001,G$3,BD!$B$3:$B$5001,$A$5))) | H17: =IF(H$3="","",IF(COUNTIFS(BD!$A$3:$A$5001,H$3,BD!$B$3:$B$5001,$A$5,BD!$AA$3:$AA$5001,"<>")=0,"",SUMIFS(BD!$AA$3:$AA$5001,BD!$A$3:$A$5001,H$3,BD!$B$3:$B$5001,$A$5))) | I17: =IF(I$3="","",IF(COUNTIFS(BD!$A$3:$A$5001,I$3,BD!$B$3:$B$5001,$A$5,BD!$AA$3:$AA$5001,"<>")=0,"",SUMIFS(BD!$AA$3:$AA$5001,BD!$A$3:$A$5001,I$3,BD!$B$3:$B$5001,$A$5))) | J17: =IF(J$3="","",IF(COUNTIFS(BD!$A$3:$A$5001,J$3,BD!$B$3:$B$5001,$A$5,BD!$AA$3:$AA$5001,"<>")=0,"",SUMIFS(BD!$AA$3:$AA$5001,BD!$A$3:$A$5001,J$3,BD!$B$3:$B$5001,$A$5))) | K17: =IF(K$3="","",IF(COUNTIFS(BD!$A$3:$A$5001,K$3,BD!$B$3:$B$5001,$A$5,BD!$AA$3:$AA$5001,"<>")=0,"",SUMIFS(BD!$AA$3:$AA$5001,BD!$A$3:$A$5001,K$3,BD!$B$3:$B$5001,$A$5))) | L17: =IF(L$3="","",IF(COUNTIFS(BD!$A$3:$A$5001,L$3,BD!$B$3:$B$5001,$A$5,BD!$AA$3:$AA$5001,"<>")=0,"",SUMIFS(BD!$AA$3:$AA$5001,BD!$A$3:$A$5001,L$3,BD!$B$3:$B$5001,$A$5))) | M17: =IF(M$3="","",IF(COUNTIFS(BD!$A$3:$A$5001,M$3,BD!$B$3:$B$5001,$A$5,BD!$AA$3:$AA$5001,"<>")=0,"",SUMIFS(BD!$AA$3:$AA$5001,BD!$A$3:$A$5001,M$3,BD!$B$3:$B$5001,$A$5))) | ... AJ17: =IF(AJ$3="","",IF(COUNTIFS(BD!$A$3:$A$5001,AJ$3,BD!$B$3:$B$5001,$A$5,BD!$AA$3:$AA$5001,"<>")=0,"",SUMIFS(BD!$AA$3:$AA$5001,BD!$A$3:$A$5001,AJ$3,BD!$B$3:$B$5001,$A$5))) | AK17: =IF(COUNT(F17:AJ17)=0,"",SUM(F17:AJ17))
C18: Absenteísmo (H/H) | D18: =IFERROR(1/(1/INDEX(BD!$AL$49:$BF$49,MATCH($A$5,BD!$AL$22:$BF$22,0))),"") | F18: =IF(F$3="","",IF(COUNTIFS(BD!$A$3:$A$5001,F$3,BD!$B$3:$B$5001,$A$5,BD!$AB$3:$AB$5001,"<>")=0,"",SUMIFS(BD!$AB$3:$AB$5001,BD!$A$3:$A$5001,F$3,BD!$B$3:$B$5001,$A$5))) | G18: =IF(G$3="","",IF(COUNTIFS(BD!$A$3:$A$5001,G$3,BD!$B$3:$B$5001,$A$5,BD!$AB$3:$AB$5001,"<>")=0,"",SUMIFS(BD!$AB$3:$AB$5001,BD!$A$3:$A$5001,G$3,BD!$B$3:$B$5001,$A$5))) | H18: =IF(H$3="","",IF(COUNTIFS(BD!$A$3:$A$5001,H$3,BD!$B$3:$B$5001,$A$5,BD!$AB$3:$AB$5001,"<>")=0,"",SUMIFS(BD!$AB$3:$AB$5001,BD!$A$3:$A$5001,H$3,BD!$B$3:$B$5001,$A$5))) | I18: =IF(I$3="","",IF(COUNTIFS(BD!$A$3:$A$5001,I$3,BD!$B$3:$B$5001,$A$5,BD!$AB$3:$AB$5001,"<>")=0,"",SUMIFS(BD!$AB$3:$AB$5001,BD!$A$3:$A$5001,I$3,BD!$B$3:$B$5001,$A$5))) | J18: =IF(J$3="","",IF(COUNTIFS(BD!$A$3:$A$5001,J$3,BD!$B$3:$B$5001,$A$5,BD!$AB$3:$AB$5001,"<>")=0,"",SUMIFS(BD!$AB$3:$AB$5001,BD!$A$3:$A$5001,J$3,BD!$B$3:$B$5001,$A$5))) | K18: =IF(K$3="","",IF(COUNTIFS(BD!$A$3:$A$5001,K$3,BD!$B$3:$B$5001,$A$5,BD!$AB$3:$AB$5001,"<>")=0,"",SUMIFS(BD!$AB$3:$AB$5001,BD!$A$3:$A$5001,K$3,BD!$B$3:$B$5001,$A$5))) | L18: =IF(L$3="","",IF(COUNTIFS(BD!$A$3:$A$5001,L$3,BD!$B$3:$B$5001,$A$5,BD!$AB$3:$AB$5001,"<>")=0,"",SUMIFS(BD!$AB$3:$AB$5001,BD!$A$3:$A$5001,L$3,BD!$B$3:$B$5001,$A$5))) | M18: =IF(M$3="","",IF(COUNTIFS(BD!$A$3:$A$5001,M$3,BD!$B$3:$B$5001,$A$5,BD!$AB$3:$AB$5001,"<>")=0,"",SUMIFS(BD!$AB$3:$AB$5001,BD!$A$3:$A$5001,M$3,BD!$B$3:$B$5001,$A$5))) | ... AJ18: =IF(AJ$3="","",IF(COUNTIFS(BD!$A$3:$A$5001,AJ$3,BD!$B$3:$B$5001,$A$5,BD!$AB$3:$AB$5001,"<>")=0,"",SUMIFS(BD!$AB$3:$AB$5001,BD!$A$3:$A$5001,AJ$3,BD!$B$3:$B$5001,$A$5))) | AK18: =IF(COUNT(F18:AJ18)=0,"",SUM(F18:AJ18))
C19: Folga | D19: =IFERROR(1/(1/INDEX(BD!$AL$50:$BF$50,MATCH($A$5,BD!$AL$22:$BF$22,0))),"") | F19: =IF(F$3="","",IF(COUNTIFS(BD!$A$3:$A$5001,F$3,BD!$B$3:$B$5001,$A$5,BD!$AC$3:$AC$5001,"<>")=0,"",SUMIFS(BD!$AC$3:$AC$5001,BD!$A$3:$A$5001,F$3,BD!$B$3:$B$5001,$A$5))) | G19: =IF(G$3="","",IF(COUNTIFS(BD!$A$3:$A$5001,G$3,BD!$B$3:$B$5001,$A$5,BD!$AC$3:$AC$5001,"<>")=0,"",SUMIFS(BD!$AC$3:$AC$5001,BD!$A$3:$A$5001,G$3,BD!$B$3:$B$5001,$A$5))) | H19: =IF(H$3="","",IF(COUNTIFS(BD!$A$3:$A$5001,H$3,BD!$B$3:$B$5001,$A$5,BD!$AC$3:$AC$5001,"<>")=0,"",SUMIFS(BD!$AC$3:$AC$5001,BD!$A$3:$A$5001,H$3,BD!$B$3:$B$5001,$A$5))) | I19: =IF(I$3="","",IF(COUNTIFS(BD!$A$3:$A$5001,I$3,BD!$B$3:$B$5001,$A$5,BD!$AC$3:$AC$5001,"<>")=0,"",SUMIFS(BD!$AC$3:$AC$5001,BD!$A$3:$A$5001,I$3,BD!$B$3:$B$5001,$A$5))) | J19: =IF(J$3="","",IF(COUNTIFS(BD!$A$3:$A$5001,J$3,BD!$B$3:$B$5001,$A$5,BD!$AC$3:$AC$5001,"<>")=0,"",SUMIFS(BD!$AC$3:$AC$5001,BD!$A$3:$A$5001,J$3,BD!$B$3:$B$5001,$A$5))) | K19: =IF(K$3="","",IF(COUNTIFS(BD!$A$3:$A$5001,K$3,BD!$B$3:$B$5001,$A$5,BD!$AC$3:$AC$5001,"<>")=0,"",SUMIFS(BD!$AC$3:$AC$5001,BD!$A$3:$A$5001,K$3,BD!$B$3:$B$5001,$A$5))) | L19: =IF(L$3="","",IF(COUNTIFS(BD!$A$3:$A$5001,L$3,BD!$B$3:$B$5001,$A$5,BD!$AC$3:$AC$5001,"<>")=0,"",SUMIFS(BD!$AC$3:$AC$5001,BD!$A$3:$A$5001,L$3,BD!$B$3:$B$5001,$A$5))) | M19: =IF(M$3="","",IF(COUNTIFS(BD!$A$3:$A$5001,M$3,BD!$B$3:$B$5001,$A$5,BD!$AC$3:$AC$5001,"<>")=0,"",SUMIFS(BD!$AC$3:$AC$5001,BD!$A$3:$A$5001,M$3,BD!$B$3:$B$5001,$A$5))) | ... AJ19: =IF(AJ$3="","",IF(COUNTIFS(BD!$A$3:$A$5001,AJ$3,BD!$B$3:$B$5001,$A$5,BD!$AC$3:$AC$5001,"<>")=0,"",SUMIFS(BD!$AC$3:$AC$5001,BD!$A$3:$A$5001,AJ$3,BD!$B$3:$B$5001,$A$5))) | AK19: =IF(COUNT(F19:AJ19)=0,"",SUM(F19:AJ19))
C20: Férias | D20: =IFERROR(1/(1/INDEX(BD!$AL$51:$BF$51,MATCH($A$5,BD!$AL$22:$BF$22,0))),"") | F20: =IF(F$3="","",IF(COUNTIFS(BD!$A$3:$A$5001,F$3,BD!$B$3:$B$5001,$A$5,BD!$AD$3:$AD$5001,"<>")=0,"",SUMIFS(BD!$AD$3:$AD$5001,BD!$A$3:$A$5001,F$3,BD!$B$3:$B$5001,$A$5))) | G20: =IF(G$3="","",IF(COUNTIFS(BD!$A$3:$A$5001,G$3,BD!$B$3:$B$5001,$A$5,BD!$AD$3:$AD$5001,"<>")=0,"",SUMIFS(BD!$AD$3:$AD$5001,BD!$A$3:$A$5001,G$3,BD!$B$3:$B$5001,$A$5))) | H20: =IF(H$3="","",IF(COUNTIFS(BD!$A$3:$A$5001,H$3,BD!$B$3:$B$5001,$A$5,BD!$AD$3:$AD$5001,"<>")=0,"",SUMIFS(BD!$AD$3:$AD$5001,BD!$A$3:$A$5001,H$3,BD!$B$3:$B$5001,$A$5))) | I20: =IF(I$3="","",IF(COUNTIFS(BD!$A$3:$A$5001,I$3,BD!$B$3:$B$5001,$A$5,BD!$AD$3:$AD$5001,"<>")=0,"",SUMIFS(BD!$AD$3:$AD$5001,BD!$A$3:$A$5001,I$3,BD!$B$3:$B$5001,$A$5))) | J20: =IF(J$3="","",IF(COUNTIFS(BD!$A$3:$A$5001,J$3,BD!$B$3:$B$5001,$A$5,BD!$AD$3:$AD$5001,"<>")=0,"",SUMIFS(BD!$AD$3:$AD$5001,BD!$A$3:$A$5001,J$3,BD!$B$3:$B$5001,$A$5))) | K20: =IF(K$3="","",IF(COUNTIFS(BD!$A$3:$A$5001,K$3,BD!$B$3:$B$5001,$A$5,BD!$AD$3:$AD$5001,"<>")=0,"",SUMIFS(BD!$AD$3:$AD$5001,BD!$A$3:$A$5001,K$3,BD!$B$3:$B$5001,$A$5))) | L20: =IF(L$3="","",IF(COUNTIFS(BD!$A$3:$A$5001,L$3,BD!$B$3:$B$5001,$A$5,BD!$AD$3:$AD$5001,"<>")=0,"",SUMIFS(BD!$AD$3:$AD$5001,BD!$A$3:$A$5001,L$3,BD!$B$3:$B$5001,$A$5))) | M20: =IF(M$3="","",IF(COUNTIFS(BD!$A$3:$A$5001,M$3,BD!$B$3:$B$5001,$A$5,BD!$AD$3:$AD$5001,"<>")=0,"",SUMIFS(BD!$AD$3:$AD$5001,BD!$A$3:$A$5001,M$3,BD!$B$3:$B$5001,$A$5))) | ... AJ20: =IF(AJ$3="","",IF(COUNTIFS(BD!$A$3:$A$5001,AJ$3,BD!$B$3:$B$5001,$A$5,BD!$AD$3:$AD$5001,"<>")=0,"",SUMIFS(BD!$AD$3:$AD$5001,BD!$A$3:$A$5001,AJ$3,BD!$B$3:$B$5001,$A$5))) | AK20: =IF(COUNT(F20:AJ20)=0,"",SUM(F20:AJ20))
C21: Desligamento | D21: =IFERROR(1/(1/INDEX(BD!$AL$52:$BF$52,MATCH($A$5,BD!$AL$22:$BF$22,0))),"") | F21: =IF(F$3="","",IF(COUNTIFS(BD!$A$3:$A$5001,F$3,BD!$B$3:$B$5001,$A$5,BD!$AE$3:$AE$5001,"<>")=0,"",SUMIFS(BD!$AE$3:$AE$5001,BD!$A$3:$A$5001,F$3,BD!$B$3:$B$5001,$A$5))) | G21: =IF(G$3="","",IF(COUNTIFS(BD!$A$3:$A$5001,G$3,BD!$B$3:$B$5001,$A$5,BD!$AE$3:$AE$5001,"<>")=0,"",SUMIFS(BD!$AE$3:$AE$5001,BD!$A$3:$A$5001,G$3,BD!$B$3:$B$5001,$A$5))) | H21: =IF(H$3="","",IF(COUNTIFS(BD!$A$3:$A$5001,H$3,BD!$B$3:$B$5001,$A$5,BD!$AE$3:$AE$5001,"<>")=0,"",SUMIFS(BD!$AE$3:$AE$5001,BD!$A$3:$A$5001,H$3,BD!$B$3:$B$5001,$A$5))) | I21: =IF(I$3="","",IF(COUNTIFS(BD!$A$3:$A$5001,I$3,BD!$B$3:$B$5001,$A$5,BD!$AE$3:$AE$5001,"<>")=0,"",SUMIFS(BD!$AE$3:$AE$5001,BD!$A$3:$A$5001,I$3,BD!$B$3:$B$5001,$A$5))) | J21: =IF(J$3="","",IF(COUNTIFS(BD!$A$3:$A$5001,J$3,BD!$B$3:$B$5001,$A$5,BD!$AE$3:$AE$5001,"<>")=0,"",SUMIFS(BD!$AE$3:$AE$5001,BD!$A$3:$A$5001,J$3,BD!$B$3:$B$5001,$A$5))) | K21: =IF(K$3="","",IF(COUNTIFS(BD!$A$3:$A$5001,K$3,BD!$B$3:$B$5001,$A$5,BD!$AE$3:$AE$5001,"<>")=0,"",SUMIFS(BD!$AE$3:$AE$5001,BD!$A$3:$A$5001,K$3,BD!$B$3:$B$5001,$A$5))) | L21: =IF(L$3="","",IF(COUNTIFS(BD!$A$3:$A$5001,L$3,BD!$B$3:$B$5001,$A$5,BD!$AE$3:$AE$5001,"<>")=0,"",SUMIFS(BD!$AE$3:$AE$5001,BD!$A$3:$A$5001,L$3,BD!$B$3:$B$5001,$A$5))) | M21: =IF(M$3="","",IF(COUNTIFS(BD!$A$3:$A$5001,M$3,BD!$B$3:$B$5001,$A$5,BD!$AE$3:$AE$5001,"<>")=0,"",SUMIFS(BD!$AE$3:$AE$5001,BD!$A$3:$A$5001,M$3,BD!$B$3:$B$5001,$A$5))) | ... AJ21: =IF(AJ$3="","",IF(COUNTIFS(BD!$A$3:$A$5001,AJ$3,BD!$B$3:$B$5001,$A$5,BD!$AE$3:$AE$5001,"<>")=0,"",SUMIFS(BD!$AE$3:$AE$5001,BD!$A$3:$A$5001,AJ$3,BD!$B$3:$B$5001,$A$5))) | AK21: =IF(COUNT(F21:AJ21)=0,"",SUM(F21:AJ21))
C22: Desvios Comportamentais | D22: =IFERROR(1/(1/INDEX(BD!$AL$53:$BF$53,MATCH($A$5,BD!$AL$22:$BF$22,0))),"") | F22: =IF(F$3="","",IF(COUNTIFS(BD!$A$3:$A$5001,F$3,BD!$B$3:$B$5001,$A$5,BD!$AF$3:$AF$5001,"<>")=0,"",SUMIFS(BD!$AF$3:$AF$5001,BD!$A$3:$A$5001,F$3,BD!$B$3:$B$5001,$A$5))) | G22: =IF(G$3="","",IF(COUNTIFS(BD!$A$3:$A$5001,G$3,BD!$B$3:$B$5001,$A$5,BD!$AF$3:$AF$5001,"<>")=0,"",SUMIFS(BD!$AF$3:$AF$5001,BD!$A$3:$A$5001,G$3,BD!$B$3:$B$5001,$A$5))) | H22: =IF(H$3="","",IF(COUNTIFS(BD!$A$3:$A$5001,H$3,BD!$B$3:$B$5001,$A$5,BD!$AF$3:$AF$5001,"<>")=0,"",SUMIFS(BD!$AF$3:$AF$5001,BD!$A$3:$A$5001,H$3,BD!$B$3:$B$5001,$A$5))) | I22: =IF(I$3="","",IF(COUNTIFS(BD!$A$3:$A$5001,I$3,BD!$B$3:$B$5001,$A$5,BD!$AF$3:$AF$5001,"<>")=0,"",SUMIFS(BD!$AF$3:$AF$5001,BD!$A$3:$A$5001,I$3,BD!$B$3:$B$5001,$A$5))) | J22: =IF(J$3="","",IF(COUNTIFS(BD!$A$3:$A$5001,J$3,BD!$B$3:$B$5001,$A$5,BD!$AF$3:$AF$5001,"<>")=0,"",SUMIFS(BD!$AF$3:$AF$5001,BD!$A$3:$A$5001,J$3,BD!$B$3:$B$5001,$A$5))) | K22: =IF(K$3="","",IF(COUNTIFS(BD!$A$3:$A$5001,K$3,BD!$B$3:$B$5001,$A$5,BD!$AF$3:$AF$5001,"<>")=0,"",SUMIFS(BD!$AF$3:$AF$5001,BD!$A$3:$A$5001,K$3,BD!$B$3:$B$5001,$A$5))) | L22: =IF(L$3="","",IF(COUNTIFS(BD!$A$3:$A$5001,L$3,BD!$B$3:$B$5001,$A$5,BD!$AF$3:$AF$5001,"<>")=0,"",SUMIFS(BD!$AF$3:$AF$5001,BD!$A$3:$A$5001,L$3,BD!$B$3:$B$5001,$A$5))) | M22: =IF(M$3="","",IF(COUNTIFS(BD!$A$3:$A$5001,M$3,BD!$B$3:$B$5001,$A$5,BD!$AF$3:$AF$5001,"<>")=0,"",SUMIFS(BD!$AF$3:$AF$5001,BD!$A$3:$A$5001,M$3,BD!$B$3:$B$5001,$A$5))) | ... AJ22: =IF(AJ$3="","",IF(COUNTIFS(BD!$A$3:$A$5001,AJ$3,BD!$B$3:$B$5001,$A$5,BD!$AF$3:$AF$5001,"<>")=0,"",SUMIFS(BD!$AF$3:$AF$5001,BD!$A$3:$A$5001,AJ$3,BD!$B$3:$B$5001,$A$5))) | AK22: =IF(COUNT(F22:AJ22)=0,"",SUM(F22:AJ22))
C23: Acidentes CAF | D23: =IFERROR(1/(1/INDEX(BD!$AL$54:$BF$54,MATCH($A$5,BD!$AL$22:$BF$22,0))),"") | F23: =IF(F$3="","",IF(COUNTIFS(BD!$A$3:$A$5001,F$3,BD!$B$3:$B$5001,$A$5,BD!$AG$3:$AG$5001,"<>")=0,"",SUMIFS(BD!$AG$3:$AG$5001,BD!$A$3:$A$5001,F$3,BD!$B$3:$B$5001,$A$5))) | G23: =IF(G$3="","",IF(COUNTIFS(BD!$A$3:$A$5001,G$3,BD!$B$3:$B$5001,$A$5,BD!$AG$3:$AG$5001,"<>")=0,"",SUMIFS(BD!$AG$3:$AG$5001,BD!$A$3:$A$5001,G$3,BD!$B$3:$B$5001,$A$5))) | H23: =IF(H$3="","",IF(COUNTIFS(BD!$A$3:$A$5001,H$3,BD!$B$3:$B$5001,$A$5,BD!$AG$3:$AG$5001,"<>")=0,"",SUMIFS(BD!$AG$3:$AG$5001,BD!$A$3:$A$5001,H$3,BD!$B$3:$B$5001,$A$5))) | I23: =IF(I$3="","",IF(COUNTIFS(BD!$A$3:$A$5001,I$3,BD!$B$3:$B$5001,$A$5,BD!$AG$3:$AG$5001,"<>")=0,"",SUMIFS(BD!$AG$3:$AG$5001,BD!$A$3:$A$5001,I$3,BD!$B$3:$B$5001,$A$5))) | J23: =IF(J$3="","",IF(COUNTIFS(BD!$A$3:$A$5001,J$3,BD!$B$3:$B$5001,$A$5,BD!$AG$3:$AG$5001,"<>")=0,"",SUMIFS(BD!$AG$3:$AG$5001,BD!$A$3:$A$5001,J$3,BD!$B$3:$B$5001,$A$5))) | K23: =IF(K$3="","",IF(COUNTIFS(BD!$A$3:$A$5001,K$3,BD!$B$3:$B$5001,$A$5,BD!$AG$3:$AG$5001,"<>")=0,"",SUMIFS(BD!$AG$3:$AG$5001,BD!$A$3:$A$5001,K$3,BD!$B$3:$B$5001,$A$5))) | L23: =IF(L$3="","",IF(COUNTIFS(BD!$A$3:$A$5001,L$3,BD!$B$3:$B$5001,$A$5,BD!$AG$3:$AG$5001,"<>")=0,"",SUMIFS(BD!$AG$3:$AG$5001,BD!$A$3:$A$5001,L$3,BD!$B$3:$B$5001,$A$5))) | M23: =IF(M$3="","",IF(COUNTIFS(BD!$A$3:$A$5001,M$3,BD!$B$3:$B$5001,$A$5,BD!$AG$3:$AG$5001,"<>")=0,"",SUMIFS(BD!$AG$3:$AG$5001,BD!$A$3:$A$5001,M$3,BD!$B$3:$B$5001,$A$5))) | ... AJ23: =IF(AJ$3="","",IF(COUNTIFS(BD!$A$3:$A$5001,AJ$3,BD!$B$3:$B$5001,$A$5,BD!$AG$3:$AG$5001,"<>")=0,"",SUMIFS(BD!$AG$3:$AG$5001,BD!$A$3:$A$5001,AJ$3,BD!$B$3:$B$5001,$A$5))) | AK23: =IF(COUNT(F23:AJ23)=0,"",SUM(F23:AJ23))
C24: Acidentes SAF | D24: =IFERROR(1/(1/INDEX(BD!$AL$55:$BF$55,MATCH($A$5,BD!$AL$22:$BF$22,0))),"") | F24: =IF(F$3="","",IF(COUNTIFS(BD!$A$3:$A$5001,F$3,BD!$B$3:$B$5001,$A$5,BD!$AH$3:$AH$5001,"<>")=0,"",SUMIFS(BD!$AH$3:$AH$5001,BD!$A$3:$A$5001,F$3,BD!$B$3:$B$5001,$A$5))) | G24: =IF(G$3="","",IF(COUNTIFS(BD!$A$3:$A$5001,G$3,BD!$B$3:$B$5001,$A$5,BD!$AH$3:$AH$5001,"<>")=0,"",SUMIFS(BD!$AH$3:$AH$5001,BD!$A$3:$A$5001,G$3,BD!$B$3:$B$5001,$A$5))) | H24: =IF(H$3="","",IF(COUNTIFS(BD!$A$3:$A$5001,H$3,BD!$B$3:$B$5001,$A$5,BD!$AH$3:$AH$5001,"<>")=0,"",SUMIFS(BD!$AH$3:$AH$5001,BD!$A$3:$A$5001,H$3,BD!$B$3:$B$5001,$A$5))) | I24: =IF(I$3="","",IF(COUNTIFS(BD!$A$3:$A$5001,I$3,BD!$B$3:$B$5001,$A$5,BD!$AH$3:$AH$5001,"<>")=0,"",SUMIFS(BD!$AH$3:$AH$5001,BD!$A$3:$A$5001,I$3,BD!$B$3:$B$5001,$A$5))) | J24: =IF(J$3="","",IF(COUNTIFS(BD!$A$3:$A$5001,J$3,BD!$B$3:$B$5001,$A$5,BD!$AH$3:$AH$5001,"<>")=0,"",SUMIFS(BD!$AH$3:$AH$5001,BD!$A$3:$A$5001,J$3,BD!$B$3:$B$5001,$A$5))) | K24: =IF(K$3="","",IF(COUNTIFS(BD!$A$3:$A$5001,K$3,BD!$B$3:$B$5001,$A$5,BD!$AH$3:$AH$5001,"<>")=0,"",SUMIFS(BD!$AH$3:$AH$5001,BD!$A$3:$A$5001,K$3,BD!$B$3:$B$5001,$A$5))) | L24: =IF(L$3="","",IF(COUNTIFS(BD!$A$3:$A$5001,L$3,BD!$B$3:$B$5001,$A$5,BD!$AH$3:$AH$5001,"<>")=0,"",SUMIFS(BD!$AH$3:$AH$5001,BD!$A$3:$A$5001,L$3,BD!$B$3:$B$5001,$A$5))) | M24: =IF(M$3="","",IF(COUNTIFS(BD!$A$3:$A$5001,M$3,BD!$B$3:$B$5001,$A$5,BD!$AH$3:$AH$5001,"<>")=0,"",SUMIFS(BD!$AH$3:$AH$5001,BD!$A$3:$A$5001,M$3,BD!$B$3:$B$5001,$A$5))) | ... AJ24: =IF(AJ$3="","",IF(COUNTIFS(BD!$A$3:$A$5001,AJ$3,BD!$B$3:$B$5001,$A$5,BD!$AH$3:$AH$5001,"<>")=0,"",SUMIFS(BD!$AH$3:$AH$5001,BD!$A$3:$A$5001,AJ$3,BD!$B$3:$B$5001,$A$5))) | AK24: =IF(COUNT(F24:AJ24)=0,"",SUM(F24:AJ24))
A26: Basf | B26: IN | C26: Veículos Recebidos | D26: =IFERROR(1/(1/INDEX(BD!$AL$23:$BF$23,MATCH($A$26,BD!$AL$22:$BF$22,0))),"") | F26: =IF(F$3="","",IF(COUNTIFS(BD!$A$3:$A$5001,F$3,BD!$B$3:$B$5001,$A$26,BD!$C$3:$C$5001,"<>")=0,"",SUMIFS(BD!$C$3:$C$5001,BD!$A$3:$A$5001,F$3,BD!$B$3:$B$5001,$A$26))) | G26: =IF(G$3="","",IF(COUNTIFS(BD!$A$3:$A$5001,G$3,BD!$B$3:$B$5001,$A$26,BD!$C$3:$C$5001,"<>")=0,"",SUMIFS(BD!$C$3:$C$5001,BD!$A$3:$A$5001,G$3,BD!$B$3:$B$5001,$A$26))) | H26: =IF(H$3="","",IF(COUNTIFS(BD!$A$3:$A$5001,H$3,BD!$B$3:$B$5001,$A$26,BD!$C$3:$C$5001,"<>")=0,"",SUMIFS(BD!$C$3:$C$5001,BD!$A$3:$A$5001,H$3,BD!$B$3:$B$5001,$A$26))) | I26: =IF(I$3="","",IF(COUNTIFS(BD!$A$3:$A$5001,I$3,BD!$B$3:$B$5001,$A$26,BD!$C$3:$C$5001,"<>")=0,"",SUMIFS(BD!$C$3:$C$5001,BD!$A$3:$A$5001,I$3,BD!$B$3:$B$5001,$A$26))) | J26: =IF(J$3="","",IF(COUNTIFS(BD!$A$3:$A$5001,J$3,BD!$B$3:$B$5001,$A$26,BD!$C$3:$C$5001,"<>")=0,"",SUMIFS(BD!$C$3:$C$5001,BD!$A$3:$A$5001,J$3,BD!$B$3:$B$5001,$A$26))) | K26: =IF(K$3="","",IF(COUNTIFS(BD!$A$3:$A$5001,K$3,BD!$B$3:$B$5001,$A$26,BD!$C$3:$C$5001,"<>")=0,"",SUMIFS(BD!$C$3:$C$5001,BD!$A$3:$A$5001,K$3,BD!$B$3:$B$5001,$A$26))) | L26: =IF(L$3="","",IF(COUNTIFS(BD!$A$3:$A$5001,L$3,BD!$B$3:$B$5001,$A$26,BD!$C$3:$C$5001,"<>")=0,"",SUMIFS(BD!$C$3:$C$5001,BD!$A$3:$A$5001,L$3,BD!$B$3:$B$5001,$A$26))) | M26: =IF(M$3="","",IF(COUNTIFS(BD!$A$3:$A$5001,M$3,BD!$B$3:$B$5001,$A$26,BD!$C$3:$C$5001,"<>")=0,"",SUMIFS(BD!$C$3:$C$5001,BD!$A$3:$A$5001,M$3,BD!$B$3:$B$5001,$A$26))) | ... AJ26: =IF(AJ$3="","",IF(COUNTIFS(BD!$A$3:$A$5001,AJ$3,BD!$B$3:$B$5001,$A$26,BD!$C$3:$C$5001,"<>")=0,"",SUMIFS(BD!$C$3:$C$5001,BD!$A$3:$A$5001,AJ$3,BD!$B$3:$B$5001,$A$26))) | AK26: =IF(COUNT(F26:AJ26)=0,"",SUM(F26:AJ26))
C27: Pallets Movimentados | D27: =IFERROR(1/(1/INDEX(BD!$AL$24:$BF$24,MATCH($A$26,BD!$AL$22:$BF$22,0))),"") | F27: =IF(F$3="","",IF(COUNTIFS(BD!$A$3:$A$5001,F$3,BD!$B$3:$B$5001,$A$26,BD!$D$3:$D$5001,"<>")=0,"",SUMIFS(BD!$D$3:$D$5001,BD!$A$3:$A$5001,F$3,BD!$B$3:$B$5001,$A$26))) | G27: =IF(G$3="","",IF(COUNTIFS(BD!$A$3:$A$5001,G$3,BD!$B$3:$B$5001,$A$26,BD!$D$3:$D$5001,"<>")=0,"",SUMIFS(BD!$D$3:$D$5001,BD!$A$3:$A$5001,G$3,BD!$B$3:$B$5001,$A$26))) | H27: =IF(H$3="","",IF(COUNTIFS(BD!$A$3:$A$5001,H$3,BD!$B$3:$B$5001,$A$26,BD!$D$3:$D$5001,"<>")=0,"",SUMIFS(BD!$D$3:$D$5001,BD!$A$3:$A$5001,H$3,BD!$B$3:$B$5001,$A$26))) | I27: =IF(I$3="","",IF(COUNTIFS(BD!$A$3:$A$5001,I$3,BD!$B$3:$B$5001,$A$26,BD!$D$3:$D$5001,"<>")=0,"",SUMIFS(BD!$D$3:$D$5001,BD!$A$3:$A$5001,I$3,BD!$B$3:$B$5001,$A$26))) | J27: =IF(J$3="","",IF(COUNTIFS(BD!$A$3:$A$5001,J$3,BD!$B$3:$B$5001,$A$26,BD!$D$3:$D$5001,"<>")=0,"",SUMIFS(BD!$D$3:$D$5001,BD!$A$3:$A$5001,J$3,BD!$B$3:$B$5001,$A$26))) | K27: =IF(K$3="","",IF(COUNTIFS(BD!$A$3:$A$5001,K$3,BD!$B$3:$B$5001,$A$26,BD!$D$3:$D$5001,"<>")=0,"",SUMIFS(BD!$D$3:$D$5001,BD!$A$3:$A$5001,K$3,BD!$B$3:$B$5001,$A$26))) | L27: =IF(L$3="","",IF(COUNTIFS(BD!$A$3:$A$5001,L$3,BD!$B$3:$B$5001,$A$26,BD!$D$3:$D$5001,"<>")=0,"",SUMIFS(BD!$D$3:$D$5001,BD!$A$3:$A$5001,L$3,BD!$B$3:$B$5001,$A$26))) | M27: =IF(M$3="","",IF(COUNTIFS(BD!$A$3:$A$5001,M$3,BD!$B$3:$B$5001,$A$26,BD!$D$3:$D$5001,"<>")=0,"",SUMIFS(BD!$D$3:$D$5001,BD!$A$3:$A$5001,M$3,BD!$B$3:$B$5001,$A$26))) | ... AJ27: =IF(AJ$3="","",IF(COUNTIFS(BD!$A$3:$A$5001,AJ$3,BD!$B$3:$B$5001,$A$26,BD!$D$3:$D$5001,"<>")=0,"",SUMIFS(BD!$D$3:$D$5001,BD!$A$3:$A$5001,AJ$3,BD!$B$3:$B$5001,$A$26))) | AK27: =IF(COUNT(F27:AJ27)=0,"",SUM(F27:AJ27))
C28: Toneladas Movimentadas | D28: =IFERROR(1/(1/INDEX(BD!$AL$25:$BF$25,MATCH($A$26,BD!$AL$22:$BF$22,0))),"") | F28: =IF(F$3="","",IF(COUNTIFS(BD!$A$3:$A$5001,F$3,BD!$B$3:$B$5001,$A$26,BD!$E$3:$E$5001,"<>")=0,"",SUMIFS(BD!$E$3:$E$5001,BD!$A$3:$A$5001,F$3,BD!$B$3:$B$5001,$A$26))) | G28: =IF(G$3="","",IF(COUNTIFS(BD!$A$3:$A$5001,G$3,BD!$B$3:$B$5001,$A$26,BD!$E$3:$E$5001,"<>")=0,"",SUMIFS(BD!$E$3:$E$5001,BD!$A$3:$A$5001,G$3,BD!$B$3:$B$5001,$A$26))) | H28: =IF(H$3="","",IF(COUNTIFS(BD!$A$3:$A$5001,H$3,BD!$B$3:$B$5001,$A$26,BD!$E$3:$E$5001,"<>")=0,"",SUMIFS(BD!$E$3:$E$5001,BD!$A$3:$A$5001,H$3,BD!$B$3:$B$5001,$A$26))) | I28: =IF(I$3="","",IF(COUNTIFS(BD!$A$3:$A$5001,I$3,BD!$B$3:$B$5001,$A$26,BD!$E$3:$E$5001,"<>")=0,"",SUMIFS(BD!$E$3:$E$5001,BD!$A$3:$A$5001,I$3,BD!$B$3:$B$5001,$A$26))) | J28: =IF(J$3="","",IF(COUNTIFS(BD!$A$3:$A$5001,J$3,BD!$B$3:$B$5001,$A$26,BD!$E$3:$E$5001,"<>")=0,"",SUMIFS(BD!$E$3:$E$5001,BD!$A$3:$A$5001,J$3,BD!$B$3:$B$5001,$A$26))) | K28: =IF(K$3="","",IF(COUNTIFS(BD!$A$3:$A$5001,K$3,BD!$B$3:$B$5001,$A$26,BD!$E$3:$E$5001,"<>")=0,"",SUMIFS(BD!$E$3:$E$5001,BD!$A$3:$A$5001,K$3,BD!$B$3:$B$5001,$A$26))) | L28: =IF(L$3="","",IF(COUNTIFS(BD!$A$3:$A$5001,L$3,BD!$B$3:$B$5001,$A$26,BD!$E$3:$E$5001,"<>")=0,"",SUMIFS(BD!$E$3:$E$5001,BD!$A$3:$A$5001,L$3,BD!$B$3:$B$5001,$A$26))) | M28: =IF(M$3="","",IF(COUNTIFS(BD!$A$3:$A$5001,M$3,BD!$B$3:$B$5001,$A$26,BD!$E$3:$E$5001,"<>")=0,"",SUMIFS(BD!$E$3:$E$5001,BD!$A$3:$A$5001,M$3,BD!$B$3:$B$5001,$A$26))) | ... AJ28: =IF(AJ$3="","",IF(COUNTIFS(BD!$A$3:$A$5001,AJ$3,BD!$B$3:$B$5001,$A$26,BD!$E$3:$E$5001,"<>")=0,"",SUMIFS(BD!$E$3:$E$5001,BD!$A$3:$A$5001,AJ$3,BD!$B$3:$B$5001,$A$26))) | AK28: =IF(COUNT(F28:AJ28)=0,"",SUM(F28:AJ28))
B29: OUT | C29: Veículos Expedidos | D29: =IFERROR(1/(1/INDEX(BD!$AL$32:$BF$32,MATCH($A$26,BD!$AL$22:$BF$22,0))),"") | F29: =IF(F$3="","",IF(COUNTIFS(BD!$A$3:$A$5001,F$3,BD!$B$3:$B$5001,$A$26,BD!$L$3:$L$5001,"<>")=0,"",SUMIFS(BD!$L$3:$L$5001,BD!$A$3:$A$5001,F$3,BD!$B$3:$B$5001,$A$26))) | G29: =IF(G$3="","",IF(COUNTIFS(BD!$A$3:$A$5001,G$3,BD!$B$3:$B$5001,$A$26,BD!$L$3:$L$5001,"<>")=0,"",SUMIFS(BD!$L$3:$L$5001,BD!$A$3:$A$5001,G$3,BD!$B$3:$B$5001,$A$26))) | H29: =IF(H$3="","",IF(COUNTIFS(BD!$A$3:$A$5001,H$3,BD!$B$3:$B$5001,$A$26,BD!$L$3:$L$5001,"<>")=0,"",SUMIFS(BD!$L$3:$L$5001,BD!$A$3:$A$5001,H$3,BD!$B$3:$B$5001,$A$26))) | I29: =IF(I$3="","",IF(COUNTIFS(BD!$A$3:$A$5001,I$3,BD!$B$3:$B$5001,$A$26,BD!$L$3:$L$5001,"<>")=0,"",SUMIFS(BD!$L$3:$L$5001,BD!$A$3:$A$5001,I$3,BD!$B$3:$B$5001,$A$26))) | J29: =IF(J$3="","",IF(COUNTIFS(BD!$A$3:$A$5001,J$3,BD!$B$3:$B$5001,$A$26,BD!$L$3:$L$5001,"<>")=0,"",SUMIFS(BD!$L$3:$L$5001,BD!$A$3:$A$5001,J$3,BD!$B$3:$B$5001,$A$26))) | K29: =IF(K$3="","",IF(COUNTIFS(BD!$A$3:$A$5001,K$3,BD!$B$3:$B$5001,$A$26,BD!$L$3:$L$5001,"<>")=0,"",SUMIFS(BD!$L$3:$L$5001,BD!$A$3:$A$5001,K$3,BD!$B$3:$B$5001,$A$26))) | L29: =IF(L$3="","",IF(COUNTIFS(BD!$A$3:$A$5001,L$3,BD!$B$3:$B$5001,$A$26,BD!$L$3:$L$5001,"<>")=0,"",SUMIFS(BD!$L$3:$L$5001,BD!$A$3:$A$5001,L$3,BD!$B$3:$B$5001,$A$26))) | M29: =IF(M$3="","",IF(COUNTIFS(BD!$A$3:$A$5001,M$3,BD!$B$3:$B$5001,$A$26,BD!$L$3:$L$5001,"<>")=0,"",SUMIFS(BD!$L$3:$L$5001,BD!$A$3:$A$5001,M$3,BD!$B$3:$B$5001,$A$26))) | ... AJ29: =IF(AJ$3="","",IF(COUNTIFS(BD!$A$3:$A$5001,AJ$3,BD!$B$3:$B$5001,$A$26,BD!$L$3:$L$5001,"<>")=0,"",SUMIFS(BD!$L$3:$L$5001,BD!$A$3:$A$5001,AJ$3,BD!$B$3:$B$5001,$A$26))) | AK29: =IF(COUNT(F29:AJ29)=0,"",SUM(F29:AJ29))
C30: Pallets Movimentados | D30: =IFERROR(1/(1/INDEX(BD!$AL$38:$BF$38,MATCH($A$26,BD!$AL$22:$BF$22,0))),"") | F30: =IF(F$3="","",IF(COUNTIFS(BD!$A$3:$A$5001,F$3,BD!$B$3:$B$5001,$A$26,BD!$R$3:$R$5001,"<>")=0,"",SUMIFS(BD!$R$3:$R$5001,BD!$A$3:$A$5001,F$3,BD!$B$3:$B$5001,$A$26))) | G30: =IF(G$3="","",IF(COUNTIFS(BD!$A$3:$A$5001,G$3,BD!$B$3:$B$5001,$A$26,BD!$R$3:$R$5001,"<>")=0,"",SUMIFS(BD!$R$3:$R$5001,BD!$A$3:$A$5001,G$3,BD!$B$3:$B$5001,$A$26))) | H30: =IF(H$3="","",IF(COUNTIFS(BD!$A$3:$A$5001,H$3,BD!$B$3:$B$5001,$A$26,BD!$R$3:$R$5001,"<>")=0,"",SUMIFS(BD!$R$3:$R$5001,BD!$A$3:$A$5001,H$3,BD!$B$3:$B$5001,$A$26))) | I30: =IF(I$3="","",IF(COUNTIFS(BD!$A$3:$A$5001,I$3,BD!$B$3:$B$5001,$A$26,BD!$R$3:$R$5001,"<>")=0,"",SUMIFS(BD!$R$3:$R$5001,BD!$A$3:$A$5001,I$3,BD!$B$3:$B$5001,$A$26))) | J30: =IF(J$3="","",IF(COUNTIFS(BD!$A$3:$A$5001,J$3,BD!$B$3:$B$5001,$A$26,BD!$R$3:$R$5001,"<>")=0,"",SUMIFS(BD!$R$3:$R$5001,BD!$A$3:$A$5001,J$3,BD!$B$3:$B$5001,$A$26))) | K30: =IF(K$3="","",IF(COUNTIFS(BD!$A$3:$A$5001,K$3,BD!$B$3:$B$5001,$A$26,BD!$R$3:$R$5001,"<>")=0,"",SUMIFS(BD!$R$3:$R$5001,BD!$A$3:$A$5001,K$3,BD!$B$3:$B$5001,$A$26))) | L30: =IF(L$3="","",IF(COUNTIFS(BD!$A$3:$A$5001,L$3,BD!$B$3:$B$5001,$A$26,BD!$R$3:$R$5001,"<>")=0,"",SUMIFS(BD!$R$3:$R$5001,BD!$A$3:$A$5001,L$3,BD!$B$3:$B$5001,$A$26))) | M30: =IF(M$3="","",IF(COUNTIFS(BD!$A$3:$A$5001,M$3,BD!$B$3:$B$5001,$A$26,BD!$R$3:$R$5001,"<>")=0,"",SUMIFS(BD!$R$3:$R$5001,BD!$A$3:$A$5001,M$3,BD!$B$3:$B$5001,$A$26))) | ... AJ30: =IF(AJ$3="","",IF(COUNTIFS(BD!$A$3:$A$5001,AJ$3,BD!$B$3:$B$5001,$A$26,BD!$R$3:$R$5001,"<>")=0,"",SUMIFS(BD!$R$3:$R$5001,BD!$A$3:$A$5001,AJ$3,BD!$B$3:$B$5001,$A$26))) | AK30: =IF(COUNT(F30:AJ30)=0,"",SUM(F30:AJ30))
C31: Toneladas Movimentadas | D31: =IFERROR(1/(1/INDEX(BD!$AL$39:$BF$39,MATCH($A$26,BD!$AL$22:$BF$22,0))),"") | F31: =IF(F$3="","",IF(COUNTIFS(BD!$A$3:$A$5001,F$3,BD!$B$3:$B$5001,$A$26,BD!$S$3:$S$5001,"<>")=0,"",SUMIFS(BD!$S$3:$S$5001,BD!$A$3:$A$5001,F$3,BD!$B$3:$B$5001,$A$26))) | G31: =IF(G$3="","",IF(COUNTIFS(BD!$A$3:$A$5001,G$3,BD!$B$3:$B$5001,$A$26,BD!$S$3:$S$5001,"<>")=0,"",SUMIFS(BD!$S$3:$S$5001,BD!$A$3:$A$5001,G$3,BD!$B$3:$B$5001,$A$26))) | H31: =IF(H$3="","",IF(COUNTIFS(BD!$A$3:$A$5001,H$3,BD!$B$3:$B$5001,$A$26,BD!$S$3:$S$5001,"<>")=0,"",SUMIFS(BD!$S$3:$S$5001,BD!$A$3:$A$5001,H$3,BD!$B$3:$B$5001,$A$26))) | I31: =IF(I$3="","",IF(COUNTIFS(BD!$A$3:$A$5001,I$3,BD!$B$3:$B$5001,$A$26,BD!$S$3:$S$5001,"<>")=0,"",SUMIFS(BD!$S$3:$S$5001,BD!$A$3:$A$5001,I$3,BD!$B$3:$B$5001,$A$26))) | J31: =IF(J$3="","",IF(COUNTIFS(BD!$A$3:$A$5001,J$3,BD!$B$3:$B$5001,$A$26,BD!$S$3:$S$5001,"<>")=0,"",SUMIFS(BD!$S$3:$S$5001,BD!$A$3:$A$5001,J$3,BD!$B$3:$B$5001,$A$26))) | K31: =IF(K$3="","",IF(COUNTIFS(BD!$A$3:$A$5001,K$3,BD!$B$3:$B$5001,$A$26,BD!$S$3:$S$5001,"<>")=0,"",SUMIFS(BD!$S$3:$S$5001,BD!$A$3:$A$5001,K$3,BD!$B$3:$B$5001,$A$26))) | L31: =IF(L$3="","",IF(COUNTIFS(BD!$A$3:$A$5001,L$3,BD!$B$3:$B$5001,$A$26,BD!$S$3:$S$5001,"<>")=0,"",SUMIFS(BD!$S$3:$S$5001,BD!$A$3:$A$5001,L$3,BD!$B$3:$B$5001,$A$26))) | M31: =IF(M$3="","",IF(COUNTIFS(BD!$A$3:$A$5001,M$3,BD!$B$3:$B$5001,$A$26,BD!$S$3:$S$5001,"<>")=0,"",SUMIFS(BD!$S$3:$S$5001,BD!$A$3:$A$5001,M$3,BD!$B$3:$B$5001,$A$26))) | ... AJ31: =IF(AJ$3="","",IF(COUNTIFS(BD!$A$3:$A$5001,AJ$3,BD!$B$3:$B$5001,$A$26,BD!$S$3:$S$5001,"<>")=0,"",SUMIFS(BD!$S$3:$S$5001,BD!$A$3:$A$5001,AJ$3,BD!$B$3:$B$5001,$A$26))) | AK31: =IF(COUNT(F31:AJ31)=0,"",SUM(F31:AJ31))
B32: NC | C32: Incidentes | D32: =IFERROR(1/(1/INDEX(BD!$AL$40:$BF$40,MATCH($A$26,BD!$AL$22:$BF$22,0))),"") | F32: =IF(F$3="","",IF(COUNTIFS(BD!$A$3:$A$5001,F$3,BD!$B$3:$B$5001,$A$26,BD!$T$3:$T$5001,"<>")=0,"",SUMIFS(BD!$T$3:$T$5001,BD!$A$3:$A$5001,F$3,BD!$B$3:$B$5001,$A$26))) | G32: =IF(G$3="","",IF(COUNTIFS(BD!$A$3:$A$5001,G$3,BD!$B$3:$B$5001,$A$26,BD!$T$3:$T$5001,"<>")=0,"",SUMIFS(BD!$T$3:$T$5001,BD!$A$3:$A$5001,G$3,BD!$B$3:$B$5001,$A$26))) | H32: =IF(H$3="","",IF(COUNTIFS(BD!$A$3:$A$5001,H$3,BD!$B$3:$B$5001,$A$26,BD!$T$3:$T$5001,"<>")=0,"",SUMIFS(BD!$T$3:$T$5001,BD!$A$3:$A$5001,H$3,BD!$B$3:$B$5001,$A$26))) | I32: =IF(I$3="","",IF(COUNTIFS(BD!$A$3:$A$5001,I$3,BD!$B$3:$B$5001,$A$26,BD!$T$3:$T$5001,"<>")=0,"",SUMIFS(BD!$T$3:$T$5001,BD!$A$3:$A$5001,I$3,BD!$B$3:$B$5001,$A$26))) | J32: =IF(J$3="","",IF(COUNTIFS(BD!$A$3:$A$5001,J$3,BD!$B$3:$B$5001,$A$26,BD!$T$3:$T$5001,"<>")=0,"",SUMIFS(BD!$T$3:$T$5001,BD!$A$3:$A$5001,J$3,BD!$B$3:$B$5001,$A$26))) | K32: =IF(K$3="","",IF(COUNTIFS(BD!$A$3:$A$5001,K$3,BD!$B$3:$B$5001,$A$26,BD!$T$3:$T$5001,"<>")=0,"",SUMIFS(BD!$T$3:$T$5001,BD!$A$3:$A$5001,K$3,BD!$B$3:$B$5001,$A$26))) | L32: =IF(L$3="","",IF(COUNTIFS(BD!$A$3:$A$5001,L$3,BD!$B$3:$B$5001,$A$26,BD!$T$3:$T$5001,"<>")=0,"",SUMIFS(BD!$T$3:$T$5001,BD!$A$3:$A$5001,L$3,BD!$B$3:$B$5001,$A$26))) | M32: =IF(M$3="","",IF(COUNTIFS(BD!$A$3:$A$5001,M$3,BD!$B$3:$B$5001,$A$26,BD!$T$3:$T$5001,"<>")=0,"",SUMIFS(BD!$T$3:$T$5001,BD!$A$3:$A$5001,M$3,BD!$B$3:$B$5001,$A$26))) | ... AJ32: =IF(AJ$3="","",IF(COUNTIFS(BD!$A$3:$A$5001,AJ$3,BD!$B$3:$B$5001,$A$26,BD!$T$3:$T$5001,"<>")=0,"",SUMIFS(BD!$T$3:$T$5001,BD!$A$3:$A$5001,AJ$3,BD!$B$3:$B$5001,$A$26))) | AK32: =IF(COUNT(F32:AJ32)=0,"",SUM(F32:AJ32))
C33: No show | D33: =IFERROR(1/(1/INDEX(BD!$AL$41:$BF$41,MATCH($A$26,BD!$AL$22:$BF$22,0))),"") | F33: =IF(F$3="","",IF(COUNTIFS(BD!$A$3:$A$5001,F$3,BD!$B$3:$B$5001,$A$26,BD!$U$3:$U$5001,"<>")=0,"",SUMIFS(BD!$U$3:$U$5001,BD!$A$3:$A$5001,F$3,BD!$B$3:$B$5001,$A$26))) | G33: =IF(G$3="","",IF(COUNTIFS(BD!$A$3:$A$5001,G$3,BD!$B$3:$B$5001,$A$26,BD!$U$3:$U$5001,"<>")=0,"",SUMIFS(BD!$U$3:$U$5001,BD!$A$3:$A$5001,G$3,BD!$B$3:$B$5001,$A$26))) | H33: =IF(H$3="","",IF(COUNTIFS(BD!$A$3:$A$5001,H$3,BD!$B$3:$B$5001,$A$26,BD!$U$3:$U$5001,"<>")=0,"",SUMIFS(BD!$U$3:$U$5001,BD!$A$3:$A$5001,H$3,BD!$B$3:$B$5001,$A$26))) | I33: =IF(I$3="","",IF(COUNTIFS(BD!$A$3:$A$5001,I$3,BD!$B$3:$B$5001,$A$26,BD!$U$3:$U$5001,"<>")=0,"",SUMIFS(BD!$U$3:$U$5001,BD!$A$3:$A$5001,I$3,BD!$B$3:$B$5001,$A$26))) | J33: =IF(J$3="","",IF(COUNTIFS(BD!$A$3:$A$5001,J$3,BD!$B$3:$B$5001,$A$26,BD!$U$3:$U$5001,"<>")=0,"",SUMIFS(BD!$U$3:$U$5001,BD!$A$3:$A$5001,J$3,BD!$B$3:$B$5001,$A$26))) | K33: =IF(K$3="","",IF(COUNTIFS(BD!$A$3:$A$5001,K$3,BD!$B$3:$B$5001,$A$26,BD!$U$3:$U$5001,"<>")=0,"",SUMIFS(BD!$U$3:$U$5001,BD!$A$3:$A$5001,K$3,BD!$B$3:$B$5001,$A$26))) | L33: =IF(L$3="","",IF(COUNTIFS(BD!$A$3:$A$5001,L$3,BD!$B$3:$B$5001,$A$26,BD!$U$3:$U$5001,"<>")=0,"",SUMIFS(BD!$U$3:$U$5001,BD!$A$3:$A$5001,L$3,BD!$B$3:$B$5001,$A$26))) | M33: =IF(M$3="","",IF(COUNTIFS(BD!$A$3:$A$5001,M$3,BD!$B$3:$B$5001,$A$26,BD!$U$3:$U$5001,"<>")=0,"",SUMIFS(BD!$U$3:$U$5001,BD!$A$3:$A$5001,M$3,BD!$B$3:$B$5001,$A$26))) | ... AJ33: =IF(AJ$3="","",IF(COUNTIFS(BD!$A$3:$A$5001,AJ$3,BD!$B$3:$B$5001,$A$26,BD!$U$3:$U$5001,"<>")=0,"",SUMIFS(BD!$U$3:$U$5001,BD!$A$3:$A$5001,AJ$3,BD!$B$3:$B$5001,$A$26))) | AK33: =IF(COUNT(F33:AJ33)=0,"",SUM(F33:AJ33))
C34: Backlog Intralog | D34: =IFERROR(1/(1/INDEX(BD!$AL$42:$BF$42,MATCH($A$26,BD!$AL$22:$BF$22,0))),"") | F34: =IF(F$3="","",IF(COUNTIFS(BD!$A$3:$A$5001,F$3,BD!$B$3:$B$5001,$A$26,BD!$V$3:$V$5001,"<>")=0,"",SUMIFS(BD!$V$3:$V$5001,BD!$A$3:$A$5001,F$3,BD!$B$3:$B$5001,$A$26))) | G34: =IF(G$3="","",IF(COUNTIFS(BD!$A$3:$A$5001,G$3,BD!$B$3:$B$5001,$A$26,BD!$V$3:$V$5001,"<>")=0,"",SUMIFS(BD!$V$3:$V$5001,BD!$A$3:$A$5001,G$3,BD!$B$3:$B$5001,$A$26))) | H34: =IF(H$3="","",IF(COUNTIFS(BD!$A$3:$A$5001,H$3,BD!$B$3:$B$5001,$A$26,BD!$V$3:$V$5001,"<>")=0,"",SUMIFS(BD!$V$3:$V$5001,BD!$A$3:$A$5001,H$3,BD!$B$3:$B$5001,$A$26))) | I34: =IF(I$3="","",IF(COUNTIFS(BD!$A$3:$A$5001,I$3,BD!$B$3:$B$5001,$A$26,BD!$V$3:$V$5001,"<>")=0,"",SUMIFS(BD!$V$3:$V$5001,BD!$A$3:$A$5001,I$3,BD!$B$3:$B$5001,$A$26))) | J34: =IF(J$3="","",IF(COUNTIFS(BD!$A$3:$A$5001,J$3,BD!$B$3:$B$5001,$A$26,BD!$V$3:$V$5001,"<>")=0,"",SUMIFS(BD!$V$3:$V$5001,BD!$A$3:$A$5001,J$3,BD!$B$3:$B$5001,$A$26))) | K34: =IF(K$3="","",IF(COUNTIFS(BD!$A$3:$A$5001,K$3,BD!$B$3:$B$5001,$A$26,BD!$V$3:$V$5001,"<>")=0,"",SUMIFS(BD!$V$3:$V$5001,BD!$A$3:$A$5001,K$3,BD!$B$3:$B$5001,$A$26))) | L34: =IF(L$3="","",IF(COUNTIFS(BD!$A$3:$A$5001,L$3,BD!$B$3:$B$5001,$A$26,BD!$V$3:$V$5001,"<>")=0,"",SUMIFS(BD!$V$3:$V$5001,BD!$A$3:$A$5001,L$3,BD!$B$3:$B$5001,$A$26))) | M34: =IF(M$3="","",IF(COUNTIFS(BD!$A$3:$A$5001,M$3,BD!$B$3:$B$5001,$A$26,BD!$V$3:$V$5001,"<>")=0,"",SUMIFS(BD!$V$3:$V$5001,BD!$A$3:$A$5001,M$3,BD!$B$3:$B$5001,$A$26))) | ... AJ34: =IF(AJ$3="","",IF(COUNTIFS(BD!$A$3:$A$5001,AJ$3,BD!$B$3:$B$5001,$A$26,BD!$V$3:$V$5001,"<>")=0,"",SUMIFS(BD!$V$3:$V$5001,BD!$A$3:$A$5001,AJ$3,BD!$B$3:$B$5001,$A$26))) | AK34: =IFERROR(LOOKUP(9.99E+307,F34:AJ34),"")
C35: Backlog Cliente | D35: =IFERROR(1/(1/INDEX(BD!$AL$43:$BF$43,MATCH($A$26,BD!$AL$22:$BF$22,0))),"") | F35: =IF(F$3="","",IF(COUNTIFS(BD!$A$3:$A$5001,F$3,BD!$B$3:$B$5001,$A$26,BD!$W$3:$W$5001,"<>")=0,"",SUMIFS(BD!$W$3:$W$5001,BD!$A$3:$A$5001,F$3,BD!$B$3:$B$5001,$A$26))) | G35: =IF(G$3="","",IF(COUNTIFS(BD!$A$3:$A$5001,G$3,BD!$B$3:$B$5001,$A$26,BD!$W$3:$W$5001,"<>")=0,"",SUMIFS(BD!$W$3:$W$5001,BD!$A$3:$A$5001,G$3,BD!$B$3:$B$5001,$A$26))) | H35: =IF(H$3="","",IF(COUNTIFS(BD!$A$3:$A$5001,H$3,BD!$B$3:$B$5001,$A$26,BD!$W$3:$W$5001,"<>")=0,"",SUMIFS(BD!$W$3:$W$5001,BD!$A$3:$A$5001,H$3,BD!$B$3:$B$5001,$A$26))) | I35: =IF(I$3="","",IF(COUNTIFS(BD!$A$3:$A$5001,I$3,BD!$B$3:$B$5001,$A$26,BD!$W$3:$W$5001,"<>")=0,"",SUMIFS(BD!$W$3:$W$5001,BD!$A$3:$A$5001,I$3,BD!$B$3:$B$5001,$A$26))) | J35: =IF(J$3="","",IF(COUNTIFS(BD!$A$3:$A$5001,J$3,BD!$B$3:$B$5001,$A$26,BD!$W$3:$W$5001,"<>")=0,"",SUMIFS(BD!$W$3:$W$5001,BD!$A$3:$A$5001,J$3,BD!$B$3:$B$5001,$A$26))) | K35: =IF(K$3="","",IF(COUNTIFS(BD!$A$3:$A$5001,K$3,BD!$B$3:$B$5001,$A$26,BD!$W$3:$W$5001,"<>")=0,"",SUMIFS(BD!$W$3:$W$5001,BD!$A$3:$A$5001,K$3,BD!$B$3:$B$5001,$A$26))) | L35: =IF(L$3="","",IF(COUNTIFS(BD!$A$3:$A$5001,L$3,BD!$B$3:$B$5001,$A$26,BD!$W$3:$W$5001,"<>")=0,"",SUMIFS(BD!$W$3:$W$5001,BD!$A$3:$A$5001,L$3,BD!$B$3:$B$5001,$A$26))) | M35: =IF(M$3="","",IF(COUNTIFS(BD!$A$3:$A$5001,M$3,BD!$B$3:$B$5001,$A$26,BD!$W$3:$W$5001,"<>")=0,"",SUMIFS(BD!$W$3:$W$5001,BD!$A$3:$A$5001,M$3,BD!$B$3:$B$5001,$A$26))) | ... AJ35: =IF(AJ$3="","",IF(COUNTIFS(BD!$A$3:$A$5001,AJ$3,BD!$B$3:$B$5001,$A$26,BD!$W$3:$W$5001,"<>")=0,"",SUMIFS(BD!$W$3:$W$5001,BD!$A$3:$A$5001,AJ$3,BD!$B$3:$B$5001,$A$26))) | AK35: =IFERROR(LOOKUP(9.99E+307,F35:AJ35),"")
B36: OCUPAÇÃO (P.P) | C36: Posições Disponíveis | D36: =IFERROR(1/(1/INDEX(BD!$AL$44:$BF$44,MATCH($A$26,BD!$AL$22:$BF$22,0))),"") | F36: =IF(F$3="","",IF(COUNTIFS(BD!$A$3:$A$5001,F$3,BD!$B$3:$B$5001,$A$26,BD!$X$3:$X$5001,"<>")=0,"",SUMIFS(BD!$X$3:$X$5001,BD!$A$3:$A$5001,F$3,BD!$B$3:$B$5001,$A$26))) | G36: =IF(G$3="","",IF(COUNTIFS(BD!$A$3:$A$5001,G$3,BD!$B$3:$B$5001,$A$26,BD!$X$3:$X$5001,"<>")=0,"",SUMIFS(BD!$X$3:$X$5001,BD!$A$3:$A$5001,G$3,BD!$B$3:$B$5001,$A$26))) | H36: =IF(H$3="","",IF(COUNTIFS(BD!$A$3:$A$5001,H$3,BD!$B$3:$B$5001,$A$26,BD!$X$3:$X$5001,"<>")=0,"",SUMIFS(BD!$X$3:$X$5001,BD!$A$3:$A$5001,H$3,BD!$B$3:$B$5001,$A$26))) | I36: =IF(I$3="","",IF(COUNTIFS(BD!$A$3:$A$5001,I$3,BD!$B$3:$B$5001,$A$26,BD!$X$3:$X$5001,"<>")=0,"",SUMIFS(BD!$X$3:$X$5001,BD!$A$3:$A$5001,I$3,BD!$B$3:$B$5001,$A$26))) | J36: =IF(J$3="","",IF(COUNTIFS(BD!$A$3:$A$5001,J$3,BD!$B$3:$B$5001,$A$26,BD!$X$3:$X$5001,"<>")=0,"",SUMIFS(BD!$X$3:$X$5001,BD!$A$3:$A$5001,J$3,BD!$B$3:$B$5001,$A$26))) | K36: =IF(K$3="","",IF(COUNTIFS(BD!$A$3:$A$5001,K$3,BD!$B$3:$B$5001,$A$26,BD!$X$3:$X$5001,"<>")=0,"",SUMIFS(BD!$X$3:$X$5001,BD!$A$3:$A$5001,K$3,BD!$B$3:$B$5001,$A$26))) | L36: =IF(L$3="","",IF(COUNTIFS(BD!$A$3:$A$5001,L$3,BD!$B$3:$B$5001,$A$26,BD!$X$3:$X$5001,"<>")=0,"",SUMIFS(BD!$X$3:$X$5001,BD!$A$3:$A$5001,L$3,BD!$B$3:$B$5001,$A$26))) | M36: =IF(M$3="","",IF(COUNTIFS(BD!$A$3:$A$5001,M$3,BD!$B$3:$B$5001,$A$26,BD!$X$3:$X$5001,"<>")=0,"",SUMIFS(BD!$X$3:$X$5001,BD!$A$3:$A$5001,M$3,BD!$B$3:$B$5001,$A$26))) | ... AJ36: =IF(AJ$3="","",IF(COUNTIFS(BD!$A$3:$A$5001,AJ$3,BD!$B$3:$B$5001,$A$26,BD!$X$3:$X$5001,"<>")=0,"",SUMIFS(BD!$X$3:$X$5001,BD!$A$3:$A$5001,AJ$3,BD!$B$3:$B$5001,$A$26))) | AK36: =IF(COUNT(F36:AJ36)>0,LOOKUP(9.99E+307,F36:AJ36),IFERROR(IF(INDEX(BD!$AI$3:$AI$5001,MATCH($A$26,BD!$B$3:$B$5001,0))&""="Contrato","",INDEX(BD!$AI$3:$AI$5001,MATCH($A$26,BD!$B$3:$B$5001,0))&""),""))
C37: Posições Ocupadas | D37: =IFERROR(1/(1/INDEX(BD!$AL$45:$BF$45,MATCH($A$26,BD!$AL$22:$BF$22,0))),"") | F37: =IF(F$3="","",IF(COUNTIFS(BD!$A$3:$A$5001,F$3,BD!$B$3:$B$5001,$A$26,BD!$Y$3:$Y$5001,"<>")=0,"",SUMIFS(BD!$Y$3:$Y$5001,BD!$A$3:$A$5001,F$3,BD!$B$3:$B$5001,$A$26))) | G37: =IF(G$3="","",IF(COUNTIFS(BD!$A$3:$A$5001,G$3,BD!$B$3:$B$5001,$A$26,BD!$Y$3:$Y$5001,"<>")=0,"",SUMIFS(BD!$Y$3:$Y$5001,BD!$A$3:$A$5001,G$3,BD!$B$3:$B$5001,$A$26))) | H37: =IF(H$3="","",IF(COUNTIFS(BD!$A$3:$A$5001,H$3,BD!$B$3:$B$5001,$A$26,BD!$Y$3:$Y$5001,"<>")=0,"",SUMIFS(BD!$Y$3:$Y$5001,BD!$A$3:$A$5001,H$3,BD!$B$3:$B$5001,$A$26))) | I37: =IF(I$3="","",IF(COUNTIFS(BD!$A$3:$A$5001,I$3,BD!$B$3:$B$5001,$A$26,BD!$Y$3:$Y$5001,"<>")=0,"",SUMIFS(BD!$Y$3:$Y$5001,BD!$A$3:$A$5001,I$3,BD!$B$3:$B$5001,$A$26))) | J37: =IF(J$3="","",IF(COUNTIFS(BD!$A$3:$A$5001,J$3,BD!$B$3:$B$5001,$A$26,BD!$Y$3:$Y$5001,"<>")=0,"",SUMIFS(BD!$Y$3:$Y$5001,BD!$A$3:$A$5001,J$3,BD!$B$3:$B$5001,$A$26))) | K37: =IF(K$3="","",IF(COUNTIFS(BD!$A$3:$A$5001,K$3,BD!$B$3:$B$5001,$A$26,BD!$Y$3:$Y$5001,"<>")=0,"",SUMIFS(BD!$Y$3:$Y$5001,BD!$A$3:$A$5001,K$3,BD!$B$3:$B$5001,$A$26))) | L37: =IF(L$3="","",IF(COUNTIFS(BD!$A$3:$A$5001,L$3,BD!$B$3:$B$5001,$A$26,BD!$Y$3:$Y$5001,"<>")=0,"",SUMIFS(BD!$Y$3:$Y$5001,BD!$A$3:$A$5001,L$3,BD!$B$3:$B$5001,$A$26))) | M37: =IF(M$3="","",IF(COUNTIFS(BD!$A$3:$A$5001,M$3,BD!$B$3:$B$5001,$A$26,BD!$Y$3:$Y$5001,"<>")=0,"",SUMIFS(BD!$Y$3:$Y$5001,BD!$A$3:$A$5001,M$3,BD!$B$3:$B$5001,$A$26))) | ... AJ37: =IF(AJ$3="","",IF(COUNTIFS(BD!$A$3:$A$5001,AJ$3,BD!$B$3:$B$5001,$A$26,BD!$Y$3:$Y$5001,"<>")=0,"",SUMIFS(BD!$Y$3:$Y$5001,BD!$A$3:$A$5001,AJ$3,BD!$B$3:$B$5001,$A$26))) | AK37: =IFERROR(LOOKUP(9.99E+307,F37:AJ37),"")
C38: Taxa de Ocupação | D38: =IFERROR(1/(1/INDEX(BD!$AL$46:$BF$46,MATCH($A$26,BD!$AL$22:$BF$22,0))),"") | F38: =IF(AND(ISNUMBER(F36),ISNUMBER(F37)),IF(F36>0,F37/F36,""),"") | G38: =IF(AND(ISNUMBER(G36),ISNUMBER(G37)),IF(G36>0,G37/G36,""),"") | H38: =IF(AND(ISNUMBER(H36),ISNUMBER(H37)),IF(H36>0,H37/H36,""),"") | I38: =IF(AND(ISNUMBER(I36),ISNUMBER(I37)),IF(I36>0,I37/I36,""),"") | J38: =IF(AND(ISNUMBER(J36),ISNUMBER(J37)),IF(J36>0,J37/J36,""),"") | K38: =IF(AND(ISNUMBER(K36),ISNUMBER(K37)),IF(K36>0,K37/K36,""),"") | L38: =IF(AND(ISNUMBER(L36),ISNUMBER(L37)),IF(L36>0,L37/L36,""),"") | M38: =IF(AND(ISNUMBER(M36),ISNUMBER(M37)),IF(M36>0,M37/M36,""),"") | ... AK38: =IF(AND(ISNUMBER(AK36),ISNUMBER(AK37)),IF(AK36>0,AK37/AK36,""),"")
