Workbook

Sheet Dashboard
G1: DASHBOARD · INDICADORES OPERACIONAIS
B3: CLIENTE ▸ | D3: Todos | L3: PERÍODO ▸ | Q3: 46296 | T3: até | V3: 46326
B4: ="Período "&TEXT(calculos!$F$7,"dd/mm")&"/"&YEAR(calculos!$F$7)&" a "&TEXT(calculos!$G$7,"dd/mm")&"/"&YEAR(calculos!$G$7)&" · ▲▼ comparado a "&TEXT(calculos!$F$8,"dd/mm")&"–"&TEXT(calculos!$G$8,"dd/mm")&" (mesmo número de dias) · gráficos diários: "&calculos!$B$7 -> Período 01/10/2026 a 31/10/2026 · ▲▼ comparado a 31/08–30/09 (mesmo número de dias) · gráficos diários: Outubro/2026
C6: =Config!$D$60&"" -> RECEBIMENTO (IN) | H6: =Config!$D$62&"" -> EXPEDIÇÃO (OUT) | M6: =Config!$D$64&"" -> NC OPERACIONAL | R6: =Config!$D$69&"" -> ÍNDICE DE OCUPAÇÃO (P.P) | W6: =Config!$D$75&"" -> GENTE
B7: =IF(calculos!$AX$366="Não se aplica","—",calculos!$B$330) -> 0 | G7: =IF(calculos!$AY$366="Não se aplica","—",calculos!$B$333) -> 0 | L7: =calculos!$B$336 -> 0 | Q7: =IF(calculos!$AZ$366="Só ocupadas","CONTRATO",IF(OR(calculos!$AZ$366="Completo",calculos!$AZ$366=""),calculos!$BA$366&"","")) -> ARMAZÉM | S7: =IF(calculos!$AZ$366="Só ocupadas",IF(calculos!$BC$366="","—",UPPER(calculos!$BC$366)),IF(OR(calculos!$AZ$366="Completo",calculos!$AZ$366=""),calculos!$B$341,"")) | V7: =Config!$D$76&"" -> EFETIVO | X7: =calculos!$B$344
Q8: =IF(calculos!$AZ$366="Não se aplica","",Config!$D$72&"") -> OCUPADA | S8: =IF(calculos!$AZ$366="Não se aplica","",calculos!$B$340) | V8: =Config!$D$77&"" -> ABSENTEÍSMO (H/H) | X8: =calculos!$B$347 -> 0
L9: =Config!$D$65&"" -> incidentes no período | Q9: =IF(OR(calculos!$AZ$366="Completo",calculos!$AZ$366=""),Config!$D$73&"","") -> TX OCUPAÇÃO | S9: =IF(OR(calculos!$AZ$366="Completo",calculos!$AZ$366=""),calculos!$B$342,"") | V9: =Config!$D$78&"" -> FÉRIAS | X9: =calculos!$B$350 -> 0
B10: =IF(calculos!$AX$366="Não se aplica","não se aplica a este cliente",Config!$D$61&"") -> veículos recebidos | G10: =IF(calculos!$AY$366="Não se aplica","não se aplica a este cliente",Config!$D$63&"") -> veículos expedidos | L10: =Config!$D$66&"" -> NO SHOW | N10: =calculos!$B$337 -> 0 | Q10: =IF(OR(calculos!$AZ$366="Completo",calculos!$AZ$366=""),Config!$D$74&"","") -> OCIOSIDADE | S10: =IF(OR(calculos!$AZ$366="Completo",calculos!$AZ$366=""),calculos!$B$343,"") | V10: =Config!$D$79&"" -> TURNOVER | X10: =calculos!$B$352
B11: =IF(calculos!$AX$366="Não se aplica","",calculos!$B$364) -> 0 pallets movimentados | G11: =IF(calculos!$AY$366="Não se aplica","",calculos!$F$364) -> 0 pallets movimentados | L11: =Config!$D$67&"" -> BACKLOG INTRALOG | N11: =calculos!$B$338 | Q11: =IF(calculos!$AZ$366="Não se aplica","não se aplica a este cliente",IF(calculos!$AZ$366="Só ocupadas","posições ocupadas · contrato "&IF(calculos!$BC$366="","não informado",calculos!$BC$366),IF(ISNUMBER(calculos!$B$342),"taxa de ocupação · "&IF(calculos!$B$342>1,"excede o contratado",IF(calculos!$B$342>=calculos!$B$6,"ocupação alta",IF(calculos!$B$342>=calculos!$B$5,"ocupação média","ociosidade alta"))),""))) | V11: =Config!$D$80&"" -> DESVIOS COMPORTAM. | X11: =calculos!$B$353 -> 0
B12: =IF(calculos!$AX$366="Não se aplica","",calculos!$D$364) -> 0,0 t movimentadas | G12: =IF(calculos!$AY$366="Não se aplica","",calculos!$H$364) -> 0,0 t movimentadas | L12: =Config!$D$68&"" -> BACKLOG CLIENTE | N12: =calculos!$B$339 | V12: =Config!$D$81&"" -> ACIDENTES (CAF/SAF) | X12: =N(calculos!$B$354)&" / "&N(calculos!$B$355) -> 0 / 0
B13: =IF(calculos!$AX$366="Não se aplica","",calculos!$D$330) | G13: =IF(calculos!$AY$366="Não se aplica","",calculos!$D$333) | L13: =calculos!$D$336 | Q13: =IF(AND(calculos!$AZ$366<>"Completo",calculos!$AZ$366<>""),"",calculos!$D$342) | V13: =calculos!$D$344
B65: Cards: período digitado (dia inicial e final). Gráficos: mês do dia inicial. Absenteísmo (H/H) = horas de ausência lançadas na BD (soma do período) · Turnover = desligamentos ÷ efetivo · CAF/SAF = acidentes com / sem afastamento. Metas: aba BD.

Sheet Monitoramento
G1: MONITORAMENTO DIÁRIO DE PERFORMANCE | AE1: OUTUBRO · 2026
A2: CLIENTE | B2: INDICADORES | D2: META | F2: REALIZADO P/DIA | AK2: MÊS
F3: =IF(ISNUMBER($AE$1),DATE(YEAR($AE$1),MONTH($AE$1),1),IFERROR(DATE(VALUE(RIGHT(TRIM($AE$1),4)),MATCH(TRIM(LEFT($AE$1,FIND("·",$AE$1)-1)),{"JANEIRO","FEVEREIRO","MARÇO","ABRIL","MAIO","JUNHO","JULHO","AGOSTO","SETEMBRO","OUTUBRO","NOVEMBRO","DEZEMBRO"},0),1),DATE(2026,10,1))) -> 46296 | G3: =IF(F3="","",IF(MONTH(F3+1)=MONTH($F$3),F3+1,"")) -> 46297 | H3: =IF(G3="","",IF(MONTH(G3+1)=MONTH($F$3),G3+1,"")) -> 46298 | I3: =IF(H3="","",IF(MONTH(H3+1)=MONTH($F$3),H3+1,"")) -> 46299 | J3: =IF(I3="","",IF(MONTH(I3+1)=MONTH($F$3),I3+1,"")) -> 46300 | K3: =IF(J3="","",IF(MONTH(J3+1)=MONTH($F$3),J3+1,"")) -> 46301 | L3: =IF(K3="","",IF(MONTH(K3+1)=MONTH($F$3),K3+1,"")) -> 46302 | M3: =IF(L3="","",IF(MONTH(L3+1)=MONTH($F$3),L3+1,"")) -> 46303 | N3: =IF(M3="","",IF(MONTH(M3+1)=MONTH($F$3),M3+1,"")) -> 46304 | ... AJ3: =IF(AI3="","",IF(MONTH(AI3+1)=MONTH($F$3),AI3+1,"")) -> 46326
A5: Barry Callebaut | B5: IN | C5: Veículos Recebidos | D5: =IFERROR(1/(1/INDEX(BD!$AF$23:$AZ$23,MATCH($A$5,BD!$AF$22:$AZ$22,0))),"") | F5: =IF(F$3="","",IF(COUNTIFS(BD!$A$3:$A$5001,F$3,BD!$B$3:$B$5001,$A$5,BD!$C$3:$C$5001,"<>")=0,"",SUMIFS(BD!$C$3:$C$5001,BD!$A$3:$A$5001,F$3,BD!$B$3:$B$5001,$A$5))) | G5: =IF(G$3="","",IF(COUNTIFS(BD!$A$3:$A$5001,G$3,BD!$B$3:$B$5001,$A$5,BD!$C$3:$C$5001,"<>")=0,"",SUMIFS(BD!$C$3:$C$5001,BD!$A$3:$A$5001,G$3,BD!$B$3:$B$5001,$A$5))) | H5: =IF(H$3="","",IF(COUNTIFS(BD!$A$3:$A$5001,H$3,BD!$B$3:$B$5001,$A$5,BD!$C$3:$C$5001,"<>")=0,"",SUMIFS(BD!$C$3:$C$5001,BD!$A$3:$A$5001,H$3,BD!$B$3:$B$5001,$A$5))) | I5: =IF(I$3="","",IF(COUNTIFS(BD!$A$3:$A$5001,I$3,BD!$B$3:$B$5001,$A$5,BD!$C$3:$C$5001,"<>")=0,"",SUMIFS(BD!$C$3:$C$5001,BD!$A$3:$A$5001,I$3,BD!$B$3:$B$5001,$A$5))) | J5: =IF(J$3="","",IF(COUNTIFS(BD!$A$3:$A$5001,J$3,BD!$B$3:$B$5001,$A$5,BD!$C$3:$C$5001,"<>")=0,"",SUMIFS(BD!$C$3:$C$5001,BD!$A$3:$A$5001,J$3,BD!$B$3:$B$5001,$A$5))) | K5: =IF(K$3="","",IF(COUNTIFS(BD!$A$3:$A$5001,K$3,BD!$B$3:$B$5001,$A$5,BD!$C$3:$C$5001,"<>")=0,"",SUMIFS(BD!$C$3:$C$5001,BD!$A$3:$A$5001,K$3,BD!$B$3:$B$5001,$A$5))) | L5: =IF(L$3="","",IF(COUNTIFS(BD!$A$3:$A$5001,L$3,BD!$B$3:$B$5001,$A$5,BD!$C$3:$C$5001,"<>")=0,"",SUMIFS(BD!$C$3:$C$5001,BD!$A$3:$A$5001,L$3,BD!$B$3:$B$5001,$A$5))) | M5: =IF(M$3="","",IF(COUNTIFS(BD!$A$3:$A$5001,M$3,BD!$B$3:$B$5001,$A$5,BD!$C$3:$C$5001,"<>")=0,"",SUMIFS(BD!$C$3:$C$5001,BD!$A$3:$A$5001,M$3,BD!$B$3:$B$5001,$A$5))) | ... AJ5: =IF(AJ$3="","",IF(COUNTIFS(BD!$A$3:$A$5001,AJ$3,BD!$B$3:$B$5001,$A$5,BD!$C$3:$C$5001,"<>")=0,"",SUMIFS(BD!$C$3:$C$5001,BD!$A$3:$A$5001,AJ$3,BD!$B$3:$B$5001,$A$5))) | AK5: =IF(COUNT(F5:AJ5)=0,"",SUM(F5:AJ5))
C6: Pallets Movimentados | D6: =IFERROR(1/(1/INDEX(BD!$AF$24:$AZ$24,MATCH($A$5,BD!$AF$22:$AZ$22,0))),"") | F6: =IF(F$3="","",IF(COUNTIFS(BD!$A$3:$A$5001,F$3,BD!$B$3:$B$5001,$A$5,BD!$D$3:$D$5001,"<>")=0,"",SUMIFS(BD!$D$3:$D$5001,BD!$A$3:$A$5001,F$3,BD!$B$3:$B$5001,$A$5))) | G6: =IF(G$3="","",IF(COUNTIFS(BD!$A$3:$A$5001,G$3,BD!$B$3:$B$5001,$A$5,BD!$D$3:$D$5001,"<>")=0,"",SUMIFS(BD!$D$3:$D$5001,BD!$A$3:$A$5001,G$3,BD!$B$3:$B$5001,$A$5))) | H6: =IF(H$3="","",IF(COUNTIFS(BD!$A$3:$A$5001,H$3,BD!$B$3:$B$5001,$A$5,BD!$D$3:$D$5001,"<>")=0,"",SUMIFS(BD!$D$3:$D$5001,BD!$A$3:$A$5001,H$3,BD!$B$3:$B$5001,$A$5))) | I6: =IF(I$3="","",IF(COUNTIFS(BD!$A$3:$A$5001,I$3,BD!$B$3:$B$5001,$A$5,BD!$D$3:$D$5001,"<>")=0,"",SUMIFS(BD!$D$3:$D$5001,BD!$A$3:$A$5001,I$3,BD!$B$3:$B$5001,$A$5))) | J6: =IF(J$3="","",IF(COUNTIFS(BD!$A$3:$A$5001,J$3,BD!$B$3:$B$5001,$A$5,BD!$D$3:$D$5001,"<>")=0,"",SUMIFS(BD!$D$3:$D$5001,BD!$A$3:$A$5001,J$3,BD!$B$3:$B$5001,$A$5))) | K6: =IF(K$3="","",IF(COUNTIFS(BD!$A$3:$A$5001,K$3,BD!$B$3:$B$5001,$A$5,BD!$D$3:$D$5001,"<>")=0,"",SUMIFS(BD!$D$3:$D$5001,BD!$A$3:$A$5001,K$3,BD!$B$3:$B$5001,$A$5))) | L6: =IF(L$3="","",IF(COUNTIFS(BD!$A$3:$A$5001,L$3,BD!$B$3:$B$5001,$A$5,BD!$D$3:$D$5001,"<>")=0,"",SUMIFS(BD!$D$3:$D$5001,BD!$A$3:$A$5001,L$3,BD!$B$3:$B$5001,$A$5))) | M6: =IF(M$3="","",IF(COUNTIFS(BD!$A$3:$A$5001,M$3,BD!$B$3:$B$5001,$A$5,BD!$D$3:$D$5001,"<>")=0,"",SUMIFS(BD!$D$3:$D$5001,BD!$A$3:$A$5001,M$3,BD!$B$3:$B$5001,$A$5))) | ... AJ6: =IF(AJ$3="","",IF(COUNTIFS(BD!$A$3:$A$5001,AJ$3,BD!$B$3:$B$5001,$A$5,BD!$D$3:$D$5001,"<>")=0,"",SUMIFS(BD!$D$3:$D$5001,BD!$A$3:$A$5001,AJ$3,BD!$B$3:$B$5001,$A$5))) | AK6: =IF(COUNT(F6:AJ6)=0,"",SUM(F6:AJ6))
C7: Toneladas Movimentadas | D7: =IFERROR(1/(1/INDEX(BD!$AF$25:$AZ$25,MATCH($A$5,BD!$AF$22:$AZ$22,0))),"") | F7: =IF(F$3="","",IF(COUNTIFS(BD!$A$3:$A$5001,F$3,BD!$B$3:$B$5001,$A$5,BD!$E$3:$E$5001,"<>")=0,"",SUMIFS(BD!$E$3:$E$5001,BD!$A$3:$A$5001,F$3,BD!$B$3:$B$5001,$A$5))) | G7: =IF(G$3="","",IF(COUNTIFS(BD!$A$3:$A$5001,G$3,BD!$B$3:$B$5001,$A$5,BD!$E$3:$E$5001,"<>")=0,"",SUMIFS(BD!$E$3:$E$5001,BD!$A$3:$A$5001,G$3,BD!$B$3:$B$5001,$A$5))) | H7: =IF(H$3="","",IF(COUNTIFS(BD!$A$3:$A$5001,H$3,BD!$B$3:$B$5001,$A$5,BD!$E$3:$E$5001,"<>")=0,"",SUMIFS(BD!$E$3:$E$5001,BD!$A$3:$A$5001,H$3,BD!$B$3:$B$5001,$A$5))) | I7: =IF(I$3="","",IF(COUNTIFS(BD!$A$3:$A$5001,I$3,BD!$B$3:$B$5001,$A$5,BD!$E$3:$E$5001,"<>")=0,"",SUMIFS(BD!$E$3:$E$5001,BD!$A$3:$A$5001,I$3,BD!$B$3:$B$5001,$A$5))) | J7: =IF(J$3="","",IF(COUNTIFS(BD!$A$3:$A$5001,J$3,BD!$B$3:$B$5001,$A$5,BD!$E$3:$E$5001,"<>")=0,"",SUMIFS(BD!$E$3:$E$5001,BD!$A$3:$A$5001,J$3,BD!$B$3:$B$5001,$A$5))) | K7: =IF(K$3="","",IF(COUNTIFS(BD!$A$3:$A$5001,K$3,BD!$B$3:$B$5001,$A$5,BD!$E$3:$E$5001,"<>")=0,"",SUMIFS(BD!$E$3:$E$5001,BD!$A$3:$A$5001,K$3,BD!$B$3:$B$5001,$A$5))) | L7: =IF(L$3="","",IF(COUNTIFS(BD!$A$3:$A$5001,L$3,BD!$B$3:$B$5001,$A$5,BD!$E$3:$E$5001,"<>")=0,"",SUMIFS(BD!$E$3:$E$5001,BD!$A$3:$A$5001,L$3,BD!$B$3:$B$5001,$A$5))) | M7: =IF(M$3="","",IF(COUNTIFS(BD!$A$3:$A$5001,M$3,BD!$B$3:$B$5001,$A$5,BD!$E$3:$E$5001,"<>")=0,"",SUMIFS(BD!$E$3:$E$5001,BD!$A$3:$A$5001,M$3,BD!$B$3:$B$5001,$A$5))) | ... AJ7: =IF(AJ$3="","",IF(COUNTIFS(BD!$A$3:$A$5001,AJ$3,BD!$B$3:$B$5001,$A$5,BD!$E$3:$E$5001,"<>")=0,"",SUMIFS(BD!$E$3:$E$5001,BD!$A$3:$A$5001,AJ$3,BD!$B$3:$B$5001,$A$5))) | AK7: =IF(COUNT(F7:AJ7)=0,"",SUM(F7:AJ7))
C8: Caixas Recebidas | D8: =IFERROR(1/(1/INDEX(BD!$AF$26:$AZ$26,MATCH($A$5,BD!$AF$22:$AZ$22,0))),"") | F8: =IF(F$3="","",IF(COUNTIFS(BD!$A$3:$A$5001,F$3,BD!$B$3:$B$5001,$A$5,BD!$F$3:$F$5001,"<>")=0,"",SUMIFS(BD!$F$3:$F$5001,BD!$A$3:$A$5001,F$3,BD!$B$3:$B$5001,$A$5))) | G8: =IF(G$3="","",IF(COUNTIFS(BD!$A$3:$A$5001,G$3,BD!$B$3:$B$5001,$A$5,BD!$F$3:$F$5001,"<>")=0,"",SUMIFS(BD!$F$3:$F$5001,BD!$A$3:$A$5001,G$3,BD!$B$3:$B$5001,$A$5))) | H8: =IF(H$3="","",IF(COUNTIFS(BD!$A$3:$A$5001,H$3,BD!$B$3:$B$5001,$A$5,BD!$F$3:$F$5001,"<>")=0,"",SUMIFS(BD!$F$3:$F$5001,BD!$A$3:$A$5001,H$3,BD!$B$3:$B$5001,$A$5))) | I8: =IF(I$3="","",IF(COUNTIFS(BD!$A$3:$A$5001,I$3,BD!$B$3:$B$5001,$A$5,BD!$F$3:$F$5001,"<>")=0,"",SUMIFS(BD!$F$3:$F$5001,BD!$A$3:$A$5001,I$3,BD!$B$3:$B$5001,$A$5))) | J8: =IF(J$3="","",IF(COUNTIFS(BD!$A$3:$A$5001,J$3,BD!$B$3:$B$5001,$A$5,BD!$F$3:$F$5001,"<>")=0,"",SUMIFS(BD!$F$3:$F$5001,BD!$A$3:$A$5001,J$3,BD!$B$3:$B$5001,$A$5))) | K8: =IF(K$3="","",IF(COUNTIFS(BD!$A$3:$A$5001,K$3,BD!$B$3:$B$5001,$A$5,BD!$F$3:$F$5001,"<>")=0,"",SUMIFS(BD!$F$3:$F$5001,BD!$A$3:$A$5001,K$3,BD!$B$3:$B$5001,$A$5))) | L8: =IF(L$3="","",IF(COUNTIFS(BD!$A$3:$A$5001,L$3,BD!$B$3:$B$5001,$A$5,BD!$F$3:$F$5001,"<>")=0,"",SUMIFS(BD!$F$3:$F$5001,BD!$A$3:$A$5001,L$3,BD!$B$3:$B$5001,$A$5))) | M8: =IF(M$3="","",IF(COUNTIFS(BD!$A$3:$A$5001,M$3,BD!$B$3:$B$5001,$A$5,BD!$F$3:$F$5001,"<>")=0,"",SUMIFS(BD!$F$3:$F$5001,BD!$A$3:$A$5001,M$3,BD!$B$3:$B$5001,$A$5))) | ... AJ8: =IF(AJ$3="","",IF(COUNTIFS(BD!$A$3:$A$5001,AJ$3,BD!$B$3:$B$5001,$A$5,BD!$F$3:$F$5001,"<>")=0,"",SUMIFS(BD!$F$3:$F$5001,BD!$A$3:$A$5001,AJ$3,BD!$B$3:$B$5001,$A$5))) | AK8: =IF(COUNT(F8:AJ8)=0,"",SUM(F8:AJ8))
C9: Bags Recebidos | D9: =IFERROR(1/(1/INDEX(BD!$AF$27:$AZ$27,MATCH($A$5,BD!$AF$22:$AZ$22,0))),"") | F9: =IF(F$3="","",IF(COUNTIFS(BD!$A$3:$A$5001,F$3,BD!$B$3:$B$5001,$A$5,BD!$G$3:$G$5001,"<>")=0,"",SUMIFS(BD!$G$3:$G$5001,BD!$A$3:$A$5001,F$3,BD!$B$3:$B$5001,$A$5))) | G9: =IF(G$3="","",IF(COUNTIFS(BD!$A$3:$A$5001,G$3,BD!$B$3:$B$5001,$A$5,BD!$G$3:$G$5001,"<>")=0,"",SUMIFS(BD!$G$3:$G$5001,BD!$A$3:$A$5001,G$3,BD!$B$3:$B$5001,$A$5))) | H9: =IF(H$3="","",IF(COUNTIFS(BD!$A$3:$A$5001,H$3,BD!$B$3:$B$5001,$A$5,BD!$G$3:$G$5001,"<>")=0,"",SUMIFS(BD!$G$3:$G$5001,BD!$A$3:$A$5001,H$3,BD!$B$3:$B$5001,$A$5))) | I9: =IF(I$3="","",IF(COUNTIFS(BD!$A$3:$A$5001,I$3,BD!$B$3:$B$5001,$A$5,BD!$G$3:$G$5001,"<>")=0,"",SUMIFS(BD!$G$3:$G$5001,BD!$A$3:$A$5001,I$3,BD!$B$3:$B$5001,$A$5))) | J9: =IF(J$3="","",IF(COUNTIFS(BD!$A$3:$A$5001,J$3,BD!$B$3:$B$5001,$A$5,BD!$G$3:$G$5001,"<>")=0,"",SUMIFS(BD!$G$3:$G$5001,BD!$A$3:$A$5001,J$3,BD!$B$3:$B$5001,$A$5))) | K9: =IF(K$3="","",IF(COUNTIFS(BD!$A$3:$A$5001,K$3,BD!$B$3:$B$5001,$A$5,BD!$G$3:$G$5001,"<>")=0,"",SUMIFS(BD!$G$3:$G$5001,BD!$A$3:$A$5001,K$3,BD!$B$3:$B$5001,$A$5))) | L9: =IF(L$3="","",IF(COUNTIFS(BD!$A$3:$A$5001,L$3,BD!$B$3:$B$5001,$A$5,BD!$G$3:$G$5001,"<>")=0,"",SUMIFS(BD!$G$3:$G$5001,BD!$A$3:$A$5001,L$3,BD!$B$3:$B$5001,$A$5))) | M9: =IF(M$3="","",IF(COUNTIFS(BD!$A$3:$A$5001,M$3,BD!$B$3:$B$5001,$A$5,BD!$G$3:$G$5001,"<>")=0,"",SUMIFS(BD!$G$3:$G$5001,BD!$A$3:$A$5001,M$3,BD!$B$3:$B$5001,$A$5))) | ... AJ9: =IF(AJ$3="","",IF(COUNTIFS(BD!$A$3:$A$5001,AJ$3,BD!$B$3:$B$5001,$A$5,BD!$G$3:$G$5001,"<>")=0,"",SUMIFS(BD!$G$3:$G$5001,BD!$A$3:$A$5001,AJ$3,BD!$B$3:$B$5001,$A$5))) | AK9: =IF(COUNT(F9:AJ9)=0,"",SUM(F9:AJ9))
B10: OUT | C10: Veículos Expedidos | D10: =IFERROR(1/(1/INDEX(BD!$AF$28:$AZ$28,MATCH($A$5,BD!$AF$22:$AZ$22,0))),"") | F10: =IF(F$3="","",IF(COUNTIFS(BD!$A$3:$A$5001,F$3,BD!$B$3:$B$5001,$A$5,BD!$H$3:$H$5001,"<>")=0,"",SUMIFS(BD!$H$3:$H$5001,BD!$A$3:$A$5001,F$3,BD!$B$3:$B$5001,$A$5))) | G10: =IF(G$3="","",IF(COUNTIFS(BD!$A$3:$A$5001,G$3,BD!$B$3:$B$5001,$A$5,BD!$H$3:$H$5001,"<>")=0,"",SUMIFS(BD!$H$3:$H$5001,BD!$A$3:$A$5001,G$3,BD!$B$3:$B$5001,$A$5))) | H10: =IF(H$3="","",IF(COUNTIFS(BD!$A$3:$A$5001,H$3,BD!$B$3:$B$5001,$A$5,BD!$H$3:$H$5001,"<>")=0,"",SUMIFS(BD!$H$3:$H$5001,BD!$A$3:$A$5001,H$3,BD!$B$3:$B$5001,$A$5))) | I10: =IF(I$3="","",IF(COUNTIFS(BD!$A$3:$A$5001,I$3,BD!$B$3:$B$5001,$A$5,BD!$H$3:$H$5001,"<>")=0,"",SUMIFS(BD!$H$3:$H$5001,BD!$A$3:$A$5001,I$3,BD!$B$3:$B$5001,$A$5))) | J10: =IF(J$3="","",IF(COUNTIFS(BD!$A$3:$A$5001,J$3,BD!$B$3:$B$5001,$A$5,BD!$H$3:$H$5001,"<>")=0,"",SUMIFS(BD!$H$3:$H$5001,BD!$A$3:$A$5001,J$3,BD!$B$3:$B$5001,$A$5))) | K10: =IF(K$3="","",IF(COUNTIFS(BD!$A$3:$A$5001,K$3,BD!$B$3:$B$5001,$A$5,BD!$H$3:$H$5001,"<>")=0,"",SUMIFS(BD!$H$3:$H$5001,BD!$A$3:$A$5001,K$3,BD!$B$3:$B$5001,$A$5))) | L10: =IF(L$3="","",IF(COUNTIFS(BD!$A$3:$A$5001,L$3,BD!$B$3:$B$5001,$A$5,BD!$H$3:$H$5001,"<>")=0,"",SUMIFS(BD!$H$3:$H$5001,BD!$A$3:$A$5001,L$3,BD!$B$3:$B$5001,$A$5))) | M10: =IF(M$3="","",IF(COUNTIFS(BD!$A$3:$A$5001,M$3,BD!$B$3:$B$5001,$A$5,BD!$H$3:$H$5001,"<>")=0,"",SUMIFS(BD!$H$3:$H$5001,BD!$A$3:$A$5001,M$3,BD!$B$3:$B$5001,$A$5))) | ... AJ10: =IF(AJ$3="","",IF(COUNTIFS(BD!$A$3:$A$5001,AJ$3,BD!$B$3:$B$5001,$A$5,BD!$H$3:$H$5001,"<>")=0,"",SUMIFS(BD!$H$3:$H$5001,BD!$A$3:$A$5001,AJ$3,BD!$B$3:$B$5001,$A$5))) | AK10: =IF(COUNT(F10:AJ10)=0,"",SUM(F10:AJ10))
C11: Pallets Movimentados | D11: =IFERROR(1/(1/INDEX(BD!$AF$29:$AZ$29,MATCH($A$5,BD!$AF$22:$AZ$22,0))),"") | F11: =IF(F$3="","",IF(COUNTIFS(BD!$A$3:$A$5001,F$3,BD!$B$3:$B$5001,$A$5,BD!$I$3:$I$5001,"<>")=0,"",SUMIFS(BD!$I$3:$I$5001,BD!$A$3:$A$5001,F$3,BD!$B$3:$B$5001,$A$5))) | G11: =IF(G$3="","",IF(COUNTIFS(BD!$A$3:$A$5001,G$3,BD!$B$3:$B$5001,$A$5,BD!$I$3:$I$5001,"<>")=0,"",SUMIFS(BD!$I$3:$I$5001,BD!$A$3:$A$5001,G$3,BD!$B$3:$B$5001,$A$5))) | H11: =IF(H$3="","",IF(COUNTIFS(BD!$A$3:$A$5001,H$3,BD!$B$3:$B$5001,$A$5,BD!$I$3:$I$5001,"<>")=0,"",SUMIFS(BD!$I$3:$I$5001,BD!$A$3:$A$5001,H$3,BD!$B$3:$B$5001,$A$5))) | I11: =IF(I$3="","",IF(COUNTIFS(BD!$A$3:$A$5001,I$3,BD!$B$3:$B$5001,$A$5,BD!$I$3:$I$5001,"<>")=0,"",SUMIFS(BD!$I$3:$I$5001,BD!$A$3:$A$5001,I$3,BD!$B$3:$B$5001,$A$5))) | J11: =IF(J$3="","",IF(COUNTIFS(BD!$A$3:$A$5001,J$3,BD!$B$3:$B$5001,$A$5,BD!$I$3:$I$5001,"<>")=0,"",SUMIFS(BD!$I$3:$I$5001,BD!$A$3:$A$5001,J$3,BD!$B$3:$B$5001,$A$5))) | K11: =IF(K$3="","",IF(COUNTIFS(BD!$A$3:$A$5001,K$3,BD!$B$3:$B$5001,$A$5,BD!$I$3:$I$5001,"<>")=0,"",SUMIFS(BD!$I$3:$I$5001,BD!$A$3:$A$5001,K$3,BD!$B$3:$B$5001,$A$5))) | L11: =IF(L$3="","",IF(COUNTIFS(BD!$A$3:$A$5001,L$3,BD!$B$3:$B$5001,$A$5,BD!$I$3:$I$5001,"<>")=0,"",SUMIFS(BD!$I$3:$I$5001,BD!$A$3:$A$5001,L$3,BD!$B$3:$B$5001,$A$5))) | M11: =IF(M$3="","",IF(COUNTIFS(BD!$A$3:$A$5001,M$3,BD!$B$3:$B$5001,$A$5,BD!$I$3:$I$5001,"<>")=0,"",SUMIFS(BD!$I$3:$I$5001,BD!$A$3:$A$5001,M$3,BD!$B$3:$B$5001,$A$5))) | ... AJ11: =IF(AJ$3="","",IF(COUNTIFS(BD!$A$3:$A$5001,AJ$3,BD!$B$3:$B$5001,$A$5,BD!$I$3:$I$5001,"<>")=0,"",SUMIFS(BD!$I$3:$I$5001,BD!$A$3:$A$5001,AJ$3,BD!$B$3:$B$5001,$A$5))) | AK11: =IF(COUNT(F11:AJ11)=0,"",SUM(F11:AJ11))
C12: Toneladas Movimentadas | D12: =IFERROR(1/(1/INDEX(BD!$AF$30:$AZ$30,MATCH($A$5,BD!$AF$22:$AZ$22,0))),"") | F12: =IF(F$3="","",IF(COUNTIFS(BD!$A$3:$A$5001,F$3,BD!$B$3:$B$5001,$A$5,BD!$J$3:$J$5001,"<>")=0,"",SUMIFS(BD!$J$3:$J$5001,BD!$A$3:$A$5001,F$3,BD!$B$3:$B$5001,$A$5))) | G12: =IF(G$3="","",IF(COUNTIFS(BD!$A$3:$A$5001,G$3,BD!$B$3:$B$5001,$A$5,BD!$J$3:$J$5001,"<>")=0,"",SUMIFS(BD!$J$3:$J$5001,BD!$A$3:$A$5001,G$3,BD!$B$3:$B$5001,$A$5))) | H12: =IF(H$3="","",IF(COUNTIFS(BD!$A$3:$A$5001,H$3,BD!$B$3:$B$5001,$A$5,BD!$J$3:$J$5001,"<>")=0,"",SUMIFS(BD!$J$3:$J$5001,BD!$A$3:$A$5001,H$3,BD!$B$3:$B$5001,$A$5))) | I12: =IF(I$3="","",IF(COUNTIFS(BD!$A$3:$A$5001,I$3,BD!$B$3:$B$5001,$A$5,BD!$J$3:$J$5001,"<>")=0,"",SUMIFS(BD!$J$3:$J$5001,BD!$A$3:$A$5001,I$3,BD!$B$3:$B$5001,$A$5))) | J12: =IF(J$3="","",IF(COUNTIFS(BD!$A$3:$A$5001,J$3,BD!$B$3:$B$5001,$A$5,BD!$J$3:$J$5001,"<>")=0,"",SUMIFS(BD!$J$3:$J$5001,BD!$A$3:$A$5001,J$3,BD!$B$3:$B$5001,$A$5))) | K12: =IF(K$3="","",IF(COUNTIFS(BD!$A$3:$A$5001,K$3,BD!$B$3:$B$5001,$A$5,BD!$J$3:$J$5001,"<>")=0,"",SUMIFS(BD!$J$3:$J$5001,BD!$A$3:$A$5001,K$3,BD!$B$3:$B$5001,$A$5))) | L12: =IF(L$3="","",IF(COUNTIFS(BD!$A$3:$A$5001,L$3,BD!$B$3:$B$5001,$A$5,BD!$J$3:$J$5001,"<>")=0,"",SUMIFS(BD!$J$3:$J$5001,BD!$A$3:$A$5001,L$3,BD!$B$3:$B$5001,$A$5))) | M12: =IF(M$3="","",IF(COUNTIFS(BD!$A$3:$A$5001,M$3,BD!$B$3:$B$5001,$A$5,BD!$J$3:$J$5001,"<>")=0,"",SUMIFS(BD!$J$3:$J$5001,BD!$A$3:$A$5001,M$3,BD!$B$3:$B$5001,$A$5))) | ... AJ12: =IF(AJ$3="","",IF(COUNTIFS(BD!$A$3:$A$5001,AJ$3,BD!$B$3:$B$5001,$A$5,BD!$J$3:$J$5001,"<>")=0,"",SUMIFS(BD!$J$3:$J$5001,BD!$A$3:$A$5001,AJ$3,BD!$B$3:$B$5001,$A$5))) | AK12: =IF(COUNT(F12:AJ12)=0,"",SUM(F12:AJ12))
C13: Caixas Expedidas | D13: =IFERROR(1/(1/INDEX(BD!$AF$31:$AZ$31,MATCH($A$5,BD!$AF$22:$AZ$22,0))),"") | F13: =IF(F$3="","",IF(COUNTIFS(BD!$A$3:$A$5001,F$3,BD!$B$3:$B$5001,$A$5,BD!$K$3:$K$5001,"<>")=0,"",SUMIFS(BD!$K$3:$K$5001,BD!$A$3:$A$5001,F$3,BD!$B$3:$B$5001,$A$5))) | G13: =IF(G$3="","",IF(COUNTIFS(BD!$A$3:$A$5001,G$3,BD!$B$3:$B$5001,$A$5,BD!$K$3:$K$5001,"<>")=0,"",SUMIFS(BD!$K$3:$K$5001,BD!$A$3:$A$5001,G$3,BD!$B$3:$B$5001,$A$5))) | H13: =IF(H$3="","",IF(COUNTIFS(BD!$A$3:$A$5001,H$3,BD!$B$3:$B$5001,$A$5,BD!$K$3:$K$5001,"<>")=0,"",SUMIFS(BD!$K$3:$K$5001,BD!$A$3:$A$5001,H$3,BD!$B$3:$B$5001,$A$5))) | I13: =IF(I$3="","",IF(COUNTIFS(BD!$A$3:$A$5001,I$3,BD!$B$3:$B$5001,$A$5,BD!$K$3:$K$5001,"<>")=0,"",SUMIFS(BD!$K$3:$K$5001,BD!$A$3:$A$5001,I$3,BD!$B$3:$B$5001,$A$5))) | J13: =IF(J$3="","",IF(COUNTIFS(BD!$A$3:$A$5001,J$3,BD!$B$3:$B$5001,$A$5,BD!$K$3:$K$5001,"<>")=0,"",SUMIFS(BD!$K$3:$K$5001,BD!$A$3:$A$5001,J$3,BD!$B$3:$B$5001,$A$5))) | K13: =IF(K$3="","",IF(COUNTIFS(BD!$A$3:$A$5001,K$3,BD!$B$3:$B$5001,$A$5,BD!$K$3:$K$5001,"<>")=0,"",SUMIFS(BD!$K$3:$K$5001,BD!$A$3:$A$5001,K$3,BD!$B$3:$B$5001,$A$5))) | L13: =IF(L$3="","",IF(COUNTIFS(BD!$A$3:$A$5001,L$3,BD!$B$3:$B$5001,$A$5,BD!$K$3:$K$5001,"<>")=0,"",SUMIFS(BD!$K$3:$K$5001,BD!$A$3:$A$5001,L$3,BD!$B$3:$B$5001,$A$5))) | M13: =IF(M$3="","",IF(COUNTIFS(BD!$A$3:$A$5001,M$3,BD!$B$3:$B$5001,$A$5,BD!$K$3:$K$5001,"<>")=0,"",SUMIFS(BD!$K$3:$K$5001,BD!$A$3:$A$5001,M$3,BD!$B$3:$B$5001,$A$5))) | ... AJ13: =IF(AJ$3="","",IF(COUNTIFS(BD!$A$3:$A$5001,AJ$3,BD!$B$3:$B$5001,$A$5,BD!$K$3:$K$5001,"<>")=0,"",SUMIFS(BD!$K$3:$K$5001,BD!$A$3:$A$5001,AJ$3,BD!$B$3:$B$5001,$A$5))) | AK13: =IF(COUNT(F13:AJ13)=0,"",SUM(F13:AJ13))
C14: Pedidos Faturados | D14: =IFERROR(1/(1/INDEX(BD!$AF$32:$AZ$32,MATCH($A$5,BD!$AF$22:$AZ$22,0))),"") | F14: =IF(F$3="","",IF(COUNTIFS(BD!$A$3:$A$5001,F$3,BD!$B$3:$B$5001,$A$5,BD!$L$3:$L$5001,"<>")=0,"",SUMIFS(BD!$L$3:$L$5001,BD!$A$3:$A$5001,F$3,BD!$B$3:$B$5001,$A$5))) | G14: =IF(G$3="","",IF(COUNTIFS(BD!$A$3:$A$5001,G$3,BD!$B$3:$B$5001,$A$5,BD!$L$3:$L$5001,"<>")=0,"",SUMIFS(BD!$L$3:$L$5001,BD!$A$3:$A$5001,G$3,BD!$B$3:$B$5001,$A$5))) | H14: =IF(H$3="","",IF(COUNTIFS(BD!$A$3:$A$5001,H$3,BD!$B$3:$B$5001,$A$5,BD!$L$3:$L$5001,"<>")=0,"",SUMIFS(BD!$L$3:$L$5001,BD!$A$3:$A$5001,H$3,BD!$B$3:$B$5001,$A$5))) | I14: =IF(I$3="","",IF(COUNTIFS(BD!$A$3:$A$5001,I$3,BD!$B$3:$B$5001,$A$5,BD!$L$3:$L$5001,"<>")=0,"",SUMIFS(BD!$L$3:$L$5001,BD!$A$3:$A$5001,I$3,BD!$B$3:$B$5001,$A$5))) | J14: =IF(J$3="","",IF(COUNTIFS(BD!$A$3:$A$5001,J$3,BD!$B$3:$B$5001,$A$5,BD!$L$3:$L$5001,"<>")=0,"",SUMIFS(BD!$L$3:$L$5001,BD!$A$3:$A$5001,J$3,BD!$B$3:$B$5001,$A$5))) | K14: =IF(K$3="","",IF(COUNTIFS(BD!$A$3:$A$5001,K$3,BD!$B$3:$B$5001,$A$5,BD!$L$3:$L$5001,"<>")=0,"",SUMIFS(BD!$L$3:$L$5001,BD!$A$3:$A$5001,K$3,BD!$B$3:$B$5001,$A$5))) | L14: =IF(L$3="","",IF(COUNTIFS(BD!$A$3:$A$5001,L$3,BD!$B$3:$B$5001,$A$5,BD!$L$3:$L$5001,"<>")=0,"",SUMIFS(BD!$L$3:$L$5001,BD!$A$3:$A$5001,L$3,BD!$B$3:$B$5001,$A$5))) | M14: =IF(M$3="","",IF(COUNTIFS(BD!$A$3:$A$5001,M$3,BD!$B$3:$B$5001,$A$5,BD!$L$3:$L$5001,"<>")=0,"",SUMIFS(BD!$L$3:$L$5001,BD!$A$3:$A$5001,M$3,BD!$B$3:$B$5001,$A$5))) | ... AJ14: =IF(AJ$3="","",IF(COUNTIFS(BD!$A$3:$A$5001,AJ$3,BD!$B$3:$B$5001,$A$5,BD!$L$3:$L$5001,"<>")=0,"",SUMIFS(BD!$L$3:$L$5001,BD!$A$3:$A$5001,AJ$3,BD!$B$3:$B$5001,$A$5))) | AK14: =IF(COUNT(F14:AJ14)=0,"",SUM(F14:AJ14))
C15: Bags Expedidos | D15: =IFERROR(1/(1/INDEX(BD!$AF$33:$AZ$33,MATCH($A$5,BD!$AF$22:$AZ$22,0))),"") | F15: =IF(F$3="","",IF(COUNTIFS(BD!$A$3:$A$5001,F$3,BD!$B$3:$B$5001,$A$5,BD!$M$3:$M$5001,"<>")=0,"",SUMIFS(BD!$M$3:$M$5001,BD!$A$3:$A$5001,F$3,BD!$B$3:$B$5001,$A$5))) | G15: =IF(G$3="","",IF(COUNTIFS(BD!$A$3:$A$5001,G$3,BD!$B$3:$B$5001,$A$5,BD!$M$3:$M$5001,"<>")=0,"",SUMIFS(BD!$M$3:$M$5001,BD!$A$3:$A$5001,G$3,BD!$B$3:$B$5001,$A$5))) | H15: =IF(H$3="","",IF(COUNTIFS(BD!$A$3:$A$5001,H$3,BD!$B$3:$B$5001,$A$5,BD!$M$3:$M$5001,"<>")=0,"",SUMIFS(BD!$M$3:$M$5001,BD!$A$3:$A$5001,H$3,BD!$B$3:$B$5001,$A$5))) | I15: =IF(I$3="","",IF(COUNTIFS(BD!$A$3:$A$5001,I$3,BD!$B$3:$B$5001,$A$5,BD!$M$3:$M$5001,"<>")=0,"",SUMIFS(BD!$M$3:$M$5001,BD!$A$3:$A$5001,I$3,BD!$B$3:$B$5001,$A$5))) | J15: =IF(J$3="","",IF(COUNTIFS(BD!$A$3:$A$5001,J$3,BD!$B$3:$B$5001,$A$5,BD!$M$3:$M$5001,"<>")=0,"",SUMIFS(BD!$M$3:$M$5001,BD!$A$3:$A$5001,J$3,BD!$B$3:$B$5001,$A$5))) | K15: =IF(K$3="","",IF(COUNTIFS(BD!$A$3:$A$5001,K$3,BD!$B$3:$B$5001,$A$5,BD!$M$3:$M$5001,"<>")=0,"",SUMIFS(BD!$M$3:$M$5001,BD!$A$3:$A$5001,K$3,BD!$B$3:$B$5001,$A$5))) | L15: =IF(L$3="","",IF(COUNTIFS(BD!$A$3:$A$5001,L$3,BD!$B$3:$B$5001,$A$5,BD!$M$3:$M$5001,"<>")=0,"",SUMIFS(BD!$M$3:$M$5001,BD!$A$3:$A$5001,L$3,BD!$B$3:$B$5001,$A$5))) | M15: =IF(M$3="","",IF(COUNTIFS(BD!$A$3:$A$5001,M$3,BD!$B$3:$B$5001,$A$5,BD!$M$3:$M$5001,"<>")=0,"",SUMIFS(BD!$M$3:$M$5001,BD!$A$3:$A$5001,M$3,BD!$B$3:$B$5001,$A$5))) | ... AJ15: =IF(AJ$3="","",IF(COUNTIFS(BD!$A$3:$A$5001,AJ$3,BD!$B$3:$B$5001,$A$5,BD!$M$3:$M$5001,"<>")=0,"",SUMIFS(BD!$M$3:$M$5001,BD!$A$3:$A$5001,AJ$3,BD!$B$3:$B$5001,$A$5))) | AK15: =IF(COUNT(F15:AJ15)=0,"",SUM(F15:AJ15))
B16: NC | C16: Incidentes | D16: =IFERROR(1/(1/INDEX(BD!$AF$34:$AZ$34,MATCH($A$5,BD!$AF$22:$AZ$22,0))),"") | F16: =IF(F$3="","",IF(COUNTIFS(BD!$A$3:$A$5001,F$3,BD!$B$3:$B$5001,$A$5,BD!$N$3:$N$5001,"<>")=0,"",SUMIFS(BD!$N$3:$N$5001,BD!$A$3:$A$5001,F$3,BD!$B$3:$B$5001,$A$5))) | G16: =IF(G$3="","",IF(COUNTIFS(BD!$A$3:$A$5001,G$3,BD!$B$3:$B$5001,$A$5,BD!$N$3:$N$5001,"<>")=0,"",SUMIFS(BD!$N$3:$N$5001,BD!$A$3:$A$5001,G$3,BD!$B$3:$B$5001,$A$5))) | H16: =IF(H$3="","",IF(COUNTIFS(BD!$A$3:$A$5001,H$3,BD!$B$3:$B$5001,$A$5,BD!$N$3:$N$5001,"<>")=0,"",SUMIFS(BD!$N$3:$N$5001,BD!$A$3:$A$5001,H$3,BD!$B$3:$B$5001,$A$5))) | I16: =IF(I$3="","",IF(COUNTIFS(BD!$A$3:$A$5001,I$3,BD!$B$3:$B$5001,$A$5,BD!$N$3:$N$5001,"<>")=0,"",SUMIFS(BD!$N$3:$N$5001,BD!$A$3:$A$5001,I$3,BD!$B$3:$B$5001,$A$5))) | J16: =IF(J$3="","",IF(COUNTIFS(BD!$A$3:$A$5001,J$3,BD!$B$3:$B$5001,$A$5,BD!$N$3:$N$5001,"<>")=0,"",SUMIFS(BD!$N$3:$N$5001,BD!$A$3:$A$5001,J$3,BD!$B$3:$B$5001,$A$5))) | K16: =IF(K$3="","",IF(COUNTIFS(BD!$A$3:$A$5001,K$3,BD!$B$3:$B$5001,$A$5,BD!$N$3:$N$5001,"<>")=0,"",SUMIFS(BD!$N$3:$N$5001,BD!$A$3:$A$5001,K$3,BD!$B$3:$B$5001,$A$5))) | L16: =IF(L$3="","",IF(COUNTIFS(BD!$A$3:$A$5001,L$3,BD!$B$3:$B$5001,$A$5,BD!$N$3:$N$5001,"<>")=0,"",SUMIFS(BD!$N$3:$N$5001,BD!$A$3:$A$5001,L$3,BD!$B$3:$B$5001,$A$5))) | M16: =IF(M$3="","",IF(COUNTIFS(BD!$A$3:$A$5001,M$3,BD!$B$3:$B$5001,$A$5,BD!$N$3:$N$5001,"<>")=0,"",SUMIFS(BD!$N$3:$N$5001,BD!$A$3:$A$5001,M$3,BD!$B$3:$B$5001,$A$5))) | ... AJ16: =IF(AJ$3="","",IF(COUNTIFS(BD!$A$3:$A$5001,AJ$3,BD!$B$3:$B$5001,$A$5,BD!$N$3:$N$5001,"<>")=0,"",SUMIFS(BD!$N$3:$N$5001,BD!$A$3:$A$5001,AJ$3,BD!$B$3:$B$5001,$A$5))) | AK16: =IF(COUNT(F16:AJ16)=0,"",SUM(F16:AJ16))
C17: No show | D17: =IFERROR(1/(1/INDEX(BD!$AF$35:$AZ$35,MATCH($A$5,BD!$AF$22:$AZ$22,0))),"") | F17: =IF(F$3="","",IF(COUNTIFS(BD!$A$3:$A$5001,F$3,BD!$B$3:$B$5001,$A$5,BD!$O$3:$O$5001,"<>")=0,"",SUMIFS(BD!$O$3:$O$5001,BD!$A$3:$A$5001,F$3,BD!$B$3:$B$5001,$A$5))) | G17: =IF(G$3="","",IF(COUNTIFS(BD!$A$3:$A$5001,G$3,BD!$B$3:$B$5001,$A$5,BD!$O$3:$O$5001,"<>")=0,"",SUMIFS(BD!$O$3:$O$5001,BD!$A$3:$A$5001,G$3,BD!$B$3:$B$5001,$A$5))) | H17: =IF(H$3="","",IF(COUNTIFS(BD!$A$3:$A$5001,H$3,BD!$B$3:$B$5001,$A$5,BD!$O$3:$O$5001,"<>")=0,"",SUMIFS(BD!$O$3:$O$5001,BD!$A$3:$A$5001,H$3,BD!$B$3:$B$5001,$A$5))) | I17: =IF(I$3="","",IF(COUNTIFS(BD!$A$3:$A$5001,I$3,BD!$B$3:$B$5001,$A$5,BD!$O$3:$O$5001,"<>")=0,"",SUMIFS(BD!$O$3:$O$5001,BD!$A$3:$A$5001,I$3,BD!$B$3:$B$5001,$A$5))) | J17: =IF(J$3="","",IF(COUNTIFS(BD!$A$3:$A$5001,J$3,BD!$B$3:$B$5001,$A$5,BD!$O$3:$O$5001,"<>")=0,"",SUMIFS(BD!$O$3:$O$5001,BD!$A$3:$A$5001,J$3,BD!$B$3:$B$5001,$A$5))) | K17: =IF(K$3="","",IF(COUNTIFS(BD!$A$3:$A$5001,K$3,BD!$B$3:$B$5001,$A$5,BD!$O$3:$O$5001,"<>")=0,"",SUMIFS(BD!$O$3:$O$5001,BD!$A$3:$A$5001,K$3,BD!$B$3:$B$5001,$A$5))) | L17: =IF(L$3="","",IF(COUNTIFS(BD!$A$3:$A$5001,L$3,BD!$B$3:$B$5001,$A$5,BD!$O$3:$O$5001,"<>")=0,"",SUMIFS(BD!$O$3:$O$5001,BD!$A$3:$A$5001,L$3,BD!$B$3:$B$5001,$A$5))) | M17: =IF(M$3="","",IF(COUNTIFS(BD!$A$3:$A$5001,M$3,BD!$B$3:$B$5001,$A$5,BD!$O$3:$O$5001,"<>")=0,"",SUMIFS(BD!$O$3:$O$5001,BD!$A$3:$A$5001,M$3,BD!$B$3:$B$5001,$A$5))) | ... AJ17: =IF(AJ$3="","",IF(COUNTIFS(BD!$A$3:$A$5001,AJ$3,BD!$B$3:$B$5001,$A$5,BD!$O$3:$O$5001,"<>")=0,"",SUMIFS(BD!$O$3:$O$5001,BD!$A$3:$A$5001,AJ$3,BD!$B$3:$B$5001,$A$5))) | AK17: =IF(COUNT(F17:AJ17)=0,"",SUM(F17:AJ17))
C18: Backlog Intralog | D18: =IFERROR(1/(1/INDEX(BD!$AF$36:$AZ$36,MATCH($A$5,BD!$AF$22:$AZ$22,0))),"") | F18: =IF(F$3="","",IF(COUNTIFS(BD!$A$3:$A$5001,F$3,BD!$B$3:$B$5001,$A$5,BD!$P$3:$P$5001,"<>")=0,"",SUMIFS(BD!$P$3:$P$5001,BD!$A$3:$A$5001,F$3,BD!$B$3:$B$5001,$A$5))) | G18: =IF(G$3="","",IF(COUNTIFS(BD!$A$3:$A$5001,G$3,BD!$B$3:$B$5001,$A$5,BD!$P$3:$P$5001,"<>")=0,"",SUMIFS(BD!$P$3:$P$5001,BD!$A$3:$A$5001,G$3,BD!$B$3:$B$5001,$A$5))) | H18: =IF(H$3="","",IF(COUNTIFS(BD!$A$3:$A$5001,H$3,BD!$B$3:$B$5001,$A$5,BD!$P$3:$P$5001,"<>")=0,"",SUMIFS(BD!$P$3:$P$5001,BD!$A$3:$A$5001,H$3,BD!$B$3:$B$5001,$A$5))) | I18: =IF(I$3="","",IF(COUNTIFS(BD!$A$3:$A$5001,I$3,BD!$B$3:$B$5001,$A$5,BD!$P$3:$P$5001,"<>")=0,"",SUMIFS(BD!$P$3:$P$5001,BD!$A$3:$A$5001,I$3,BD!$B$3:$B$5001,$A$5))) | J18: =IF(J$3="","",IF(COUNTIFS(BD!$A$3:$A$5001,J$3,BD!$B$3:$B$5001,$A$5,BD!$P$3:$P$5001,"<>")=0,"",SUMIFS(BD!$P$3:$P$5001,BD!$A$3:$A$5001,J$3,BD!$B$3:$B$5001,$A$5))) | K18: =IF(K$3="","",IF(COUNTIFS(BD!$A$3:$A$5001,K$3,BD!$B$3:$B$5001,$A$5,BD!$P$3:$P$5001,"<>")=0,"",SUMIFS(BD!$P$3:$P$5001,BD!$A$3:$A$5001,K$3,BD!$B$3:$B$5001,$A$5))) | L18: =IF(L$3="","",IF(COUNTIFS(BD!$A$3:$A$5001,L$3,BD!$B$3:$B$5001,$A$5,BD!$P$3:$P$5001,"<>")=0,"",SUMIFS(BD!$P$3:$P$5001,BD!$A$3:$A$5001,L$3,BD!$B$3:$B$5001,$A$5))) | M18: =IF(M$3="","",IF(COUNTIFS(BD!$A$3:$A$5001,M$3,BD!$B$3:$B$5001,$A$5,BD!$P$3:$P$5001,"<>")=0,"",SUMIFS(BD!$P$3:$P$5001,BD!$A$3:$A$5001,M$3,BD!$B$3:$B$5001,$A$5))) | ... AJ18: =IF(AJ$3="","",IF(COUNTIFS(BD!$A$3:$A$5001,AJ$3,BD!$B$3:$B$5001,$A$5,BD!$P$3:$P$5001,"<>")=0,"",SUMIFS(BD!$P$3:$P$5001,BD!$A$3:$A$5001,AJ$3,BD!$B$3:$B$5001,$A$5))) | AK18: =IFERROR(LOOKUP(9.99E+307,F18:AJ18),"")
C19: Backlog Cliente | D19: =IFERROR(1/(1/INDEX(BD!$AF$37:$AZ$37,MATCH($A$5,BD!$AF$22:$AZ$22,0))),"") | F19: =IF(F$3="","",IF(COUNTIFS(BD!$A$3:$A$5001,F$3,BD!$B$3:$B$5001,$A$5,BD!$Q$3:$Q$5001,"<>")=0,"",SUMIFS(BD!$Q$3:$Q$5001,BD!$A$3:$A$5001,F$3,BD!$B$3:$B$5001,$A$5))) | G19: =IF(G$3="","",IF(COUNTIFS(BD!$A$3:$A$5001,G$3,BD!$B$3:$B$5001,$A$5,BD!$Q$3:$Q$5001,"<>")=0,"",SUMIFS(BD!$Q$3:$Q$5001,BD!$A$3:$A$5001,G$3,BD!$B$3:$B$5001,$A$5))) | H19: =IF(H$3="","",IF(COUNTIFS(BD!$A$3:$A$5001,H$3,BD!$B$3:$B$5001,$A$5,BD!$Q$3:$Q$5001,"<>")=0,"",SUMIFS(BD!$Q$3:$Q$5001,BD!$A$3:$A$5001,H$3,BD!$B$3:$B$5001,$A$5))) | I19: =IF(I$3="","",IF(COUNTIFS(BD!$A$3:$A$5001,I$3,BD!$B$3:$B$5001,$A$5,BD!$Q$3:$Q$5001,"<>")=0,"",SUMIFS(BD!$Q$3:$Q$5001,BD!$A$3:$A$5001,I$3,BD!$B$3:$B$5001,$A$5))) | J19: =IF(J$3="","",IF(COUNTIFS(BD!$A$3:$A$5001,J$3,BD!$B$3:$B$5001,$A$5,BD!$Q$3:$Q$5001,"<>")=0,"",SUMIFS(BD!$Q$3:$Q$5001,BD!$A$3:$A$5001,J$3,BD!$B$3:$B$5001,$A$5))) | K19: =IF(K$3="","",IF(COUNTIFS(BD!$A$3:$A$5001,K$3,BD!$B$3:$B$5001,$A$5,BD!$Q$3:$Q$5001,"<>")=0,"",SUMIFS(BD!$Q$3:$Q$5001,BD!$A$3:$A$5001,K$3,BD!$B$3:$B$5001,$A$5))) | L19: =IF(L$3="","",IF(COUNTIFS(BD!$A$3:$A$5001,L$3,BD!$B$3:$B$5001,$A$5,BD!$Q$3:$Q$5001,"<>")=0,"",SUMIFS(BD!$Q$3:$Q$5001,BD!$A$3:$A$5001,L$3,BD!$B$3:$B$5001,$A$5))) | M19: =IF(M$3="","",IF(COUNTIFS(BD!$A$3:$A$5001,M$3,BD!$B$3:$B$5001,$A$5,BD!$Q$3:$Q$5001,"<>")=0,"",SUMIFS(BD!$Q$3:$Q$5001,BD!$A$3:$A$5001,M$3,BD!$B$3:$B$5001,$A$5))) | ... AJ19: =IF(AJ$3="","",IF(COUNTIFS(BD!$A$3:$A$5001,AJ$3,BD!$B$3:$B$5001,$A$5,BD!$Q$3:$Q$5001,"<>")=0,"",SUMIFS(BD!$Q$3:$Q$5001,BD!$A$3:$A$5001,AJ$3,BD!$B$3:$B$5001,$A$5))) | AK19: =IFERROR(LOOKUP(9.99E+307,F19:AJ19),"")
B20: OCUPAÇÃO (P.P) | C20: Posições Disponíveis | D20: =IFERROR(1/(1/INDEX(BD!$AF$38:$AZ$38,MATCH($A$5,BD!$AF$22:$AZ$22,0))),"") | F20: =IF(F$3="","",IF(COUNTIFS(BD!$A$3:$A$5001,F$3,BD!$B$3:$B$5001,$A$5,BD!$R$3:$R$5001,"<>")=0,"",SUMIFS(BD!$R$3:$R$5001,BD!$A$3:$A$5001,F$3,BD!$B$3:$B$5001,$A$5))) | G20: =IF(G$3="","",IF(COUNTIFS(BD!$A$3:$A$5001,G$3,BD!$B$3:$B$5001,$A$5,BD!$R$3:$R$5001,"<>")=0,"",SUMIFS(BD!$R$3:$R$5001,BD!$A$3:$A$5001,G$3,BD!$B$3:$B$5001,$A$5))) | H20: =IF(H$3="","",IF(COUNTIFS(BD!$A$3:$A$5001,H$3,BD!$B$3:$B$5001,$A$5,BD!$R$3:$R$5001,"<>")=0,"",SUMIFS(BD!$R$3:$R$5001,BD!$A$3:$A$5001,H$3,BD!$B$3:$B$5001,$A$5))) | I20: =IF(I$3="","",IF(COUNTIFS(BD!$A$3:$A$5001,I$3,BD!$B$3:$B$5001,$A$5,BD!$R$3:$R$5001,"<>")=0,"",SUMIFS(BD!$R$3:$R$5001,BD!$A$3:$A$5001,I$3,BD!$B$3:$B$5001,$A$5))) | J20: =IF(J$3="","",IF(COUNTIFS(BD!$A$3:$A$5001,J$3,BD!$B$3:$B$5001,$A$5,BD!$R$3:$R$5001,"<>")=0,"",SUMIFS(BD!$R$3:$R$5001,BD!$A$3:$A$5001,J$3,BD!$B$3:$B$5001,$A$5))) | K20: =IF(K$3="","",IF(COUNTIFS(BD!$A$3:$A$5001,K$3,BD!$B$3:$B$5001,$A$5,BD!$R$3:$R$5001,"<>")=0,"",SUMIFS(BD!$R$3:$R$5001,BD!$A$3:$A$5001,K$3,BD!$B$3:$B$5001,$A$5))) | L20: =IF(L$3="","",IF(COUNTIFS(BD!$A$3:$A$5001,L$3,BD!$B$3:$B$5001,$A$5,BD!$R$3:$R$5001,"<>")=0,"",SUMIFS(BD!$R$3:$R$5001,BD!$A$3:$A$5001,L$3,BD!$B$3:$B$5001,$A$5))) | M20: =IF(M$3="","",IF(COUNTIFS(BD!$A$3:$A$5001,M$3,BD!$B$3:$B$5001,$A$5,BD!$R$3:$R$5001,"<>")=0,"",SUMIFS(BD!$R$3:$R$5001,BD!$A$3:$A$5001,M$3,BD!$B$3:$B$5001,$A$5))) | ... AJ20: =IF(AJ$3="","",IF(COUNTIFS(BD!$A$3:$A$5001,AJ$3,BD!$B$3:$B$5001,$A$5,BD!$R$3:$R$5001,"<>")=0,"",SUMIFS(BD!$R$3:$R$5001,BD!$A$3:$A$5001,AJ$3,BD!$B$3:$B$5001,$A$5))) | AK20: =IF(COUNT(F20:AJ20)>0,LOOKUP(9.99E+307,F20:AJ20),IFERROR(IF(INDEX(BD!$AC$3:$AC$5001,MATCH($A$5,BD!$B$3:$B$5001,0))&""="Contrato","",INDEX(BD!$AC$3:$AC$5001,MATCH($A$5,BD!$B$3:$B$5001,0))&""),""))
C21: Posições Ocupadas | D21: =IFERROR(1/(1/INDEX(BD!$AF$39:$AZ$39,MATCH($A$5,BD!$AF$22:$AZ$22,0))),"") | F21: =IF(F$3="","",IF(COUNTIFS(BD!$A$3:$A$5001,F$3,BD!$B$3:$B$5001,$A$5,BD!$S$3:$S$5001,"<>")=0,"",SUMIFS(BD!$S$3:$S$5001,BD!$A$3:$A$5001,F$3,BD!$B$3:$B$5001,$A$5))) | G21: =IF(G$3="","",IF(COUNTIFS(BD!$A$3:$A$5001,G$3,BD!$B$3:$B$5001,$A$5,BD!$S$3:$S$5001,"<>")=0,"",SUMIFS(BD!$S$3:$S$5001,BD!$A$3:$A$5001,G$3,BD!$B$3:$B$5001,$A$5))) | H21: =IF(H$3="","",IF(COUNTIFS(BD!$A$3:$A$5001,H$3,BD!$B$3:$B$5001,$A$5,BD!$S$3:$S$5001,"<>")=0,"",SUMIFS(BD!$S$3:$S$5001,BD!$A$3:$A$5001,H$3,BD!$B$3:$B$5001,$A$5))) | I21: =IF(I$3="","",IF(COUNTIFS(BD!$A$3:$A$5001,I$3,BD!$B$3:$B$5001,$A$5,BD!$S$3:$S$5001,"<>")=0,"",SUMIFS(BD!$S$3:$S$5001,BD!$A$3:$A$5001,I$3,BD!$B$3:$B$5001,$A$5))) | J21: =IF(J$3="","",IF(COUNTIFS(BD!$A$3:$A$5001,J$3,BD!$B$3:$B$5001,$A$5,BD!$S$3:$S$5001,"<>")=0,"",SUMIFS(BD!$S$3:$S$5001,BD!$A$3:$A$5001,J$3,BD!$B$3:$B$5001,$A$5))) | K21: =IF(K$3="","",IF(COUNTIFS(BD!$A$3:$A$5001,K$3,BD!$B$3:$B$5001,$A$5,BD!$S$3:$S$5001,"<>")=0,"",SUMIFS(BD!$S$3:$S$5001,BD!$A$3:$A$5001,K$3,BD!$B$3:$B$5001,$A$5))) | L21: =IF(L$3="","",IF(COUNTIFS(BD!$A$3:$A$5001,L$3,BD!$B$3:$B$5001,$A$5,BD!$S$3:$S$5001,"<>")=0,"",SUMIFS(BD!$S$3:$S$5001,BD!$A$3:$A$5001,L$3,BD!$B$3:$B$5001,$A$5))) | M21: =IF(M$3="","",IF(COUNTIFS(BD!$A$3:$A$5001,M$3,BD!$B$3:$B$5001,$A$5,BD!$S$3:$S$5001,"<>")=0,"",SUMIFS(BD!$S$3:$S$5001,BD!$A$3:$A$5001,M$3,BD!$B$3:$B$5001,$A$5))) | ... AJ21: =IF(AJ$3="","",IF(COUNTIFS(BD!$A$3:$A$5001,AJ$3,BD!$B$3:$B$5001,$A$5,BD!$S$3:$S$5001,"<>")=0,"",SUMIFS(BD!$S$3:$S$5001,BD!$A$3:$A$5001,AJ$3,BD!$B$3:$B$5001,$A$5))) | AK21: =IFERROR(LOOKUP(9.99E+307,F21:AJ21),"")
C22: Taxa de Ocupação | D22: =IFERROR(1/(1/INDEX(BD!$AF$40:$AZ$40,MATCH($A$5,BD!$AF$22:$AZ$22,0))),"") | F22: =IF(AND(ISNUMBER(F20),ISNUMBER(F21)),IF(F20>0,F21/F20,""),"") | G22: =IF(AND(ISNUMBER(G20),ISNUMBER(G21)),IF(G20>0,G21/G20,""),"") | H22: =IF(AND(ISNUMBER(H20),ISNUMBER(H21)),IF(H20>0,H21/H20,""),"") | I22: =IF(AND(ISNUMBER(I20),ISNUMBER(I21)),IF(I20>0,I21/I20,""),"") | J22: =IF(AND(ISNUMBER(J20),ISNUMBER(J21)),IF(J20>0,J21/J20,""),"") | K22: =IF(AND(ISNUMBER(K20),ISNUMBER(K21)),IF(K20>0,K21/K20,""),"") | L22: =IF(AND(ISNUMBER(L20),ISNUMBER(L21)),IF(L20>0,L21/L20,""),"") | M22: =IF(AND(ISNUMBER(M20),ISNUMBER(M21)),IF(M20>0,M21/M20,""),"") | ... AK22: =IF(AND(ISNUMBER(AK20),ISNUMBER(AK21)),IF(AK20>0,AK21/AK20,""),"")
B23: GENTE | C23: Efetivo Op. | D23: =IFERROR(1/(1/INDEX(BD!$AF$41:$AZ$41,MATCH($A$5,BD!$AF$22:$AZ$22,0))),"") | F23: =IF(F$3="","",IF(COUNTIFS(BD!$A$3:$A$5001,F$3,BD!$B$3:$B$5001,$A$5,BD!$T$3:$T$5001,"<>")=0,"",SUMIFS(BD!$T$3:$T$5001,BD!$A$3:$A$5001,F$3,BD!$B$3:$B$5001,$A$5))) | G23: =IF(G$3="","",IF(COUNTIFS(BD!$A$3:$A$5001,G$3,BD!$B$3:$B$5001,$A$5,BD!$T$3:$T$5001,"<>")=0,"",SUMIFS(BD!$T$3:$T$5001,BD!$A$3:$A$5001,G$3,BD!$B$3:$B$5001,$A$5))) | H23: =IF(H$3="","",IF(COUNTIFS(BD!$A$3:$A$5001,H$3,BD!$B$3:$B$5001,$A$5,BD!$T$3:$T$5001,"<>")=0,"",SUMIFS(BD!$T$3:$T$5001,BD!$A$3:$A$5001,H$3,BD!$B$3:$B$5001,$A$5))) | I23: =IF(I$3="","",IF(COUNTIFS(BD!$A$3:$A$5001,I$3,BD!$B$3:$B$5001,$A$5,BD!$T$3:$T$5001,"<>")=0,"",SUMIFS(BD!$T$3:$T$5001,BD!$A$3:$A$5001,I$3,BD!$B$3:$B$5001,$A$5))) | J23: =IF(J$3="","",IF(COUNTIFS(BD!$A$3:$A$5001,J$3,BD!$B$3:$B$5001,$A$5,BD!$T$3:$T$5001,"<>")=0,"",SUMIFS(BD!$T$3:$T$5001,BD!$A$3:$A$5001,J$3,BD!$B$3:$B$5001,$A$5))) | K23: =IF(K$3="","",IF(COUNTIFS(BD!$A$3:$A$5001,K$3,BD!$B$3:$B$5001,$A$5,BD!$T$3:$T$5001,"<>")=0,"",SUMIFS(BD!$T$3:$T$5001,BD!$A$3:$A$5001,K$3,BD!$B$3:$B$5001,$A$5))) | L23: =IF(L$3="","",IF(COUNTIFS(BD!$A$3:$A$5001,L$3,BD!$B$3:$B$5001,$A$5,BD!$T$3:$T$5001,"<>")=0,"",SUMIFS(BD!$T$3:$T$5001,BD!$A$3:$A$5001,L$3,BD!$B$3:$B$5001,$A$5))) | M23: =IF(M$3="","",IF(COUNTIFS(BD!$A$3:$A$5001,M$3,BD!$B$3:$B$5001,$A$5,BD!$T$3:$T$5001,"<>")=0,"",SUMIFS(BD!$T$3:$T$5001,BD!$A$3:$A$5001,M$3,BD!$B$3:$B$5001,$A$5))) | ... AJ23: =IF(AJ$3="","",IF(COUNTIFS(BD!$A$3:$A$5001,AJ$3,BD!$B$3:$B$5001,$A$5,BD!$T$3:$T$5001,"<>")=0,"",SUMIFS(BD!$T$3:$T$5001,BD!$A$3:$A$5001,AJ$3,BD!$B$3:$B$5001,$A$5))) | AK23: =IFERROR(LOOKUP(9.99E+307,F23:AJ23),"")
C24: Falta | D24: =IFERROR(1/(1/INDEX(BD!$AF$42:$AZ$42,MATCH($A$5,BD!$AF$22:$AZ$22,0))),"") | F24: =IF(F$3="","",IF(COUNTIFS(BD!$A$3:$A$5001,F$3,BD!$B$3:$B$5001,$A$5,BD!$U$3:$U$5001,"<>")=0,"",SUMIFS(BD!$U$3:$U$5001,BD!$A$3:$A$5001,F$3,BD!$B$3:$B$5001,$A$5))) | G24: =IF(G$3="","",IF(COUNTIFS(BD!$A$3:$A$5001,G$3,BD!$B$3:$B$5001,$A$5,BD!$U$3:$U$5001,"<>")=0,"",SUMIFS(BD!$U$3:$U$5001,BD!$A$3:$A$5001,G$3,BD!$B$3:$B$5001,$A$5))) | H24: =IF(H$3="","",IF(COUNTIFS(BD!$A$3:$A$5001,H$3,BD!$B$3:$B$5001,$A$5,BD!$U$3:$U$5001,"<>")=0,"",SUMIFS(BD!$U$3:$U$5001,BD!$A$3:$A$5001,H$3,BD!$B$3:$B$5001,$A$5))) | I24: =IF(I$3="","",IF(COUNTIFS(BD!$A$3:$A$5001,I$3,BD!$B$3:$B$5001,$A$5,BD!$U$3:$U$5001,"<>")=0,"",SUMIFS(BD!$U$3:$U$5001,BD!$A$3:$A$5001,I$3,BD!$B$3:$B$5001,$A$5))) | J24: =IF(J$3="","",IF(COUNTIFS(BD!$A$3:$A$5001,J$3,BD!$B$3:$B$5001,$A$5,BD!$U$3:$U$5001,"<>")=0,"",SUMIFS(BD!$U$3:$U$5001,BD!$A$3:$A$5001,J$3,BD!$B$3:$B$5001,$A$5))) | K24: =IF(K$3="","",IF(COUNTIFS(BD!$A$3:$A$5001,K$3,BD!$B$3:$B$5001,$A$5,BD!$U$3:$U$5001,"<>")=0,"",SUMIFS(BD!$U$3:$U$5001,BD!$A$3:$A$5001,K$3,BD!$B$3:$B$5001,$A$5))) | L24: =IF(L$3="","",IF(COUNTIFS(BD!$A$3:$A$5001,L$3,BD!$B$3:$B$5001,$A$5,BD!$U$3:$U$5001,"<>")=0,"",SUMIFS(BD!$U$3:$U$5001,BD!$A$3:$A$5001,L$3,BD!$B$3:$B$5001,$A$5))) | M24: =IF(M$3="","",IF(COUNTIFS(BD!$A$3:$A$5001,M$3,BD!$B$3:$B$5001,$A$5,BD!$U$3:$U$5001,"<>")=0,"",SUMIFS(BD!$U$3:$U$5001,BD!$A$3:$A$5001,M$3,BD!$B$3:$B$5001,$A$5))) | ... AJ24: =IF(AJ$3="","",IF(COUNTIFS(BD!$A$3:$A$5001,AJ$3,BD!$B$3:$B$5001,$A$5,BD!$U$3:$U$5001,"<>")=0,"",SUMIFS(BD!$U$3:$U$5001,BD!$A$3:$A$5001,AJ$3,BD!$B$3:$B$5001,$A$5))) | AK24: =IF(COUNT(F24:AJ24)=0,"",SUM(F24:AJ24))
C25: Absenteísmo (H/H) | D25: =IFERROR(1/(1/INDEX(BD!$AF$43:$AZ$43,MATCH($A$5,BD!$AF$22:$AZ$22,0))),"") | F25: =IF(F$3="","",IF(COUNTIFS(BD!$A$3:$A$5001,F$3,BD!$B$3:$B$5001,$A$5,BD!$V$3:$V$5001,"<>")=0,"",SUMIFS(BD!$V$3:$V$5001,BD!$A$3:$A$5001,F$3,BD!$B$3:$B$5001,$A$5))) | G25: =IF(G$3="","",IF(COUNTIFS(BD!$A$3:$A$5001,G$3,BD!$B$3:$B$5001,$A$5,BD!$V$3:$V$5001,"<>")=0,"",SUMIFS(BD!$V$3:$V$5001,BD!$A$3:$A$5001,G$3,BD!$B$3:$B$5001,$A$5))) | H25: =IF(H$3="","",IF(COUNTIFS(BD!$A$3:$A$5001,H$3,BD!$B$3:$B$5001,$A$5,BD!$V$3:$V$5001,"<>")=0,"",SUMIFS(BD!$V$3:$V$5001,BD!$A$3:$A$5001,H$3,BD!$B$3:$B$5001,$A$5))) | I25: =IF(I$3="","",IF(COUNTIFS(BD!$A$3:$A$5001,I$3,BD!$B$3:$B$5001,$A$5,BD!$V$3:$V$5001,"<>")=0,"",SUMIFS(BD!$V$3:$V$5001,BD!$A$3:$A$5001,I$3,BD!$B$3:$B$5001,$A$5))) | J25: =IF(J$3="","",IF(COUNTIFS(BD!$A$3:$A$5001,J$3,BD!$B$3:$B$5001,$A$5,BD!$V$3:$V$5001,"<>")=0,"",SUMIFS(BD!$V$3:$V$5001,BD!$A$3:$A$5001,J$3,BD!$B$3:$B$5001,$A$5))) | K25: =IF(K$3="","",IF(COUNTIFS(BD!$A$3:$A$5001,K$3,BD!$B$3:$B$5001,$A$5,BD!$V$3:$V$5001,"<>")=0,"",SUMIFS(BD!$V$3:$V$5001,BD!$A$3:$A$5001,K$3,BD!$B$3:$B$5001,$A$5))) | L25: =IF(L$3="","",IF(COUNTIFS(BD!$A$3:$A$5001,L$3,BD!$B$3:$B$5001,$A$5,BD!$V$3:$V$5001,"<>")=0,"",SUMIFS(BD!$V$3:$V$5001,BD!$A$3:$A$5001,L$3,BD!$B$3:$B$5001,$A$5))) | M25: =IF(M$3="","",IF(COUNTIFS(BD!$A$3:$A$5001,M$3,BD!$B$3:$B$5001,$A$5,BD!$V$3:$V$5001,"<>")=0,"",SUMIFS(BD!$V$3:$V$5001,BD!$A$3:$A$5001,M$3,BD!$B$3:$B$5001,$A$5))) | ... AJ25: =IF(AJ$3="","",IF(COUNTIFS(BD!$A$3:$A$5001,AJ$3,BD!$B$3:$B$5001,$A$5,BD!$V$3:$V$5001,"<>")=0,"",SUMIFS(BD!$V$3:$V$5001,BD!$A$3:$A$5001,AJ$3,BD!$B$3:$B$5001,$A$5))) | AK25: =IF(COUNT(F25:AJ25)=0,"",SUM(F25:AJ25))
C26: Folga | D26: =IFERROR(1/(1/INDEX(BD!$AF$44:$AZ$44,MATCH($A$5,BD!$AF$22:$AZ$22,0))),"") | F26: =IF(F$3="","",IF(COUNTIFS(BD!$A$3:$A$5001,F$3,BD!$B$3:$B$5001,$A$5,BD!$W$3:$W$5001,"<>")=0,"",SUMIFS(BD!$W$3:$W$5001,BD!$A$3:$A$5001,F$3,BD!$B$3:$B$5001,$A$5))) | G26: =IF(G$3="","",IF(COUNTIFS(BD!$A$3:$A$5001,G$3,BD!$B$3:$B$5001,$A$5,BD!$W$3:$W$5001,"<>")=0,"",SUMIFS(BD!$W$3:$W$5001,BD!$A$3:$A$5001,G$3,BD!$B$3:$B$5001,$A$5))) | H26: =IF(H$3="","",IF(COUNTIFS(BD!$A$3:$A$5001,H$3,BD!$B$3:$B$5001,$A$5,BD!$W$3:$W$5001,"<>")=0,"",SUMIFS(BD!$W$3:$W$5001,BD!$A$3:$A$5001,H$3,BD!$B$3:$B$5001,$A$5))) | I26: =IF(I$3="","",IF(COUNTIFS(BD!$A$3:$A$5001,I$3,BD!$B$3:$B$5001,$A$5,BD!$W$3:$W$5001,"<>")=0,"",SUMIFS(BD!$W$3:$W$5001,BD!$A$3:$A$5001,I$3,BD!$B$3:$B$5001,$A$5))) | J26: =IF(J$3="","",IF(COUNTIFS(BD!$A$3:$A$5001,J$3,BD!$B$3:$B$5001,$A$5,BD!$W$3:$W$5001,"<>")=0,"",SUMIFS(BD!$W$3:$W$5001,BD!$A$3:$A$5001,J$3,BD!$B$3:$B$5001,$A$5))) | K26: =IF(K$3="","",IF(COUNTIFS(BD!$A$3:$A$5001,K$3,BD!$B$3:$B$5001,$A$5,BD!$W$3:$W$5001,"<>")=0,"",SUMIFS(BD!$W$3:$W$5001,BD!$A$3:$A$5001,K$3,BD!$B$3:$B$5001,$A$5))) | L26: =IF(L$3="","",IF(COUNTIFS(BD!$A$3:$A$5001,L$3,BD!$B$3:$B$5001,$A$5,BD!$W$3:$W$5001,"<>")=0,"",SUMIFS(BD!$W$3:$W$5001,BD!$A$3:$A$5001,L$3,BD!$B$3:$B$5001,$A$5))) | M26: =IF(M$3="","",IF(COUNTIFS(BD!$A$3:$A$5001,M$3,BD!$B$3:$B$5001,$A$5,BD!$W$3:$W$5001,"<>")=0,"",SUMIFS(BD!$W$3:$W$5001,BD!$A$3:$A$5001,M$3,BD!$B$3:$B$5001,$A$5))) | ... AJ26: =IF(AJ$3="","",IF(COUNTIFS(BD!$A$3:$A$5001,AJ$3,BD!$B$3:$B$5001,$A$5,BD!$W$3:$W$5001,"<>")=0,"",SUMIFS(BD!$W$3:$W$5001,BD!$A$3:$A$5001,AJ$3,BD!$B$3:$B$5001,$A$5))) | AK26: =IF(COUNT(F26:AJ26)=0,"",SUM(F26:AJ26))
C27: Férias | D27: =IFERROR(1/(1/INDEX(BD!$AF$45:$AZ$45,MATCH($A$5,BD!$AF$22:$AZ$22,0))),"") | F27: =IF(F$3="","",IF(COUNTIFS(BD!$A$3:$A$5001,F$3,BD!$B$3:$B$5001,$A$5,BD!$X$3:$X$5001,"<>")=0,"",SUMIFS(BD!$X$3:$X$5001,BD!$A$3:$A$5001,F$3,BD!$B$3:$B$5001,$A$5))) | G27: =IF(G$3="","",IF(COUNTIFS(BD!$A$3:$A$5001,G$3,BD!$B$3:$B$5001,$A$5,BD!$X$3:$X$5001,"<>")=0,"",SUMIFS(BD!$X$3:$X$5001,BD!$A$3:$A$5001,G$3,BD!$B$3:$B$5001,$A$5))) | H27: =IF(H$3="","",IF(COUNTIFS(BD!$A$3:$A$5001,H$3,BD!$B$3:$B$5001,$A$5,BD!$X$3:$X$5001,"<>")=0,"",SUMIFS(BD!$X$3:$X$5001,BD!$A$3:$A$5001,H$3,BD!$B$3:$B$5001,$A$5))) | I27: =IF(I$3="","",IF(COUNTIFS(BD!$A$3:$A$5001,I$3,BD!$B$3:$B$5001,$A$5,BD!$X$3:$X$5001,"<>")=0,"",SUMIFS(BD!$X$3:$X$5001,BD!$A$3:$A$5001,I$3,BD!$B$3:$B$5001,$A$5))) | J27: =IF(J$3="","",IF(COUNTIFS(BD!$A$3:$A$5001,J$3,BD!$B$3:$B$5001,$A$5,BD!$X$3:$X$5001,"<>")=0,"",SUMIFS(BD!$X$3:$X$5001,BD!$A$3:$A$5001,J$3,BD!$B$3:$B$5001,$A$5))) | K27: =IF(K$3="","",IF(COUNTIFS(BD!$A$3:$A$5001,K$3,BD!$B$3:$B$5001,$A$5,BD!$X$3:$X$5001,"<>")=0,"",SUMIFS(BD!$X$3:$X$5001,BD!$A$3:$A$5001,K$3,BD!$B$3:$B$5001,$A$5))) | L27: =IF(L$3="","",IF(COUNTIFS(BD!$A$3:$A$5001,L$3,BD!$B$3:$B$5001,$A$5,BD!$X$3:$X$5001,"<>")=0,"",SUMIFS(BD!$X$3:$X$5001,BD!$A$3:$A$5001,L$3,BD!$B$3:$B$5001,$A$5))) | M27: =IF(M$3="","",IF(COUNTIFS(BD!$A$3:$A$5001,M$3,BD!$B$3:$B$5001,$A$5,BD!$X$3:$X$5001,"<>")=0,"",SUMIFS(BD!$X$3:$X$5001,BD!$A$3:$A$5001,M$3,BD!$B$3:$B$5001,$A$5))) | ... AJ27: =IF(AJ$3="","",IF(COUNTIFS(BD!$A$3:$A$5001,AJ$3,BD!$B$3:$B$5001,$A$5,BD!$X$3:$X$5001,"<>")=0,"",SUMIFS(BD!$X$3:$X$5001,BD!$A$3:$A$5001,AJ$3,BD!$B$3:$B$5001,$A$5))) | AK27: =IF(COUNT(F27:AJ27)=0,"",SUM(F27:AJ27))
C28: Desligamento | D28: =IFERROR(1/(1/INDEX(BD!$AF$46:$AZ$46,MATCH($A$5,BD!$AF$22:$AZ$22,0))),"") | F28: =IF(F$3="","",IF(COUNTIFS(BD!$A$3:$A$5001,F$3,BD!$B$3:$B$5001,$A$5,BD!$Y$3:$Y$5001,"<>")=0,"",SUMIFS(BD!$Y$3:$Y$5001,BD!$A$3:$A$5001,F$3,BD!$B$3:$B$5001,$A$5))) | G28: =IF(G$3="","",IF(COUNTIFS(BD!$A$3:$A$5001,G$3,BD!$B$3:$B$5001,$A$5,BD!$Y$3:$Y$5001,"<>")=0,"",SUMIFS(BD!$Y$3:$Y$5001,BD!$A$3:$A$5001,G$3,BD!$B$3:$B$5001,$A$5))) | H28: =IF(H$3="","",IF(COUNTIFS(BD!$A$3:$A$5001,H$3,BD!$B$3:$B$5001,$A$5,BD!$Y$3:$Y$5001,"<>")=0,"",SUMIFS(BD!$Y$3:$Y$5001,BD!$A$3:$A$5001,H$3,BD!$B$3:$B$5001,$A$5))) | I28: =IF(I$3="","",IF(COUNTIFS(BD!$A$3:$A$5001,I$3,BD!$B$3:$B$5001,$A$5,BD!$Y$3:$Y$5001,"<>")=0,"",SUMIFS(BD!$Y$3:$Y$5001,BD!$A$3:$A$5001,I$3,BD!$B$3:$B$5001,$A$5))) | J28: =IF(J$3="","",IF(COUNTIFS(BD!$A$3:$A$5001,J$3,BD!$B$3:$B$5001,$A$5,BD!$Y$3:$Y$5001,"<>")=0,"",SUMIFS(BD!$Y$3:$Y$5001,BD!$A$3:$A$5001,J$3,BD!$B$3:$B$5001,$A$5))) | K28: =IF(K$3="","",IF(COUNTIFS(BD!$A$3:$A$5001,K$3,BD!$B$3:$B$5001,$A$5,BD!$Y$3:$Y$5001,"<>")=0,"",SUMIFS(BD!$Y$3:$Y$5001,BD!$A$3:$A$5001,K$3,BD!$B$3:$B$5001,$A$5))) | L28: =IF(L$3="","",IF(COUNTIFS(BD!$A$3:$A$5001,L$3,BD!$B$3:$B$5001,$A$5,BD!$Y$3:$Y$5001,"<>")=0,"",SUMIFS(BD!$Y$3:$Y$5001,BD!$A$3:$A$5001,L$3,BD!$B$3:$B$5001,$A$5))) | M28: =IF(M$3="","",IF(COUNTIFS(BD!$A$3:$A$5001,M$3,BD!$B$3:$B$5001,$A$5,BD!$Y$3:$Y$5001,"<>")=0,"",SUMIFS(BD!$Y$3:$Y$5001,BD!$A$3:$A$5001,M$3,BD!$B$3:$B$5001,$A$5))) | ... AJ28: =IF(AJ$3="","",IF(COUNTIFS(BD!$A$3:$A$5001,AJ$3,BD!$B$3:$B$5001,$A$5,BD!$Y$3:$Y$5001,"<>")=0,"",SUMIFS(BD!$Y$3:$Y$5001,BD!$A$3:$A$5001,AJ$3,BD!$B$3:$B$5001,$A$5))) | AK28: =IF(COUNT(F28:AJ28)=0,"",SUM(F28:AJ28))
C29: Desvios Comportamentais | D29: =IFERROR(1/(1/INDEX(BD!$AF$47:$AZ$47,MATCH($A$5,BD!$AF$22:$AZ$22,0))),"") | F29: =IF(F$3="","",IF(COUNTIFS(BD!$A$3:$A$5001,F$3,BD!$B$3:$B$5001,$A$5,BD!$Z$3:$Z$5001,"<>")=0,"",SUMIFS(BD!$Z$3:$Z$5001,BD!$A$3:$A$5001,F$3,BD!$B$3:$B$5001,$A$5))) | G29: =IF(G$3="","",IF(COUNTIFS(BD!$A$3:$A$5001,G$3,BD!$B$3:$B$5001,$A$5,BD!$Z$3:$Z$5001,"<>")=0,"",SUMIFS(BD!$Z$3:$Z$5001,BD!$A$3:$A$5001,G$3,BD!$B$3:$B$5001,$A$5))) | H29: =IF(H$3="","",IF(COUNTIFS(BD!$A$3:$A$5001,H$3,BD!$B$3:$B$5001,$A$5,BD!$Z$3:$Z$5001,"<>")=0,"",SUMIFS(BD!$Z$3:$Z$5001,BD!$A$3:$A$5001,H$3,BD!$B$3:$B$5001,$A$5))) | I29: =IF(I$3="","",IF(COUNTIFS(BD!$A$3:$A$5001,I$3,BD!$B$3:$B$5001,$A$5,BD!$Z$3:$Z$5001,"<>")=0,"",SUMIFS(BD!$Z$3:$Z$5001,BD!$A$3:$A$5001,I$3,BD!$B$3:$B$5001,$A$5))) | J29: =IF(J$3="","",IF(COUNTIFS(BD!$A$3:$A$5001,J$3,BD!$B$3:$B$5001,$A$5,BD!$Z$3:$Z$5001,"<>")=0,"",SUMIFS(BD!$Z$3:$Z$5001,BD!$A$3:$A$5001,J$3,BD!$B$3:$B$5001,$A$5))) | K29: =IF(K$3="","",IF(COUNTIFS(BD!$A$3:$A$5001,K$3,BD!$B$3:$B$5001,$A$5,BD!$Z$3:$Z$5001,"<>")=0,"",SUMIFS(BD!$Z$3:$Z$5001,BD!$A$3:$A$5001,K$3,BD!$B$3:$B$5001,$A$5))) | L29: =IF(L$3="","",IF(COUNTIFS(BD!$A$3:$A$5001,L$3,BD!$B$3:$B$5001,$A$5,BD!$Z$3:$Z$5001,"<>")=0,"",SUMIFS(BD!$Z$3:$Z$5001,BD!$A$3:$A$5001,L$3,BD!$B$3:$B$5001,$A$5))) | M29: =IF(M$3="","",IF(COUNTIFS(BD!$A$3:$A$5001,M$3,BD!$B$3:$B$5001,$A$5,BD!$Z$3:$Z$5001,"<>")=0,"",SUMIFS(BD!$Z$3:$Z$5001,BD!$A$3:$A$5001,M$3,BD!$B$3:$B$5001,$A$5))) | ... AJ29: =IF(AJ$3="","",IF(COUNTIFS(BD!$A$3:$A$5001,AJ$3,BD!$B$3:$B$5001,$A$5,BD!$Z$3:$Z$5001,"<>")=0,"",SUMIFS(BD!$Z$3:$Z$5001,BD!$A$3:$A$5001,AJ$3,BD!$B$3:$B$5001,$A$5))) | AK29: =IF(COUNT(F29:AJ29)=0,"",SUM(F29:AJ29))
C30: Acidentes CAF | D30: =IFERROR(1/(1/INDEX(BD!$AF$48:$AZ$48,MATCH($A$5,BD!$AF$22:$AZ$22,0))),"") | F30: =IF(F$3="","",IF(COUNTIFS(BD!$A$3:$A$5001,F$3,BD!$B$3:$B$5001,$A$5,BD!$AA$3:$AA$5001,"<>")=0,"",SUMIFS(BD!$AA$3:$AA$5001,BD!$A$3:$A$5001,F$3,BD!$B$3:$B$5001,$A$5))) | G30: =IF(G$3="","",IF(COUNTIFS(BD!$A$3:$A$5001,G$3,BD!$B$3:$B$5001,$A$5,BD!$AA$3:$AA$5001,"<>")=0,"",SUMIFS(BD!$AA$3:$AA$5001,BD!$A$3:$A$5001,G$3,BD!$B$3:$B$5001,$A$5))) | H30: =IF(H$3="","",IF(COUNTIFS(BD!$A$3:$A$5001,H$3,BD!$B$3:$B$5001,$A$5,BD!$AA$3:$AA$5001,"<>")=0,"",SUMIFS(BD!$AA$3:$AA$5001,BD!$A$3:$A$5001,H$3,BD!$B$3:$B$5001,$A$5))) | I30: =IF(I$3="","",IF(COUNTIFS(BD!$A$3:$A$5001,I$3,BD!$B$3:$B$5001,$A$5,BD!$AA$3:$AA$5001,"<>")=0,"",SUMIFS(BD!$AA$3:$AA$5001,BD!$A$3:$A$5001,I$3,BD!$B$3:$B$5001,$A$5))) | J30: =IF(J$3="","",IF(COUNTIFS(BD!$A$3:$A$5001,J$3,BD!$B$3:$B$5001,$A$5,BD!$AA$3:$AA$5001,"<>")=0,"",SUMIFS(BD!$AA$3:$AA$5001,BD!$A$3:$A$5001,J$3,BD!$B$3:$B$5001,$A$5))) | K30: =IF(K$3="","",IF(COUNTIFS(BD!$A$3:$A$5001,K$3,BD!$B$3:$B$5001,$A$5,BD!$AA$3:$AA$5001,"<>")=0,"",SUMIFS(BD!$AA$3:$AA$5001,BD!$A$3:$A$5001,K$3,BD!$B$3:$B$5001,$A$5))) | L30: =IF(L$3="","",IF(COUNTIFS(BD!$A$3:$A$5001,L$3,BD!$B$3:$B$5001,$A$5,BD!$AA$3:$AA$5001,"<>")=0,"",SUMIFS(BD!$AA$3:$AA$5001,BD!$A$3:$A$5001,L$3,BD!$B$3:$B$5001,$A$5))) | M30: =IF(M$3="","",IF(COUNTIFS(BD!$A$3:$A$5001,M$3,BD!$B$3:$B$5001,$A$5,BD!$AA$3:$AA$5001,"<>")=0,"",SUMIFS(BD!$AA$3:$AA$5001,BD!$A$3:$A$5001,M$3,BD!$B$3:$B$5001,$A$5))) | ... AJ30: =IF(AJ$3="","",IF(COUNTIFS(BD!$A$3:$A$5001,AJ$3,BD!$B$3:$B$5001,$A$5,BD!$AA$3:$AA$5001,"<>")=0,"",SUMIFS(BD!$AA$3:$AA$5001,BD!$A$3:$A$5001,AJ$3,BD!$B$3:$B$5001,$A$5))) | AK30: =IF(COUNT(F30:AJ30)=0,"",SUM(F30:AJ30))
C31: Acidentes SAF | D31: =IFERROR(1/(1/INDEX(BD!$AF$49:$AZ$49,MATCH($A$5,BD!$AF$22:$AZ$22,0))),"") | F31: =IF(F$3="","",IF(COUNTIFS(BD!$A$3:$A$5001,F$3,BD!$B$3:$B$5001,$A$5,BD!$AB$3:$AB$5001,"<>")=0,"",SUMIFS(BD!$AB$3:$AB$5001,BD!$A$3:$A$5001,F$3,BD!$B$3:$B$5001,$A$5))) | G31: =IF(G$3="","",IF(COUNTIFS(BD!$A$3:$A$5001,G$3,BD!$B$3:$B$5001,$A$5,BD!$AB$3:$AB$5001,"<>")=0,"",SUMIFS(BD!$AB$3:$AB$5001,BD!$A$3:$A$5001,G$3,BD!$B$3:$B$5001,$A$5))) | H31: =IF(H$3="","",IF(COUNTIFS(BD!$A$3:$A$5001,H$3,BD!$B$3:$B$5001,$A$5,BD!$AB$3:$AB$5001,"<>")=0,"",SUMIFS(BD!$AB$3:$AB$5001,BD!$A$3:$A$5001,H$3,BD!$B$3:$B$5001,$A$5))) | I31: =IF(I$3="","",IF(COUNTIFS(BD!$A$3:$A$5001,I$3,BD!$B$3:$B$5001,$A$5,BD!$AB$3:$AB$5001,"<>")=0,"",SUMIFS(BD!$AB$3:$AB$5001,BD!$A$3:$A$5001,I$3,BD!$B$3:$B$5001,$A$5))) | J31: =IF(J$3="","",IF(COUNTIFS(BD!$A$3:$A$5001,J$3,BD!$B$3:$B$5001,$A$5,BD!$AB$3:$AB$5001,"<>")=0,"",SUMIFS(BD!$AB$3:$AB$5001,BD!$A$3:$A$5001,J$3,BD!$B$3:$B$5001,$A$5))) | K31: =IF(K$3="","",IF(COUNTIFS(BD!$A$3:$A$5001,K$3,BD!$B$3:$B$5001,$A$5,BD!$AB$3:$AB$5001,"<>")=0,"",SUMIFS(BD!$AB$3:$AB$5001,BD!$A$3:$A$5001,K$3,BD!$B$3:$B$5001,$A$5))) | L31: =IF(L$3="","",IF(COUNTIFS(BD!$A$3:$A$5001,L$3,BD!$B$3:$B$5001,$A$5,BD!$AB$3:$AB$5001,"<>")=0,"",SUMIFS(BD!$AB$3:$AB$5001,BD!$A$3:$A$5001,L$3,BD!$B$3:$B$5001,$A$5))) | M31: =IF(M$3="","",IF(COUNTIFS(BD!$A$3:$A$5001,M$3,BD!$B$3:$B$5001,$A$5,BD!$AB$3:$AB$5001,"<>")=0,"",SUMIFS(BD!$AB$3:$AB$5001,BD!$A$3:$A$5001,M$3,BD!$B$3:$B$5001,$A$5))) | ... AJ31: =IF(AJ$3="","",IF(COUNTIFS(BD!$A$3:$A$5001,AJ$3,BD!$B$3:$B$5001,$A$5,BD!$AB$3:$AB$5001,"<>")=0,"",SUMIFS(BD!$AB$3:$AB$5001,BD!$A$3:$A$5001,AJ$3,BD!$B$3:$B$5001,$A$5))) | AK31: =IF(COUNT(F31:AJ31)=0,"",SUM(F31:AJ31))
A33: GM | B33: OUT | C33: Veículos Expedidos | D33: =IFERROR(1/(1/INDEX(BD!$AF$28:$AZ$28,MATCH($A$33,BD!$AF$22:$AZ$22,0))),"") | F33: =IF(F$3="","",IF(COUNTIFS(BD!$A$3:$A$5001,F$3,BD!$B$3:$B$5001,$A$33,BD!$H$3:$H$5001,"<>")=0,"",SUMIFS(BD!$H$3:$H$5001,BD!$A$3:$A$5001,F$3,BD!$B$3:$B$5001,$A$33))) | G33: =IF(G$3="","",IF(COUNTIFS(BD!$A$3:$A$5001,G$3,BD!$B$3:$B$5001,$A$33,BD!$H$3:$H$5001,"<>")=0,"",SUMIFS(BD!$H$3:$H$5001,BD!$A$3:$A$5001,G$3,BD!$B$3:$B$5001,$A$33))) | H33: =IF(H$3="","",IF(COUNTIFS(BD!$A$3:$A$5001,H$3,BD!$B$3:$B$5001,$A$33,BD!$H$3:$H$5001,"<>")=0,"",SUMIFS(BD!$H$3:$H$5001,BD!$A$3:$A$5001,H$3,BD!$B$3:$B$5001,$A$33))) | I33: =IF(I$3="","",IF(COUNTIFS(BD!$A$3:$A$5001,I$3,BD!$B$3:$B$5001,$A$33,BD!$H$3:$H$5001,"<>")=0,"",SUMIFS(BD!$H$3:$H$5001,BD!$A$3:$A$5001,I$3,BD!$B$3:$B$5001,$A$33))) | J33: =IF(J$3="","",IF(COUNTIFS(BD!$A$3:$A$5001,J$3,BD!$B$3:$B$5001,$A$33,BD!$H$3:$H$5001,"<>")=0,"",SUMIFS(BD!$H$3:$H$5001,BD!$A$3:$A$5001,J$3,BD!$B$3:$B$5001,$A$33))) | K33: =IF(K$3="","",IF(COUNTIFS(BD!$A$3:$A$5001,K$3,BD!$B$3:$B$5001,$A$33,BD!$H$3:$H$5001,"<>")=0,"",SUMIFS(BD!$H$3:$H$5001,BD!$A$3:$A$5001,K$3,BD!$B$3:$B$5001,$A$33))) | L33: =IF(L$3="","",IF(COUNTIFS(BD!$A$3:$A$5001,L$3,BD!$B$3:$B$5001,$A$33,BD!$H$3:$H$5001,"<>")=0,"",SUMIFS(BD!$H$3:$H$5001,BD!$A$3:$A$5001,L$3,BD!$B$3:$B$5001,$A$33))) | M33: =IF(M$3="","",IF(COUNTIFS(BD!$A$3:$A$5001,M$3,BD!$B$3:$B$5001,$A$33,BD!$H$3:$H$5001,"<>")=0,"",SUMIFS(BD!$H$3:$H$5001,BD!$A$3:$A$5001,M$3,BD!$B$3:$B$5001,$A$33))) | ... AJ33: =IF(AJ$3="","",IF(COUNTIFS(BD!$A$3:$A$5001,AJ$3,BD!$B$3:$B$5001,$A$33,BD!$H$3:$H$5001,"<>")=0,"",SUMIFS(BD!$H$3:$H$5001,BD!$A$3:$A$5001,AJ$3,BD!$B$3:$B$5001,$A$33))) | AK33: =IF(COUNT(F33:AJ33)=0,"",SUM(F33:AJ33))
C34: Pallets Movimentados | D34: =IFERROR(1/(1/INDEX(BD!$AF$29:$AZ$29,MATCH($A$33,BD!$AF$22:$AZ$22,0))),"") | F34: =IF(F$3="","",IF(COUNTIFS(BD!$A$3:$A$5001,F$3,BD!$B$3:$B$5001,$A$33,BD!$I$3:$I$5001,"<>")=0,"",SUMIFS(BD!$I$3:$I$5001,BD!$A$3:$A$5001,F$3,BD!$B$3:$B$5001,$A$33))) | G34: =IF(G$3="","",IF(COUNTIFS(BD!$A$3:$A$5001,G$3,BD!$B$3:$B$5001,$A$33,BD!$I$3:$I$5001,"<>")=0,"",SUMIFS(BD!$I$3:$I$5001,BD!$A$3:$A$5001,G$3,BD!$B$3:$B$5001,$A$33))) | H34: =IF(H$3="","",IF(COUNTIFS(BD!$A$3:$A$5001,H$3,BD!$B$3:$B$5001,$A$33,BD!$I$3:$I$5001,"<>")=0,"",SUMIFS(BD!$I$3:$I$5001,BD!$A$3:$A$5001,H$3,BD!$B$3:$B$5001,$A$33))) | I34: =IF(I$3="","",IF(COUNTIFS(BD!$A$3:$A$5001,I$3,BD!$B$3:$B$5001,$A$33,BD!$I$3:$I$5001,"<>")=0,"",SUMIFS(BD!$I$3:$I$5001,BD!$A$3:$A$5001,I$3,BD!$B$3:$B$5001,$A$33))) | J34: =IF(J$3="","",IF(COUNTIFS(BD!$A$3:$A$5001,J$3,BD!$B$3:$B$5001,$A$33,BD!$I$3:$I$5001,"<>")=0,"",SUMIFS(BD!$I$3:$I$5001,BD!$A$3:$A$5001,J$3,BD!$B$3:$B$5001,$A$33))) | K34: =IF(K$3="","",IF(COUNTIFS(BD!$A$3:$A$5001,K$3,BD!$B$3:$B$5001,$A$33,BD!$I$3:$I$5001,"<>")=0,"",SUMIFS(BD!$I$3:$I$5001,BD!$A$3:$A$5001,K$3,BD!$B$3:$B$5001,$A$33))) | L34: =IF(L$3="","",IF(COUNTIFS(BD!$A$3:$A$5001,L$3,BD!$B$3:$B$5001,$A$33,BD!$I$3:$I$5001,"<>")=0,"",SUMIFS(BD!$I$3:$I$5001,BD!$A$3:$A$5001,L$3,BD!$B$3:$B$5001,$A$33))) | M34: =IF(M$3="","",IF(COUNTIFS(BD!$A$3:$A$5001,M$3,BD!$B$3:$B$5001,$A$33,BD!$I$3:$I$5001,"<>")=0,"",SUMIFS(BD!$I$3:$I$5001,BD!$A$3:$A$5001,M$3,BD!$B$3:$B$5001,$A$33))) | ... AJ34: =IF(AJ$3="","",IF(COUNTIFS(BD!$A$3:$A$5001,AJ$3,BD!$B$3:$B$5001,$A$33,BD!$I$3:$I$5001,"<>")=0,"",SUMIFS(BD!$I$3:$I$5001,BD!$A$3:$A$5001,AJ$3,BD!$B$3:$B$5001,$A$33))) | AK34: =IF(COUNT(F34:AJ34)=0,"",SUM(F34:AJ34))
C35: Toneladas Movimentadas | D35: =IFERROR(1/(1/INDEX(BD!$AF$30:$AZ$30,MATCH($A$33,BD!$AF$22:$AZ$22,0))),"") | F35: =IF(F$3="","",IF(COUNTIFS(BD!$A$3:$A$5001,F$3,BD!$B$3:$B$5001,$A$33,BD!$J$3:$J$5001,"<>")=0,"",SUMIFS(BD!$J$3:$J$5001,BD!$A$3:$A$5001,F$3,BD!$B$3:$B$5001,$A$33))) | G35: =IF(G$3="","",IF(COUNTIFS(BD!$A$3:$A$5001,G$3,BD!$B$3:$B$5001,$A$33,BD!$J$3:$J$5001,"<>")=0,"",SUMIFS(BD!$J$3:$J$5001,BD!$A$3:$A$5001,G$3,BD!$B$3:$B$5001,$A$33))) | H35: =IF(H$3="","",IF(COUNTIFS(BD!$A$3:$A$5001,H$3,BD!$B$3:$B$5001,$A$33,BD!$J$3:$J$5001,"<>")=0,"",SUMIFS(BD!$J$3:$J$5001,BD!$A$3:$A$5001,H$3,BD!$B$3:$B$5001,$A$33))) | I35: =IF(I$3="","",IF(COUNTIFS(BD!$A$3:$A$5001,I$3,BD!$B$3:$B$5001,$A$33,BD!$J$3:$J$5001,"<>")=0,"",SUMIFS(BD!$J$3:$J$5001,BD!$A$3:$A$5001,I$3,BD!$B$3:$B$5001,$A$33))) | J35: =IF(J$3="","",IF(COUNTIFS(BD!$A$3:$A$5001,J$3,BD!$B$3:$B$5001,$A$33,BD!$J$3:$J$5001,"<>")=0,"",SUMIFS(BD!$J$3:$J$5001,BD!$A$3:$A$5001,J$3,BD!$B$3:$B$5001,$A$33))) | K35: =IF(K$3="","",IF(COUNTIFS(BD!$A$3:$A$5001,K$3,BD!$B$3:$B$5001,$A$33,BD!$J$3:$J$5001,"<>")=0,"",SUMIFS(BD!$J$3:$J$5001,BD!$A$3:$A$5001,K$3,BD!$B$3:$B$5001,$A$33))) | L35: =IF(L$3="","",IF(COUNTIFS(BD!$A$3:$A$5001,L$3,BD!$B$3:$B$5001,$A$33,BD!$J$3:$J$5001,"<>")=0,"",SUMIFS(BD!$J$3:$J$5001,BD!$A$3:$A$5001,L$3,BD!$B$3:$B$5001,$A$33))) | M35: =IF(M$3="","",IF(COUNTIFS(BD!$A$3:$A$5001,M$3,BD!$B$3:$B$5001,$A$33,BD!$J$3:$J$5001,"<>")=0,"",SUMIFS(BD!$J$3:$J$5001,BD!$A$3:$A$5001,M$3,BD!$B$3:$B$5001,$A$33))) | ... AJ35: =IF(AJ$3="","",IF(COUNTIFS(BD!$A$3:$A$5001,AJ$3,BD!$B$3:$B$5001,$A$33,BD!$J$3:$J$5001,"<>")=0,"",SUMIFS(BD!$J$3:$J$5001,BD!$A$3:$A$5001,AJ$3,BD!$B$3:$B$5001,$A$33))) | AK35: =IF(COUNT(F35:AJ35)=0,"",SUM(F35:AJ35))
C36: Caixas Expedidas | D36: =IFERROR(1/(1/INDEX(BD!$AF$31:$AZ$31,MATCH($A$33,BD!$AF$22:$AZ$22,0))),"") | F36: =IF(F$3="","",IF(COUNTIFS(BD!$A$3:$A$5001,F$3,BD!$B$3:$B$5001,$A$33,BD!$K$3:$K$5001,"<>")=0,"",SUMIFS(BD!$K$3:$K$5001,BD!$A$3:$A$5001,F$3,BD!$B$3:$B$5001,$A$33))) | G36: =IF(G$3="","",IF(COUNTIFS(BD!$A$3:$A$5001,G$3,BD!$B$3:$B$5001,$A$33,BD!$K$3:$K$5001,"<>")=0,"",SUMIFS(BD!$K$3:$K$5001,BD!$A$3:$A$5001,G$3,BD!$B$3:$B$5001,$A$33))) | H36: =IF(H$3="","",IF(COUNTIFS(BD!$A$3:$A$5001,H$3,BD!$B$3:$B$5001,$A$33,BD!$K$3:$K$5001,"<>")=0,"",SUMIFS(BD!$K$3:$K$5001,BD!$A$3:$A$5001,H$3,BD!$B$3:$B$5001,$A$33))) | I36: =IF(I$3="","",IF(COUNTIFS(BD!$A$3:$A$5001,I$3,BD!$B$3:$B$5001,$A$33,BD!$K$3:$K$5001,"<>")=0,"",SUMIFS(BD!$K$3:$K$5001,BD!$A$3:$A$5001,I$3,BD!$B$3:$B$5001,$A$33))) | J36: =IF(J$3="","",IF(COUNTIFS(BD!$A$3:$A$5001,J$3,BD!$B$3:$B$5001,$A$33,BD!$K$3:$K$5001,"<>")=0,"",SUMIFS(BD!$K$3:$K$5001,BD!$A$3:$A$5001,J$3,BD!$B$3:$B$5001,$A$33))) | K36: =IF(K$3="","",IF(COUNTIFS(BD!$A$3:$A$5001,K$3,BD!$B$3:$B$5001,$A$33,BD!$K$3:$K$5001,"<>")=0,"",SUMIFS(BD!$K$3:$K$5001,BD!$A$3:$A$5001,K$3,BD!$B$3:$B$5001,$A$33))) | L36: =IF(L$3="","",IF(COUNTIFS(BD!$A$3:$A$5001,L$3,BD!$B$3:$B$5001,$A$33,BD!$K$3:$K$5001,"<>")=0,"",SUMIFS(BD!$K$3:$K$5001,BD!$A$3:$A$5001,L$3,BD!$B$3:$B$5001,$A$33))) | M36: =IF(M$3="","",IF(COUNTIFS(BD!$A$3:$A$5001,M$3,BD!$B$3:$B$5001,$A$33,BD!$K$3:$K$5001,"<>")=0,"",SUMIFS(BD!$K$3:$K$5001,BD!$A$3:$A$5001,M$3,BD!$B$3:$B$5001,$A$33))) | ... AJ36: =IF(AJ$3="","",IF(COUNTIFS(BD!$A$3:$A$5001,AJ$3,BD!$B$3:$B$5001,$A$33,BD!$K$3:$K$5001,"<>")=0,"",SUMIFS(BD!$K$3:$K$5001,BD!$A$3:$A$5001,AJ$3,BD!$B$3:$B$5001,$A$33))) | AK36: =IF(COUNT(F36:AJ36)=0,"",SUM(F36:AJ36))
C37: Pedidos Faturados | D37: =IFERROR(1/(1/INDEX(BD!$AF$32:$AZ$32,MATCH($A$33,BD!$AF$22:$AZ$22,0))),"") | F37: =IF(F$3="","",IF(COUNTIFS(BD!$A$3:$A$5001,F$3,BD!$B$3:$B$5001,$A$33,BD!$L$3:$L$5001,"<>")=0,"",SUMIFS(BD!$L$3:$L$5001,BD!$A$3:$A$5001,F$3,BD!$B$3:$B$5001,$A$33))) | G37: =IF(G$3="","",IF(COUNTIFS(BD!$A$3:$A$5001,G$3,BD!$B$3:$B$5001,$A$33,BD!$L$3:$L$5001,"<>")=0,"",SUMIFS(BD!$L$3:$L$5001,BD!$A$3:$A$5001,G$3,BD!$B$3:$B$5001,$A$33))) | H37: =IF(H$3="","",IF(COUNTIFS(BD!$A$3:$A$5001,H$3,BD!$B$3:$B$5001,$A$33,BD!$L$3:$L$5001,"<>")=0,"",SUMIFS(BD!$L$3:$L$5001,BD!$A$3:$A$5001,H$3,BD!$B$3:$B$5001,$A$33))) | I37: =IF(I$3="","",IF(COUNTIFS(BD!$A$3:$A$5001,I$3,BD!$B$3:$B$5001,$A$33,BD!$L$3:$L$5001,"<>")=0,"",SUMIFS(BD!$L$3:$L$5001,BD!$A$3:$A$5001,I$3,BD!$B$3:$B$5001,$A$33))) | J37: =IF(J$3="","",IF(COUNTIFS(BD!$A$3:$A$5001,J$3,BD!$B$3:$B$5001,$A$33,BD!$L$3:$L$5001,"<>")=0,"",SUMIFS(BD!$L$3:$L$5001,BD!$A$3:$A$5001,J$3,BD!$B$3:$B$5001,$A$33))) | K37: =IF(K$3="","",IF(COUNTIFS(BD!$A$3:$A$5001,K$3,BD!$B$3:$B$5001,$A$33,BD!$L$3:$L$5001,"<>")=0,"",SUMIFS(BD!$L$3:$L$5001,BD!$A$3:$A$5001,K$3,BD!$B$3:$B$5001,$A$33))) | L37: =IF(L$3="","",IF(COUNTIFS(BD!$A$3:$A$5001,L$3,BD!$B$3:$B$5001,$A$33,BD!$L$3:$L$5001,"<>")=0,"",SUMIFS(BD!$L$3:$L$5001,BD!$A$3:$A$5001,L$3,BD!$B$3:$B$5001,$A$33))) | M37: =IF(M$3="","",IF(COUNTIFS(BD!$A$3:$A$5001,M$3,BD!$B$3:$B$5001,$A$33,BD!$L$3:$L$5001,"<>")=0,"",SUMIFS(BD!$L$3:$L$5001,BD!$A$3:$A$5001,M$3,BD!$B$3:$B$5001,$A$33))) | ... AJ37: =IF(AJ$3="","",IF(COUNTIFS(BD!$A$3:$A$5001,AJ$3,BD!$B$3:$B$5001,$A$33,BD!$L$3:$L$5001,"<>")=0,"",SUMIFS(BD!$L$3:$L$5001,BD!$A$3:$A$5001,AJ$3,BD!$B$3:$B$5001,$A$33))) | AK37: =IF(COUNT(F37:AJ37)=0,"",SUM(F37:AJ37))
B38: NC | C38: Incidentes | D38: =IFERROR(1/(1/INDEX(BD!$AF$34:$AZ$34,MATCH($A$33,BD!$AF$22:$AZ$22,0))),"") | F38: =IF(F$3="","",IF(COUNTIFS(BD!$A$3:$A$5001,F$3,BD!$B$3:$B$5001,$A$33,BD!$N$3:$N$5001,"<>")=0,"",SUMIFS(BD!$N$3:$N$5001,BD!$A$3:$A$5001,F$3,BD!$B$3:$B$5001,$A$33))) | G38: =IF(G$3="","",IF(COUNTIFS(BD!$A$3:$A$5001,G$3,BD!$B$3:$B$5001,$A$33,BD!$N$3:$N$5001,"<>")=0,"",SUMIFS(BD!$N$3:$N$5001,BD!$A$3:$A$5001,G$3,BD!$B$3:$B$5001,$A$33))) | H38: =IF(H$3="","",IF(COUNTIFS(BD!$A$3:$A$5001,H$3,BD!$B$3:$B$5001,$A$33,BD!$N$3:$N$5001,"<>")=0,"",SUMIFS(BD!$N$3:$N$5001,BD!$A$3:$A$5001,H$3,BD!$B$3:$B$5001,$A$33))) | I38: =IF(I$3="","",IF(COUNTIFS(BD!$A$3:$A$5001,I$3,BD!$B$3:$B$5001,$A$33,BD!$N$3:$N$5001,"<>")=0,"",SUMIFS(BD!$N$3:$N$5001,BD!$A$3:$A$5001,I$3,BD!$B$3:$B$5001,$A$33))) | J38: =IF(J$3="","",IF(COUNTIFS(BD!$A$3:$A$5001,J$3,BD!$B$3:$B$5001,$A$33,BD!$N$3:$N$5001,"<>")=0,"",SUMIFS(BD!$N$3:$N$5001,BD!$A$3:$A$5001,J$3,BD!$B$3:$B$5001,$A$33))) | K38: =IF(K$3="","",IF(COUNTIFS(BD!$A$3:$A$5001,K$3,BD!$B$3:$B$5001,$A$33,BD!$N$3:$N$5001,"<>")=0,"",SUMIFS(BD!$N$3:$N$5001,BD!$A$3:$A$5001,K$3,BD!$B$3:$B$5001,$A$33))) | L38: =IF(L$3="","",IF(COUNTIFS(BD!$A$3:$A$5001,L$3,BD!$B$3:$B$5001,$A$33,BD!$N$3:$N$5001,"<>")=0,"",SUMIFS(BD!$N$3:$N$5001,BD!$A$3:$A$5001,L$3,BD!$B$3:$B$5001,$A$33))) | M38: =IF(M$3="","",IF(COUNTIFS(BD!$A$3:$A$5001,M$3,BD!$B$3:$B$5001,$A$33,BD!$N$3:$N$5001,"<>")=0,"",SUMIFS(BD!$N$3:$N$5001,BD!$A$3:$A$5001,M$3,BD!$B$3:$B$5001,$A$33))) | ... AJ38: =IF(AJ$3="","",IF(COUNTIFS(BD!$A$3:$A$5001,AJ$3,BD!$B$3:$B$5001,$A$33,BD!$N$3:$N$5001,"<>")=0,"",SUMIFS(BD!$N$3:$N$5001,BD!$A$3:$A$5001,AJ$3,BD!$B$3:$B$5001,$A$33))) | AK38: =IF(COUNT(F38:AJ38)=0,"",SUM(F38:AJ38))
