Workbook

Sheet Indicadores
G1: INDICADORES OPERACIONAIS | U1: SETEMBRO · 2026
B3: CLIENTE ▸ | D3: Todos | Q3: =IF(calculos!$B$9=0,"Sem dados na Base para o mês escolhido","Dados até "&TEXT(calculos!$C$7+calculos!$B$9-1,"dd/mm")&" · ▲▼ comparado a "&LOWER(LEFT(calculos!$B$8,FIND("/",calculos!$B$8)-1))&" (dias 1 a "&calculos!$B$9&")") -> Dados até 29/09 · ▲▼ comparado a agosto (dias 1 a 29)
B5: RECEBIMENTO (IN) | G5: EXPEDIÇÃO (OUT) | L5: NÃO CONFORMIDADES | Q5: OCUPAÇÃO (P.P) | V5: GENTE
C6: =calculos!$C$43 -> 458 | H6: =calculos!$F$43 -> 702 | M6: =calculos!$I$43 -> 11 | R6: =calculos!$N$43 -> 0.71985695 | W6: =calculos!$O$43 -> 26
B9: veículos recebidos | G9: veículos expedidos | L9: incidentes no mês | Q9: ="taxa de ocupação · "&calculos!$N$50 -> taxa de ocupação · atenção | V9: efetivo operacional
B10: =calculos!$E$43 -> 7373.34 | G10: =calculos!$H$43 -> 8393.51 | L10: =calculos!$J$43 -> 0 | Q10: =calculos!$M$43 -> 4227 | V10: =calculos!$P$43 -> 0
B11: =calculos!$C$47 -> -0.021367521 | G11: =calculos!$F$47 -> 0.005730659 | L11: =calculos!$I$47 -> 1.75 | Q11: =calculos!$N$47 -> 0.076120163 | V11: =calculos!$O$47 -> 0
B48: Cartões e gráficos seguem o filtro de cliente (o ranking mostra todos). Detalhe dos 16 indicadores na aba “Quadro de Indicadores”. Fonte: Power Automate · IntraLog.

Sheet Monitoramento
F1: MONITORAMENTO DIÁRIO DE PERFORMANCE | AE1: SETEMBRO · 2026
A2: CLIENTE | B2: INDICADORES | D2: META | F2: REALIZADO P/DIA | AK2: MÊS
F3: =IF(ISNUMBER($AE$1),DATE(YEAR($AE$1),MONTH($AE$1),1),IFERROR(DATE(VALUE(RIGHT(TRIM($AE$1),4)),MATCH(TRIM(LEFT($AE$1,FIND("·",$AE$1)-1)),{"JANEIRO","FEVEREIRO","MARÇO","ABRIL","MAIO","JUNHO","JULHO","AGOSTO","SETEMBRO","OUTUBRO","NOVEMBRO","DEZEMBRO"},0),1),DATE(2026,9,1))) -> 46266 | G3: =IF(F3="","",IF(MONTH(F3+1)=MONTH($F$3),F3+1,"")) -> 46267 | H3: =IF(G3="","",IF(MONTH(G3+1)=MONTH($F$3),G3+1,"")) -> 46268 | I3: =IF(H3="","",IF(MONTH(H3+1)=MONTH($F$3),H3+1,"")) -> 46269 | J3: =IF(I3="","",IF(MONTH(I3+1)=MONTH($F$3),I3+1,"")) -> 46270 | K3: =IF(J3="","",IF(MONTH(J3+1)=MONTH($F$3),J3+1,"")) -> 46271 | L3: =IF(K3="","",IF(MONTH(K3+1)=MONTH($F$3),K3+1,"")) -> 46272 | M3: =IF(L3="","",IF(MONTH(L3+1)=MONTH($F$3),L3+1,"")) -> 46273 | N3: =IF(M3="","",IF(MONTH(M3+1)=MONTH($F$3),M3+1,"")) -> 46274 | ... AJ3: =IF(AI3="","",IF(MONTH(AI3+1)=MONTH($F$3),AI3+1,""))
A5: Barry Callebaut | B5: IN | C5: Veículos Recebidos | D5: 150 | F5: =IF(F$3="","",IF(COUNTIFS(Base!$A$3:$A$5001,F$3,Base!$B$3:$B$5001,$A$5,Base!$C$3:$C$5001,"<>")=0,"",SUMIFS(Base!$C$3:$C$5001,Base!$A$3:$A$5001,F$3,Base!$B$3:$B$5001,$A$5))) -> 5 | G5: =IF(G$3="","",IF(COUNTIFS(Base!$A$3:$A$5001,G$3,Base!$B$3:$B$5001,$A$5,Base!$C$3:$C$5001,"<>")=0,"",SUMIFS(Base!$C$3:$C$5001,Base!$A$3:$A$5001,G$3,Base!$B$3:$B$5001,$A$5))) -> 0 | H5: =IF(H$3="","",IF(COUNTIFS(Base!$A$3:$A$5001,H$3,Base!$B$3:$B$5001,$A$5,Base!$C$3:$C$5001,"<>")=0,"",SUMIFS(Base!$C$3:$C$5001,Base!$A$3:$A$5001,H$3,Base!$B$3:$B$5001,$A$5))) -> 9 | I5: =IF(I$3="","",IF(COUNTIFS(Base!$A$3:$A$5001,I$3,Base!$B$3:$B$5001,$A$5,Base!$C$3:$C$5001,"<>")=0,"",SUMIFS(Base!$C$3:$C$5001,Base!$A$3:$A$5001,I$3,Base!$B$3:$B$5001,$A$5))) -> 4 | J5: =IF(J$3="","",IF(COUNTIFS(Base!$A$3:$A$5001,J$3,Base!$B$3:$B$5001,$A$5,Base!$C$3:$C$5001,"<>")=0,"",SUMIFS(Base!$C$3:$C$5001,Base!$A$3:$A$5001,J$3,Base!$B$3:$B$5001,$A$5))) -> 0 | K5: =IF(K$3="","",IF(COUNTIFS(Base!$A$3:$A$5001,K$3,Base!$B$3:$B$5001,$A$5,Base!$C$3:$C$5001,"<>")=0,"",SUMIFS(Base!$C$3:$C$5001,Base!$A$3:$A$5001,K$3,Base!$B$3:$B$5001,$A$5))) | L5: =IF(L$3="","",IF(COUNTIFS(Base!$A$3:$A$5001,L$3,Base!$B$3:$B$5001,$A$5,Base!$C$3:$C$5001,"<>")=0,"",SUMIFS(Base!$C$3:$C$5001,Base!$A$3:$A$5001,L$3,Base!$B$3:$B$5001,$A$5))) -> 1 | M5: =IF(M$3="","",IF(COUNTIFS(Base!$A$3:$A$5001,M$3,Base!$B$3:$B$5001,$A$5,Base!$C$3:$C$5001,"<>")=0,"",SUMIFS(Base!$C$3:$C$5001,Base!$A$3:$A$5001,M$3,Base!$B$3:$B$5001,$A$5))) -> 2 | ... AJ5: =IF(AJ$3="","",IF(COUNTIFS(Base!$A$3:$A$5001,AJ$3,Base!$B$3:$B$5001,$A$5,Base!$C$3:$C$5001,"<>")=0,"",SUMIFS(Base!$C$3:$C$5001,Base!$A$3:$A$5001,AJ$3,Base!$B$3:$B$5001,$A$5))) | AK5: =IF(COUNT(F5:AJ5)=0,"",SUM(F5:AJ5)) -> 84
C6: Pallets Movimentados | F6: =IF(F$3="","",IF(COUNTIFS(Base!$A$3:$A$5001,F$3,Base!$B$3:$B$5001,$A$5,Base!$D$3:$D$5001,"<>")=0,"",SUMIFS(Base!$D$3:$D$5001,Base!$A$3:$A$5001,F$3,Base!$B$3:$B$5001,$A$5))) -> 130 | G6: =IF(G$3="","",IF(COUNTIFS(Base!$A$3:$A$5001,G$3,Base!$B$3:$B$5001,$A$5,Base!$D$3:$D$5001,"<>")=0,"",SUMIFS(Base!$D$3:$D$5001,Base!$A$3:$A$5001,G$3,Base!$B$3:$B$5001,$A$5))) -> 0 | H6: =IF(H$3="","",IF(COUNTIFS(Base!$A$3:$A$5001,H$3,Base!$B$3:$B$5001,$A$5,Base!$D$3:$D$5001,"<>")=0,"",SUMIFS(Base!$D$3:$D$5001,Base!$A$3:$A$5001,H$3,Base!$B$3:$B$5001,$A$5))) -> 216 | I6: =IF(I$3="","",IF(COUNTIFS(Base!$A$3:$A$5001,I$3,Base!$B$3:$B$5001,$A$5,Base!$D$3:$D$5001,"<>")=0,"",SUMIFS(Base!$D$3:$D$5001,Base!$A$3:$A$5001,I$3,Base!$B$3:$B$5001,$A$5))) -> 88 | J6: =IF(J$3="","",IF(COUNTIFS(Base!$A$3:$A$5001,J$3,Base!$B$3:$B$5001,$A$5,Base!$D$3:$D$5001,"<>")=0,"",SUMIFS(Base!$D$3:$D$5001,Base!$A$3:$A$5001,J$3,Base!$B$3:$B$5001,$A$5))) -> 0 | K6: =IF(K$3="","",IF(COUNTIFS(Base!$A$3:$A$5001,K$3,Base!$B$3:$B$5001,$A$5,Base!$D$3:$D$5001,"<>")=0,"",SUMIFS(Base!$D$3:$D$5001,Base!$A$3:$A$5001,K$3,Base!$B$3:$B$5001,$A$5))) | L6: =IF(L$3="","",IF(COUNTIFS(Base!$A$3:$A$5001,L$3,Base!$B$3:$B$5001,$A$5,Base!$D$3:$D$5001,"<>")=0,"",SUMIFS(Base!$D$3:$D$5001,Base!$A$3:$A$5001,L$3,Base!$B$3:$B$5001,$A$5))) -> 26 | M6: =IF(M$3="","",IF(COUNTIFS(Base!$A$3:$A$5001,M$3,Base!$B$3:$B$5001,$A$5,Base!$D$3:$D$5001,"<>")=0,"",SUMIFS(Base!$D$3:$D$5001,Base!$A$3:$A$5001,M$3,Base!$B$3:$B$5001,$A$5))) -> 50 | ... AJ6: =IF(AJ$3="","",IF(COUNTIFS(Base!$A$3:$A$5001,AJ$3,Base!$B$3:$B$5001,$A$5,Base!$D$3:$D$5001,"<>")=0,"",SUMIFS(Base!$D$3:$D$5001,Base!$A$3:$A$5001,AJ$3,Base!$B$3:$B$5001,$A$5))) | AK6: =IF(COUNT(F6:AJ6)=0,"",SUM(F6:AJ6)) -> 1960
C7: Toneladas Movimentadas | F7: =IF(F$3="","",IF(COUNTIFS(Base!$A$3:$A$5001,F$3,Base!$B$3:$B$5001,$A$5,Base!$E$3:$E$5001,"<>")=0,"",SUMIFS(Base!$E$3:$E$5001,Base!$A$3:$A$5001,F$3,Base!$B$3:$B$5001,$A$5))) -> 90.09 | G7: =IF(G$3="","",IF(COUNTIFS(Base!$A$3:$A$5001,G$3,Base!$B$3:$B$5001,$A$5,Base!$E$3:$E$5001,"<>")=0,"",SUMIFS(Base!$E$3:$E$5001,Base!$A$3:$A$5001,G$3,Base!$B$3:$B$5001,$A$5))) -> 0 | H7: =IF(H$3="","",IF(COUNTIFS(Base!$A$3:$A$5001,H$3,Base!$B$3:$B$5001,$A$5,Base!$E$3:$E$5001,"<>")=0,"",SUMIFS(Base!$E$3:$E$5001,Base!$A$3:$A$5001,H$3,Base!$B$3:$B$5001,$A$5))) -> 208.42 | I7: =IF(I$3="","",IF(COUNTIFS(Base!$A$3:$A$5001,I$3,Base!$B$3:$B$5001,$A$5,Base!$E$3:$E$5001,"<>")=0,"",SUMIFS(Base!$E$3:$E$5001,Base!$A$3:$A$5001,I$3,Base!$B$3:$B$5001,$A$5))) -> 54.09 | J7: =IF(J$3="","",IF(COUNTIFS(Base!$A$3:$A$5001,J$3,Base!$B$3:$B$5001,$A$5,Base!$E$3:$E$5001,"<>")=0,"",SUMIFS(Base!$E$3:$E$5001,Base!$A$3:$A$5001,J$3,Base!$B$3:$B$5001,$A$5))) -> 0 | K7: =IF(K$3="","",IF(COUNTIFS(Base!$A$3:$A$5001,K$3,Base!$B$3:$B$5001,$A$5,Base!$E$3:$E$5001,"<>")=0,"",SUMIFS(Base!$E$3:$E$5001,Base!$A$3:$A$5001,K$3,Base!$B$3:$B$5001,$A$5))) | L7: =IF(L$3="","",IF(COUNTIFS(Base!$A$3:$A$5001,L$3,Base!$B$3:$B$5001,$A$5,Base!$E$3:$E$5001,"<>")=0,"",SUMIFS(Base!$E$3:$E$5001,Base!$A$3:$A$5001,L$3,Base!$B$3:$B$5001,$A$5))) -> 12.37 | M7: =IF(M$3="","",IF(COUNTIFS(Base!$A$3:$A$5001,M$3,Base!$B$3:$B$5001,$A$5,Base!$E$3:$E$5001,"<>")=0,"",SUMIFS(Base!$E$3:$E$5001,Base!$A$3:$A$5001,M$3,Base!$B$3:$B$5001,$A$5))) -> 33.92 | ... AJ7: =IF(AJ$3="","",IF(COUNTIFS(Base!$A$3:$A$5001,AJ$3,Base!$B$3:$B$5001,$A$5,Base!$E$3:$E$5001,"<>")=0,"",SUMIFS(Base!$E$3:$E$5001,Base!$A$3:$A$5001,AJ$3,Base!$B$3:$B$5001,$A$5))) | AK7: =IF(COUNT(F7:AJ7)=0,"",SUM(F7:AJ7)) -> 1445.28
B8: OUT | C8: Veículos Expedidos | D8: 200 | F8: =IF(F$3="","",IF(COUNTIFS(Base!$A$3:$A$5001,F$3,Base!$B$3:$B$5001,$A$5,Base!$F$3:$F$5001,"<>")=0,"",SUMIFS(Base!$F$3:$F$5001,Base!$A$3:$A$5001,F$3,Base!$B$3:$B$5001,$A$5))) -> 11 | G8: =IF(G$3="","",IF(COUNTIFS(Base!$A$3:$A$5001,G$3,Base!$B$3:$B$5001,$A$5,Base!$F$3:$F$5001,"<>")=0,"",SUMIFS(Base!$F$3:$F$5001,Base!$A$3:$A$5001,G$3,Base!$B$3:$B$5001,$A$5))) -> 10 | H8: =IF(H$3="","",IF(COUNTIFS(Base!$A$3:$A$5001,H$3,Base!$B$3:$B$5001,$A$5,Base!$F$3:$F$5001,"<>")=0,"",SUMIFS(Base!$F$3:$F$5001,Base!$A$3:$A$5001,H$3,Base!$B$3:$B$5001,$A$5))) -> 11 | I8: =IF(I$3="","",IF(COUNTIFS(Base!$A$3:$A$5001,I$3,Base!$B$3:$B$5001,$A$5,Base!$F$3:$F$5001,"<>")=0,"",SUMIFS(Base!$F$3:$F$5001,Base!$A$3:$A$5001,I$3,Base!$B$3:$B$5001,$A$5))) -> 3 | J8: =IF(J$3="","",IF(COUNTIFS(Base!$A$3:$A$5001,J$3,Base!$B$3:$B$5001,$A$5,Base!$F$3:$F$5001,"<>")=0,"",SUMIFS(Base!$F$3:$F$5001,Base!$A$3:$A$5001,J$3,Base!$B$3:$B$5001,$A$5))) -> 1 | K8: =IF(K$3="","",IF(COUNTIFS(Base!$A$3:$A$5001,K$3,Base!$B$3:$B$5001,$A$5,Base!$F$3:$F$5001,"<>")=0,"",SUMIFS(Base!$F$3:$F$5001,Base!$A$3:$A$5001,K$3,Base!$B$3:$B$5001,$A$5))) | L8: =IF(L$3="","",IF(COUNTIFS(Base!$A$3:$A$5001,L$3,Base!$B$3:$B$5001,$A$5,Base!$F$3:$F$5001,"<>")=0,"",SUMIFS(Base!$F$3:$F$5001,Base!$A$3:$A$5001,L$3,Base!$B$3:$B$5001,$A$5))) -> 12 | M8: =IF(M$3="","",IF(COUNTIFS(Base!$A$3:$A$5001,M$3,Base!$B$3:$B$5001,$A$5,Base!$F$3:$F$5001,"<>")=0,"",SUMIFS(Base!$F$3:$F$5001,Base!$A$3:$A$5001,M$3,Base!$B$3:$B$5001,$A$5))) -> 10 | ... AJ8: =IF(AJ$3="","",IF(COUNTIFS(Base!$A$3:$A$5001,AJ$3,Base!$B$3:$B$5001,$A$5,Base!$F$3:$F$5001,"<>")=0,"",SUMIFS(Base!$F$3:$F$5001,Base!$A$3:$A$5001,AJ$3,Base!$B$3:$B$5001,$A$5))) | AK8: =IF(COUNT(F8:AJ8)=0,"",SUM(F8:AJ8)) -> 205
C9: Pallets Movimentados | F9: =IF(F$3="","",IF(COUNTIFS(Base!$A$3:$A$5001,F$3,Base!$B$3:$B$5001,$A$5,Base!$G$3:$G$5001,"<>")=0,"",SUMIFS(Base!$G$3:$G$5001,Base!$A$3:$A$5001,F$3,Base!$B$3:$B$5001,$A$5))) -> 198 | G9: =IF(G$3="","",IF(COUNTIFS(Base!$A$3:$A$5001,G$3,Base!$B$3:$B$5001,$A$5,Base!$G$3:$G$5001,"<>")=0,"",SUMIFS(Base!$G$3:$G$5001,Base!$A$3:$A$5001,G$3,Base!$B$3:$B$5001,$A$5))) -> 180 | H9: =IF(H$3="","",IF(COUNTIFS(Base!$A$3:$A$5001,H$3,Base!$B$3:$B$5001,$A$5,Base!$G$3:$G$5001,"<>")=0,"",SUMIFS(Base!$G$3:$G$5001,Base!$A$3:$A$5001,H$3,Base!$B$3:$B$5001,$A$5))) -> 198 | I9: =IF(I$3="","",IF(COUNTIFS(Base!$A$3:$A$5001,I$3,Base!$B$3:$B$5001,$A$5,Base!$G$3:$G$5001,"<>")=0,"",SUMIFS(Base!$G$3:$G$5001,Base!$A$3:$A$5001,I$3,Base!$B$3:$B$5001,$A$5))) -> 54 | J9: =IF(J$3="","",IF(COUNTIFS(Base!$A$3:$A$5001,J$3,Base!$B$3:$B$5001,$A$5,Base!$G$3:$G$5001,"<>")=0,"",SUMIFS(Base!$G$3:$G$5001,Base!$A$3:$A$5001,J$3,Base!$B$3:$B$5001,$A$5))) -> 18 | K9: =IF(K$3="","",IF(COUNTIFS(Base!$A$3:$A$5001,K$3,Base!$B$3:$B$5001,$A$5,Base!$G$3:$G$5001,"<>")=0,"",SUMIFS(Base!$G$3:$G$5001,Base!$A$3:$A$5001,K$3,Base!$B$3:$B$5001,$A$5))) | L9: =IF(L$3="","",IF(COUNTIFS(Base!$A$3:$A$5001,L$3,Base!$B$3:$B$5001,$A$5,Base!$G$3:$G$5001,"<>")=0,"",SUMIFS(Base!$G$3:$G$5001,Base!$A$3:$A$5001,L$3,Base!$B$3:$B$5001,$A$5))) -> 216 | M9: =IF(M$3="","",IF(COUNTIFS(Base!$A$3:$A$5001,M$3,Base!$B$3:$B$5001,$A$5,Base!$G$3:$G$5001,"<>")=0,"",SUMIFS(Base!$G$3:$G$5001,Base!$A$3:$A$5001,M$3,Base!$B$3:$B$5001,$A$5))) -> 180 | ... AJ9: =IF(AJ$3="","",IF(COUNTIFS(Base!$A$3:$A$5001,AJ$3,Base!$B$3:$B$5001,$A$5,Base!$G$3:$G$5001,"<>")=0,"",SUMIFS(Base!$G$3:$G$5001,Base!$A$3:$A$5001,AJ$3,Base!$B$3:$B$5001,$A$5))) | AK9: =IF(COUNT(F9:AJ9)=0,"",SUM(F9:AJ9)) -> 3690
C10: Toneladas Movimentadas | F10: =IF(F$3="","",IF(COUNTIFS(Base!$A$3:$A$5001,F$3,Base!$B$3:$B$5001,$A$5,Base!$H$3:$H$5001,"<>")=0,"",SUMIFS(Base!$H$3:$H$5001,Base!$A$3:$A$5001,F$3,Base!$B$3:$B$5001,$A$5))) -> 193.85 | G10: =IF(G$3="","",IF(COUNTIFS(Base!$A$3:$A$5001,G$3,Base!$B$3:$B$5001,$A$5,Base!$H$3:$H$5001,"<>")=0,"",SUMIFS(Base!$H$3:$H$5001,Base!$A$3:$A$5001,G$3,Base!$B$3:$B$5001,$A$5))) -> 64.98 | H10: =IF(H$3="","",IF(COUNTIFS(Base!$A$3:$A$5001,H$3,Base!$B$3:$B$5001,$A$5,Base!$H$3:$H$5001,"<>")=0,"",SUMIFS(Base!$H$3:$H$5001,Base!$A$3:$A$5001,H$3,Base!$B$3:$B$5001,$A$5))) -> 82.36 | I10: =IF(I$3="","",IF(COUNTIFS(Base!$A$3:$A$5001,I$3,Base!$B$3:$B$5001,$A$5,Base!$H$3:$H$5001,"<>")=0,"",SUMIFS(Base!$H$3:$H$5001,Base!$A$3:$A$5001,I$3,Base!$B$3:$B$5001,$A$5))) -> 42.13 | J10: =IF(J$3="","",IF(COUNTIFS(Base!$A$3:$A$5001,J$3,Base!$B$3:$B$5001,$A$5,Base!$H$3:$H$5001,"<>")=0,"",SUMIFS(Base!$H$3:$H$5001,Base!$A$3:$A$5001,J$3,Base!$B$3:$B$5001,$A$5))) -> 8.64 | K10: =IF(K$3="","",IF(COUNTIFS(Base!$A$3:$A$5001,K$3,Base!$B$3:$B$5001,$A$5,Base!$H$3:$H$5001,"<>")=0,"",SUMIFS(Base!$H$3:$H$5001,Base!$A$3:$A$5001,K$3,Base!$B$3:$B$5001,$A$5))) | L10: =IF(L$3="","",IF(COUNTIFS(Base!$A$3:$A$5001,L$3,Base!$B$3:$B$5001,$A$5,Base!$H$3:$H$5001,"<>")=0,"",SUMIFS(Base!$H$3:$H$5001,Base!$A$3:$A$5001,L$3,Base!$B$3:$B$5001,$A$5))) -> 143.18 | M10: =IF(M$3="","",IF(COUNTIFS(Base!$A$3:$A$5001,M$3,Base!$B$3:$B$5001,$A$5,Base!$H$3:$H$5001,"<>")=0,"",SUMIFS(Base!$H$3:$H$5001,Base!$A$3:$A$5001,M$3,Base!$B$3:$B$5001,$A$5))) -> 192.77 | ... AJ10: =IF(AJ$3="","",IF(COUNTIFS(Base!$A$3:$A$5001,AJ$3,Base!$B$3:$B$5001,$A$5,Base!$H$3:$H$5001,"<>")=0,"",SUMIFS(Base!$H$3:$H$5001,Base!$A$3:$A$5001,AJ$3,Base!$B$3:$B$5001,$A$5))) | AK10: =IF(COUNT(F10:AJ10)=0,"",SUM(F10:AJ10)) -> 2495.13
B11: NC | C11: Incidentes | F11: =IF(F$3="","",IF(COUNTIFS(Base!$A$3:$A$5001,F$3,Base!$B$3:$B$5001,$A$5,Base!$I$3:$I$5001,"<>")=0,"",SUMIFS(Base!$I$3:$I$5001,Base!$A$3:$A$5001,F$3,Base!$B$3:$B$5001,$A$5))) -> 0 | G11: =IF(G$3="","",IF(COUNTIFS(Base!$A$3:$A$5001,G$3,Base!$B$3:$B$5001,$A$5,Base!$I$3:$I$5001,"<>")=0,"",SUMIFS(Base!$I$3:$I$5001,Base!$A$3:$A$5001,G$3,Base!$B$3:$B$5001,$A$5))) -> 0 | H11: =IF(H$3="","",IF(COUNTIFS(Base!$A$3:$A$5001,H$3,Base!$B$3:$B$5001,$A$5,Base!$I$3:$I$5001,"<>")=0,"",SUMIFS(Base!$I$3:$I$5001,Base!$A$3:$A$5001,H$3,Base!$B$3:$B$5001,$A$5))) -> 0 | I11: =IF(I$3="","",IF(COUNTIFS(Base!$A$3:$A$5001,I$3,Base!$B$3:$B$5001,$A$5,Base!$I$3:$I$5001,"<>")=0,"",SUMIFS(Base!$I$3:$I$5001,Base!$A$3:$A$5001,I$3,Base!$B$3:$B$5001,$A$5))) -> 0 | J11: =IF(J$3="","",IF(COUNTIFS(Base!$A$3:$A$5001,J$3,Base!$B$3:$B$5001,$A$5,Base!$I$3:$I$5001,"<>")=0,"",SUMIFS(Base!$I$3:$I$5001,Base!$A$3:$A$5001,J$3,Base!$B$3:$B$5001,$A$5))) -> 0 | K11: =IF(K$3="","",IF(COUNTIFS(Base!$A$3:$A$5001,K$3,Base!$B$3:$B$5001,$A$5,Base!$I$3:$I$5001,"<>")=0,"",SUMIFS(Base!$I$3:$I$5001,Base!$A$3:$A$5001,K$3,Base!$B$3:$B$5001,$A$5))) | L11: =IF(L$3="","",IF(COUNTIFS(Base!$A$3:$A$5001,L$3,Base!$B$3:$B$5001,$A$5,Base!$I$3:$I$5001,"<>")=0,"",SUMIFS(Base!$I$3:$I$5001,Base!$A$3:$A$5001,L$3,Base!$B$3:$B$5001,$A$5))) -> 0 | M11: =IF(M$3="","",IF(COUNTIFS(Base!$A$3:$A$5001,M$3,Base!$B$3:$B$5001,$A$5,Base!$I$3:$I$5001,"<>")=0,"",SUMIFS(Base!$I$3:$I$5001,Base!$A$3:$A$5001,M$3,Base!$B$3:$B$5001,$A$5))) -> 0 | ... AJ11: =IF(AJ$3="","",IF(COUNTIFS(Base!$A$3:$A$5001,AJ$3,Base!$B$3:$B$5001,$A$5,Base!$I$3:$I$5001,"<>")=0,"",SUMIFS(Base!$I$3:$I$5001,Base!$A$3:$A$5001,AJ$3,Base!$B$3:$B$5001,$A$5))) | AK11: =IF(COUNT(F11:AJ11)=0,"",SUM(F11:AJ11)) -> 2
C12: No show | F12: =IF(F$3="","",IF(COUNTIFS(Base!$A$3:$A$5001,F$3,Base!$B$3:$B$5001,$A$5,Base!$J$3:$J$5001,"<>")=0,"",SUMIFS(Base!$J$3:$J$5001,Base!$A$3:$A$5001,F$3,Base!$B$3:$B$5001,$A$5))) | G12: =IF(G$3="","",IF(COUNTIFS(Base!$A$3:$A$5001,G$3,Base!$B$3:$B$5001,$A$5,Base!$J$3:$J$5001,"<>")=0,"",SUMIFS(Base!$J$3:$J$5001,Base!$A$3:$A$5001,G$3,Base!$B$3:$B$5001,$A$5))) | H12: =IF(H$3="","",IF(COUNTIFS(Base!$A$3:$A$5001,H$3,Base!$B$3:$B$5001,$A$5,Base!$J$3:$J$5001,"<>")=0,"",SUMIFS(Base!$J$3:$J$5001,Base!$A$3:$A$5001,H$3,Base!$B$3:$B$5001,$A$5))) | I12: =IF(I$3="","",IF(COUNTIFS(Base!$A$3:$A$5001,I$3,Base!$B$3:$B$5001,$A$5,Base!$J$3:$J$5001,"<>")=0,"",SUMIFS(Base!$J$3:$J$5001,Base!$A$3:$A$5001,I$3,Base!$B$3:$B$5001,$A$5))) | J12: =IF(J$3="","",IF(COUNTIFS(Base!$A$3:$A$5001,J$3,Base!$B$3:$B$5001,$A$5,Base!$J$3:$J$5001,"<>")=0,"",SUMIFS(Base!$J$3:$J$5001,Base!$A$3:$A$5001,J$3,Base!$B$3:$B$5001,$A$5))) | K12: =IF(K$3="","",IF(COUNTIFS(Base!$A$3:$A$5001,K$3,Base!$B$3:$B$5001,$A$5,Base!$J$3:$J$5001,"<>")=0,"",SUMIFS(Base!$J$3:$J$5001,Base!$A$3:$A$5001,K$3,Base!$B$3:$B$5001,$A$5))) | L12: =IF(L$3="","",IF(COUNTIFS(Base!$A$3:$A$5001,L$3,Base!$B$3:$B$5001,$A$5,Base!$J$3:$J$5001,"<>")=0,"",SUMIFS(Base!$J$3:$J$5001,Base!$A$3:$A$5001,L$3,Base!$B$3:$B$5001,$A$5))) | M12: =IF(M$3="","",IF(COUNTIFS(Base!$A$3:$A$5001,M$3,Base!$B$3:$B$5001,$A$5,Base!$J$3:$J$5001,"<>")=0,"",SUMIFS(Base!$J$3:$J$5001,Base!$A$3:$A$5001,M$3,Base!$B$3:$B$5001,$A$5))) | ... AJ12: =IF(AJ$3="","",IF(COUNTIFS(Base!$A$3:$A$5001,AJ$3,Base!$B$3:$B$5001,$A$5,Base!$J$3:$J$5001,"<>")=0,"",SUMIFS(Base!$J$3:$J$5001,Base!$A$3:$A$5001,AJ$3,Base!$B$3:$B$5001,$A$5))) | AK12: =IF(COUNT(F12:AJ12)=0,"",SUM(F12:AJ12))
C13: Backlog | F13: =IF(F$3="","",IF(COUNTIFS(Base!$A$3:$A$5001,F$3,Base!$B$3:$B$5001,$A$5,Base!$K$3:$K$5001,"<>")=0,"",SUMIFS(Base!$K$3:$K$5001,Base!$A$3:$A$5001,F$3,Base!$B$3:$B$5001,$A$5))) | G13: =IF(G$3="","",IF(COUNTIFS(Base!$A$3:$A$5001,G$3,Base!$B$3:$B$5001,$A$5,Base!$K$3:$K$5001,"<>")=0,"",SUMIFS(Base!$K$3:$K$5001,Base!$A$3:$A$5001,G$3,Base!$B$3:$B$5001,$A$5))) | H13: =IF(H$3="","",IF(COUNTIFS(Base!$A$3:$A$5001,H$3,Base!$B$3:$B$5001,$A$5,Base!$K$3:$K$5001,"<>")=0,"",SUMIFS(Base!$K$3:$K$5001,Base!$A$3:$A$5001,H$3,Base!$B$3:$B$5001,$A$5))) | I13: =IF(I$3="","",IF(COUNTIFS(Base!$A$3:$A$5001,I$3,Base!$B$3:$B$5001,$A$5,Base!$K$3:$K$5001,"<>")=0,"",SUMIFS(Base!$K$3:$K$5001,Base!$A$3:$A$5001,I$3,Base!$B$3:$B$5001,$A$5))) | J13: =IF(J$3="","",IF(COUNTIFS(Base!$A$3:$A$5001,J$3,Base!$B$3:$B$5001,$A$5,Base!$K$3:$K$5001,"<>")=0,"",SUMIFS(Base!$K$3:$K$5001,Base!$A$3:$A$5001,J$3,Base!$B$3:$B$5001,$A$5))) | K13: =IF(K$3="","",IF(COUNTIFS(Base!$A$3:$A$5001,K$3,Base!$B$3:$B$5001,$A$5,Base!$K$3:$K$5001,"<>")=0,"",SUMIFS(Base!$K$3:$K$5001,Base!$A$3:$A$5001,K$3,Base!$B$3:$B$5001,$A$5))) | L13: =IF(L$3="","",IF(COUNTIFS(Base!$A$3:$A$5001,L$3,Base!$B$3:$B$5001,$A$5,Base!$K$3:$K$5001,"<>")=0,"",SUMIFS(Base!$K$3:$K$5001,Base!$A$3:$A$5001,L$3,Base!$B$3:$B$5001,$A$5))) | M13: =IF(M$3="","",IF(COUNTIFS(Base!$A$3:$A$5001,M$3,Base!$B$3:$B$5001,$A$5,Base!$K$3:$K$5001,"<>")=0,"",SUMIFS(Base!$K$3:$K$5001,Base!$A$3:$A$5001,M$3,Base!$B$3:$B$5001,$A$5))) | ... AJ13: =IF(AJ$3="","",IF(COUNTIFS(Base!$A$3:$A$5001,AJ$3,Base!$B$3:$B$5001,$A$5,Base!$K$3:$K$5001,"<>")=0,"",SUMIFS(Base!$K$3:$K$5001,Base!$A$3:$A$5001,AJ$3,Base!$B$3:$B$5001,$A$5))) | AK13: =IFERROR(LOOKUP(9.99E+307,F13:AJ13),"")
B14: OCUPAÇÃO (P.P) | C14: Posições Disponíveis | F14: =IF(F$3="","",IF(COUNTIFS(Base!$A$3:$A$5001,F$3,Base!$B$3:$B$5001,$A$5,Base!$L$3:$L$5001,"<>")=0,"",SUMIFS(Base!$L$3:$L$5001,Base!$A$3:$A$5001,F$3,Base!$B$3:$B$5001,$A$5))) -> 1950 | G14: =IF(G$3="","",IF(COUNTIFS(Base!$A$3:$A$5001,G$3,Base!$B$3:$B$5001,$A$5,Base!$L$3:$L$5001,"<>")=0,"",SUMIFS(Base!$L$3:$L$5001,Base!$A$3:$A$5001,G$3,Base!$B$3:$B$5001,$A$5))) -> 1950 | H14: =IF(H$3="","",IF(COUNTIFS(Base!$A$3:$A$5001,H$3,Base!$B$3:$B$5001,$A$5,Base!$L$3:$L$5001,"<>")=0,"",SUMIFS(Base!$L$3:$L$5001,Base!$A$3:$A$5001,H$3,Base!$B$3:$B$5001,$A$5))) -> 1950 | I14: =IF(I$3="","",IF(COUNTIFS(Base!$A$3:$A$5001,I$3,Base!$B$3:$B$5001,$A$5,Base!$L$3:$L$5001,"<>")=0,"",SUMIFS(Base!$L$3:$L$5001,Base!$A$3:$A$5001,I$3,Base!$B$3:$B$5001,$A$5))) -> 1950 | J14: =IF(J$3="","",IF(COUNTIFS(Base!$A$3:$A$5001,J$3,Base!$B$3:$B$5001,$A$5,Base!$L$3:$L$5001,"<>")=0,"",SUMIFS(Base!$L$3:$L$5001,Base!$A$3:$A$5001,J$3,Base!$B$3:$B$5001,$A$5))) -> 1950 | K14: =IF(K$3="","",IF(COUNTIFS(Base!$A$3:$A$5001,K$3,Base!$B$3:$B$5001,$A$5,Base!$L$3:$L$5001,"<>")=0,"",SUMIFS(Base!$L$3:$L$5001,Base!$A$3:$A$5001,K$3,Base!$B$3:$B$5001,$A$5))) | L14: =IF(L$3="","",IF(COUNTIFS(Base!$A$3:$A$5001,L$3,Base!$B$3:$B$5001,$A$5,Base!$L$3:$L$5001,"<>")=0,"",SUMIFS(Base!$L$3:$L$5001,Base!$A$3:$A$5001,L$3,Base!$B$3:$B$5001,$A$5))) -> 1950 | M14: =IF(M$3="","",IF(COUNTIFS(Base!$A$3:$A$5001,M$3,Base!$B$3:$B$5001,$A$5,Base!$L$3:$L$5001,"<>")=0,"",SUMIFS(Base!$L$3:$L$5001,Base!$A$3:$A$5001,M$3,Base!$B$3:$B$5001,$A$5))) -> 1950 | ... AJ14: =IF(AJ$3="","",IF(COUNTIFS(Base!$A$3:$A$5001,AJ$3,Base!$B$3:$B$5001,$A$5,Base!$L$3:$L$5001,"<>")=0,"",SUMIFS(Base!$L$3:$L$5001,Base!$A$3:$A$5001,AJ$3,Base!$B$3:$B$5001,$A$5))) | AK14: =IFERROR(LOOKUP(9.99E+307,F14:AJ14),"") -> 1950
C15: Posições Ocupadas | F15: =IF(F$3="","",IF(COUNTIFS(Base!$A$3:$A$5001,F$3,Base!$B$3:$B$5001,$A$5,Base!$M$3:$M$5001,"<>")=0,"",SUMIFS(Base!$M$3:$M$5001,Base!$A$3:$A$5001,F$3,Base!$B$3:$B$5001,$A$5))) -> 1449 | G15: =IF(G$3="","",IF(COUNTIFS(Base!$A$3:$A$5001,G$3,Base!$B$3:$B$5001,$A$5,Base!$M$3:$M$5001,"<>")=0,"",SUMIFS(Base!$M$3:$M$5001,Base!$A$3:$A$5001,G$3,Base!$B$3:$B$5001,$A$5))) -> 1000 | H15: =IF(H$3="","",IF(COUNTIFS(Base!$A$3:$A$5001,H$3,Base!$B$3:$B$5001,$A$5,Base!$M$3:$M$5001,"<>")=0,"",SUMIFS(Base!$M$3:$M$5001,Base!$A$3:$A$5001,H$3,Base!$B$3:$B$5001,$A$5))) -> 1861 | I15: =IF(I$3="","",IF(COUNTIFS(Base!$A$3:$A$5001,I$3,Base!$B$3:$B$5001,$A$5,Base!$M$3:$M$5001,"<>")=0,"",SUMIFS(Base!$M$3:$M$5001,Base!$A$3:$A$5001,I$3,Base!$B$3:$B$5001,$A$5))) -> 1256 | J15: =IF(J$3="","",IF(COUNTIFS(Base!$A$3:$A$5001,J$3,Base!$B$3:$B$5001,$A$5,Base!$M$3:$M$5001,"<>")=0,"",SUMIFS(Base!$M$3:$M$5001,Base!$A$3:$A$5001,J$3,Base!$B$3:$B$5001,$A$5))) -> 1309 | K15: =IF(K$3="","",IF(COUNTIFS(Base!$A$3:$A$5001,K$3,Base!$B$3:$B$5001,$A$5,Base!$M$3:$M$5001,"<>")=0,"",SUMIFS(Base!$M$3:$M$5001,Base!$A$3:$A$5001,K$3,Base!$B$3:$B$5001,$A$5))) | L15: =IF(L$3="","",IF(COUNTIFS(Base!$A$3:$A$5001,L$3,Base!$B$3:$B$5001,$A$5,Base!$M$3:$M$5001,"<>")=0,"",SUMIFS(Base!$M$3:$M$5001,Base!$A$3:$A$5001,L$3,Base!$B$3:$B$5001,$A$5))) -> 1068 | M15: =IF(M$3="","",IF(COUNTIFS(Base!$A$3:$A$5001,M$3,Base!$B$3:$B$5001,$A$5,Base!$M$3:$M$5001,"<>")=0,"",SUMIFS(Base!$M$3:$M$5001,Base!$A$3:$A$5001,M$3,Base!$B$3:$B$5001,$A$5))) -> 1571 | ... AJ15: =IF(AJ$3="","",IF(COUNTIFS(Base!$A$3:$A$5001,AJ$3,Base!$B$3:$B$5001,$A$5,Base!$M$3:$M$5001,"<>")=0,"",SUMIFS(Base!$M$3:$M$5001,Base!$A$3:$A$5001,AJ$3,Base!$B$3:$B$5001,$A$5))) | AK15: =IFERROR(LOOKUP(9.99E+307,F15:AJ15),"") -> 1872
C16: Taxa de Ocupação | D16: 0.85 | F16: =IF(AND(ISNUMBER(F14),ISNUMBER(F15)),IF(F14>0,F15/F14,""),"") -> 0.74307692 | G16: =IF(AND(ISNUMBER(G14),ISNUMBER(G15)),IF(G14>0,G15/G14,""),"") -> 0.51282051 | H16: =IF(AND(ISNUMBER(H14),ISNUMBER(H15)),IF(H14>0,H15/H14,""),"") -> 0.95435897 | I16: =IF(AND(ISNUMBER(I14),ISNUMBER(I15)),IF(I14>0,I15/I14,""),"") -> 0.64410256 | J16: =IF(AND(ISNUMBER(J14),ISNUMBER(J15)),IF(J14>0,J15/J14,""),"") -> 0.67128205 | K16: =IF(AND(ISNUMBER(K14),ISNUMBER(K15)),IF(K14>0,K15/K14,""),"") | L16: =IF(AND(ISNUMBER(L14),ISNUMBER(L15)),IF(L14>0,L15/L14,""),"") -> 0.54769231 | M16: =IF(AND(ISNUMBER(M14),ISNUMBER(M15)),IF(M14>0,M15/M14,""),"") -> 0.80564103 | ... AK16: =IF(AND(ISNUMBER(AK14),ISNUMBER(AK15)),IF(AK14>0,AK15/AK14,""),"") -> 0.96
B17: GENTE | C17: Efetivo Op. | F17: =IF(F$3="","",IF(COUNTIFS(Base!$A$3:$A$5001,F$3,Base!$B$3:$B$5001,$A$5,Base!$N$3:$N$5001,"<>")=0,"",SUMIFS(Base!$N$3:$N$5001,Base!$A$3:$A$5001,F$3,Base!$B$3:$B$5001,$A$5))) -> 9 | G17: =IF(G$3="","",IF(COUNTIFS(Base!$A$3:$A$5001,G$3,Base!$B$3:$B$5001,$A$5,Base!$N$3:$N$5001,"<>")=0,"",SUMIFS(Base!$N$3:$N$5001,Base!$A$3:$A$5001,G$3,Base!$B$3:$B$5001,$A$5))) -> 9 | H17: =IF(H$3="","",IF(COUNTIFS(Base!$A$3:$A$5001,H$3,Base!$B$3:$B$5001,$A$5,Base!$N$3:$N$5001,"<>")=0,"",SUMIFS(Base!$N$3:$N$5001,Base!$A$3:$A$5001,H$3,Base!$B$3:$B$5001,$A$5))) -> 9 | I17: =IF(I$3="","",IF(COUNTIFS(Base!$A$3:$A$5001,I$3,Base!$B$3:$B$5001,$A$5,Base!$N$3:$N$5001,"<>")=0,"",SUMIFS(Base!$N$3:$N$5001,Base!$A$3:$A$5001,I$3,Base!$B$3:$B$5001,$A$5))) -> 8 | J17: =IF(J$3="","",IF(COUNTIFS(Base!$A$3:$A$5001,J$3,Base!$B$3:$B$5001,$A$5,Base!$N$3:$N$5001,"<>")=0,"",SUMIFS(Base!$N$3:$N$5001,Base!$A$3:$A$5001,J$3,Base!$B$3:$B$5001,$A$5))) -> 5 | K17: =IF(K$3="","",IF(COUNTIFS(Base!$A$3:$A$5001,K$3,Base!$B$3:$B$5001,$A$5,Base!$N$3:$N$5001,"<>")=0,"",SUMIFS(Base!$N$3:$N$5001,Base!$A$3:$A$5001,K$3,Base!$B$3:$B$5001,$A$5))) | L17: =IF(L$3="","",IF(COUNTIFS(Base!$A$3:$A$5001,L$3,Base!$B$3:$B$5001,$A$5,Base!$N$3:$N$5001,"<>")=0,"",SUMIFS(Base!$N$3:$N$5001,Base!$A$3:$A$5001,L$3,Base!$B$3:$B$5001,$A$5))) -> 7 | M17: =IF(M$3="","",IF(COUNTIFS(Base!$A$3:$A$5001,M$3,Base!$B$3:$B$5001,$A$5,Base!$N$3:$N$5001,"<>")=0,"",SUMIFS(Base!$N$3:$N$5001,Base!$A$3:$A$5001,M$3,Base!$B$3:$B$5001,$A$5))) -> 8 | ... AJ17: =IF(AJ$3="","",IF(COUNTIFS(Base!$A$3:$A$5001,AJ$3,Base!$B$3:$B$5001,$A$5,Base!$N$3:$N$5001,"<>")=0,"",SUMIFS(Base!$N$3:$N$5001,Base!$A$3:$A$5001,AJ$3,Base!$B$3:$B$5001,$A$5))) | AK17: =IFERROR(LOOKUP(9.99E+307,F17:AJ17),"") -> 5
C18: Falta | F18: =IF(F$3="","",IF(COUNTIFS(Base!$A$3:$A$5001,F$3,Base!$B$3:$B$5001,$A$5,Base!$O$3:$O$5001,"<>")=0,"",SUMIFS(Base!$O$3:$O$5001,Base!$A$3:$A$5001,F$3,Base!$B$3:$B$5001,$A$5))) | G18: =IF(G$3="","",IF(COUNTIFS(Base!$A$3:$A$5001,G$3,Base!$B$3:$B$5001,$A$5,Base!$O$3:$O$5001,"<>")=0,"",SUMIFS(Base!$O$3:$O$5001,Base!$A$3:$A$5001,G$3,Base!$B$3:$B$5001,$A$5))) | H18: =IF(H$3="","",IF(COUNTIFS(Base!$A$3:$A$5001,H$3,Base!$B$3:$B$5001,$A$5,Base!$O$3:$O$5001,"<>")=0,"",SUMIFS(Base!$O$3:$O$5001,Base!$A$3:$A$5001,H$3,Base!$B$3:$B$5001,$A$5))) | I18: =IF(I$3="","",IF(COUNTIFS(Base!$A$3:$A$5001,I$3,Base!$B$3:$B$5001,$A$5,Base!$O$3:$O$5001,"<>")=0,"",SUMIFS(Base!$O$3:$O$5001,Base!$A$3:$A$5001,I$3,Base!$B$3:$B$5001,$A$5))) | J18: =IF(J$3="","",IF(COUNTIFS(Base!$A$3:$A$5001,J$3,Base!$B$3:$B$5001,$A$5,Base!$O$3:$O$5001,"<>")=0,"",SUMIFS(Base!$O$3:$O$5001,Base!$A$3:$A$5001,J$3,Base!$B$3:$B$5001,$A$5))) | K18: =IF(K$3="","",IF(COUNTIFS(Base!$A$3:$A$5001,K$3,Base!$B$3:$B$5001,$A$5,Base!$O$3:$O$5001,"<>")=0,"",SUMIFS(Base!$O$3:$O$5001,Base!$A$3:$A$5001,K$3,Base!$B$3:$B$5001,$A$5))) | L18: =IF(L$3="","",IF(COUNTIFS(Base!$A$3:$A$5001,L$3,Base!$B$3:$B$5001,$A$5,Base!$O$3:$O$5001,"<>")=0,"",SUMIFS(Base!$O$3:$O$5001,Base!$A$3:$A$5001,L$3,Base!$B$3:$B$5001,$A$5))) | M18: =IF(M$3="","",IF(COUNTIFS(Base!$A$3:$A$5001,M$3,Base!$B$3:$B$5001,$A$5,Base!$O$3:$O$5001,"<>")=0,"",SUMIFS(Base!$O$3:$O$5001,Base!$A$3:$A$5001,M$3,Base!$B$3:$B$5001,$A$5))) | ... AJ18: =IF(AJ$3="","",IF(COUNTIFS(Base!$A$3:$A$5001,AJ$3,Base!$B$3:$B$5001,$A$5,Base!$O$3:$O$5001,"<>")=0,"",SUMIFS(Base!$O$3:$O$5001,Base!$A$3:$A$5001,AJ$3,Base!$B$3:$B$5001,$A$5))) | AK18: =IF(COUNT(F18:AJ18)=0,"",SUM(F18:AJ18))
C19: Folga | F19: =IF(F$3="","",IF(COUNTIFS(Base!$A$3:$A$5001,F$3,Base!$B$3:$B$5001,$A$5,Base!$P$3:$P$5001,"<>")=0,"",SUMIFS(Base!$P$3:$P$5001,Base!$A$3:$A$5001,F$3,Base!$B$3:$B$5001,$A$5))) | G19: =IF(G$3="","",IF(COUNTIFS(Base!$A$3:$A$5001,G$3,Base!$B$3:$B$5001,$A$5,Base!$P$3:$P$5001,"<>")=0,"",SUMIFS(Base!$P$3:$P$5001,Base!$A$3:$A$5001,G$3,Base!$B$3:$B$5001,$A$5))) | H19: =IF(H$3="","",IF(COUNTIFS(Base!$A$3:$A$5001,H$3,Base!$B$3:$B$5001,$A$5,Base!$P$3:$P$5001,"<>")=0,"",SUMIFS(Base!$P$3:$P$5001,Base!$A$3:$A$5001,H$3,Base!$B$3:$B$5001,$A$5))) | I19: =IF(I$3="","",IF(COUNTIFS(Base!$A$3:$A$5001,I$3,Base!$B$3:$B$5001,$A$5,Base!$P$3:$P$5001,"<>")=0,"",SUMIFS(Base!$P$3:$P$5001,Base!$A$3:$A$5001,I$3,Base!$B$3:$B$5001,$A$5))) | J19: =IF(J$3="","",IF(COUNTIFS(Base!$A$3:$A$5001,J$3,Base!$B$3:$B$5001,$A$5,Base!$P$3:$P$5001,"<>")=0,"",SUMIFS(Base!$P$3:$P$5001,Base!$A$3:$A$5001,J$3,Base!$B$3:$B$5001,$A$5))) | K19: =IF(K$3="","",IF(COUNTIFS(Base!$A$3:$A$5001,K$3,Base!$B$3:$B$5001,$A$5,Base!$P$3:$P$5001,"<>")=0,"",SUMIFS(Base!$P$3:$P$5001,Base!$A$3:$A$5001,K$3,Base!$B$3:$B$5001,$A$5))) | L19: =IF(L$3="","",IF(COUNTIFS(Base!$A$3:$A$5001,L$3,Base!$B$3:$B$5001,$A$5,Base!$P$3:$P$5001,"<>")=0,"",SUMIFS(Base!$P$3:$P$5001,Base!$A$3:$A$5001,L$3,Base!$B$3:$B$5001,$A$5))) | M19: =IF(M$3="","",IF(COUNTIFS(Base!$A$3:$A$5001,M$3,Base!$B$3:$B$5001,$A$5,Base!$P$3:$P$5001,"<>")=0,"",SUMIFS(Base!$P$3:$P$5001,Base!$A$3:$A$5001,M$3,Base!$B$3:$B$5001,$A$5))) | ... AJ19: =IF(AJ$3="","",IF(COUNTIFS(Base!$A$3:$A$5001,AJ$3,Base!$B$3:$B$5001,$A$5,Base!$P$3:$P$5001,"<>")=0,"",SUMIFS(Base!$P$3:$P$5001,Base!$A$3:$A$5001,AJ$3,Base!$B$3:$B$5001,$A$5))) | AK19: =IF(COUNT(F19:AJ19)=0,"",SUM(F19:AJ19))
C20: Férias | F20: =IF(F$3="","",IF(COUNTIFS(Base!$A$3:$A$5001,F$3,Base!$B$3:$B$5001,$A$5,Base!$Q$3:$Q$5001,"<>")=0,"",SUMIFS(Base!$Q$3:$Q$5001,Base!$A$3:$A$5001,F$3,Base!$B$3:$B$5001,$A$5))) | G20: =IF(G$3="","",IF(COUNTIFS(Base!$A$3:$A$5001,G$3,Base!$B$3:$B$5001,$A$5,Base!$Q$3:$Q$5001,"<>")=0,"",SUMIFS(Base!$Q$3:$Q$5001,Base!$A$3:$A$5001,G$3,Base!$B$3:$B$5001,$A$5))) | H20: =IF(H$3="","",IF(COUNTIFS(Base!$A$3:$A$5001,H$3,Base!$B$3:$B$5001,$A$5,Base!$Q$3:$Q$5001,"<>")=0,"",SUMIFS(Base!$Q$3:$Q$5001,Base!$A$3:$A$5001,H$3,Base!$B$3:$B$5001,$A$5))) | I20: =IF(I$3="","",IF(COUNTIFS(Base!$A$3:$A$5001,I$3,Base!$B$3:$B$5001,$A$5,Base!$Q$3:$Q$5001,"<>")=0,"",SUMIFS(Base!$Q$3:$Q$5001,Base!$A$3:$A$5001,I$3,Base!$B$3:$B$5001,$A$5))) | J20: =IF(J$3="","",IF(COUNTIFS(Base!$A$3:$A$5001,J$3,Base!$B$3:$B$5001,$A$5,Base!$Q$3:$Q$5001,"<>")=0,"",SUMIFS(Base!$Q$3:$Q$5001,Base!$A$3:$A$5001,J$3,Base!$B$3:$B$5001,$A$5))) | K20: =IF(K$3="","",IF(COUNTIFS(Base!$A$3:$A$5001,K$3,Base!$B$3:$B$5001,$A$5,Base!$Q$3:$Q$5001,"<>")=0,"",SUMIFS(Base!$Q$3:$Q$5001,Base!$A$3:$A$5001,K$3,Base!$B$3:$B$5001,$A$5))) | L20: =IF(L$3="","",IF(COUNTIFS(Base!$A$3:$A$5001,L$3,Base!$B$3:$B$5001,$A$5,Base!$Q$3:$Q$5001,"<>")=0,"",SUMIFS(Base!$Q$3:$Q$5001,Base!$A$3:$A$5001,L$3,Base!$B$3:$B$5001,$A$5))) | M20: =IF(M$3="","",IF(COUNTIFS(Base!$A$3:$A$5001,M$3,Base!$B$3:$B$5001,$A$5,Base!$Q$3:$Q$5001,"<>")=0,"",SUMIFS(Base!$Q$3:$Q$5001,Base!$A$3:$A$5001,M$3,Base!$B$3:$B$5001,$A$5))) | ... AJ20: =IF(AJ$3="","",IF(COUNTIFS(Base!$A$3:$A$5001,AJ$3,Base!$B$3:$B$5001,$A$5,Base!$Q$3:$Q$5001,"<>")=0,"",SUMIFS(Base!$Q$3:$Q$5001,Base!$A$3:$A$5001,AJ$3,Base!$B$3:$B$5001,$A$5))) | AK20: =IF(COUNT(F20:AJ20)=0,"",SUM(F20:AJ20))
C21: Desligamento | F21: =IF(F$3="","",IF(COUNTIFS(Base!$A$3:$A$5001,F$3,Base!$B$3:$B$5001,$A$5,Base!$R$3:$R$5001,"<>")=0,"",SUMIFS(Base!$R$3:$R$5001,Base!$A$3:$A$5001,F$3,Base!$B$3:$B$5001,$A$5))) | G21: =IF(G$3="","",IF(COUNTIFS(Base!$A$3:$A$5001,G$3,Base!$B$3:$B$5001,$A$5,Base!$R$3:$R$5001,"<>")=0,"",SUMIFS(Base!$R$3:$R$5001,Base!$A$3:$A$5001,G$3,Base!$B$3:$B$5001,$A$5))) | H21: =IF(H$3="","",IF(COUNTIFS(Base!$A$3:$A$5001,H$3,Base!$B$3:$B$5001,$A$5,Base!$R$3:$R$5001,"<>")=0,"",SUMIFS(Base!$R$3:$R$5001,Base!$A$3:$A$5001,H$3,Base!$B$3:$B$5001,$A$5))) | I21: =IF(I$3="","",IF(COUNTIFS(Base!$A$3:$A$5001,I$3,Base!$B$3:$B$5001,$A$5,Base!$R$3:$R$5001,"<>")=0,"",SUMIFS(Base!$R$3:$R$5001,Base!$A$3:$A$5001,I$3,Base!$B$3:$B$5001,$A$5))) | J21: =IF(J$3="","",IF(COUNTIFS(Base!$A$3:$A$5001,J$3,Base!$B$3:$B$5001,$A$5,Base!$R$3:$R$5001,"<>")=0,"",SUMIFS(Base!$R$3:$R$5001,Base!$A$3:$A$5001,J$3,Base!$B$3:$B$5001,$A$5))) | K21: =IF(K$3="","",IF(COUNTIFS(Base!$A$3:$A$5001,K$3,Base!$B$3:$B$5001,$A$5,Base!$R$3:$R$5001,"<>")=0,"",SUMIFS(Base!$R$3:$R$5001,Base!$A$3:$A$5001,K$3,Base!$B$3:$B$5001,$A$5))) | L21: =IF(L$3="","",IF(COUNTIFS(Base!$A$3:$A$5001,L$3,Base!$B$3:$B$5001,$A$5,Base!$R$3:$R$5001,"<>")=0,"",SUMIFS(Base!$R$3:$R$5001,Base!$A$3:$A$5001,L$3,Base!$B$3:$B$5001,$A$5))) | M21: =IF(M$3="","",IF(COUNTIFS(Base!$A$3:$A$5001,M$3,Base!$B$3:$B$5001,$A$5,Base!$R$3:$R$5001,"<>")=0,"",SUMIFS(Base!$R$3:$R$5001,Base!$A$3:$A$5001,M$3,Base!$B$3:$B$5001,$A$5))) | ... AJ21: =IF(AJ$3="","",IF(COUNTIFS(Base!$A$3:$A$5001,AJ$3,Base!$B$3:$B$5001,$A$5,Base!$R$3:$R$5001,"<>")=0,"",SUMIFS(Base!$R$3:$R$5001,Base!$A$3:$A$5001,AJ$3,Base!$B$3:$B$5001,$A$5))) | AK21: =IF(COUNT(F21:AJ21)=0,"",SUM(F21:AJ21))
A23: Gm | B23: IN | C23: Veículos Recebidos | F23: =IF(F$3="","",IF(COUNTIFS(Base!$A$3:$A$5001,F$3,Base!$B$3:$B$5001,$A$23,Base!$C$3:$C$5001,"<>")=0,"",SUMIFS(Base!$C$3:$C$5001,Base!$A$3:$A$5001,F$3,Base!$B$3:$B$5001,$A$23))) -> 3 | G23: =IF(G$3="","",IF(COUNTIFS(Base!$A$3:$A$5001,G$3,Base!$B$3:$B$5001,$A$23,Base!$C$3:$C$5001,"<>")=0,"",SUMIFS(Base!$C$3:$C$5001,Base!$A$3:$A$5001,G$3,Base!$B$3:$B$5001,$A$23))) -> 0 | H23: =IF(H$3="","",IF(COUNTIFS(Base!$A$3:$A$5001,H$3,Base!$B$3:$B$5001,$A$23,Base!$C$3:$C$5001,"<>")=0,"",SUMIFS(Base!$C$3:$C$5001,Base!$A$3:$A$5001,H$3,Base!$B$3:$B$5001,$A$23))) -> 7 | I23: =IF(I$3="","",IF(COUNTIFS(Base!$A$3:$A$5001,I$3,Base!$B$3:$B$5001,$A$23,Base!$C$3:$C$5001,"<>")=0,"",SUMIFS(Base!$C$3:$C$5001,Base!$A$3:$A$5001,I$3,Base!$B$3:$B$5001,$A$23))) -> 7 | J23: =IF(J$3="","",IF(COUNTIFS(Base!$A$3:$A$5001,J$3,Base!$B$3:$B$5001,$A$23,Base!$C$3:$C$5001,"<>")=0,"",SUMIFS(Base!$C$3:$C$5001,Base!$A$3:$A$5001,J$3,Base!$B$3:$B$5001,$A$23))) | K23: =IF(K$3="","",IF(COUNTIFS(Base!$A$3:$A$5001,K$3,Base!$B$3:$B$5001,$A$23,Base!$C$3:$C$5001,"<>")=0,"",SUMIFS(Base!$C$3:$C$5001,Base!$A$3:$A$5001,K$3,Base!$B$3:$B$5001,$A$23))) | L23: =IF(L$3="","",IF(COUNTIFS(Base!$A$3:$A$5001,L$3,Base!$B$3:$B$5001,$A$23,Base!$C$3:$C$5001,"<>")=0,"",SUMIFS(Base!$C$3:$C$5001,Base!$A$3:$A$5001,L$3,Base!$B$3:$B$5001,$A$23))) -> 7 | M23: =IF(M$3="","",IF(COUNTIFS(Base!$A$3:$A$5001,M$3,Base!$B$3:$B$5001,$A$23,Base!$C$3:$C$5001,"<>")=0,"",SUMIFS(Base!$C$3:$C$5001,Base!$A$3:$A$5001,M$3,Base!$B$3:$B$5001,$A$23))) -> 7 | ... AJ23: =IF(AJ$3="","",IF(COUNTIFS(Base!$A$3:$A$5001,AJ$3,Base!$B$3:$B$5001,$A$23,Base!$C$3:$C$5001,"<>")=0,"",SUMIFS(Base!$C$3:$C$5001,Base!$A$3:$A$5001,AJ$3,Base!$B$3:$B$5001,$A$23))) | AK23: =IF(COUNT(F23:AJ23)=0,"",SUM(F23:AJ23)) -> 80
C24: Pallets Movimentados | F24: =IF(F$3="","",IF(COUNTIFS(Base!$A$3:$A$5001,F$3,Base!$B$3:$B$5001,$A$23,Base!$D$3:$D$5001,"<>")=0,"",SUMIFS(Base!$D$3:$D$5001,Base!$A$3:$A$5001,F$3,Base!$B$3:$B$5001,$A$23))) -> 63 | G24: =IF(G$3="","",IF(COUNTIFS(Base!$A$3:$A$5001,G$3,Base!$B$3:$B$5001,$A$23,Base!$D$3:$D$5001,"<>")=0,"",SUMIFS(Base!$D$3:$D$5001,Base!$A$3:$A$5001,G$3,Base!$B$3:$B$5001,$A$23))) -> 0 | H24: =IF(H$3="","",IF(COUNTIFS(Base!$A$3:$A$5001,H$3,Base!$B$3:$B$5001,$A$23,Base!$D$3:$D$5001,"<>")=0,"",SUMIFS(Base!$D$3:$D$5001,Base!$A$3:$A$5001,H$3,Base!$B$3:$B$5001,$A$23))) -> 168 | I24: =IF(I$3="","",IF(COUNTIFS(Base!$A$3:$A$5001,I$3,Base!$B$3:$B$5001,$A$23,Base!$D$3:$D$5001,"<>")=0,"",SUMIFS(Base!$D$3:$D$5001,Base!$A$3:$A$5001,I$3,Base!$B$3:$B$5001,$A$23))) -> 182 | J24: =IF(J$3="","",IF(COUNTIFS(Base!$A$3:$A$5001,J$3,Base!$B$3:$B$5001,$A$23,Base!$D$3:$D$5001,"<>")=0,"",SUMIFS(Base!$D$3:$D$5001,Base!$A$3:$A$5001,J$3,Base!$B$3:$B$5001,$A$23))) | K24: =IF(K$3="","",IF(COUNTIFS(Base!$A$3:$A$5001,K$3,Base!$B$3:$B$5001,$A$23,Base!$D$3:$D$5001,"<>")=0,"",SUMIFS(Base!$D$3:$D$5001,Base!$A$3:$A$5001,K$3,Base!$B$3:$B$5001,$A$23))) | L24: =IF(L$3="","",IF(COUNTIFS(Base!$A$3:$A$5001,L$3,Base!$B$3:$B$5001,$A$23,Base!$D$3:$D$5001,"<>")=0,"",SUMIFS(Base!$D$3:$D$5001,Base!$A$3:$A$5001,L$3,Base!$B$3:$B$5001,$A$23))) -> 147 | M24: =IF(M$3="","",IF(COUNTIFS(Base!$A$3:$A$5001,M$3,Base!$B$3:$B$5001,$A$23,Base!$D$3:$D$5001,"<>")=0,"",SUMIFS(Base!$D$3:$D$5001,Base!$A$3:$A$5001,M$3,Base!$B$3:$B$5001,$A$23))) -> 189 | ... AJ24: =IF(AJ$3="","",IF(COUNTIFS(Base!$A$3:$A$5001,AJ$3,Base!$B$3:$B$5001,$A$23,Base!$D$3:$D$5001,"<>")=0,"",SUMIFS(Base!$D$3:$D$5001,Base!$A$3:$A$5001,AJ$3,Base!$B$3:$B$5001,$A$23))) | AK24: =IF(COUNT(F24:AJ24)=0,"",SUM(F24:AJ24)) -> 1902
C25: Toneladas Movimentadas | F25: =IF(F$3="","",IF(COUNTIFS(Base!$A$3:$A$5001,F$3,Base!$B$3:$B$5001,$A$23,Base!$E$3:$E$5001,"<>")=0,"",SUMIFS(Base!$E$3:$E$5001,Base!$A$3:$A$5001,F$3,Base!$B$3:$B$5001,$A$23))) -> 67.11 | G25: =IF(G$3="","",IF(COUNTIFS(Base!$A$3:$A$5001,G$3,Base!$B$3:$B$5001,$A$23,Base!$E$3:$E$5001,"<>")=0,"",SUMIFS(Base!$E$3:$E$5001,Base!$A$3:$A$5001,G$3,Base!$B$3:$B$5001,$A$23))) -> 0 | H25: =IF(H$3="","",IF(COUNTIFS(Base!$A$3:$A$5001,H$3,Base!$B$3:$B$5001,$A$23,Base!$E$3:$E$5001,"<>")=0,"",SUMIFS(Base!$E$3:$E$5001,Base!$A$3:$A$5001,H$3,Base!$B$3:$B$5001,$A$23))) -> 135.35 | I25: =IF(I$3="","",IF(COUNTIFS(Base!$A$3:$A$5001,I$3,Base!$B$3:$B$5001,$A$23,Base!$E$3:$E$5001,"<>")=0,"",SUMIFS(Base!$E$3:$E$5001,Base!$A$3:$A$5001,I$3,Base!$B$3:$B$5001,$A$23))) -> 77.89 | J25: =IF(J$3="","",IF(COUNTIFS(Base!$A$3:$A$5001,J$3,Base!$B$3:$B$5001,$A$23,Base!$E$3:$E$5001,"<>")=0,"",SUMIFS(Base!$E$3:$E$5001,Base!$A$3:$A$5001,J$3,Base!$B$3:$B$5001,$A$23))) | K25: =IF(K$3="","",IF(COUNTIFS(Base!$A$3:$A$5001,K$3,Base!$B$3:$B$5001,$A$23,Base!$E$3:$E$5001,"<>")=0,"",SUMIFS(Base!$E$3:$E$5001,Base!$A$3:$A$5001,K$3,Base!$B$3:$B$5001,$A$23))) | L25: =IF(L$3="","",IF(COUNTIFS(Base!$A$3:$A$5001,L$3,Base!$B$3:$B$5001,$A$23,Base!$E$3:$E$5001,"<>")=0,"",SUMIFS(Base!$E$3:$E$5001,Base!$A$3:$A$5001,L$3,Base!$B$3:$B$5001,$A$23))) -> 128.45 | M25: =IF(M$3="","",IF(COUNTIFS(Base!$A$3:$A$5001,M$3,Base!$B$3:$B$5001,$A$23,Base!$E$3:$E$5001,"<>")=0,"",SUMIFS(Base!$E$3:$E$5001,Base!$A$3:$A$5001,M$3,Base!$B$3:$B$5001,$A$23))) -> 121.51 | ... AJ25: =IF(AJ$3="","",IF(COUNTIFS(Base!$A$3:$A$5001,AJ$3,Base!$B$3:$B$5001,$A$23,Base!$E$3:$E$5001,"<>")=0,"",SUMIFS(Base!$E$3:$E$5001,Base!$A$3:$A$5001,AJ$3,Base!$B$3:$B$5001,$A$23))) | AK25: =IF(COUNT(F25:AJ25)=0,"",SUM(F25:AJ25)) -> 1368.17
B26: OUT | C26: Veículos Expedidos | F26: =IF(F$3="","",IF(COUNTIFS(Base!$A$3:$A$5001,F$3,Base!$B$3:$B$5001,$A$23,Base!$F$3:$F$5001,"<>")=0,"",SUMIFS(Base!$F$3:$F$5001,Base!$A$3:$A$5001,F$3,Base!$B$3:$B$5001,$A$23))) -> 11 | G26: =IF(G$3="","",IF(COUNTIFS(Base!$A$3:$A$5001,G$3,Base!$B$3:$B$5001,$A$23,Base!$F$3:$F$5001,"<>")=0,"",SUMIFS(Base!$F$3:$F$5001,Base!$A$3:$A$5001,G$3,Base!$B$3:$B$5001,$A$23))) -> 2 | H26: =IF(H$3="","",IF(COUNTIFS(Base!$A$3:$A$5001,H$3,Base!$B$3:$B$5001,$A$23,Base!$F$3:$F$5001,"<>")=0,"",SUMIFS(Base!$F$3:$F$5001,Base!$A$3:$A$5001,H$3,Base!$B$3:$B$5001,$A$23))) -> 5 | I26: =IF(I$3="","",IF(COUNTIFS(Base!$A$3:$A$5001,I$3,Base!$B$3:$B$5001,$A$23,Base!$F$3:$F$5001,"<>")=0,"",SUMIFS(Base!$F$3:$F$5001,Base!$A$3:$A$5001,I$3,Base!$B$3:$B$5001,$A$23))) -> 6 | J26: =IF(J$3="","",IF(COUNTIFS(Base!$A$3:$A$5001,J$3,Base!$B$3:$B$5001,$A$23,Base!$F$3:$F$5001,"<>")=0,"",SUMIFS(Base!$F$3:$F$5001,Base!$A$3:$A$5001,J$3,Base!$B$3:$B$5001,$A$23))) | K26: =IF(K$3="","",IF(COUNTIFS(Base!$A$3:$A$5001,K$3,Base!$B$3:$B$5001,$A$23,Base!$F$3:$F$5001,"<>")=0,"",SUMIFS(Base!$F$3:$F$5001,Base!$A$3:$A$5001,K$3,Base!$B$3:$B$5001,$A$23))) | L26: =IF(L$3="","",IF(COUNTIFS(Base!$A$3:$A$5001,L$3,Base!$B$3:$B$5001,$A$23,Base!$F$3:$F$5001,"<>")=0,"",SUMIFS(Base!$F$3:$F$5001,Base!$A$3:$A$5001,L$3,Base!$B$3:$B$5001,$A$23))) -> 2 | M26: =IF(M$3="","",IF(COUNTIFS(Base!$A$3:$A$5001,M$3,Base!$B$3:$B$5001,$A$23,Base!$F$3:$F$5001,"<>")=0,"",SUMIFS(Base!$F$3:$F$5001,Base!$A$3:$A$5001,M$3,Base!$B$3:$B$5001,$A$23))) -> 11 | ... AJ26: =IF(AJ$3="","",IF(COUNTIFS(Base!$A$3:$A$5001,AJ$3,Base!$B$3:$B$5001,$A$23,Base!$F$3:$F$5001,"<>")=0,"",SUMIFS(Base!$F$3:$F$5001,Base!$A$3:$A$5001,AJ$3,Base!$B$3:$B$5001,$A$23))) | AK26: =IF(COUNT(F26:AJ26)=0,"",SUM(F26:AJ26)) -> 86
C27: Pallets Movimentados | F27: =IF(F$3="","",IF(COUNTIFS(Base!$A$3:$A$5001,F$3,Base!$B$3:$B$5001,$A$23,Base!$G$3:$G$5001,"<>")=0,"",SUMIFS(Base!$G$3:$G$5001,Base!$A$3:$A$5001,F$3,Base!$B$3:$B$5001,$A$23))) -> 198 | G27: =IF(G$3="","",IF(COUNTIFS(Base!$A$3:$A$5001,G$3,Base!$B$3:$B$5001,$A$23,Base!$G$3:$G$5001,"<>")=0,"",SUMIFS(Base!$G$3:$G$5001,Base!$A$3:$A$5001,G$3,Base!$B$3:$B$5001,$A$23))) -> 36 | H27: =IF(H$3="","",IF(COUNTIFS(Base!$A$3:$A$5001,H$3,Base!$B$3:$B$5001,$A$23,Base!$G$3:$G$5001,"<>")=0,"",SUMIFS(Base!$G$3:$G$5001,Base!$A$3:$A$5001,H$3,Base!$B$3:$B$5001,$A$23))) -> 90 | I27: =IF(I$3="","",IF(COUNTIFS(Base!$A$3:$A$5001,I$3,Base!$B$3:$B$5001,$A$23,Base!$G$3:$G$5001,"<>")=0,"",SUMIFS(Base!$G$3:$G$5001,Base!$A$3:$A$5001,I$3,Base!$B$3:$B$5001,$A$23))) -> 108 | J27: =IF(J$3="","",IF(COUNTIFS(Base!$A$3:$A$5001,J$3,Base!$B$3:$B$5001,$A$23,Base!$G$3:$G$5001,"<>")=0,"",SUMIFS(Base!$G$3:$G$5001,Base!$A$3:$A$5001,J$3,Base!$B$3:$B$5001,$A$23))) | K27: =IF(K$3="","",IF(COUNTIFS(Base!$A$3:$A$5001,K$3,Base!$B$3:$B$5001,$A$23,Base!$G$3:$G$5001,"<>")=0,"",SUMIFS(Base!$G$3:$G$5001,Base!$A$3:$A$5001,K$3,Base!$B$3:$B$5001,$A$23))) | L27: =IF(L$3="","",IF(COUNTIFS(Base!$A$3:$A$5001,L$3,Base!$B$3:$B$5001,$A$23,Base!$G$3:$G$5001,"<>")=0,"",SUMIFS(Base!$G$3:$G$5001,Base!$A$3:$A$5001,L$3,Base!$B$3:$B$5001,$A$23))) -> 36 | M27: =IF(M$3="","",IF(COUNTIFS(Base!$A$3:$A$5001,M$3,Base!$B$3:$B$5001,$A$23,Base!$G$3:$G$5001,"<>")=0,"",SUMIFS(Base!$G$3:$G$5001,Base!$A$3:$A$5001,M$3,Base!$B$3:$B$5001,$A$23))) -> 198 | ... AJ27: =IF(AJ$3="","",IF(COUNTIFS(Base!$A$3:$A$5001,AJ$3,Base!$B$3:$B$5001,$A$23,Base!$G$3:$G$5001,"<>")=0,"",SUMIFS(Base!$G$3:$G$5001,Base!$A$3:$A$5001,AJ$3,Base!$B$3:$B$5001,$A$23))) | AK27: =IF(COUNT(F27:AJ27)=0,"",SUM(F27:AJ27)) -> 1548
C28: Toneladas Movimentadas | F28: =IF(F$3="","",IF(COUNTIFS(Base!$A$3:$A$5001,F$3,Base!$B$3:$B$5001,$A$23,Base!$H$3:$H$5001,"<>")=0,"",SUMIFS(Base!$H$3:$H$5001,Base!$A$3:$A$5001,F$3,Base!$B$3:$B$5001,$A$23))) -> 88.52 | G28: =IF(G$3="","",IF(COUNTIFS(Base!$A$3:$A$5001,G$3,Base!$B$3:$B$5001,$A$23,Base!$H$3:$H$5001,"<>")=0,"",SUMIFS(Base!$H$3:$H$5001,Base!$A$3:$A$5001,G$3,Base!$B$3:$B$5001,$A$23))) -> 34.96 | H28: =IF(H$3="","",IF(COUNTIFS(Base!$A$3:$A$5001,H$3,Base!$B$3:$B$5001,$A$23,Base!$H$3:$H$5001,"<>")=0,"",SUMIFS(Base!$H$3:$H$5001,Base!$A$3:$A$5001,H$3,Base!$B$3:$B$5001,$A$23))) -> 42.85 | I28: =IF(I$3="","",IF(COUNTIFS(Base!$A$3:$A$5001,I$3,Base!$B$3:$B$5001,$A$23,Base!$H$3:$H$5001,"<>")=0,"",SUMIFS(Base!$H$3:$H$5001,Base!$A$3:$A$5001,I$3,Base!$B$3:$B$5001,$A$23))) -> 88.72 | J28: =IF(J$3="","",IF(COUNTIFS(Base!$A$3:$A$5001,J$3,Base!$B$3:$B$5001,$A$23,Base!$H$3:$H$5001,"<>")=0,"",SUMIFS(Base!$H$3:$H$5001,Base!$A$3:$A$5001,J$3,Base!$B$3:$B$5001,$A$23))) | K28: =IF(K$3="","",IF(COUNTIFS(Base!$A$3:$A$5001,K$3,Base!$B$3:$B$5001,$A$23,Base!$H$3:$H$5001,"<>")=0,"",SUMIFS(Base!$H$3:$H$5001,Base!$A$3:$A$5001,K$3,Base!$B$3:$B$5001,$A$23))) | L28: =IF(L$3="","",IF(COUNTIFS(Base!$A$3:$A$5001,L$3,Base!$B$3:$B$5001,$A$23,Base!$H$3:$H$5001,"<>")=0,"",SUMIFS(Base!$H$3:$H$5001,Base!$A$3:$A$5001,L$3,Base!$B$3:$B$5001,$A$23))) -> 34.84 | M28: =IF(M$3="","",IF(COUNTIFS(Base!$A$3:$A$5001,M$3,Base!$B$3:$B$5001,$A$23,Base!$H$3:$H$5001,"<>")=0,"",SUMIFS(Base!$H$3:$H$5001,Base!$A$3:$A$5001,M$3,Base!$B$3:$B$5001,$A$23))) -> 144.02 | ... AJ28: =IF(AJ$3="","",IF(COUNTIFS(Base!$A$3:$A$5001,AJ$3,Base!$B$3:$B$5001,$A$23,Base!$H$3:$H$5001,"<>")=0,"",SUMIFS(Base!$H$3:$H$5001,Base!$A$3:$A$5001,AJ$3,Base!$B$3:$B$5001,$A$23))) | AK28: =IF(COUNT(F28:AJ28)=0,"",SUM(F28:AJ28)) -> 1123.68
B29: NC | C29: Incidentes | F29: =IF(F$3="","",IF(COUNTIFS(Base!$A$3:$A$5001,F$3,Base!$B$3:$B$5001,$A$23,Base!$I$3:$I$5001,"<>")=0,"",SUMIFS(Base!$I$3:$I$5001,Base!$A$3:$A$5001,F$3,Base!$B$3:$B$5001,$A$23))) -> 0 | G29: =IF(G$3="","",IF(COUNTIFS(Base!$A$3:$A$5001,G$3,Base!$B$3:$B$5001,$A$23,Base!$I$3:$I$5001,"<>")=0,"",SUMIFS(Base!$I$3:$I$5001,Base!$A$3:$A$5001,G$3,Base!$B$3:$B$5001,$A$23))) -> 0 | H29: =IF(H$3="","",IF(COUNTIFS(Base!$A$3:$A$5001,H$3,Base!$B$3:$B$5001,$A$23,Base!$I$3:$I$5001,"<>")=0,"",SUMIFS(Base!$I$3:$I$5001,Base!$A$3:$A$5001,H$3,Base!$B$3:$B$5001,$A$23))) -> 0 | I29: =IF(I$3="","",IF(COUNTIFS(Base!$A$3:$A$5001,I$3,Base!$B$3:$B$5001,$A$23,Base!$I$3:$I$5001,"<>")=0,"",SUMIFS(Base!$I$3:$I$5001,Base!$A$3:$A$5001,I$3,Base!$B$3:$B$5001,$A$23))) -> 0 | J29: =IF(J$3="","",IF(COUNTIFS(Base!$A$3:$A$5001,J$3,Base!$B$3:$B$5001,$A$23,Base!$I$3:$I$5001,"<>")=0,"",SUMIFS(Base!$I$3:$I$5001,Base!$A$3:$A$5001,J$3,Base!$B$3:$B$5001,$A$23))) | K29: =IF(K$3="","",IF(COUNTIFS(Base!$A$3:$A$5001,K$3,Base!$B$3:$B$5001,$A$23,Base!$I$3:$I$5001,"<>")=0,"",SUMIFS(Base!$I$3:$I$5001,Base!$A$3:$A$5001,K$3,Base!$B$3:$B$5001,$A$23))) | L29: =IF(L$3="","",IF(COUNTIFS(Base!$A$3:$A$5001,L$3,Base!$B$3:$B$5001,$A$23,Base!$I$3:$I$5001,"<>")=0,"",SUMIFS(Base!$I$3:$I$5001,Base!$A$3:$A$5001,L$3,Base!$B$3:$B$5001,$A$23))) -> 0 | M29: =IF(M$3="","",IF(COUNTIFS(Base!$A$3:$A$5001,M$3,Base!$B$3:$B$5001,$A$23,Base!$I$3:$I$5001,"<>")=0,"",SUMIFS(Base!$I$3:$I$5001,Base!$A$3:$A$5001,M$3,Base!$B$3:$B$5001,$A$23))) -> 0 | ... AJ29: =IF(AJ$3="","",IF(COUNTIFS(Base!$A$3:$A$5001,AJ$3,Base!$B$3:$B$5001,$A$23,Base!$I$3:$I$5001,"<>")=0,"",SUMIFS(Base!$I$3:$I$5001,Base!$A$3:$A$5001,AJ$3,Base!$B$3:$B$5001,$A$23))) | AK29: =IF(COUNT(F29:AJ29)=0,"",SUM(F29:AJ29)) -> 1
C30: No show | F30: =IF(F$3="","",IF(COUNTIFS(Base!$A$3:$A$5001,F$3,Base!$B$3:$B$5001,$A$23,Base!$J$3:$J$5001,"<>")=0,"",SUMIFS(Base!$J$3:$J$5001,Base!$A$3:$A$5001,F$3,Base!$B$3:$B$5001,$A$23))) | G30: =IF(G$3="","",IF(COUNTIFS(Base!$A$3:$A$5001,G$3,Base!$B$3:$B$5001,$A$23,Base!$J$3:$J$5001,"<>")=0,"",SUMIFS(Base!$J$3:$J$5001,Base!$A$3:$A$5001,G$3,Base!$B$3:$B$5001,$A$23))) | H30: =IF(H$3="","",IF(COUNTIFS(Base!$A$3:$A$5001,H$3,Base!$B$3:$B$5001,$A$23,Base!$J$3:$J$5001,"<>")=0,"",SUMIFS(Base!$J$3:$J$5001,Base!$A$3:$A$5001,H$3,Base!$B$3:$B$5001,$A$23))) | I30: =IF(I$3="","",IF(COUNTIFS(Base!$A$3:$A$5001,I$3,Base!$B$3:$B$5001,$A$23,Base!$J$3:$J$5001,"<>")=0,"",SUMIFS(Base!$J$3:$J$5001,Base!$A$3:$A$5001,I$3,Base!$B$3:$B$5001,$A$23))) | J30: =IF(J$3="","",IF(COUNTIFS(Base!$A$3:$A$5001,J$3,Base!$B$3:$B$5001,$A$23,Base!$J$3:$J$5001,"<>")=0,"",SUMIFS(Base!$J$3:$J$5001,Base!$A$3:$A$5001,J$3,Base!$B$3:$B$5001,$A$23))) | K30: =IF(K$3="","",IF(COUNTIFS(Base!$A$3:$A$5001,K$3,Base!$B$3:$B$5001,$A$23,Base!$J$3:$J$5001,"<>")=0,"",SUMIFS(Base!$J$3:$J$5001,Base!$A$3:$A$5001,K$3,Base!$B$3:$B$5001,$A$23))) | L30: =IF(L$3="","",IF(COUNTIFS(Base!$A$3:$A$5001,L$3,Base!$B$3:$B$5001,$A$23,Base!$J$3:$J$5001,"<>")=0,"",SUMIFS(Base!$J$3:$J$5001,Base!$A$3:$A$5001,L$3,Base!$B$3:$B$5001,$A$23))) | M30: =IF(M$3="","",IF(COUNTIFS(Base!$A$3:$A$5001,M$3,Base!$B$3:$B$5001,$A$23,Base!$J$3:$J$5001,"<>")=0,"",SUMIFS(Base!$J$3:$J$5001,Base!$A$3:$A$5001,M$3,Base!$B$3:$B$5001,$A$23))) | ... AJ30: =IF(AJ$3="","",IF(COUNTIFS(Base!$A$3:$A$5001,AJ$3,Base!$B$3:$B$5001,$A$23,Base!$J$3:$J$5001,"<>")=0,"",SUMIFS(Base!$J$3:$J$5001,Base!$A$3:$A$5001,AJ$3,Base!$B$3:$B$5001,$A$23))) | AK30: =IF(COUNT(F30:AJ30)=0,"",SUM(F30:AJ30))
C31: Backlog | F31: =IF(F$3="","",IF(COUNTIFS(Base!$A$3:$A$5001,F$3,Base!$B$3:$B$5001,$A$23,Base!$K$3:$K$5001,"<>")=0,"",SUMIFS(Base!$K$3:$K$5001,Base!$A$3:$A$5001,F$3,Base!$B$3:$B$5001,$A$23))) | G31: =IF(G$3="","",IF(COUNTIFS(Base!$A$3:$A$5001,G$3,Base!$B$3:$B$5001,$A$23,Base!$K$3:$K$5001,"<>")=0,"",SUMIFS(Base!$K$3:$K$5001,Base!$A$3:$A$5001,G$3,Base!$B$3:$B$5001,$A$23))) | H31: =IF(H$3="","",IF(COUNTIFS(Base!$A$3:$A$5001,H$3,Base!$B$3:$B$5001,$A$23,Base!$K$3:$K$5001,"<>")=0,"",SUMIFS(Base!$K$3:$K$5001,Base!$A$3:$A$5001,H$3,Base!$B$3:$B$5001,$A$23))) | I31: =IF(I$3="","",IF(COUNTIFS(Base!$A$3:$A$5001,I$3,Base!$B$3:$B$5001,$A$23,Base!$K$3:$K$5001,"<>")=0,"",SUMIFS(Base!$K$3:$K$5001,Base!$A$3:$A$5001,I$3,Base!$B$3:$B$5001,$A$23))) | J31: =IF(J$3="","",IF(COUNTIFS(Base!$A$3:$A$5001,J$3,Base!$B$3:$B$5001,$A$23,Base!$K$3:$K$5001,"<>")=0,"",SUMIFS(Base!$K$3:$K$5001,Base!$A$3:$A$5001,J$3,Base!$B$3:$B$5001,$A$23))) | K31: =IF(K$3="","",IF(COUNTIFS(Base!$A$3:$A$5001,K$3,Base!$B$3:$B$5001,$A$23,Base!$K$3:$K$5001,"<>")=0,"",SUMIFS(Base!$K$3:$K$5001,Base!$A$3:$A$5001,K$3,Base!$B$3:$B$5001,$A$23))) | L31: =IF(L$3="","",IF(COUNTIFS(Base!$A$3:$A$5001,L$3,Base!$B$3:$B$5001,$A$23,Base!$K$3:$K$5001,"<>")=0,"",SUMIFS(Base!$K$3:$K$5001,Base!$A$3:$A$5001,L$3,Base!$B$3:$B$5001,$A$23))) | M31: =IF(M$3="","",IF(COUNTIFS(Base!$A$3:$A$5001,M$3,Base!$B$3:$B$5001,$A$23,Base!$K$3:$K$5001,"<>")=0,"",SUMIFS(Base!$K$3:$K$5001,Base!$A$3:$A$5001,M$3,Base!$B$3:$B$5001,$A$23))) | ... AJ31: =IF(AJ$3="","",IF(COUNTIFS(Base!$A$3:$A$5001,AJ$3,Base!$B$3:$B$5001,$A$23,Base!$K$3:$K$5001,"<>")=0,"",SUMIFS(Base!$K$3:$K$5001,Base!$A$3:$A$5001,AJ$3,Base!$B$3:$B$5001,$A$23))) | AK31: =IFERROR(LOOKUP(9.99E+307,F31:AJ31),"")
B32: OCUPAÇÃO (P.P) | C32: Posições Disponíveis | F32: =IF(F$3="","",IF(COUNTIFS(Base!$A$3:$A$5001,F$3,Base!$B$3:$B$5001,$A$23,Base!$L$3:$L$5001,"<>")=0,"",SUMIFS(Base!$L$3:$L$5001,Base!$A$3:$A$5001,F$3,Base!$B$3:$B$5001,$A$23))) -> 800 | G32: =IF(G$3="","",IF(COUNTIFS(Base!$A$3:$A$5001,G$3,Base!$B$3:$B$5001,$A$23,Base!$L$3:$L$5001,"<>")=0,"",SUMIFS(Base!$L$3:$L$5001,Base!$A$3:$A$5001,G$3,Base!$B$3:$B$5001,$A$23))) -> 800 | H32: =IF(H$3="","",IF(COUNTIFS(Base!$A$3:$A$5001,H$3,Base!$B$3:$B$5001,$A$23,Base!$L$3:$L$5001,"<>")=0,"",SUMIFS(Base!$L$3:$L$5001,Base!$A$3:$A$5001,H$3,Base!$B$3:$B$5001,$A$23))) -> 800 | I32: =IF(I$3="","",IF(COUNTIFS(Base!$A$3:$A$5001,I$3,Base!$B$3:$B$5001,$A$23,Base!$L$3:$L$5001,"<>")=0,"",SUMIFS(Base!$L$3:$L$5001,Base!$A$3:$A$5001,I$3,Base!$B$3:$B$5001,$A$23))) -> 800 | J32: =IF(J$3="","",IF(COUNTIFS(Base!$A$3:$A$5001,J$3,Base!$B$3:$B$5001,$A$23,Base!$L$3:$L$5001,"<>")=0,"",SUMIFS(Base!$L$3:$L$5001,Base!$A$3:$A$5001,J$3,Base!$B$3:$B$5001,$A$23))) | K32: =IF(K$3="","",IF(COUNTIFS(Base!$A$3:$A$5001,K$3,Base!$B$3:$B$5001,$A$23,Base!$L$3:$L$5001,"<>")=0,"",SUMIFS(Base!$L$3:$L$5001,Base!$A$3:$A$5001,K$3,Base!$B$3:$B$5001,$A$23))) | L32: =IF(L$3="","",IF(COUNTIFS(Base!$A$3:$A$5001,L$3,Base!$B$3:$B$5001,$A$23,Base!$L$3:$L$5001,"<>")=0,"",SUMIFS(Base!$L$3:$L$5001,Base!$A$3:$A$5001,L$3,Base!$B$3:$B$5001,$A$23))) -> 800 | M32: =IF(M$3="","",IF(COUNTIFS(Base!$A$3:$A$5001,M$3,Base!$B$3:$B$5001,$A$23,Base!$L$3:$L$5001,"<>")=0,"",SUMIFS(Base!$L$3:$L$5001,Base!$A$3:$A$5001,M$3,Base!$B$3:$B$5001,$A$23))) -> 800 | ... AJ32: =IF(AJ$3="","",IF(COUNTIFS(Base!$A$3:$A$5001,AJ$3,Base!$B$3:$B$5001,$A$23,Base!$L$3:$L$5001,"<>")=0,"",SUMIFS(Base!$L$3:$L$5001,Base!$A$3:$A$5001,AJ$3,Base!$B$3:$B$5001,$A$23))) | AK32: =IFERROR(LOOKUP(9.99E+307,F32:AJ32),"") -> 800
C33: Posições Ocupadas | F33: =IF(F$3="","",IF(COUNTIFS(Base!$A$3:$A$5001,F$3,Base!$B$3:$B$5001,$A$23,Base!$M$3:$M$5001,"<>")=0,"",SUMIFS(Base!$M$3:$M$5001,Base!$A$3:$A$5001,F$3,Base!$B$3:$B$5001,$A$23))) -> 517 | G33: =IF(G$3="","",IF(COUNTIFS(Base!$A$3:$A$5001,G$3,Base!$B$3:$B$5001,$A$23,Base!$M$3:$M$5001,"<>")=0,"",SUMIFS(Base!$M$3:$M$5001,Base!$A$3:$A$5001,G$3,Base!$B$3:$B$5001,$A$23))) -> 633 | H33: =IF(H$3="","",IF(COUNTIFS(Base!$A$3:$A$5001,H$3,Base!$B$3:$B$5001,$A$23,Base!$M$3:$M$5001,"<>")=0,"",SUMIFS(Base!$M$3:$M$5001,Base!$A$3:$A$5001,H$3,Base!$B$3:$B$5001,$A$23))) -> 598 | I33: =IF(I$3="","",IF(COUNTIFS(Base!$A$3:$A$5001,I$3,Base!$B$3:$B$5001,$A$23,Base!$M$3:$M$5001,"<>")=0,"",SUMIFS(Base!$M$3:$M$5001,Base!$A$3:$A$5001,I$3,Base!$B$3:$B$5001,$A$23))) -> 617 | J33: =IF(J$3="","",IF(COUNTIFS(Base!$A$3:$A$5001,J$3,Base!$B$3:$B$5001,$A$23,Base!$M$3:$M$5001,"<>")=0,"",SUMIFS(Base!$M$3:$M$5001,Base!$A$3:$A$5001,J$3,Base!$B$3:$B$5001,$A$23))) | K33: =IF(K$3="","",IF(COUNTIFS(Base!$A$3:$A$5001,K$3,Base!$B$3:$B$5001,$A$23,Base!$M$3:$M$5001,"<>")=0,"",SUMIFS(Base!$M$3:$M$5001,Base!$A$3:$A$5001,K$3,Base!$B$3:$B$5001,$A$23))) | L33: =IF(L$3="","",IF(COUNTIFS(Base!$A$3:$A$5001,L$3,Base!$B$3:$B$5001,$A$23,Base!$M$3:$M$5001,"<>")=0,"",SUMIFS(Base!$M$3:$M$5001,Base!$A$3:$A$5001,L$3,Base!$B$3:$B$5001,$A$23))) -> 666 | M33: =IF(M$3="","",IF(COUNTIFS(Base!$A$3:$A$5001,M$3,Base!$B$3:$B$5001,$A$23,Base!$M$3:$M$5001,"<>")=0,"",SUMIFS(Base!$M$3:$M$5001,Base!$A$3:$A$5001,M$3,Base!$B$3:$B$5001,$A$23))) -> 503 | ... AJ33: =IF(AJ$3="","",IF(COUNTIFS(Base!$A$3:$A$5001,AJ$3,Base!$B$3:$B$5001,$A$23,Base!$M$3:$M$5001,"<>")=0,"",SUMIFS(Base!$M$3:$M$5001,Base!$A$3:$A$5001,AJ$3,Base!$B$3:$B$5001,$A$23))) | AK33: =IFERROR(LOOKUP(9.99E+307,F33:AJ33),"") -> 565
C34: Taxa de Ocupação | F34: =IF(AND(ISNUMBER(F32),ISNUMBER(F33)),IF(F32>0,F33/F32,""),"") -> 0.64625 | G34: =IF(AND(ISNUMBER(G32),ISNUMBER(G33)),IF(G32>0,G33/G32,""),"") -> 0.79125 | H34: =IF(AND(ISNUMBER(H32),ISNUMBER(H33)),IF(H32>0,H33/H32,""),"") -> 0.7475 | I34: =IF(AND(ISNUMBER(I32),ISNUMBER(I33)),IF(I32>0,I33/I32,""),"") -> 0.77125 | J34: =IF(AND(ISNUMBER(J32),ISNUMBER(J33)),IF(J32>0,J33/J32,""),"") | K34: =IF(AND(ISNUMBER(K32),ISNUMBER(K33)),IF(K32>0,K33/K32,""),"") | L34: =IF(AND(ISNUMBER(L32),ISNUMBER(L33)),IF(L32>0,L33/L32,""),"") -> 0.8325 | M34: =IF(AND(ISNUMBER(M32),ISNUMBER(M33)),IF(M32>0,M33/M32,""),"") -> 0.62875 | ... AK34: =IF(AND(ISNUMBER(AK32),ISNUMBER(AK33)),IF(AK32>0,AK33/AK32,""),"") -> 0.70625
B35: GENTE | C35: Efetivo Op. | F35: =IF(F$3="","",IF(COUNTIFS(Base!$A$3:$A$5001,F$3,Base!$B$3:$B$5001,$A$23,Base!$N$3:$N$5001,"<>")=0,"",SUMIFS(Base!$N$3:$N$5001,Base!$A$3:$A$5001,F$3,Base!$B$3:$B$5001,$A$23))) -> 9 | G35: =IF(G$3="","",IF(COUNTIFS(Base!$A$3:$A$5001,G$3,Base!$B$3:$B$5001,$A$23,Base!$N$3:$N$5001,"<>")=0,"",SUMIFS(Base!$N$3:$N$5001,Base!$A$3:$A$5001,G$3,Base!$B$3:$B$5001,$A$23))) -> 6 | H35: =IF(H$3="","",IF(COUNTIFS(Base!$A$3:$A$5001,H$3,Base!$B$3:$B$5001,$A$23,Base!$N$3:$N$5001,"<>")=0,"",SUMIFS(Base!$N$3:$N$5001,Base!$A$3:$A$5001,H$3,Base!$B$3:$B$5001,$A$23))) -> 7 | I35: =IF(I$3="","",IF(COUNTIFS(Base!$A$3:$A$5001,I$3,Base!$B$3:$B$5001,$A$23,Base!$N$3:$N$5001,"<>")=0,"",SUMIFS(Base!$N$3:$N$5001,Base!$A$3:$A$5001,I$3,Base!$B$3:$B$5001,$A$23))) -> 3 | J35: =IF(J$3="","",IF(COUNTIFS(Base!$A$3:$A$5001,J$3,Base!$B$3:$B$5001,$A$23,Base!$N$3:$N$5001,"<>")=0,"",SUMIFS(Base!$N$3:$N$5001,Base!$A$3:$A$5001,J$3,Base!$B$3:$B$5001,$A$23))) | K35: =IF(K$3="","",IF(COUNTIFS(Base!$A$3:$A$5001,K$3,Base!$B$3:$B$5001,$A$23,Base!$N$3:$N$5001,"<>")=0,"",SUMIFS(Base!$N$3:$N$5001,Base!$A$3:$A$5001,K$3,Base!$B$3:$B$5001,$A$23))) | L35: =IF(L$3="","",IF(COUNTIFS(Base!$A$3:$A$5001,L$3,Base!$B$3:$B$5001,$A$23,Base!$N$3:$N$5001,"<>")=0,"",SUMIFS(Base!$N$3:$N$5001,Base!$A$3:$A$5001,L$3,Base!$B$3:$B$5001,$A$23))) -> 8 | M35: =IF(M$3="","",IF(COUNTIFS(Base!$A$3:$A$5001,M$3,Base!$B$3:$B$5001,$A$23,Base!$N$3:$N$5001,"<>")=0,"",SUMIFS(Base!$N$3:$N$5001,Base!$A$3:$A$5001,M$3,Base!$B$3:$B$5001,$A$23))) -> 6 | ... AJ35: =IF(AJ$3="","",IF(COUNTIFS(Base!$A$3:$A$5001,AJ$3,Base!$B$3:$B$5001,$A$23,Base!$N$3:$N$5001,"<>")=0,"",SUMIFS(Base!$N$3:$N$5001,Base!$A$3:$A$5001,AJ$3,Base!$B$3:$B$5001,$A$23))) | AK35: =IFERROR(LOOKUP(9.99E+307,F35:AJ35),"") -> 5
C36: Falta | F36: =IF(F$3="","",IF(COUNTIFS(Base!$A$3:$A$5001,F$3,Base!$B$3:$B$5001,$A$23,Base!$O$3:$O$5001,"<>")=0,"",SUMIFS(Base!$O$3:$O$5001,Base!$A$3:$A$5001,F$3,Base!$B$3:$B$5001,$A$23))) | G36: =IF(G$3="","",IF(COUNTIFS(Base!$A$3:$A$5001,G$3,Base!$B$3:$B$5001,$A$23,Base!$O$3:$O$5001,"<>")=0,"",SUMIFS(Base!$O$3:$O$5001,Base!$A$3:$A$5001,G$3,Base!$B$3:$B$5001,$A$23))) | H36: =IF(H$3="","",IF(COUNTIFS(Base!$A$3:$A$5001,H$3,Base!$B$3:$B$5001,$A$23,Base!$O$3:$O$5001,"<>")=0,"",SUMIFS(Base!$O$3:$O$5001,Base!$A$3:$A$5001,H$3,Base!$B$3:$B$5001,$A$23))) | I36: =IF(I$3="","",IF(COUNTIFS(Base!$A$3:$A$5001,I$3,Base!$B$3:$B$5001,$A$23,Base!$O$3:$O$5001,"<>")=0,"",SUMIFS(Base!$O$3:$O$5001,Base!$A$3:$A$5001,I$3,Base!$B$3:$B$5001,$A$23))) | J36: =IF(J$3="","",IF(COUNTIFS(Base!$A$3:$A$5001,J$3,Base!$B$3:$B$5001,$A$23,Base!$O$3:$O$5001,"<>")=0,"",SUMIFS(Base!$O$3:$O$5001,Base!$A$3:$A$5001,J$3,Base!$B$3:$B$5001,$A$23))) | K36: =IF(K$3="","",IF(COUNTIFS(Base!$A$3:$A$5001,K$3,Base!$B$3:$B$5001,$A$23,Base!$O$3:$O$5001,"<>")=0,"",SUMIFS(Base!$O$3:$O$5001,Base!$A$3:$A$5001,K$3,Base!$B$3:$B$5001,$A$23))) | L36: =IF(L$3="","",IF(COUNTIFS(Base!$A$3:$A$5001,L$3,Base!$B$3:$B$5001,$A$23,Base!$O$3:$O$5001,"<>")=0,"",SUMIFS(Base!$O$3:$O$5001,Base!$A$3:$A$5001,L$3,Base!$B$3:$B$5001,$A$23))) | M36: =IF(M$3="","",IF(COUNTIFS(Base!$A$3:$A$5001,M$3,Base!$B$3:$B$5001,$A$23,Base!$O$3:$O$5001,"<>")=0,"",SUMIFS(Base!$O$3:$O$5001,Base!$A$3:$A$5001,M$3,Base!$B$3:$B$5001,$A$23))) | ... AJ36: =IF(AJ$3="","",IF(COUNTIFS(Base!$A$3:$A$5001,AJ$3,Base!$B$3:$B$5001,$A$23,Base!$O$3:$O$5001,"<>")=0,"",SUMIFS(Base!$O$3:$O$5001,Base!$A$3:$A$5001,AJ$3,Base!$B$3:$B$5001,$A$23))) | AK36: =IF(COUNT(F36:AJ36)=0,"",SUM(F36:AJ36))
C37: Folga | F37: =IF(F$3="","",IF(COUNTIFS(Base!$A$3:$A$5001,F$3,Base!$B$3:$B$5001,$A$23,Base!$P$3:$P$5001,"<>")=0,"",SUMIFS(Base!$P$3:$P$5001,Base!$A$3:$A$5001,F$3,Base!$B$3:$B$5001,$A$23))) | G37: =IF(G$3="","",IF(COUNTIFS(Base!$A$3:$A$5001,G$3,Base!$B$3:$B$5001,$A$23,Base!$P$3:$P$5001,"<>")=0,"",SUMIFS(Base!$P$3:$P$5001,Base!$A$3:$A$5001,G$3,Base!$B$3:$B$5001,$A$23))) | H37: =IF(H$3="","",IF(COUNTIFS(Base!$A$3:$A$5001,H$3,Base!$B$3:$B$5001,$A$23,Base!$P$3:$P$5001,"<>")=0,"",SUMIFS(Base!$P$3:$P$5001,Base!$A$3:$A$5001,H$3,Base!$B$3:$B$5001,$A$23))) | I37: =IF(I$3="","",IF(COUNTIFS(Base!$A$3:$A$5001,I$3,Base!$B$3:$B$5001,$A$23,Base!$P$3:$P$5001,"<>")=0,"",SUMIFS(Base!$P$3:$P$5001,Base!$A$3:$A$5001,I$3,Base!$B$3:$B$5001,$A$23))) | J37: =IF(J$3="","",IF(COUNTIFS(Base!$A$3:$A$5001,J$3,Base!$B$3:$B$5001,$A$23,Base!$P$3:$P$5001,"<>")=0,"",SUMIFS(Base!$P$3:$P$5001,Base!$A$3:$A$5001,J$3,Base!$B$3:$B$5001,$A$23))) | K37: =IF(K$3="","",IF(COUNTIFS(Base!$A$3:$A$5001,K$3,Base!$B$3:$B$5001,$A$23,Base!$P$3:$P$5001,"<>")=0,"",SUMIFS(Base!$P$3:$P$5001,Base!$A$3:$A$5001,K$3,Base!$B$3:$B$5001,$A$23))) | L37: =IF(L$3="","",IF(COUNTIFS(Base!$A$3:$A$5001,L$3,Base!$B$3:$B$5001,$A$23,Base!$P$3:$P$5001,"<>")=0,"",SUMIFS(Base!$P$3:$P$5001,Base!$A$3:$A$5001,L$3,Base!$B$3:$B$5001,$A$23))) | M37: =IF(M$3="","",IF(COUNTIFS(Base!$A$3:$A$5001,M$3,Base!$B$3:$B$5001,$A$23,Base!$P$3:$P$5001,"<>")=0,"",SUMIFS(Base!$P$3:$P$5001,Base!$A$3:$A$5001,M$3,Base!$B$3:$B$5001,$A$23))) | ... AJ37: =IF(AJ$3="","",IF(COUNTIFS(Base!$A$3:$A$5001,AJ$3,Base!$B$3:$B$5001,$A$23,Base!$P$3:$P$5001,"<>")=0,"",SUMIFS(Base!$P$3:$P$5001,Base!$A$3:$A$5001,AJ$3,Base!$B$3:$B$5001,$A$23))) | AK37: =IF(COUNT(F37:AJ37)=0,"",SUM(F37:AJ37))
C38: Férias | F38: =IF(F$3="","",IF(COUNTIFS(Base!$A$3:$A$5001,F$3,Base!$B$3:$B$5001,$A$23,Base!$Q$3:$Q$5001,"<>")=0,"",SUMIFS(Base!$Q$3:$Q$5001,Base!$A$3:$A$5001,F$3,Base!$B$3:$B$5001,$A$23))) | G38: =IF(G$3="","",IF(COUNTIFS(Base!$A$3:$A$5001,G$3,Base!$B$3:$B$5001,$A$23,Base!$Q$3:$Q$5001,"<>")=0,"",SUMIFS(Base!$Q$3:$Q$5001,Base!$A$3:$A$5001,G$3,Base!$B$3:$B$5001,$A$23))) | H38: =IF(H$3="","",IF(COUNTIFS(Base!$A$3:$A$5001,H$3,Base!$B$3:$B$5001,$A$23,Base!$Q$3:$Q$5001,"<>")=0,"",SUMIFS(Base!$Q$3:$Q$5001,Base!$A$3:$A$5001,H$3,Base!$B$3:$B$5001,$A$23))) | I38: =IF(I$3="","",IF(COUNTIFS(Base!$A$3:$A$5001,I$3,Base!$B$3:$B$5001,$A$23,Base!$Q$3:$Q$5001,"<>")=0,"",SUMIFS(Base!$Q$3:$Q$5001,Base!$A$3:$A$5001,I$3,Base!$B$3:$B$5001,$A$23))) | J38: =IF(J$3="","",IF(COUNTIFS(Base!$A$3:$A$5001,J$3,Base!$B$3:$B$5001,$A$23,Base!$Q$3:$Q$5001,"<>")=0,"",SUMIFS(Base!$Q$3:$Q$5001,Base!$A$3:$A$5001,J$3,Base!$B$3:$B$5001,$A$23))) | K38: =IF(K$3="","",IF(COUNTIFS(Base!$A$3:$A$5001,K$3,Base!$B$3:$B$5001,$A$23,Base!$Q$3:$Q$5001,"<>")=0,"",SUMIFS(Base!$Q$3:$Q$5001,Base!$A$3:$A$5001,K$3,Base!$B$3:$B$5001,$A$23))) | L38: =IF(L$3="","",IF(COUNTIFS(Base!$A$3:$A$5001,L$3,Base!$B$3:$B$5001,$A$23,Base!$Q$3:$Q$5001,"<>")=0,"",SUMIFS(Base!$Q$3:$Q$5001,Base!$A$3:$A$5001,L$3,Base!$B$3:$B$5001,$A$23))) | M38: =IF(M$3="","",IF(COUNTIFS(Base!$A$3:$A$5001,M$3,Base!$B$3:$B$5001,$A$23,Base!$Q$3:$Q$5001,"<>")=0,"",SUMIFS(Base!$Q$3:$Q$5001,Base!$A$3:$A$5001,M$3,Base!$B$3:$B$5001,$A$23))) | ... AJ38: =IF(AJ$3="","",IF(COUNTIFS(Base!$A$3:$A$5001,AJ$3,Base!$B$3:$B$5001,$A$23,Base!$Q$3:$Q$5001,"<>")=0,"",SUMIFS(Base!$Q$3:$Q$5001,Base!$A$3:$A$5001,AJ$3,Base!$B$3:$B$5001,$A$23))) | AK38: =IF(COUNT(F38:AJ38)=0,"",SUM(F38:AJ38))
C39: Desligamento | F39: =IF(F$3="","",IF(COUNTIFS(Base!$A$3:$A$5001,F$3,Base!$B$3:$B$5001,$A$23,Base!$R$3:$R$5001,"<>")=0,"",SUMIFS(Base!$R$3:$R$5001,Base!$A$3:$A$5001,F$3,Base!$B$3:$B$5001,$A$23))) | G39: =IF(G$3="","",IF(COUNTIFS(Base!$A$3:$A$5001,G$3,Base!$B$3:$B$5001,$A$23,Base!$R$3:$R$5001,"<>")=0,"",SUMIFS(Base!$R$3:$R$5001,Base!$A$3:$A$5001,G$3,Base!$B$3:$B$5001,$A$23))) | H39: =IF(H$3="","",IF(COUNTIFS(Base!$A$3:$A$5001,H$3,Base!$B$3:$B$5001,$A$23,Base!$R$3:$R$5001,"<>")=0,"",SUMIFS(Base!$R$3:$R$5001,Base!$A$3:$A$5001,H$3,Base!$B$3:$B$5001,$A$23))) | I39: =IF(I$3="","",IF(COUNTIFS(Base!$A$3:$A$5001,I$3,Base!$B$3:$B$5001,$A$23,Base!$R$3:$R$5001,"<>")=0,"",SUMIFS(Base!$R$3:$R$5001,Base!$A$3:$A$5001,I$3,Base!$B$3:$B$5001,$A$23))) | J39: =IF(J$3="","",IF(COUNTIFS(Base!$A$3:$A$5001,J$3,Base!$B$3:$B$5001,$A$23,Base!$R$3:$R$5001,"<>")=0,"",SUMIFS(Base!$R$3:$R$5001,Base!$A$3:$A$5001,J$3,Base!$B$3:$B$5001,$A$23))) | K39: =IF(K$3="","",IF(COUNTIFS(Base!$A$3:$A$5001,K$3,Base!$B$3:$B$5001,$A$23,Base!$R$3:$R$5001,"<>")=0,"",SUMIFS(Base!$R$3:$R$5001,Base!$A$3:$A$5001,K$3,Base!$B$3:$B$5001,$A$23))) | L39: =IF(L$3="","",IF(COUNTIFS(Base!$A$3:$A$5001,L$3,Base!$B$3:$B$5001,$A$23,Base!$R$3:$R$5001,"<>")=0,"",SUMIFS(Base!$R$3:$R$5001,Base!$A$3:$A$5001,L$3,Base!$B$3:$B$5001,$A$23))) | M39: =IF(M$3="","",IF(COUNTIFS(Base!$A$3:$A$5001,M$3,Base!$B$3:$B$5001,$A$23,Base!$R$3:$R$5001,"<>")=0,"",SUMIFS(Base!$R$3:$R$5001,Base!$A$3:$A$5001,M$3,Base!$B$3:$B$5001,$A$23))) | ... AJ39: =IF(AJ$3="","",IF(COUNTIFS(Base!$A$3:$A$5001,AJ$3,Base!$B$3:$B$5001,$A$23,Base!$R$3:$R$5001,"<>")=0,"",SUMIFS(Base!$R$3:$R$5001,Base!$A$3:$A$5001,AJ$3,Base!$B$3:$B$5001,$A$23))) | AK39: =IF(COUNT(F39:AJ39)=0,"",SUM(F39:AJ39))
