Workbook

Sheet Indicadores
G1: INDICADORES OPERACIONAIS | U1: SETEMBRO · 2026
B3: CLIENTE ▸ | D3: Todos | Q3: =IF(calculos!$B$9=0,"Sem dados na Base para o mês escolhido","Dados até "&TEXT(calculos!$C$7+calculos!$B$9-1,"dd/mm")&" · ▲▼ comparado a "&LOWER(LEFT(calculos!$B$8,FIND("/",calculos!$B$8)-1))&" (dias 1 a "&calculos!$B$9&")") -> Sem dados na Base para o mês escolhido
B5: RECEBIMENTO (IN) | G5: EXPEDIÇÃO (OUT) | L5: NÃO CONFORMIDADES | Q5: OCUPAÇÃO (P.P) | V5: GENTE
C6: =calculos!$C$43 -> 0 | H6: =calculos!$L$43 -> 0 | M6: =calculos!$U$43 -> 0 | R6: =calculos!$Z$43 | W6: =calculos!$AA$43
B9: veículos recebidos | G9: veículos expedidos | L9: incidentes no mês | Q9: ="taxa de ocupação · "&calculos!$Z$50 -> taxa de ocupação · | V9: efetivo operacional
B10: =IFERROR(IF(calculos!$B$3="","",FIXED(INDEX(calculos!$C$43:$AE$43,MATCH(calculos!$B$3,calculos!$C$11:$AE$11,0)),IF(ISNUMBER(SEARCH("Toneladas",calculos!$B$3)),1,0))&" "&MID(calculos!$B$3,FIND(" ",calculos!$B$3)+1,99)),"") -> 0 Pallets Movimentados | G10: =IFERROR(IF(calculos!$C$3="","",FIXED(INDEX(calculos!$C$43:$AE$43,MATCH(calculos!$C$3,calculos!$C$11:$AE$11,0)),IF(ISNUMBER(SEARCH("Toneladas",calculos!$C$3)),1,0))&" "&MID(calculos!$C$3,FIND(" ",calculos!$C$3)+1,99)),"") -> 0 Pallets Movimentados | L10: =calculos!$V$43 -> 0 | Q10: =calculos!$Y$43 | V10: =calculos!$AB$43 -> 0
B11: =calculos!$C$47 | G11: =calculos!$L$47 | L11: =calculos!$U$47 | Q11: =calculos!$Z$47 | V11: =calculos!$AA$47
B48: Cartões e gráficos seguem o filtro de cliente (o ranking mostra todos). Detalhe dos indicadores de cada cliente na aba “Quadro de Indicadores”. Fonte: Power Automate · IntraLog.

Sheet Monitoramento
F1: MONITORAMENTO DIÁRIO DE PERFORMANCE | AE1: SETEMBRO · 2026
A2: CLIENTE | B2: INDICADORES | D2: META | F2: REALIZADO P/DIA | AK2: MÊS
F3: =IF(ISNUMBER($AE$1),DATE(YEAR($AE$1),MONTH($AE$1),1),IFERROR(DATE(VALUE(RIGHT(TRIM($AE$1),4)),MATCH(TRIM(LEFT($AE$1,FIND("·",$AE$1)-1)),{"JANEIRO","FEVEREIRO","MARÇO","ABRIL","MAIO","JUNHO","JULHO","AGOSTO","SETEMBRO","OUTUBRO","NOVEMBRO","DEZEMBRO"},0),1),DATE(2026,9,1))) -> 46266 | G3: =IF(F3="","",IF(MONTH(F3+1)=MONTH($F$3),F3+1,"")) -> 46267 | H3: =IF(G3="","",IF(MONTH(G3+1)=MONTH($F$3),G3+1,"")) -> 46268 | I3: =IF(H3="","",IF(MONTH(H3+1)=MONTH($F$3),H3+1,"")) -> 46269 | J3: =IF(I3="","",IF(MONTH(I3+1)=MONTH($F$3),I3+1,"")) -> 46270 | K3: =IF(J3="","",IF(MONTH(J3+1)=MONTH($F$3),J3+1,"")) -> 46271 | L3: =IF(K3="","",IF(MONTH(K3+1)=MONTH($F$3),K3+1,"")) -> 46272 | M3: =IF(L3="","",IF(MONTH(L3+1)=MONTH($F$3),L3+1,"")) -> 46273 | N3: =IF(M3="","",IF(MONTH(M3+1)=MONTH($F$3),M3+1,"")) -> 46274 | ... AJ3: =IF(AI3="","",IF(MONTH(AI3+1)=MONTH($F$3),AI3+1,""))
A5: BASF | B5: IN | C5: Veículos Recebidos | D5: =IFERROR(1/(1/INDEX(calculos!$C$55:$K$83,MATCH("IN Veículos Recebidos",calculos!$A$55:$A$83,0),MATCH($A$5,calculos!$C$54:$K$54,0))),"") | F5: =IF(F$3="","",IF(COUNTIFS(Base!$A$3:$A$5001,F$3,Base!$B$3:$B$5001,$A$5,Base!$C$3:$C$5001,"<>")=0,"",SUMIFS(Base!$C$3:$C$5001,Base!$A$3:$A$5001,F$3,Base!$B$3:$B$5001,$A$5))) | G5: =IF(G$3="","",IF(COUNTIFS(Base!$A$3:$A$5001,G$3,Base!$B$3:$B$5001,$A$5,Base!$C$3:$C$5001,"<>")=0,"",SUMIFS(Base!$C$3:$C$5001,Base!$A$3:$A$5001,G$3,Base!$B$3:$B$5001,$A$5))) | H5: =IF(H$3="","",IF(COUNTIFS(Base!$A$3:$A$5001,H$3,Base!$B$3:$B$5001,$A$5,Base!$C$3:$C$5001,"<>")=0,"",SUMIFS(Base!$C$3:$C$5001,Base!$A$3:$A$5001,H$3,Base!$B$3:$B$5001,$A$5))) | I5: =IF(I$3="","",IF(COUNTIFS(Base!$A$3:$A$5001,I$3,Base!$B$3:$B$5001,$A$5,Base!$C$3:$C$5001,"<>")=0,"",SUMIFS(Base!$C$3:$C$5001,Base!$A$3:$A$5001,I$3,Base!$B$3:$B$5001,$A$5))) | J5: =IF(J$3="","",IF(COUNTIFS(Base!$A$3:$A$5001,J$3,Base!$B$3:$B$5001,$A$5,Base!$C$3:$C$5001,"<>")=0,"",SUMIFS(Base!$C$3:$C$5001,Base!$A$3:$A$5001,J$3,Base!$B$3:$B$5001,$A$5))) | K5: =IF(K$3="","",IF(COUNTIFS(Base!$A$3:$A$5001,K$3,Base!$B$3:$B$5001,$A$5,Base!$C$3:$C$5001,"<>")=0,"",SUMIFS(Base!$C$3:$C$5001,Base!$A$3:$A$5001,K$3,Base!$B$3:$B$5001,$A$5))) | L5: =IF(L$3="","",IF(COUNTIFS(Base!$A$3:$A$5001,L$3,Base!$B$3:$B$5001,$A$5,Base!$C$3:$C$5001,"<>")=0,"",SUMIFS(Base!$C$3:$C$5001,Base!$A$3:$A$5001,L$3,Base!$B$3:$B$5001,$A$5))) | M5: =IF(M$3="","",IF(COUNTIFS(Base!$A$3:$A$5001,M$3,Base!$B$3:$B$5001,$A$5,Base!$C$3:$C$5001,"<>")=0,"",SUMIFS(Base!$C$3:$C$5001,Base!$A$3:$A$5001,M$3,Base!$B$3:$B$5001,$A$5))) | ... AJ5: =IF(AJ$3="","",IF(COUNTIFS(Base!$A$3:$A$5001,AJ$3,Base!$B$3:$B$5001,$A$5,Base!$C$3:$C$5001,"<>")=0,"",SUMIFS(Base!$C$3:$C$5001,Base!$A$3:$A$5001,AJ$3,Base!$B$3:$B$5001,$A$5))) | AK5: =IF(COUNT(F5:AJ5)=0,"",SUM(F5:AJ5))
C6: Pallets Movimentados | D6: =IFERROR(1/(1/INDEX(calculos!$C$55:$K$83,MATCH("IN Pallets Movimentados",calculos!$A$55:$A$83,0),MATCH($A$5,calculos!$C$54:$K$54,0))),"") | F6: =IF(F$3="","",IF(COUNTIFS(Base!$A$3:$A$5001,F$3,Base!$B$3:$B$5001,$A$5,Base!$D$3:$D$5001,"<>")=0,"",SUMIFS(Base!$D$3:$D$5001,Base!$A$3:$A$5001,F$3,Base!$B$3:$B$5001,$A$5))) | G6: =IF(G$3="","",IF(COUNTIFS(Base!$A$3:$A$5001,G$3,Base!$B$3:$B$5001,$A$5,Base!$D$3:$D$5001,"<>")=0,"",SUMIFS(Base!$D$3:$D$5001,Base!$A$3:$A$5001,G$3,Base!$B$3:$B$5001,$A$5))) | H6: =IF(H$3="","",IF(COUNTIFS(Base!$A$3:$A$5001,H$3,Base!$B$3:$B$5001,$A$5,Base!$D$3:$D$5001,"<>")=0,"",SUMIFS(Base!$D$3:$D$5001,Base!$A$3:$A$5001,H$3,Base!$B$3:$B$5001,$A$5))) | I6: =IF(I$3="","",IF(COUNTIFS(Base!$A$3:$A$5001,I$3,Base!$B$3:$B$5001,$A$5,Base!$D$3:$D$5001,"<>")=0,"",SUMIFS(Base!$D$3:$D$5001,Base!$A$3:$A$5001,I$3,Base!$B$3:$B$5001,$A$5))) | J6: =IF(J$3="","",IF(COUNTIFS(Base!$A$3:$A$5001,J$3,Base!$B$3:$B$5001,$A$5,Base!$D$3:$D$5001,"<>")=0,"",SUMIFS(Base!$D$3:$D$5001,Base!$A$3:$A$5001,J$3,Base!$B$3:$B$5001,$A$5))) | K6: =IF(K$3="","",IF(COUNTIFS(Base!$A$3:$A$5001,K$3,Base!$B$3:$B$5001,$A$5,Base!$D$3:$D$5001,"<>")=0,"",SUMIFS(Base!$D$3:$D$5001,Base!$A$3:$A$5001,K$3,Base!$B$3:$B$5001,$A$5))) | L6: =IF(L$3="","",IF(COUNTIFS(Base!$A$3:$A$5001,L$3,Base!$B$3:$B$5001,$A$5,Base!$D$3:$D$5001,"<>")=0,"",SUMIFS(Base!$D$3:$D$5001,Base!$A$3:$A$5001,L$3,Base!$B$3:$B$5001,$A$5))) | M6: =IF(M$3="","",IF(COUNTIFS(Base!$A$3:$A$5001,M$3,Base!$B$3:$B$5001,$A$5,Base!$D$3:$D$5001,"<>")=0,"",SUMIFS(Base!$D$3:$D$5001,Base!$A$3:$A$5001,M$3,Base!$B$3:$B$5001,$A$5))) | ... AJ6: =IF(AJ$3="","",IF(COUNTIFS(Base!$A$3:$A$5001,AJ$3,Base!$B$3:$B$5001,$A$5,Base!$D$3:$D$5001,"<>")=0,"",SUMIFS(Base!$D$3:$D$5001,Base!$A$3:$A$5001,AJ$3,Base!$B$3:$B$5001,$A$5))) | AK6: =IF(COUNT(F6:AJ6)=0,"",SUM(F6:AJ6))
C7: Toneladas Movimentadas | D7: =IFERROR(1/(1/INDEX(calculos!$C$55:$K$83,MATCH("IN Toneladas Movimentadas",calculos!$A$55:$A$83,0),MATCH($A$5,calculos!$C$54:$K$54,0))),"") | F7: =IF(F$3="","",IF(COUNTIFS(Base!$A$3:$A$5001,F$3,Base!$B$3:$B$5001,$A$5,Base!$E$3:$E$5001,"<>")=0,"",SUMIFS(Base!$E$3:$E$5001,Base!$A$3:$A$5001,F$3,Base!$B$3:$B$5001,$A$5))) | G7: =IF(G$3="","",IF(COUNTIFS(Base!$A$3:$A$5001,G$3,Base!$B$3:$B$5001,$A$5,Base!$E$3:$E$5001,"<>")=0,"",SUMIFS(Base!$E$3:$E$5001,Base!$A$3:$A$5001,G$3,Base!$B$3:$B$5001,$A$5))) | H7: =IF(H$3="","",IF(COUNTIFS(Base!$A$3:$A$5001,H$3,Base!$B$3:$B$5001,$A$5,Base!$E$3:$E$5001,"<>")=0,"",SUMIFS(Base!$E$3:$E$5001,Base!$A$3:$A$5001,H$3,Base!$B$3:$B$5001,$A$5))) | I7: =IF(I$3="","",IF(COUNTIFS(Base!$A$3:$A$5001,I$3,Base!$B$3:$B$5001,$A$5,Base!$E$3:$E$5001,"<>")=0,"",SUMIFS(Base!$E$3:$E$5001,Base!$A$3:$A$5001,I$3,Base!$B$3:$B$5001,$A$5))) | J7: =IF(J$3="","",IF(COUNTIFS(Base!$A$3:$A$5001,J$3,Base!$B$3:$B$5001,$A$5,Base!$E$3:$E$5001,"<>")=0,"",SUMIFS(Base!$E$3:$E$5001,Base!$A$3:$A$5001,J$3,Base!$B$3:$B$5001,$A$5))) | K7: =IF(K$3="","",IF(COUNTIFS(Base!$A$3:$A$5001,K$3,Base!$B$3:$B$5001,$A$5,Base!$E$3:$E$5001,"<>")=0,"",SUMIFS(Base!$E$3:$E$5001,Base!$A$3:$A$5001,K$3,Base!$B$3:$B$5001,$A$5))) | L7: =IF(L$3="","",IF(COUNTIFS(Base!$A$3:$A$5001,L$3,Base!$B$3:$B$5001,$A$5,Base!$E$3:$E$5001,"<>")=0,"",SUMIFS(Base!$E$3:$E$5001,Base!$A$3:$A$5001,L$3,Base!$B$3:$B$5001,$A$5))) | M7: =IF(M$3="","",IF(COUNTIFS(Base!$A$3:$A$5001,M$3,Base!$B$3:$B$5001,$A$5,Base!$E$3:$E$5001,"<>")=0,"",SUMIFS(Base!$E$3:$E$5001,Base!$A$3:$A$5001,M$3,Base!$B$3:$B$5001,$A$5))) | ... AJ7: =IF(AJ$3="","",IF(COUNTIFS(Base!$A$3:$A$5001,AJ$3,Base!$B$3:$B$5001,$A$5,Base!$E$3:$E$5001,"<>")=0,"",SUMIFS(Base!$E$3:$E$5001,Base!$A$3:$A$5001,AJ$3,Base!$B$3:$B$5001,$A$5))) | AK7: =IF(COUNT(F7:AJ7)=0,"",SUM(F7:AJ7))
B8: OUT | C8: Veículos Expedidos | D8: =IFERROR(1/(1/INDEX(calculos!$C$55:$K$83,MATCH("OUT Veículos Expedidos",calculos!$A$55:$A$83,0),MATCH($A$5,calculos!$C$54:$K$54,0))),"") | F8: =IF(F$3="","",IF(COUNTIFS(Base!$A$3:$A$5001,F$3,Base!$B$3:$B$5001,$A$5,Base!$L$3:$L$5001,"<>")=0,"",SUMIFS(Base!$L$3:$L$5001,Base!$A$3:$A$5001,F$3,Base!$B$3:$B$5001,$A$5))) | G8: =IF(G$3="","",IF(COUNTIFS(Base!$A$3:$A$5001,G$3,Base!$B$3:$B$5001,$A$5,Base!$L$3:$L$5001,"<>")=0,"",SUMIFS(Base!$L$3:$L$5001,Base!$A$3:$A$5001,G$3,Base!$B$3:$B$5001,$A$5))) | H8: =IF(H$3="","",IF(COUNTIFS(Base!$A$3:$A$5001,H$3,Base!$B$3:$B$5001,$A$5,Base!$L$3:$L$5001,"<>")=0,"",SUMIFS(Base!$L$3:$L$5001,Base!$A$3:$A$5001,H$3,Base!$B$3:$B$5001,$A$5))) | I8: =IF(I$3="","",IF(COUNTIFS(Base!$A$3:$A$5001,I$3,Base!$B$3:$B$5001,$A$5,Base!$L$3:$L$5001,"<>")=0,"",SUMIFS(Base!$L$3:$L$5001,Base!$A$3:$A$5001,I$3,Base!$B$3:$B$5001,$A$5))) | J8: =IF(J$3="","",IF(COUNTIFS(Base!$A$3:$A$5001,J$3,Base!$B$3:$B$5001,$A$5,Base!$L$3:$L$5001,"<>")=0,"",SUMIFS(Base!$L$3:$L$5001,Base!$A$3:$A$5001,J$3,Base!$B$3:$B$5001,$A$5))) | K8: =IF(K$3="","",IF(COUNTIFS(Base!$A$3:$A$5001,K$3,Base!$B$3:$B$5001,$A$5,Base!$L$3:$L$5001,"<>")=0,"",SUMIFS(Base!$L$3:$L$5001,Base!$A$3:$A$5001,K$3,Base!$B$3:$B$5001,$A$5))) | L8: =IF(L$3="","",IF(COUNTIFS(Base!$A$3:$A$5001,L$3,Base!$B$3:$B$5001,$A$5,Base!$L$3:$L$5001,"<>")=0,"",SUMIFS(Base!$L$3:$L$5001,Base!$A$3:$A$5001,L$3,Base!$B$3:$B$5001,$A$5))) | M8: =IF(M$3="","",IF(COUNTIFS(Base!$A$3:$A$5001,M$3,Base!$B$3:$B$5001,$A$5,Base!$L$3:$L$5001,"<>")=0,"",SUMIFS(Base!$L$3:$L$5001,Base!$A$3:$A$5001,M$3,Base!$B$3:$B$5001,$A$5))) | ... AJ8: =IF(AJ$3="","",IF(COUNTIFS(Base!$A$3:$A$5001,AJ$3,Base!$B$3:$B$5001,$A$5,Base!$L$3:$L$5001,"<>")=0,"",SUMIFS(Base!$L$3:$L$5001,Base!$A$3:$A$5001,AJ$3,Base!$B$3:$B$5001,$A$5))) | AK8: =IF(COUNT(F8:AJ8)=0,"",SUM(F8:AJ8))
C9: Pallets Movimentados | D9: =IFERROR(1/(1/INDEX(calculos!$C$55:$K$83,MATCH("OUT Pallets Movimentados",calculos!$A$55:$A$83,0),MATCH($A$5,calculos!$C$54:$K$54,0))),"") | F9: =IF(F$3="","",IF(COUNTIFS(Base!$A$3:$A$5001,F$3,Base!$B$3:$B$5001,$A$5,Base!$M$3:$M$5001,"<>")=0,"",SUMIFS(Base!$M$3:$M$5001,Base!$A$3:$A$5001,F$3,Base!$B$3:$B$5001,$A$5))) | G9: =IF(G$3="","",IF(COUNTIFS(Base!$A$3:$A$5001,G$3,Base!$B$3:$B$5001,$A$5,Base!$M$3:$M$5001,"<>")=0,"",SUMIFS(Base!$M$3:$M$5001,Base!$A$3:$A$5001,G$3,Base!$B$3:$B$5001,$A$5))) | H9: =IF(H$3="","",IF(COUNTIFS(Base!$A$3:$A$5001,H$3,Base!$B$3:$B$5001,$A$5,Base!$M$3:$M$5001,"<>")=0,"",SUMIFS(Base!$M$3:$M$5001,Base!$A$3:$A$5001,H$3,Base!$B$3:$B$5001,$A$5))) | I9: =IF(I$3="","",IF(COUNTIFS(Base!$A$3:$A$5001,I$3,Base!$B$3:$B$5001,$A$5,Base!$M$3:$M$5001,"<>")=0,"",SUMIFS(Base!$M$3:$M$5001,Base!$A$3:$A$5001,I$3,Base!$B$3:$B$5001,$A$5))) | J9: =IF(J$3="","",IF(COUNTIFS(Base!$A$3:$A$5001,J$3,Base!$B$3:$B$5001,$A$5,Base!$M$3:$M$5001,"<>")=0,"",SUMIFS(Base!$M$3:$M$5001,Base!$A$3:$A$5001,J$3,Base!$B$3:$B$5001,$A$5))) | K9: =IF(K$3="","",IF(COUNTIFS(Base!$A$3:$A$5001,K$3,Base!$B$3:$B$5001,$A$5,Base!$M$3:$M$5001,"<>")=0,"",SUMIFS(Base!$M$3:$M$5001,Base!$A$3:$A$5001,K$3,Base!$B$3:$B$5001,$A$5))) | L9: =IF(L$3="","",IF(COUNTIFS(Base!$A$3:$A$5001,L$3,Base!$B$3:$B$5001,$A$5,Base!$M$3:$M$5001,"<>")=0,"",SUMIFS(Base!$M$3:$M$5001,Base!$A$3:$A$5001,L$3,Base!$B$3:$B$5001,$A$5))) | M9: =IF(M$3="","",IF(COUNTIFS(Base!$A$3:$A$5001,M$3,Base!$B$3:$B$5001,$A$5,Base!$M$3:$M$5001,"<>")=0,"",SUMIFS(Base!$M$3:$M$5001,Base!$A$3:$A$5001,M$3,Base!$B$3:$B$5001,$A$5))) | ... AJ9: =IF(AJ$3="","",IF(COUNTIFS(Base!$A$3:$A$5001,AJ$3,Base!$B$3:$B$5001,$A$5,Base!$M$3:$M$5001,"<>")=0,"",SUMIFS(Base!$M$3:$M$5001,Base!$A$3:$A$5001,AJ$3,Base!$B$3:$B$5001,$A$5))) | AK9: =IF(COUNT(F9:AJ9)=0,"",SUM(F9:AJ9))
C10: Toneladas Movimentadas | D10: =IFERROR(1/(1/INDEX(calculos!$C$55:$K$83,MATCH("OUT Toneladas Movimentadas",calculos!$A$55:$A$83,0),MATCH($A$5,calculos!$C$54:$K$54,0))),"") | F10: =IF(F$3="","",IF(COUNTIFS(Base!$A$3:$A$5001,F$3,Base!$B$3:$B$5001,$A$5,Base!$N$3:$N$5001,"<>")=0,"",SUMIFS(Base!$N$3:$N$5001,Base!$A$3:$A$5001,F$3,Base!$B$3:$B$5001,$A$5))) | G10: =IF(G$3="","",IF(COUNTIFS(Base!$A$3:$A$5001,G$3,Base!$B$3:$B$5001,$A$5,Base!$N$3:$N$5001,"<>")=0,"",SUMIFS(Base!$N$3:$N$5001,Base!$A$3:$A$5001,G$3,Base!$B$3:$B$5001,$A$5))) | H10: =IF(H$3="","",IF(COUNTIFS(Base!$A$3:$A$5001,H$3,Base!$B$3:$B$5001,$A$5,Base!$N$3:$N$5001,"<>")=0,"",SUMIFS(Base!$N$3:$N$5001,Base!$A$3:$A$5001,H$3,Base!$B$3:$B$5001,$A$5))) | I10: =IF(I$3="","",IF(COUNTIFS(Base!$A$3:$A$5001,I$3,Base!$B$3:$B$5001,$A$5,Base!$N$3:$N$5001,"<>")=0,"",SUMIFS(Base!$N$3:$N$5001,Base!$A$3:$A$5001,I$3,Base!$B$3:$B$5001,$A$5))) | J10: =IF(J$3="","",IF(COUNTIFS(Base!$A$3:$A$5001,J$3,Base!$B$3:$B$5001,$A$5,Base!$N$3:$N$5001,"<>")=0,"",SUMIFS(Base!$N$3:$N$5001,Base!$A$3:$A$5001,J$3,Base!$B$3:$B$5001,$A$5))) | K10: =IF(K$3="","",IF(COUNTIFS(Base!$A$3:$A$5001,K$3,Base!$B$3:$B$5001,$A$5,Base!$N$3:$N$5001,"<>")=0,"",SUMIFS(Base!$N$3:$N$5001,Base!$A$3:$A$5001,K$3,Base!$B$3:$B$5001,$A$5))) | L10: =IF(L$3="","",IF(COUNTIFS(Base!$A$3:$A$5001,L$3,Base!$B$3:$B$5001,$A$5,Base!$N$3:$N$5001,"<>")=0,"",SUMIFS(Base!$N$3:$N$5001,Base!$A$3:$A$5001,L$3,Base!$B$3:$B$5001,$A$5))) | M10: =IF(M$3="","",IF(COUNTIFS(Base!$A$3:$A$5001,M$3,Base!$B$3:$B$5001,$A$5,Base!$N$3:$N$5001,"<>")=0,"",SUMIFS(Base!$N$3:$N$5001,Base!$A$3:$A$5001,M$3,Base!$B$3:$B$5001,$A$5))) | ... AJ10: =IF(AJ$3="","",IF(COUNTIFS(Base!$A$3:$A$5001,AJ$3,Base!$B$3:$B$5001,$A$5,Base!$N$3:$N$5001,"<>")=0,"",SUMIFS(Base!$N$3:$N$5001,Base!$A$3:$A$5001,AJ$3,Base!$B$3:$B$5001,$A$5))) | AK10: =IF(COUNT(F10:AJ10)=0,"",SUM(F10:AJ10))
B11: NC | C11: Incidentes | D11: =IFERROR(1/(1/INDEX(calculos!$C$55:$K$83,MATCH("NC Incidentes",calculos!$A$55:$A$83,0),MATCH($A$5,calculos!$C$54:$K$54,0))),"") | F11: =IF(F$3="","",IF(COUNTIFS(Base!$A$3:$A$5001,F$3,Base!$B$3:$B$5001,$A$5,Base!$U$3:$U$5001,"<>")=0,"",SUMIFS(Base!$U$3:$U$5001,Base!$A$3:$A$5001,F$3,Base!$B$3:$B$5001,$A$5))) | G11: =IF(G$3="","",IF(COUNTIFS(Base!$A$3:$A$5001,G$3,Base!$B$3:$B$5001,$A$5,Base!$U$3:$U$5001,"<>")=0,"",SUMIFS(Base!$U$3:$U$5001,Base!$A$3:$A$5001,G$3,Base!$B$3:$B$5001,$A$5))) | H11: =IF(H$3="","",IF(COUNTIFS(Base!$A$3:$A$5001,H$3,Base!$B$3:$B$5001,$A$5,Base!$U$3:$U$5001,"<>")=0,"",SUMIFS(Base!$U$3:$U$5001,Base!$A$3:$A$5001,H$3,Base!$B$3:$B$5001,$A$5))) | I11: =IF(I$3="","",IF(COUNTIFS(Base!$A$3:$A$5001,I$3,Base!$B$3:$B$5001,$A$5,Base!$U$3:$U$5001,"<>")=0,"",SUMIFS(Base!$U$3:$U$5001,Base!$A$3:$A$5001,I$3,Base!$B$3:$B$5001,$A$5))) | J11: =IF(J$3="","",IF(COUNTIFS(Base!$A$3:$A$5001,J$3,Base!$B$3:$B$5001,$A$5,Base!$U$3:$U$5001,"<>")=0,"",SUMIFS(Base!$U$3:$U$5001,Base!$A$3:$A$5001,J$3,Base!$B$3:$B$5001,$A$5))) | K11: =IF(K$3="","",IF(COUNTIFS(Base!$A$3:$A$5001,K$3,Base!$B$3:$B$5001,$A$5,Base!$U$3:$U$5001,"<>")=0,"",SUMIFS(Base!$U$3:$U$5001,Base!$A$3:$A$5001,K$3,Base!$B$3:$B$5001,$A$5))) | L11: =IF(L$3="","",IF(COUNTIFS(Base!$A$3:$A$5001,L$3,Base!$B$3:$B$5001,$A$5,Base!$U$3:$U$5001,"<>")=0,"",SUMIFS(Base!$U$3:$U$5001,Base!$A$3:$A$5001,L$3,Base!$B$3:$B$5001,$A$5))) | M11: =IF(M$3="","",IF(COUNTIFS(Base!$A$3:$A$5001,M$3,Base!$B$3:$B$5001,$A$5,Base!$U$3:$U$5001,"<>")=0,"",SUMIFS(Base!$U$3:$U$5001,Base!$A$3:$A$5001,M$3,Base!$B$3:$B$5001,$A$5))) | ... AJ11: =IF(AJ$3="","",IF(COUNTIFS(Base!$A$3:$A$5001,AJ$3,Base!$B$3:$B$5001,$A$5,Base!$U$3:$U$5001,"<>")=0,"",SUMIFS(Base!$U$3:$U$5001,Base!$A$3:$A$5001,AJ$3,Base!$B$3:$B$5001,$A$5))) | AK11: =IF(COUNT(F11:AJ11)=0,"",SUM(F11:AJ11))
C12: No show | D12: =IFERROR(1/(1/INDEX(calculos!$C$55:$K$83,MATCH("NC No show",calculos!$A$55:$A$83,0),MATCH($A$5,calculos!$C$54:$K$54,0))),"") | F12: =IF(F$3="","",IF(COUNTIFS(Base!$A$3:$A$5001,F$3,Base!$B$3:$B$5001,$A$5,Base!$V$3:$V$5001,"<>")=0,"",SUMIFS(Base!$V$3:$V$5001,Base!$A$3:$A$5001,F$3,Base!$B$3:$B$5001,$A$5))) | G12: =IF(G$3="","",IF(COUNTIFS(Base!$A$3:$A$5001,G$3,Base!$B$3:$B$5001,$A$5,Base!$V$3:$V$5001,"<>")=0,"",SUMIFS(Base!$V$3:$V$5001,Base!$A$3:$A$5001,G$3,Base!$B$3:$B$5001,$A$5))) | H12: =IF(H$3="","",IF(COUNTIFS(Base!$A$3:$A$5001,H$3,Base!$B$3:$B$5001,$A$5,Base!$V$3:$V$5001,"<>")=0,"",SUMIFS(Base!$V$3:$V$5001,Base!$A$3:$A$5001,H$3,Base!$B$3:$B$5001,$A$5))) | I12: =IF(I$3="","",IF(COUNTIFS(Base!$A$3:$A$5001,I$3,Base!$B$3:$B$5001,$A$5,Base!$V$3:$V$5001,"<>")=0,"",SUMIFS(Base!$V$3:$V$5001,Base!$A$3:$A$5001,I$3,Base!$B$3:$B$5001,$A$5))) | J12: =IF(J$3="","",IF(COUNTIFS(Base!$A$3:$A$5001,J$3,Base!$B$3:$B$5001,$A$5,Base!$V$3:$V$5001,"<>")=0,"",SUMIFS(Base!$V$3:$V$5001,Base!$A$3:$A$5001,J$3,Base!$B$3:$B$5001,$A$5))) | K12: =IF(K$3="","",IF(COUNTIFS(Base!$A$3:$A$5001,K$3,Base!$B$3:$B$5001,$A$5,Base!$V$3:$V$5001,"<>")=0,"",SUMIFS(Base!$V$3:$V$5001,Base!$A$3:$A$5001,K$3,Base!$B$3:$B$5001,$A$5))) | L12: =IF(L$3="","",IF(COUNTIFS(Base!$A$3:$A$5001,L$3,Base!$B$3:$B$5001,$A$5,Base!$V$3:$V$5001,"<>")=0,"",SUMIFS(Base!$V$3:$V$5001,Base!$A$3:$A$5001,L$3,Base!$B$3:$B$5001,$A$5))) | M12: =IF(M$3="","",IF(COUNTIFS(Base!$A$3:$A$5001,M$3,Base!$B$3:$B$5001,$A$5,Base!$V$3:$V$5001,"<>")=0,"",SUMIFS(Base!$V$3:$V$5001,Base!$A$3:$A$5001,M$3,Base!$B$3:$B$5001,$A$5))) | ... AJ12: =IF(AJ$3="","",IF(COUNTIFS(Base!$A$3:$A$5001,AJ$3,Base!$B$3:$B$5001,$A$5,Base!$V$3:$V$5001,"<>")=0,"",SUMIFS(Base!$V$3:$V$5001,Base!$A$3:$A$5001,AJ$3,Base!$B$3:$B$5001,$A$5))) | AK12: =IF(COUNT(F12:AJ12)=0,"",SUM(F12:AJ12))
C13: Backlog | D13: =IFERROR(1/(1/INDEX(calculos!$C$55:$K$83,MATCH("NC Backlog",calculos!$A$55:$A$83,0),MATCH($A$5,calculos!$C$54:$K$54,0))),"") | F13: =IF(F$3="","",IF(COUNTIFS(Base!$A$3:$A$5001,F$3,Base!$B$3:$B$5001,$A$5,Base!$W$3:$W$5001,"<>")=0,"",SUMIFS(Base!$W$3:$W$5001,Base!$A$3:$A$5001,F$3,Base!$B$3:$B$5001,$A$5))) | G13: =IF(G$3="","",IF(COUNTIFS(Base!$A$3:$A$5001,G$3,Base!$B$3:$B$5001,$A$5,Base!$W$3:$W$5001,"<>")=0,"",SUMIFS(Base!$W$3:$W$5001,Base!$A$3:$A$5001,G$3,Base!$B$3:$B$5001,$A$5))) | H13: =IF(H$3="","",IF(COUNTIFS(Base!$A$3:$A$5001,H$3,Base!$B$3:$B$5001,$A$5,Base!$W$3:$W$5001,"<>")=0,"",SUMIFS(Base!$W$3:$W$5001,Base!$A$3:$A$5001,H$3,Base!$B$3:$B$5001,$A$5))) | I13: =IF(I$3="","",IF(COUNTIFS(Base!$A$3:$A$5001,I$3,Base!$B$3:$B$5001,$A$5,Base!$W$3:$W$5001,"<>")=0,"",SUMIFS(Base!$W$3:$W$5001,Base!$A$3:$A$5001,I$3,Base!$B$3:$B$5001,$A$5))) | J13: =IF(J$3="","",IF(COUNTIFS(Base!$A$3:$A$5001,J$3,Base!$B$3:$B$5001,$A$5,Base!$W$3:$W$5001,"<>")=0,"",SUMIFS(Base!$W$3:$W$5001,Base!$A$3:$A$5001,J$3,Base!$B$3:$B$5001,$A$5))) | K13: =IF(K$3="","",IF(COUNTIFS(Base!$A$3:$A$5001,K$3,Base!$B$3:$B$5001,$A$5,Base!$W$3:$W$5001,"<>")=0,"",SUMIFS(Base!$W$3:$W$5001,Base!$A$3:$A$5001,K$3,Base!$B$3:$B$5001,$A$5))) | L13: =IF(L$3="","",IF(COUNTIFS(Base!$A$3:$A$5001,L$3,Base!$B$3:$B$5001,$A$5,Base!$W$3:$W$5001,"<>")=0,"",SUMIFS(Base!$W$3:$W$5001,Base!$A$3:$A$5001,L$3,Base!$B$3:$B$5001,$A$5))) | M13: =IF(M$3="","",IF(COUNTIFS(Base!$A$3:$A$5001,M$3,Base!$B$3:$B$5001,$A$5,Base!$W$3:$W$5001,"<>")=0,"",SUMIFS(Base!$W$3:$W$5001,Base!$A$3:$A$5001,M$3,Base!$B$3:$B$5001,$A$5))) | ... AJ13: =IF(AJ$3="","",IF(COUNTIFS(Base!$A$3:$A$5001,AJ$3,Base!$B$3:$B$5001,$A$5,Base!$W$3:$W$5001,"<>")=0,"",SUMIFS(Base!$W$3:$W$5001,Base!$A$3:$A$5001,AJ$3,Base!$B$3:$B$5001,$A$5))) | AK13: =IFERROR(LOOKUP(9.99E+307,F13:AJ13),"")
B14: OCUPAÇÃO (P.P) | C14: Posições Disponíveis | D14: =IFERROR(1/(1/INDEX(calculos!$C$55:$K$83,MATCH("Posições Disponíveis",calculos!$A$55:$A$83,0),MATCH($A$5,calculos!$C$54:$K$54,0))),"") | F14: =IF(F$3="","",IF(COUNTIFS(Base!$A$3:$A$5001,F$3,Base!$B$3:$B$5001,$A$5,Base!$X$3:$X$5001,"<>")=0,"",SUMIFS(Base!$X$3:$X$5001,Base!$A$3:$A$5001,F$3,Base!$B$3:$B$5001,$A$5))) | G14: =IF(G$3="","",IF(COUNTIFS(Base!$A$3:$A$5001,G$3,Base!$B$3:$B$5001,$A$5,Base!$X$3:$X$5001,"<>")=0,"",SUMIFS(Base!$X$3:$X$5001,Base!$A$3:$A$5001,G$3,Base!$B$3:$B$5001,$A$5))) | H14: =IF(H$3="","",IF(COUNTIFS(Base!$A$3:$A$5001,H$3,Base!$B$3:$B$5001,$A$5,Base!$X$3:$X$5001,"<>")=0,"",SUMIFS(Base!$X$3:$X$5001,Base!$A$3:$A$5001,H$3,Base!$B$3:$B$5001,$A$5))) | I14: =IF(I$3="","",IF(COUNTIFS(Base!$A$3:$A$5001,I$3,Base!$B$3:$B$5001,$A$5,Base!$X$3:$X$5001,"<>")=0,"",SUMIFS(Base!$X$3:$X$5001,Base!$A$3:$A$5001,I$3,Base!$B$3:$B$5001,$A$5))) | J14: =IF(J$3="","",IF(COUNTIFS(Base!$A$3:$A$5001,J$3,Base!$B$3:$B$5001,$A$5,Base!$X$3:$X$5001,"<>")=0,"",SUMIFS(Base!$X$3:$X$5001,Base!$A$3:$A$5001,J$3,Base!$B$3:$B$5001,$A$5))) | K14: =IF(K$3="","",IF(COUNTIFS(Base!$A$3:$A$5001,K$3,Base!$B$3:$B$5001,$A$5,Base!$X$3:$X$5001,"<>")=0,"",SUMIFS(Base!$X$3:$X$5001,Base!$A$3:$A$5001,K$3,Base!$B$3:$B$5001,$A$5))) | L14: =IF(L$3="","",IF(COUNTIFS(Base!$A$3:$A$5001,L$3,Base!$B$3:$B$5001,$A$5,Base!$X$3:$X$5001,"<>")=0,"",SUMIFS(Base!$X$3:$X$5001,Base!$A$3:$A$5001,L$3,Base!$B$3:$B$5001,$A$5))) | M14: =IF(M$3="","",IF(COUNTIFS(Base!$A$3:$A$5001,M$3,Base!$B$3:$B$5001,$A$5,Base!$X$3:$X$5001,"<>")=0,"",SUMIFS(Base!$X$3:$X$5001,Base!$A$3:$A$5001,M$3,Base!$B$3:$B$5001,$A$5))) | ... AJ14: =IF(AJ$3="","",IF(COUNTIFS(Base!$A$3:$A$5001,AJ$3,Base!$B$3:$B$5001,$A$5,Base!$X$3:$X$5001,"<>")=0,"",SUMIFS(Base!$X$3:$X$5001,Base!$A$3:$A$5001,AJ$3,Base!$B$3:$B$5001,$A$5))) | AK14: =IFERROR(LOOKUP(9.99E+307,F14:AJ14),"")
C15: Posições Ocupadas | D15: =IFERROR(1/(1/INDEX(calculos!$C$55:$K$83,MATCH("Posições Ocupadas",calculos!$A$55:$A$83,0),MATCH($A$5,calculos!$C$54:$K$54,0))),"") | F15: =IF(F$3="","",IF(COUNTIFS(Base!$A$3:$A$5001,F$3,Base!$B$3:$B$5001,$A$5,Base!$Y$3:$Y$5001,"<>")=0,"",SUMIFS(Base!$Y$3:$Y$5001,Base!$A$3:$A$5001,F$3,Base!$B$3:$B$5001,$A$5))) | G15: =IF(G$3="","",IF(COUNTIFS(Base!$A$3:$A$5001,G$3,Base!$B$3:$B$5001,$A$5,Base!$Y$3:$Y$5001,"<>")=0,"",SUMIFS(Base!$Y$3:$Y$5001,Base!$A$3:$A$5001,G$3,Base!$B$3:$B$5001,$A$5))) | H15: =IF(H$3="","",IF(COUNTIFS(Base!$A$3:$A$5001,H$3,Base!$B$3:$B$5001,$A$5,Base!$Y$3:$Y$5001,"<>")=0,"",SUMIFS(Base!$Y$3:$Y$5001,Base!$A$3:$A$5001,H$3,Base!$B$3:$B$5001,$A$5))) | I15: =IF(I$3="","",IF(COUNTIFS(Base!$A$3:$A$5001,I$3,Base!$B$3:$B$5001,$A$5,Base!$Y$3:$Y$5001,"<>")=0,"",SUMIFS(Base!$Y$3:$Y$5001,Base!$A$3:$A$5001,I$3,Base!$B$3:$B$5001,$A$5))) | J15: =IF(J$3="","",IF(COUNTIFS(Base!$A$3:$A$5001,J$3,Base!$B$3:$B$5001,$A$5,Base!$Y$3:$Y$5001,"<>")=0,"",SUMIFS(Base!$Y$3:$Y$5001,Base!$A$3:$A$5001,J$3,Base!$B$3:$B$5001,$A$5))) | K15: =IF(K$3="","",IF(COUNTIFS(Base!$A$3:$A$5001,K$3,Base!$B$3:$B$5001,$A$5,Base!$Y$3:$Y$5001,"<>")=0,"",SUMIFS(Base!$Y$3:$Y$5001,Base!$A$3:$A$5001,K$3,Base!$B$3:$B$5001,$A$5))) | L15: =IF(L$3="","",IF(COUNTIFS(Base!$A$3:$A$5001,L$3,Base!$B$3:$B$5001,$A$5,Base!$Y$3:$Y$5001,"<>")=0,"",SUMIFS(Base!$Y$3:$Y$5001,Base!$A$3:$A$5001,L$3,Base!$B$3:$B$5001,$A$5))) | M15: =IF(M$3="","",IF(COUNTIFS(Base!$A$3:$A$5001,M$3,Base!$B$3:$B$5001,$A$5,Base!$Y$3:$Y$5001,"<>")=0,"",SUMIFS(Base!$Y$3:$Y$5001,Base!$A$3:$A$5001,M$3,Base!$B$3:$B$5001,$A$5))) | ... AJ15: =IF(AJ$3="","",IF(COUNTIFS(Base!$A$3:$A$5001,AJ$3,Base!$B$3:$B$5001,$A$5,Base!$Y$3:$Y$5001,"<>")=0,"",SUMIFS(Base!$Y$3:$Y$5001,Base!$A$3:$A$5001,AJ$3,Base!$B$3:$B$5001,$A$5))) | AK15: =IFERROR(LOOKUP(9.99E+307,F15:AJ15),"")
C16: Taxa de Ocupação | D16: =IFERROR(1/(1/INDEX(calculos!$C$55:$K$83,MATCH("Taxa de Ocupação",calculos!$A$55:$A$83,0),MATCH($A$5,calculos!$C$54:$K$54,0))),"") | F16: =IF(AND(ISNUMBER(F14),ISNUMBER(F15)),IF(F14>0,F15/F14,""),"") | G16: =IF(AND(ISNUMBER(G14),ISNUMBER(G15)),IF(G14>0,G15/G14,""),"") | H16: =IF(AND(ISNUMBER(H14),ISNUMBER(H15)),IF(H14>0,H15/H14,""),"") | I16: =IF(AND(ISNUMBER(I14),ISNUMBER(I15)),IF(I14>0,I15/I14,""),"") | J16: =IF(AND(ISNUMBER(J14),ISNUMBER(J15)),IF(J14>0,J15/J14,""),"") | K16: =IF(AND(ISNUMBER(K14),ISNUMBER(K15)),IF(K14>0,K15/K14,""),"") | L16: =IF(AND(ISNUMBER(L14),ISNUMBER(L15)),IF(L14>0,L15/L14,""),"") | M16: =IF(AND(ISNUMBER(M14),ISNUMBER(M15)),IF(M14>0,M15/M14,""),"") | ... AK16: =IF(AND(ISNUMBER(AK14),ISNUMBER(AK15)),IF(AK14>0,AK15/AK14,""),"")
B17: GENTE | C17: Efetivo | D17: =IFERROR(1/(1/INDEX(calculos!$C$55:$K$83,MATCH("Efetivo",calculos!$A$55:$A$83,0),MATCH($A$5,calculos!$C$54:$K$54,0))),"") | F17: =IF(F$3="","",IF(COUNTIFS(Base!$A$3:$A$5001,F$3,Base!$B$3:$B$5001,$A$5,Base!$Z$3:$Z$5001,"<>")=0,"",SUMIFS(Base!$Z$3:$Z$5001,Base!$A$3:$A$5001,F$3,Base!$B$3:$B$5001,$A$5))) | G17: =IF(G$3="","",IF(COUNTIFS(Base!$A$3:$A$5001,G$3,Base!$B$3:$B$5001,$A$5,Base!$Z$3:$Z$5001,"<>")=0,"",SUMIFS(Base!$Z$3:$Z$5001,Base!$A$3:$A$5001,G$3,Base!$B$3:$B$5001,$A$5))) | H17: =IF(H$3="","",IF(COUNTIFS(Base!$A$3:$A$5001,H$3,Base!$B$3:$B$5001,$A$5,Base!$Z$3:$Z$5001,"<>")=0,"",SUMIFS(Base!$Z$3:$Z$5001,Base!$A$3:$A$5001,H$3,Base!$B$3:$B$5001,$A$5))) | I17: =IF(I$3="","",IF(COUNTIFS(Base!$A$3:$A$5001,I$3,Base!$B$3:$B$5001,$A$5,Base!$Z$3:$Z$5001,"<>")=0,"",SUMIFS(Base!$Z$3:$Z$5001,Base!$A$3:$A$5001,I$3,Base!$B$3:$B$5001,$A$5))) | J17: =IF(J$3="","",IF(COUNTIFS(Base!$A$3:$A$5001,J$3,Base!$B$3:$B$5001,$A$5,Base!$Z$3:$Z$5001,"<>")=0,"",SUMIFS(Base!$Z$3:$Z$5001,Base!$A$3:$A$5001,J$3,Base!$B$3:$B$5001,$A$5))) | K17: =IF(K$3="","",IF(COUNTIFS(Base!$A$3:$A$5001,K$3,Base!$B$3:$B$5001,$A$5,Base!$Z$3:$Z$5001,"<>")=0,"",SUMIFS(Base!$Z$3:$Z$5001,Base!$A$3:$A$5001,K$3,Base!$B$3:$B$5001,$A$5))) | L17: =IF(L$3="","",IF(COUNTIFS(Base!$A$3:$A$5001,L$3,Base!$B$3:$B$5001,$A$5,Base!$Z$3:$Z$5001,"<>")=0,"",SUMIFS(Base!$Z$3:$Z$5001,Base!$A$3:$A$5001,L$3,Base!$B$3:$B$5001,$A$5))) | M17: =IF(M$3="","",IF(COUNTIFS(Base!$A$3:$A$5001,M$3,Base!$B$3:$B$5001,$A$5,Base!$Z$3:$Z$5001,"<>")=0,"",SUMIFS(Base!$Z$3:$Z$5001,Base!$A$3:$A$5001,M$3,Base!$B$3:$B$5001,$A$5))) | ... AJ17: =IF(AJ$3="","",IF(COUNTIFS(Base!$A$3:$A$5001,AJ$3,Base!$B$3:$B$5001,$A$5,Base!$Z$3:$Z$5001,"<>")=0,"",SUMIFS(Base!$Z$3:$Z$5001,Base!$A$3:$A$5001,AJ$3,Base!$B$3:$B$5001,$A$5))) | AK17: =IFERROR(LOOKUP(9.99E+307,F17:AJ17),"")
C18: Falta | D18: =IFERROR(1/(1/INDEX(calculos!$C$55:$K$83,MATCH("Falta",calculos!$A$55:$A$83,0),MATCH($A$5,calculos!$C$54:$K$54,0))),"") | F18: =IF(F$3="","",IF(COUNTIFS(Base!$A$3:$A$5001,F$3,Base!$B$3:$B$5001,$A$5,Base!$AA$3:$AA$5001,"<>")=0,"",SUMIFS(Base!$AA$3:$AA$5001,Base!$A$3:$A$5001,F$3,Base!$B$3:$B$5001,$A$5))) | G18: =IF(G$3="","",IF(COUNTIFS(Base!$A$3:$A$5001,G$3,Base!$B$3:$B$5001,$A$5,Base!$AA$3:$AA$5001,"<>")=0,"",SUMIFS(Base!$AA$3:$AA$5001,Base!$A$3:$A$5001,G$3,Base!$B$3:$B$5001,$A$5))) | H18: =IF(H$3="","",IF(COUNTIFS(Base!$A$3:$A$5001,H$3,Base!$B$3:$B$5001,$A$5,Base!$AA$3:$AA$5001,"<>")=0,"",SUMIFS(Base!$AA$3:$AA$5001,Base!$A$3:$A$5001,H$3,Base!$B$3:$B$5001,$A$5))) | I18: =IF(I$3="","",IF(COUNTIFS(Base!$A$3:$A$5001,I$3,Base!$B$3:$B$5001,$A$5,Base!$AA$3:$AA$5001,"<>")=0,"",SUMIFS(Base!$AA$3:$AA$5001,Base!$A$3:$A$5001,I$3,Base!$B$3:$B$5001,$A$5))) | J18: =IF(J$3="","",IF(COUNTIFS(Base!$A$3:$A$5001,J$3,Base!$B$3:$B$5001,$A$5,Base!$AA$3:$AA$5001,"<>")=0,"",SUMIFS(Base!$AA$3:$AA$5001,Base!$A$3:$A$5001,J$3,Base!$B$3:$B$5001,$A$5))) | K18: =IF(K$3="","",IF(COUNTIFS(Base!$A$3:$A$5001,K$3,Base!$B$3:$B$5001,$A$5,Base!$AA$3:$AA$5001,"<>")=0,"",SUMIFS(Base!$AA$3:$AA$5001,Base!$A$3:$A$5001,K$3,Base!$B$3:$B$5001,$A$5))) | L18: =IF(L$3="","",IF(COUNTIFS(Base!$A$3:$A$5001,L$3,Base!$B$3:$B$5001,$A$5,Base!$AA$3:$AA$5001,"<>")=0,"",SUMIFS(Base!$AA$3:$AA$5001,Base!$A$3:$A$5001,L$3,Base!$B$3:$B$5001,$A$5))) | M18: =IF(M$3="","",IF(COUNTIFS(Base!$A$3:$A$5001,M$3,Base!$B$3:$B$5001,$A$5,Base!$AA$3:$AA$5001,"<>")=0,"",SUMIFS(Base!$AA$3:$AA$5001,Base!$A$3:$A$5001,M$3,Base!$B$3:$B$5001,$A$5))) | ... AJ18: =IF(AJ$3="","",IF(COUNTIFS(Base!$A$3:$A$5001,AJ$3,Base!$B$3:$B$5001,$A$5,Base!$AA$3:$AA$5001,"<>")=0,"",SUMIFS(Base!$AA$3:$AA$5001,Base!$A$3:$A$5001,AJ$3,Base!$B$3:$B$5001,$A$5))) | AK18: =IF(COUNT(F18:AJ18)=0,"",SUM(F18:AJ18))
C19: Folga | D19: =IFERROR(1/(1/INDEX(calculos!$C$55:$K$83,MATCH("Folga",calculos!$A$55:$A$83,0),MATCH($A$5,calculos!$C$54:$K$54,0))),"") | F19: =IF(F$3="","",IF(COUNTIFS(Base!$A$3:$A$5001,F$3,Base!$B$3:$B$5001,$A$5,Base!$AB$3:$AB$5001,"<>")=0,"",SUMIFS(Base!$AB$3:$AB$5001,Base!$A$3:$A$5001,F$3,Base!$B$3:$B$5001,$A$5))) | G19: =IF(G$3="","",IF(COUNTIFS(Base!$A$3:$A$5001,G$3,Base!$B$3:$B$5001,$A$5,Base!$AB$3:$AB$5001,"<>")=0,"",SUMIFS(Base!$AB$3:$AB$5001,Base!$A$3:$A$5001,G$3,Base!$B$3:$B$5001,$A$5))) | H19: =IF(H$3="","",IF(COUNTIFS(Base!$A$3:$A$5001,H$3,Base!$B$3:$B$5001,$A$5,Base!$AB$3:$AB$5001,"<>")=0,"",SUMIFS(Base!$AB$3:$AB$5001,Base!$A$3:$A$5001,H$3,Base!$B$3:$B$5001,$A$5))) | I19: =IF(I$3="","",IF(COUNTIFS(Base!$A$3:$A$5001,I$3,Base!$B$3:$B$5001,$A$5,Base!$AB$3:$AB$5001,"<>")=0,"",SUMIFS(Base!$AB$3:$AB$5001,Base!$A$3:$A$5001,I$3,Base!$B$3:$B$5001,$A$5))) | J19: =IF(J$3="","",IF(COUNTIFS(Base!$A$3:$A$5001,J$3,Base!$B$3:$B$5001,$A$5,Base!$AB$3:$AB$5001,"<>")=0,"",SUMIFS(Base!$AB$3:$AB$5001,Base!$A$3:$A$5001,J$3,Base!$B$3:$B$5001,$A$5))) | K19: =IF(K$3="","",IF(COUNTIFS(Base!$A$3:$A$5001,K$3,Base!$B$3:$B$5001,$A$5,Base!$AB$3:$AB$5001,"<>")=0,"",SUMIFS(Base!$AB$3:$AB$5001,Base!$A$3:$A$5001,K$3,Base!$B$3:$B$5001,$A$5))) | L19: =IF(L$3="","",IF(COUNTIFS(Base!$A$3:$A$5001,L$3,Base!$B$3:$B$5001,$A$5,Base!$AB$3:$AB$5001,"<>")=0,"",SUMIFS(Base!$AB$3:$AB$5001,Base!$A$3:$A$5001,L$3,Base!$B$3:$B$5001,$A$5))) | M19: =IF(M$3="","",IF(COUNTIFS(Base!$A$3:$A$5001,M$3,Base!$B$3:$B$5001,$A$5,Base!$AB$3:$AB$5001,"<>")=0,"",SUMIFS(Base!$AB$3:$AB$5001,Base!$A$3:$A$5001,M$3,Base!$B$3:$B$5001,$A$5))) | ... AJ19: =IF(AJ$3="","",IF(COUNTIFS(Base!$A$3:$A$5001,AJ$3,Base!$B$3:$B$5001,$A$5,Base!$AB$3:$AB$5001,"<>")=0,"",SUMIFS(Base!$AB$3:$AB$5001,Base!$A$3:$A$5001,AJ$3,Base!$B$3:$B$5001,$A$5))) | AK19: =IF(COUNT(F19:AJ19)=0,"",SUM(F19:AJ19))
C20: Férias | D20: =IFERROR(1/(1/INDEX(calculos!$C$55:$K$83,MATCH("Férias",calculos!$A$55:$A$83,0),MATCH($A$5,calculos!$C$54:$K$54,0))),"") | F20: =IF(F$3="","",IF(COUNTIFS(Base!$A$3:$A$5001,F$3,Base!$B$3:$B$5001,$A$5,Base!$AC$3:$AC$5001,"<>")=0,"",SUMIFS(Base!$AC$3:$AC$5001,Base!$A$3:$A$5001,F$3,Base!$B$3:$B$5001,$A$5))) | G20: =IF(G$3="","",IF(COUNTIFS(Base!$A$3:$A$5001,G$3,Base!$B$3:$B$5001,$A$5,Base!$AC$3:$AC$5001,"<>")=0,"",SUMIFS(Base!$AC$3:$AC$5001,Base!$A$3:$A$5001,G$3,Base!$B$3:$B$5001,$A$5))) | H20: =IF(H$3="","",IF(COUNTIFS(Base!$A$3:$A$5001,H$3,Base!$B$3:$B$5001,$A$5,Base!$AC$3:$AC$5001,"<>")=0,"",SUMIFS(Base!$AC$3:$AC$5001,Base!$A$3:$A$5001,H$3,Base!$B$3:$B$5001,$A$5))) | I20: =IF(I$3="","",IF(COUNTIFS(Base!$A$3:$A$5001,I$3,Base!$B$3:$B$5001,$A$5,Base!$AC$3:$AC$5001,"<>")=0,"",SUMIFS(Base!$AC$3:$AC$5001,Base!$A$3:$A$5001,I$3,Base!$B$3:$B$5001,$A$5))) | J20: =IF(J$3="","",IF(COUNTIFS(Base!$A$3:$A$5001,J$3,Base!$B$3:$B$5001,$A$5,Base!$AC$3:$AC$5001,"<>")=0,"",SUMIFS(Base!$AC$3:$AC$5001,Base!$A$3:$A$5001,J$3,Base!$B$3:$B$5001,$A$5))) | K20: =IF(K$3="","",IF(COUNTIFS(Base!$A$3:$A$5001,K$3,Base!$B$3:$B$5001,$A$5,Base!$AC$3:$AC$5001,"<>")=0,"",SUMIFS(Base!$AC$3:$AC$5001,Base!$A$3:$A$5001,K$3,Base!$B$3:$B$5001,$A$5))) | L20: =IF(L$3="","",IF(COUNTIFS(Base!$A$3:$A$5001,L$3,Base!$B$3:$B$5001,$A$5,Base!$AC$3:$AC$5001,"<>")=0,"",SUMIFS(Base!$AC$3:$AC$5001,Base!$A$3:$A$5001,L$3,Base!$B$3:$B$5001,$A$5))) | M20: =IF(M$3="","",IF(COUNTIFS(Base!$A$3:$A$5001,M$3,Base!$B$3:$B$5001,$A$5,Base!$AC$3:$AC$5001,"<>")=0,"",SUMIFS(Base!$AC$3:$AC$5001,Base!$A$3:$A$5001,M$3,Base!$B$3:$B$5001,$A$5))) | ... AJ20: =IF(AJ$3="","",IF(COUNTIFS(Base!$A$3:$A$5001,AJ$3,Base!$B$3:$B$5001,$A$5,Base!$AC$3:$AC$5001,"<>")=0,"",SUMIFS(Base!$AC$3:$AC$5001,Base!$A$3:$A$5001,AJ$3,Base!$B$3:$B$5001,$A$5))) | AK20: =IF(COUNT(F20:AJ20)=0,"",SUM(F20:AJ20))
C21: Desligamentos | D21: =IFERROR(1/(1/INDEX(calculos!$C$55:$K$83,MATCH("Desligamentos",calculos!$A$55:$A$83,0),MATCH($A$5,calculos!$C$54:$K$54,0))),"") | F21: =IF(F$3="","",IF(COUNTIFS(Base!$A$3:$A$5001,F$3,Base!$B$3:$B$5001,$A$5,Base!$AD$3:$AD$5001,"<>")=0,"",SUMIFS(Base!$AD$3:$AD$5001,Base!$A$3:$A$5001,F$3,Base!$B$3:$B$5001,$A$5))) | G21: =IF(G$3="","",IF(COUNTIFS(Base!$A$3:$A$5001,G$3,Base!$B$3:$B$5001,$A$5,Base!$AD$3:$AD$5001,"<>")=0,"",SUMIFS(Base!$AD$3:$AD$5001,Base!$A$3:$A$5001,G$3,Base!$B$3:$B$5001,$A$5))) | H21: =IF(H$3="","",IF(COUNTIFS(Base!$A$3:$A$5001,H$3,Base!$B$3:$B$5001,$A$5,Base!$AD$3:$AD$5001,"<>")=0,"",SUMIFS(Base!$AD$3:$AD$5001,Base!$A$3:$A$5001,H$3,Base!$B$3:$B$5001,$A$5))) | I21: =IF(I$3="","",IF(COUNTIFS(Base!$A$3:$A$5001,I$3,Base!$B$3:$B$5001,$A$5,Base!$AD$3:$AD$5001,"<>")=0,"",SUMIFS(Base!$AD$3:$AD$5001,Base!$A$3:$A$5001,I$3,Base!$B$3:$B$5001,$A$5))) | J21: =IF(J$3="","",IF(COUNTIFS(Base!$A$3:$A$5001,J$3,Base!$B$3:$B$5001,$A$5,Base!$AD$3:$AD$5001,"<>")=0,"",SUMIFS(Base!$AD$3:$AD$5001,Base!$A$3:$A$5001,J$3,Base!$B$3:$B$5001,$A$5))) | K21: =IF(K$3="","",IF(COUNTIFS(Base!$A$3:$A$5001,K$3,Base!$B$3:$B$5001,$A$5,Base!$AD$3:$AD$5001,"<>")=0,"",SUMIFS(Base!$AD$3:$AD$5001,Base!$A$3:$A$5001,K$3,Base!$B$3:$B$5001,$A$5))) | L21: =IF(L$3="","",IF(COUNTIFS(Base!$A$3:$A$5001,L$3,Base!$B$3:$B$5001,$A$5,Base!$AD$3:$AD$5001,"<>")=0,"",SUMIFS(Base!$AD$3:$AD$5001,Base!$A$3:$A$5001,L$3,Base!$B$3:$B$5001,$A$5))) | M21: =IF(M$3="","",IF(COUNTIFS(Base!$A$3:$A$5001,M$3,Base!$B$3:$B$5001,$A$5,Base!$AD$3:$AD$5001,"<>")=0,"",SUMIFS(Base!$AD$3:$AD$5001,Base!$A$3:$A$5001,M$3,Base!$B$3:$B$5001,$A$5))) | ... AJ21: =IF(AJ$3="","",IF(COUNTIFS(Base!$A$3:$A$5001,AJ$3,Base!$B$3:$B$5001,$A$5,Base!$AD$3:$AD$5001,"<>")=0,"",SUMIFS(Base!$AD$3:$AD$5001,Base!$A$3:$A$5001,AJ$3,Base!$B$3:$B$5001,$A$5))) | AK21: =IF(COUNT(F21:AJ21)=0,"",SUM(F21:AJ21))
A23: BEAUTYBIZ | B23: IN | C23: Veículos Recebidos | D23: =IFERROR(1/(1/INDEX(calculos!$C$55:$K$83,MATCH("IN Veículos Recebidos",calculos!$A$55:$A$83,0),MATCH($A$23,calculos!$C$54:$K$54,0))),"") | F23: =IF(F$3="","",IF(COUNTIFS(Base!$A$3:$A$5001,F$3,Base!$B$3:$B$5001,$A$23,Base!$C$3:$C$5001,"<>")=0,"",SUMIFS(Base!$C$3:$C$5001,Base!$A$3:$A$5001,F$3,Base!$B$3:$B$5001,$A$23))) | G23: =IF(G$3="","",IF(COUNTIFS(Base!$A$3:$A$5001,G$3,Base!$B$3:$B$5001,$A$23,Base!$C$3:$C$5001,"<>")=0,"",SUMIFS(Base!$C$3:$C$5001,Base!$A$3:$A$5001,G$3,Base!$B$3:$B$5001,$A$23))) | H23: =IF(H$3="","",IF(COUNTIFS(Base!$A$3:$A$5001,H$3,Base!$B$3:$B$5001,$A$23,Base!$C$3:$C$5001,"<>")=0,"",SUMIFS(Base!$C$3:$C$5001,Base!$A$3:$A$5001,H$3,Base!$B$3:$B$5001,$A$23))) | I23: =IF(I$3="","",IF(COUNTIFS(Base!$A$3:$A$5001,I$3,Base!$B$3:$B$5001,$A$23,Base!$C$3:$C$5001,"<>")=0,"",SUMIFS(Base!$C$3:$C$5001,Base!$A$3:$A$5001,I$3,Base!$B$3:$B$5001,$A$23))) | J23: =IF(J$3="","",IF(COUNTIFS(Base!$A$3:$A$5001,J$3,Base!$B$3:$B$5001,$A$23,Base!$C$3:$C$5001,"<>")=0,"",SUMIFS(Base!$C$3:$C$5001,Base!$A$3:$A$5001,J$3,Base!$B$3:$B$5001,$A$23))) | K23: =IF(K$3="","",IF(COUNTIFS(Base!$A$3:$A$5001,K$3,Base!$B$3:$B$5001,$A$23,Base!$C$3:$C$5001,"<>")=0,"",SUMIFS(Base!$C$3:$C$5001,Base!$A$3:$A$5001,K$3,Base!$B$3:$B$5001,$A$23))) | L23: =IF(L$3="","",IF(COUNTIFS(Base!$A$3:$A$5001,L$3,Base!$B$3:$B$5001,$A$23,Base!$C$3:$C$5001,"<>")=0,"",SUMIFS(Base!$C$3:$C$5001,Base!$A$3:$A$5001,L$3,Base!$B$3:$B$5001,$A$23))) | M23: =IF(M$3="","",IF(COUNTIFS(Base!$A$3:$A$5001,M$3,Base!$B$3:$B$5001,$A$23,Base!$C$3:$C$5001,"<>")=0,"",SUMIFS(Base!$C$3:$C$5001,Base!$A$3:$A$5001,M$3,Base!$B$3:$B$5001,$A$23))) | ... AJ23: =IF(AJ$3="","",IF(COUNTIFS(Base!$A$3:$A$5001,AJ$3,Base!$B$3:$B$5001,$A$23,Base!$C$3:$C$5001,"<>")=0,"",SUMIFS(Base!$C$3:$C$5001,Base!$A$3:$A$5001,AJ$3,Base!$B$3:$B$5001,$A$23))) | AK23: =IF(COUNT(F23:AJ23)=0,"",SUM(F23:AJ23))
C24: Pallets Movimentados | D24: =IFERROR(1/(1/INDEX(calculos!$C$55:$K$83,MATCH("IN Pallets Movimentados",calculos!$A$55:$A$83,0),MATCH($A$23,calculos!$C$54:$K$54,0))),"") | F24: =IF(F$3="","",IF(COUNTIFS(Base!$A$3:$A$5001,F$3,Base!$B$3:$B$5001,$A$23,Base!$D$3:$D$5001,"<>")=0,"",SUMIFS(Base!$D$3:$D$5001,Base!$A$3:$A$5001,F$3,Base!$B$3:$B$5001,$A$23))) | G24: =IF(G$3="","",IF(COUNTIFS(Base!$A$3:$A$5001,G$3,Base!$B$3:$B$5001,$A$23,Base!$D$3:$D$5001,"<>")=0,"",SUMIFS(Base!$D$3:$D$5001,Base!$A$3:$A$5001,G$3,Base!$B$3:$B$5001,$A$23))) | H24: =IF(H$3="","",IF(COUNTIFS(Base!$A$3:$A$5001,H$3,Base!$B$3:$B$5001,$A$23,Base!$D$3:$D$5001,"<>")=0,"",SUMIFS(Base!$D$3:$D$5001,Base!$A$3:$A$5001,H$3,Base!$B$3:$B$5001,$A$23))) | I24: =IF(I$3="","",IF(COUNTIFS(Base!$A$3:$A$5001,I$3,Base!$B$3:$B$5001,$A$23,Base!$D$3:$D$5001,"<>")=0,"",SUMIFS(Base!$D$3:$D$5001,Base!$A$3:$A$5001,I$3,Base!$B$3:$B$5001,$A$23))) | J24: =IF(J$3="","",IF(COUNTIFS(Base!$A$3:$A$5001,J$3,Base!$B$3:$B$5001,$A$23,Base!$D$3:$D$5001,"<>")=0,"",SUMIFS(Base!$D$3:$D$5001,Base!$A$3:$A$5001,J$3,Base!$B$3:$B$5001,$A$23))) | K24: =IF(K$3="","",IF(COUNTIFS(Base!$A$3:$A$5001,K$3,Base!$B$3:$B$5001,$A$23,Base!$D$3:$D$5001,"<>")=0,"",SUMIFS(Base!$D$3:$D$5001,Base!$A$3:$A$5001,K$3,Base!$B$3:$B$5001,$A$23))) | L24: =IF(L$3="","",IF(COUNTIFS(Base!$A$3:$A$5001,L$3,Base!$B$3:$B$5001,$A$23,Base!$D$3:$D$5001,"<>")=0,"",SUMIFS(Base!$D$3:$D$5001,Base!$A$3:$A$5001,L$3,Base!$B$3:$B$5001,$A$23))) | M24: =IF(M$3="","",IF(COUNTIFS(Base!$A$3:$A$5001,M$3,Base!$B$3:$B$5001,$A$23,Base!$D$3:$D$5001,"<>")=0,"",SUMIFS(Base!$D$3:$D$5001,Base!$A$3:$A$5001,M$3,Base!$B$3:$B$5001,$A$23))) | ... AJ24: =IF(AJ$3="","",IF(COUNTIFS(Base!$A$3:$A$5001,AJ$3,Base!$B$3:$B$5001,$A$23,Base!$D$3:$D$5001,"<>")=0,"",SUMIFS(Base!$D$3:$D$5001,Base!$A$3:$A$5001,AJ$3,Base!$B$3:$B$5001,$A$23))) | AK24: =IF(COUNT(F24:AJ24)=0,"",SUM(F24:AJ24))
C25: Caixas Movimentadas | D25: =IFERROR(1/(1/INDEX(calculos!$C$55:$K$83,MATCH("IN Caixas Movimentadas",calculos!$A$55:$A$83,0),MATCH($A$23,calculos!$C$54:$K$54,0))),"") | F25: =IF(F$3="","",IF(COUNTIFS(Base!$A$3:$A$5001,F$3,Base!$B$3:$B$5001,$A$23,Base!$F$3:$F$5001,"<>")=0,"",SUMIFS(Base!$F$3:$F$5001,Base!$A$3:$A$5001,F$3,Base!$B$3:$B$5001,$A$23))) | G25: =IF(G$3="","",IF(COUNTIFS(Base!$A$3:$A$5001,G$3,Base!$B$3:$B$5001,$A$23,Base!$F$3:$F$5001,"<>")=0,"",SUMIFS(Base!$F$3:$F$5001,Base!$A$3:$A$5001,G$3,Base!$B$3:$B$5001,$A$23))) | H25: =IF(H$3="","",IF(COUNTIFS(Base!$A$3:$A$5001,H$3,Base!$B$3:$B$5001,$A$23,Base!$F$3:$F$5001,"<>")=0,"",SUMIFS(Base!$F$3:$F$5001,Base!$A$3:$A$5001,H$3,Base!$B$3:$B$5001,$A$23))) | I25: =IF(I$3="","",IF(COUNTIFS(Base!$A$3:$A$5001,I$3,Base!$B$3:$B$5001,$A$23,Base!$F$3:$F$5001,"<>")=0,"",SUMIFS(Base!$F$3:$F$5001,Base!$A$3:$A$5001,I$3,Base!$B$3:$B$5001,$A$23))) | J25: =IF(J$3="","",IF(COUNTIFS(Base!$A$3:$A$5001,J$3,Base!$B$3:$B$5001,$A$23,Base!$F$3:$F$5001,"<>")=0,"",SUMIFS(Base!$F$3:$F$5001,Base!$A$3:$A$5001,J$3,Base!$B$3:$B$5001,$A$23))) | K25: =IF(K$3="","",IF(COUNTIFS(Base!$A$3:$A$5001,K$3,Base!$B$3:$B$5001,$A$23,Base!$F$3:$F$5001,"<>")=0,"",SUMIFS(Base!$F$3:$F$5001,Base!$A$3:$A$5001,K$3,Base!$B$3:$B$5001,$A$23))) | L25: =IF(L$3="","",IF(COUNTIFS(Base!$A$3:$A$5001,L$3,Base!$B$3:$B$5001,$A$23,Base!$F$3:$F$5001,"<>")=0,"",SUMIFS(Base!$F$3:$F$5001,Base!$A$3:$A$5001,L$3,Base!$B$3:$B$5001,$A$23))) | M25: =IF(M$3="","",IF(COUNTIFS(Base!$A$3:$A$5001,M$3,Base!$B$3:$B$5001,$A$23,Base!$F$3:$F$5001,"<>")=0,"",SUMIFS(Base!$F$3:$F$5001,Base!$A$3:$A$5001,M$3,Base!$B$3:$B$5001,$A$23))) | ... AJ25: =IF(AJ$3="","",IF(COUNTIFS(Base!$A$3:$A$5001,AJ$3,Base!$B$3:$B$5001,$A$23,Base!$F$3:$F$5001,"<>")=0,"",SUMIFS(Base!$F$3:$F$5001,Base!$A$3:$A$5001,AJ$3,Base!$B$3:$B$5001,$A$23))) | AK25: =IF(COUNT(F25:AJ25)=0,"",SUM(F25:AJ25))
B26: OUT | C26: Veículos Expedidos | D26: =IFERROR(1/(1/INDEX(calculos!$C$55:$K$83,MATCH("OUT Veículos Expedidos",calculos!$A$55:$A$83,0),MATCH($A$23,calculos!$C$54:$K$54,0))),"") | F26: =IF(F$3="","",IF(COUNTIFS(Base!$A$3:$A$5001,F$3,Base!$B$3:$B$5001,$A$23,Base!$L$3:$L$5001,"<>")=0,"",SUMIFS(Base!$L$3:$L$5001,Base!$A$3:$A$5001,F$3,Base!$B$3:$B$5001,$A$23))) | G26: =IF(G$3="","",IF(COUNTIFS(Base!$A$3:$A$5001,G$3,Base!$B$3:$B$5001,$A$23,Base!$L$3:$L$5001,"<>")=0,"",SUMIFS(Base!$L$3:$L$5001,Base!$A$3:$A$5001,G$3,Base!$B$3:$B$5001,$A$23))) | H26: =IF(H$3="","",IF(COUNTIFS(Base!$A$3:$A$5001,H$3,Base!$B$3:$B$5001,$A$23,Base!$L$3:$L$5001,"<>")=0,"",SUMIFS(Base!$L$3:$L$5001,Base!$A$3:$A$5001,H$3,Base!$B$3:$B$5001,$A$23))) | I26: =IF(I$3="","",IF(COUNTIFS(Base!$A$3:$A$5001,I$3,Base!$B$3:$B$5001,$A$23,Base!$L$3:$L$5001,"<>")=0,"",SUMIFS(Base!$L$3:$L$5001,Base!$A$3:$A$5001,I$3,Base!$B$3:$B$5001,$A$23))) | J26: =IF(J$3="","",IF(COUNTIFS(Base!$A$3:$A$5001,J$3,Base!$B$3:$B$5001,$A$23,Base!$L$3:$L$5001,"<>")=0,"",SUMIFS(Base!$L$3:$L$5001,Base!$A$3:$A$5001,J$3,Base!$B$3:$B$5001,$A$23))) | K26: =IF(K$3="","",IF(COUNTIFS(Base!$A$3:$A$5001,K$3,Base!$B$3:$B$5001,$A$23,Base!$L$3:$L$5001,"<>")=0,"",SUMIFS(Base!$L$3:$L$5001,Base!$A$3:$A$5001,K$3,Base!$B$3:$B$5001,$A$23))) | L26: =IF(L$3="","",IF(COUNTIFS(Base!$A$3:$A$5001,L$3,Base!$B$3:$B$5001,$A$23,Base!$L$3:$L$5001,"<>")=0,"",SUMIFS(Base!$L$3:$L$5001,Base!$A$3:$A$5001,L$3,Base!$B$3:$B$5001,$A$23))) | M26: =IF(M$3="","",IF(COUNTIFS(Base!$A$3:$A$5001,M$3,Base!$B$3:$B$5001,$A$23,Base!$L$3:$L$5001,"<>")=0,"",SUMIFS(Base!$L$3:$L$5001,Base!$A$3:$A$5001,M$3,Base!$B$3:$B$5001,$A$23))) | ... AJ26: =IF(AJ$3="","",IF(COUNTIFS(Base!$A$3:$A$5001,AJ$3,Base!$B$3:$B$5001,$A$23,Base!$L$3:$L$5001,"<>")=0,"",SUMIFS(Base!$L$3:$L$5001,Base!$A$3:$A$5001,AJ$3,Base!$B$3:$B$5001,$A$23))) | AK26: =IF(COUNT(F26:AJ26)=0,"",SUM(F26:AJ26))
C27: Pallets Movimentados | D27: =IFERROR(1/(1/INDEX(calculos!$C$55:$K$83,MATCH("OUT Pallets Movimentados",calculos!$A$55:$A$83,0),MATCH($A$23,calculos!$C$54:$K$54,0))),"") | F27: =IF(F$3="","",IF(COUNTIFS(Base!$A$3:$A$5001,F$3,Base!$B$3:$B$5001,$A$23,Base!$M$3:$M$5001,"<>")=0,"",SUMIFS(Base!$M$3:$M$5001,Base!$A$3:$A$5001,F$3,Base!$B$3:$B$5001,$A$23))) | G27: =IF(G$3="","",IF(COUNTIFS(Base!$A$3:$A$5001,G$3,Base!$B$3:$B$5001,$A$23,Base!$M$3:$M$5001,"<>")=0,"",SUMIFS(Base!$M$3:$M$5001,Base!$A$3:$A$5001,G$3,Base!$B$3:$B$5001,$A$23))) | H27: =IF(H$3="","",IF(COUNTIFS(Base!$A$3:$A$5001,H$3,Base!$B$3:$B$5001,$A$23,Base!$M$3:$M$5001,"<>")=0,"",SUMIFS(Base!$M$3:$M$5001,Base!$A$3:$A$5001,H$3,Base!$B$3:$B$5001,$A$23))) | I27: =IF(I$3="","",IF(COUNTIFS(Base!$A$3:$A$5001,I$3,Base!$B$3:$B$5001,$A$23,Base!$M$3:$M$5001,"<>")=0,"",SUMIFS(Base!$M$3:$M$5001,Base!$A$3:$A$5001,I$3,Base!$B$3:$B$5001,$A$23))) | J27: =IF(J$3="","",IF(COUNTIFS(Base!$A$3:$A$5001,J$3,Base!$B$3:$B$5001,$A$23,Base!$M$3:$M$5001,"<>")=0,"",SUMIFS(Base!$M$3:$M$5001,Base!$A$3:$A$5001,J$3,Base!$B$3:$B$5001,$A$23))) | K27: =IF(K$3="","",IF(COUNTIFS(Base!$A$3:$A$5001,K$3,Base!$B$3:$B$5001,$A$23,Base!$M$3:$M$5001,"<>")=0,"",SUMIFS(Base!$M$3:$M$5001,Base!$A$3:$A$5001,K$3,Base!$B$3:$B$5001,$A$23))) | L27: =IF(L$3="","",IF(COUNTIFS(Base!$A$3:$A$5001,L$3,Base!$B$3:$B$5001,$A$23,Base!$M$3:$M$5001,"<>")=0,"",SUMIFS(Base!$M$3:$M$5001,Base!$A$3:$A$5001,L$3,Base!$B$3:$B$5001,$A$23))) | M27: =IF(M$3="","",IF(COUNTIFS(Base!$A$3:$A$5001,M$3,Base!$B$3:$B$5001,$A$23,Base!$M$3:$M$5001,"<>")=0,"",SUMIFS(Base!$M$3:$M$5001,Base!$A$3:$A$5001,M$3,Base!$B$3:$B$5001,$A$23))) | ... AJ27: =IF(AJ$3="","",IF(COUNTIFS(Base!$A$3:$A$5001,AJ$3,Base!$B$3:$B$5001,$A$23,Base!$M$3:$M$5001,"<>")=0,"",SUMIFS(Base!$M$3:$M$5001,Base!$A$3:$A$5001,AJ$3,Base!$B$3:$B$5001,$A$23))) | AK27: =IF(COUNT(F27:AJ27)=0,"",SUM(F27:AJ27))
C28: Pedidos Expedidos | D28: =IFERROR(1/(1/INDEX(calculos!$C$55:$K$83,MATCH("OUT Pedidos Expedidos",calculos!$A$55:$A$83,0),MATCH($A$23,calculos!$C$54:$K$54,0))),"") | F28: =IF(F$3="","",IF(COUNTIFS(Base!$A$3:$A$5001,F$3,Base!$B$3:$B$5001,$A$23,Base!$P$3:$P$5001,"<>")=0,"",SUMIFS(Base!$P$3:$P$5001,Base!$A$3:$A$5001,F$3,Base!$B$3:$B$5001,$A$23))) | G28: =IF(G$3="","",IF(COUNTIFS(Base!$A$3:$A$5001,G$3,Base!$B$3:$B$5001,$A$23,Base!$P$3:$P$5001,"<>")=0,"",SUMIFS(Base!$P$3:$P$5001,Base!$A$3:$A$5001,G$3,Base!$B$3:$B$5001,$A$23))) | H28: =IF(H$3="","",IF(COUNTIFS(Base!$A$3:$A$5001,H$3,Base!$B$3:$B$5001,$A$23,Base!$P$3:$P$5001,"<>")=0,"",SUMIFS(Base!$P$3:$P$5001,Base!$A$3:$A$5001,H$3,Base!$B$3:$B$5001,$A$23))) | I28: =IF(I$3="","",IF(COUNTIFS(Base!$A$3:$A$5001,I$3,Base!$B$3:$B$5001,$A$23,Base!$P$3:$P$5001,"<>")=0,"",SUMIFS(Base!$P$3:$P$5001,Base!$A$3:$A$5001,I$3,Base!$B$3:$B$5001,$A$23))) | J28: =IF(J$3="","",IF(COUNTIFS(Base!$A$3:$A$5001,J$3,Base!$B$3:$B$5001,$A$23,Base!$P$3:$P$5001,"<>")=0,"",SUMIFS(Base!$P$3:$P$5001,Base!$A$3:$A$5001,J$3,Base!$B$3:$B$5001,$A$23))) | K28: =IF(K$3="","",IF(COUNTIFS(Base!$A$3:$A$5001,K$3,Base!$B$3:$B$5001,$A$23,Base!$P$3:$P$5001,"<>")=0,"",SUMIFS(Base!$P$3:$P$5001,Base!$A$3:$A$5001,K$3,Base!$B$3:$B$5001,$A$23))) | L28: =IF(L$3="","",IF(COUNTIFS(Base!$A$3:$A$5001,L$3,Base!$B$3:$B$5001,$A$23,Base!$P$3:$P$5001,"<>")=0,"",SUMIFS(Base!$P$3:$P$5001,Base!$A$3:$A$5001,L$3,Base!$B$3:$B$5001,$A$23))) | M28: =IF(M$3="","",IF(COUNTIFS(Base!$A$3:$A$5001,M$3,Base!$B$3:$B$5001,$A$23,Base!$P$3:$P$5001,"<>")=0,"",SUMIFS(Base!$P$3:$P$5001,Base!$A$3:$A$5001,M$3,Base!$B$3:$B$5001,$A$23))) | ... AJ28: =IF(AJ$3="","",IF(COUNTIFS(Base!$A$3:$A$5001,AJ$3,Base!$B$3:$B$5001,$A$23,Base!$P$3:$P$5001,"<>")=0,"",SUMIFS(Base!$P$3:$P$5001,Base!$A$3:$A$5001,AJ$3,Base!$B$3:$B$5001,$A$23))) | AK28: =IF(COUNT(F28:AJ28)=0,"",SUM(F28:AJ28))
B29: NC | C29: Incidentes | D29: =IFERROR(1/(1/INDEX(calculos!$C$55:$K$83,MATCH("NC Incidentes",calculos!$A$55:$A$83,0),MATCH($A$23,calculos!$C$54:$K$54,0))),"") | F29: =IF(F$3="","",IF(COUNTIFS(Base!$A$3:$A$5001,F$3,Base!$B$3:$B$5001,$A$23,Base!$U$3:$U$5001,"<>")=0,"",SUMIFS(Base!$U$3:$U$5001,Base!$A$3:$A$5001,F$3,Base!$B$3:$B$5001,$A$23))) | G29: =IF(G$3="","",IF(COUNTIFS(Base!$A$3:$A$5001,G$3,Base!$B$3:$B$5001,$A$23,Base!$U$3:$U$5001,"<>")=0,"",SUMIFS(Base!$U$3:$U$5001,Base!$A$3:$A$5001,G$3,Base!$B$3:$B$5001,$A$23))) | H29: =IF(H$3="","",IF(COUNTIFS(Base!$A$3:$A$5001,H$3,Base!$B$3:$B$5001,$A$23,Base!$U$3:$U$5001,"<>")=0,"",SUMIFS(Base!$U$3:$U$5001,Base!$A$3:$A$5001,H$3,Base!$B$3:$B$5001,$A$23))) | I29: =IF(I$3="","",IF(COUNTIFS(Base!$A$3:$A$5001,I$3,Base!$B$3:$B$5001,$A$23,Base!$U$3:$U$5001,"<>")=0,"",SUMIFS(Base!$U$3:$U$5001,Base!$A$3:$A$5001,I$3,Base!$B$3:$B$5001,$A$23))) | J29: =IF(J$3="","",IF(COUNTIFS(Base!$A$3:$A$5001,J$3,Base!$B$3:$B$5001,$A$23,Base!$U$3:$U$5001,"<>")=0,"",SUMIFS(Base!$U$3:$U$5001,Base!$A$3:$A$5001,J$3,Base!$B$3:$B$5001,$A$23))) | K29: =IF(K$3="","",IF(COUNTIFS(Base!$A$3:$A$5001,K$3,Base!$B$3:$B$5001,$A$23,Base!$U$3:$U$5001,"<>")=0,"",SUMIFS(Base!$U$3:$U$5001,Base!$A$3:$A$5001,K$3,Base!$B$3:$B$5001,$A$23))) | L29: =IF(L$3="","",IF(COUNTIFS(Base!$A$3:$A$5001,L$3,Base!$B$3:$B$5001,$A$23,Base!$U$3:$U$5001,"<>")=0,"",SUMIFS(Base!$U$3:$U$5001,Base!$A$3:$A$5001,L$3,Base!$B$3:$B$5001,$A$23))) | M29: =IF(M$3="","",IF(COUNTIFS(Base!$A$3:$A$5001,M$3,Base!$B$3:$B$5001,$A$23,Base!$U$3:$U$5001,"<>")=0,"",SUMIFS(Base!$U$3:$U$5001,Base!$A$3:$A$5001,M$3,Base!$B$3:$B$5001,$A$23))) | ... AJ29: =IF(AJ$3="","",IF(COUNTIFS(Base!$A$3:$A$5001,AJ$3,Base!$B$3:$B$5001,$A$23,Base!$U$3:$U$5001,"<>")=0,"",SUMIFS(Base!$U$3:$U$5001,Base!$A$3:$A$5001,AJ$3,Base!$B$3:$B$5001,$A$23))) | AK29: =IF(COUNT(F29:AJ29)=0,"",SUM(F29:AJ29))
C30: No show | D30: =IFERROR(1/(1/INDEX(calculos!$C$55:$K$83,MATCH("NC No show",calculos!$A$55:$A$83,0),MATCH($A$23,calculos!$C$54:$K$54,0))),"") | F30: =IF(F$3="","",IF(COUNTIFS(Base!$A$3:$A$5001,F$3,Base!$B$3:$B$5001,$A$23,Base!$V$3:$V$5001,"<>")=0,"",SUMIFS(Base!$V$3:$V$5001,Base!$A$3:$A$5001,F$3,Base!$B$3:$B$5001,$A$23))) | G30: =IF(G$3="","",IF(COUNTIFS(Base!$A$3:$A$5001,G$3,Base!$B$3:$B$5001,$A$23,Base!$V$3:$V$5001,"<>")=0,"",SUMIFS(Base!$V$3:$V$5001,Base!$A$3:$A$5001,G$3,Base!$B$3:$B$5001,$A$23))) | H30: =IF(H$3="","",IF(COUNTIFS(Base!$A$3:$A$5001,H$3,Base!$B$3:$B$5001,$A$23,Base!$V$3:$V$5001,"<>")=0,"",SUMIFS(Base!$V$3:$V$5001,Base!$A$3:$A$5001,H$3,Base!$B$3:$B$5001,$A$23))) | I30: =IF(I$3="","",IF(COUNTIFS(Base!$A$3:$A$5001,I$3,Base!$B$3:$B$5001,$A$23,Base!$V$3:$V$5001,"<>")=0,"",SUMIFS(Base!$V$3:$V$5001,Base!$A$3:$A$5001,I$3,Base!$B$3:$B$5001,$A$23))) | J30: =IF(J$3="","",IF(COUNTIFS(Base!$A$3:$A$5001,J$3,Base!$B$3:$B$5001,$A$23,Base!$V$3:$V$5001,"<>")=0,"",SUMIFS(Base!$V$3:$V$5001,Base!$A$3:$A$5001,J$3,Base!$B$3:$B$5001,$A$23))) | K30: =IF(K$3="","",IF(COUNTIFS(Base!$A$3:$A$5001,K$3,Base!$B$3:$B$5001,$A$23,Base!$V$3:$V$5001,"<>")=0,"",SUMIFS(Base!$V$3:$V$5001,Base!$A$3:$A$5001,K$3,Base!$B$3:$B$5001,$A$23))) | L30: =IF(L$3="","",IF(COUNTIFS(Base!$A$3:$A$5001,L$3,Base!$B$3:$B$5001,$A$23,Base!$V$3:$V$5001,"<>")=0,"",SUMIFS(Base!$V$3:$V$5001,Base!$A$3:$A$5001,L$3,Base!$B$3:$B$5001,$A$23))) | M30: =IF(M$3="","",IF(COUNTIFS(Base!$A$3:$A$5001,M$3,Base!$B$3:$B$5001,$A$23,Base!$V$3:$V$5001,"<>")=0,"",SUMIFS(Base!$V$3:$V$5001,Base!$A$3:$A$5001,M$3,Base!$B$3:$B$5001,$A$23))) | ... AJ30: =IF(AJ$3="","",IF(COUNTIFS(Base!$A$3:$A$5001,AJ$3,Base!$B$3:$B$5001,$A$23,Base!$V$3:$V$5001,"<>")=0,"",SUMIFS(Base!$V$3:$V$5001,Base!$A$3:$A$5001,AJ$3,Base!$B$3:$B$5001,$A$23))) | AK30: =IF(COUNT(F30:AJ30)=0,"",SUM(F30:AJ30))
C31: Backlog | D31: =IFERROR(1/(1/INDEX(calculos!$C$55:$K$83,MATCH("NC Backlog",calculos!$A$55:$A$83,0),MATCH($A$23,calculos!$C$54:$K$54,0))),"") | F31: =IF(F$3="","",IF(COUNTIFS(Base!$A$3:$A$5001,F$3,Base!$B$3:$B$5001,$A$23,Base!$W$3:$W$5001,"<>")=0,"",SUMIFS(Base!$W$3:$W$5001,Base!$A$3:$A$5001,F$3,Base!$B$3:$B$5001,$A$23))) | G31: =IF(G$3="","",IF(COUNTIFS(Base!$A$3:$A$5001,G$3,Base!$B$3:$B$5001,$A$23,Base!$W$3:$W$5001,"<>")=0,"",SUMIFS(Base!$W$3:$W$5001,Base!$A$3:$A$5001,G$3,Base!$B$3:$B$5001,$A$23))) | H31: =IF(H$3="","",IF(COUNTIFS(Base!$A$3:$A$5001,H$3,Base!$B$3:$B$5001,$A$23,Base!$W$3:$W$5001,"<>")=0,"",SUMIFS(Base!$W$3:$W$5001,Base!$A$3:$A$5001,H$3,Base!$B$3:$B$5001,$A$23))) | I31: =IF(I$3="","",IF(COUNTIFS(Base!$A$3:$A$5001,I$3,Base!$B$3:$B$5001,$A$23,Base!$W$3:$W$5001,"<>")=0,"",SUMIFS(Base!$W$3:$W$5001,Base!$A$3:$A$5001,I$3,Base!$B$3:$B$5001,$A$23))) | J31: =IF(J$3="","",IF(COUNTIFS(Base!$A$3:$A$5001,J$3,Base!$B$3:$B$5001,$A$23,Base!$W$3:$W$5001,"<>")=0,"",SUMIFS(Base!$W$3:$W$5001,Base!$A$3:$A$5001,J$3,Base!$B$3:$B$5001,$A$23))) | K31: =IF(K$3="","",IF(COUNTIFS(Base!$A$3:$A$5001,K$3,Base!$B$3:$B$5001,$A$23,Base!$W$3:$W$5001,"<>")=0,"",SUMIFS(Base!$W$3:$W$5001,Base!$A$3:$A$5001,K$3,Base!$B$3:$B$5001,$A$23))) | L31: =IF(L$3="","",IF(COUNTIFS(Base!$A$3:$A$5001,L$3,Base!$B$3:$B$5001,$A$23,Base!$W$3:$W$5001,"<>")=0,"",SUMIFS(Base!$W$3:$W$5001,Base!$A$3:$A$5001,L$3,Base!$B$3:$B$5001,$A$23))) | M31: =IF(M$3="","",IF(COUNTIFS(Base!$A$3:$A$5001,M$3,Base!$B$3:$B$5001,$A$23,Base!$W$3:$W$5001,"<>")=0,"",SUMIFS(Base!$W$3:$W$5001,Base!$A$3:$A$5001,M$3,Base!$B$3:$B$5001,$A$23))) | ... AJ31: =IF(AJ$3="","",IF(COUNTIFS(Base!$A$3:$A$5001,AJ$3,Base!$B$3:$B$5001,$A$23,Base!$W$3:$W$5001,"<>")=0,"",SUMIFS(Base!$W$3:$W$5001,Base!$A$3:$A$5001,AJ$3,Base!$B$3:$B$5001,$A$23))) | AK31: =IFERROR(LOOKUP(9.99E+307,F31:AJ31),"")
B32: OCUPAÇÃO (P.P) | C32: Posições Disponíveis | D32: =IFERROR(1/(1/INDEX(calculos!$C$55:$K$83,MATCH("Posições Disponíveis",calculos!$A$55:$A$83,0),MATCH($A$23,calculos!$C$54:$K$54,0))),"") | F32: =IF(F$3="","",IF(COUNTIFS(Base!$A$3:$A$5001,F$3,Base!$B$3:$B$5001,$A$23,Base!$X$3:$X$5001,"<>")=0,"",SUMIFS(Base!$X$3:$X$5001,Base!$A$3:$A$5001,F$3,Base!$B$3:$B$5001,$A$23))) | G32: =IF(G$3="","",IF(COUNTIFS(Base!$A$3:$A$5001,G$3,Base!$B$3:$B$5001,$A$23,Base!$X$3:$X$5001,"<>")=0,"",SUMIFS(Base!$X$3:$X$5001,Base!$A$3:$A$5001,G$3,Base!$B$3:$B$5001,$A$23))) | H32: =IF(H$3="","",IF(COUNTIFS(Base!$A$3:$A$5001,H$3,Base!$B$3:$B$5001,$A$23,Base!$X$3:$X$5001,"<>")=0,"",SUMIFS(Base!$X$3:$X$5001,Base!$A$3:$A$5001,H$3,Base!$B$3:$B$5001,$A$23))) | I32: =IF(I$3="","",IF(COUNTIFS(Base!$A$3:$A$5001,I$3,Base!$B$3:$B$5001,$A$23,Base!$X$3:$X$5001,"<>")=0,"",SUMIFS(Base!$X$3:$X$5001,Base!$A$3:$A$5001,I$3,Base!$B$3:$B$5001,$A$23))) | J32: =IF(J$3="","",IF(COUNTIFS(Base!$A$3:$A$5001,J$3,Base!$B$3:$B$5001,$A$23,Base!$X$3:$X$5001,"<>")=0,"",SUMIFS(Base!$X$3:$X$5001,Base!$A$3:$A$5001,J$3,Base!$B$3:$B$5001,$A$23))) | K32: =IF(K$3="","",IF(COUNTIFS(Base!$A$3:$A$5001,K$3,Base!$B$3:$B$5001,$A$23,Base!$X$3:$X$5001,"<>")=0,"",SUMIFS(Base!$X$3:$X$5001,Base!$A$3:$A$5001,K$3,Base!$B$3:$B$5001,$A$23))) | L32: =IF(L$3="","",IF(COUNTIFS(Base!$A$3:$A$5001,L$3,Base!$B$3:$B$5001,$A$23,Base!$X$3:$X$5001,"<>")=0,"",SUMIFS(Base!$X$3:$X$5001,Base!$A$3:$A$5001,L$3,Base!$B$3:$B$5001,$A$23))) | M32: =IF(M$3="","",IF(COUNTIFS(Base!$A$3:$A$5001,M$3,Base!$B$3:$B$5001,$A$23,Base!$X$3:$X$5001,"<>")=0,"",SUMIFS(Base!$X$3:$X$5001,Base!$A$3:$A$5001,M$3,Base!$B$3:$B$5001,$A$23))) | ... AJ32: =IF(AJ$3="","",IF(COUNTIFS(Base!$A$3:$A$5001,AJ$3,Base!$B$3:$B$5001,$A$23,Base!$X$3:$X$5001,"<>")=0,"",SUMIFS(Base!$X$3:$X$5001,Base!$A$3:$A$5001,AJ$3,Base!$B$3:$B$5001,$A$23))) | AK32: =IFERROR(LOOKUP(9.99E+307,F32:AJ32),"")
C33: Posições Ocupadas | D33: =IFERROR(1/(1/INDEX(calculos!$C$55:$K$83,MATCH("Posições Ocupadas",calculos!$A$55:$A$83,0),MATCH($A$23,calculos!$C$54:$K$54,0))),"") | F33: =IF(F$3="","",IF(COUNTIFS(Base!$A$3:$A$5001,F$3,Base!$B$3:$B$5001,$A$23,Base!$Y$3:$Y$5001,"<>")=0,"",SUMIFS(Base!$Y$3:$Y$5001,Base!$A$3:$A$5001,F$3,Base!$B$3:$B$5001,$A$23))) | G33: =IF(G$3="","",IF(COUNTIFS(Base!$A$3:$A$5001,G$3,Base!$B$3:$B$5001,$A$23,Base!$Y$3:$Y$5001,"<>")=0,"",SUMIFS(Base!$Y$3:$Y$5001,Base!$A$3:$A$5001,G$3,Base!$B$3:$B$5001,$A$23))) | H33: =IF(H$3="","",IF(COUNTIFS(Base!$A$3:$A$5001,H$3,Base!$B$3:$B$5001,$A$23,Base!$Y$3:$Y$5001,"<>")=0,"",SUMIFS(Base!$Y$3:$Y$5001,Base!$A$3:$A$5001,H$3,Base!$B$3:$B$5001,$A$23))) | I33: =IF(I$3="","",IF(COUNTIFS(Base!$A$3:$A$5001,I$3,Base!$B$3:$B$5001,$A$23,Base!$Y$3:$Y$5001,"<>")=0,"",SUMIFS(Base!$Y$3:$Y$5001,Base!$A$3:$A$5001,I$3,Base!$B$3:$B$5001,$A$23))) | J33: =IF(J$3="","",IF(COUNTIFS(Base!$A$3:$A$5001,J$3,Base!$B$3:$B$5001,$A$23,Base!$Y$3:$Y$5001,"<>")=0,"",SUMIFS(Base!$Y$3:$Y$5001,Base!$A$3:$A$5001,J$3,Base!$B$3:$B$5001,$A$23))) | K33: =IF(K$3="","",IF(COUNTIFS(Base!$A$3:$A$5001,K$3,Base!$B$3:$B$5001,$A$23,Base!$Y$3:$Y$5001,"<>")=0,"",SUMIFS(Base!$Y$3:$Y$5001,Base!$A$3:$A$5001,K$3,Base!$B$3:$B$5001,$A$23))) | L33: =IF(L$3="","",IF(COUNTIFS(Base!$A$3:$A$5001,L$3,Base!$B$3:$B$5001,$A$23,Base!$Y$3:$Y$5001,"<>")=0,"",SUMIFS(Base!$Y$3:$Y$5001,Base!$A$3:$A$5001,L$3,Base!$B$3:$B$5001,$A$23))) | M33: =IF(M$3="","",IF(COUNTIFS(Base!$A$3:$A$5001,M$3,Base!$B$3:$B$5001,$A$23,Base!$Y$3:$Y$5001,"<>")=0,"",SUMIFS(Base!$Y$3:$Y$5001,Base!$A$3:$A$5001,M$3,Base!$B$3:$B$5001,$A$23))) | ... AJ33: =IF(AJ$3="","",IF(COUNTIFS(Base!$A$3:$A$5001,AJ$3,Base!$B$3:$B$5001,$A$23,Base!$Y$3:$Y$5001,"<>")=0,"",SUMIFS(Base!$Y$3:$Y$5001,Base!$A$3:$A$5001,AJ$3,Base!$B$3:$B$5001,$A$23))) | AK33: =IFERROR(LOOKUP(9.99E+307,F33:AJ33),"")
C34: Taxa de Ocupação | D34: =IFERROR(1/(1/INDEX(calculos!$C$55:$K$83,MATCH("Taxa de Ocupação",calculos!$A$55:$A$83,0),MATCH($A$23,calculos!$C$54:$K$54,0))),"") | F34: =IF(AND(ISNUMBER(F32),ISNUMBER(F33)),IF(F32>0,F33/F32,""),"") | G34: =IF(AND(ISNUMBER(G32),ISNUMBER(G33)),IF(G32>0,G33/G32,""),"") | H34: =IF(AND(ISNUMBER(H32),ISNUMBER(H33)),IF(H32>0,H33/H32,""),"") | I34: =IF(AND(ISNUMBER(I32),ISNUMBER(I33)),IF(I32>0,I33/I32,""),"") | J34: =IF(AND(ISNUMBER(J32),ISNUMBER(J33)),IF(J32>0,J33/J32,""),"") | K34: =IF(AND(ISNUMBER(K32),ISNUMBER(K33)),IF(K32>0,K33/K32,""),"") | L34: =IF(AND(ISNUMBER(L32),ISNUMBER(L33)),IF(L32>0,L33/L32,""),"") | M34: =IF(AND(ISNUMBER(M32),ISNUMBER(M33)),IF(M32>0,M33/M32,""),"") | ... AK34: =IF(AND(ISNUMBER(AK32),ISNUMBER(AK33)),IF(AK32>0,AK33/AK32,""),"")
B35: GENTE | C35: Efetivo | D35: =IFERROR(1/(1/INDEX(calculos!$C$55:$K$83,MATCH("Efetivo",calculos!$A$55:$A$83,0),MATCH($A$23,calculos!$C$54:$K$54,0))),"") | F35: =IF(F$3="","",IF(COUNTIFS(Base!$A$3:$A$5001,F$3,Base!$B$3:$B$5001,$A$23,Base!$Z$3:$Z$5001,"<>")=0,"",SUMIFS(Base!$Z$3:$Z$5001,Base!$A$3:$A$5001,F$3,Base!$B$3:$B$5001,$A$23))) | G35: =IF(G$3="","",IF(COUNTIFS(Base!$A$3:$A$5001,G$3,Base!$B$3:$B$5001,$A$23,Base!$Z$3:$Z$5001,"<>")=0,"",SUMIFS(Base!$Z$3:$Z$5001,Base!$A$3:$A$5001,G$3,Base!$B$3:$B$5001,$A$23))) | H35: =IF(H$3="","",IF(COUNTIFS(Base!$A$3:$A$5001,H$3,Base!$B$3:$B$5001,$A$23,Base!$Z$3:$Z$5001,"<>")=0,"",SUMIFS(Base!$Z$3:$Z$5001,Base!$A$3:$A$5001,H$3,Base!$B$3:$B$5001,$A$23))) | I35: =IF(I$3="","",IF(COUNTIFS(Base!$A$3:$A$5001,I$3,Base!$B$3:$B$5001,$A$23,Base!$Z$3:$Z$5001,"<>")=0,"",SUMIFS(Base!$Z$3:$Z$5001,Base!$A$3:$A$5001,I$3,Base!$B$3:$B$5001,$A$23))) | J35: =IF(J$3="","",IF(COUNTIFS(Base!$A$3:$A$5001,J$3,Base!$B$3:$B$5001,$A$23,Base!$Z$3:$Z$5001,"<>")=0,"",SUMIFS(Base!$Z$3:$Z$5001,Base!$A$3:$A$5001,J$3,Base!$B$3:$B$5001,$A$23))) | K35: =IF(K$3="","",IF(COUNTIFS(Base!$A$3:$A$5001,K$3,Base!$B$3:$B$5001,$A$23,Base!$Z$3:$Z$5001,"<>")=0,"",SUMIFS(Base!$Z$3:$Z$5001,Base!$A$3:$A$5001,K$3,Base!$B$3:$B$5001,$A$23))) | L35: =IF(L$3="","",IF(COUNTIFS(Base!$A$3:$A$5001,L$3,Base!$B$3:$B$5001,$A$23,Base!$Z$3:$Z$5001,"<>")=0,"",SUMIFS(Base!$Z$3:$Z$5001,Base!$A$3:$A$5001,L$3,Base!$B$3:$B$5001,$A$23))) | M35: =IF(M$3="","",IF(COUNTIFS(Base!$A$3:$A$5001,M$3,Base!$B$3:$B$5001,$A$23,Base!$Z$3:$Z$5001,"<>")=0,"",SUMIFS(Base!$Z$3:$Z$5001,Base!$A$3:$A$5001,M$3,Base!$B$3:$B$5001,$A$23))) | ... AJ35: =IF(AJ$3="","",IF(COUNTIFS(Base!$A$3:$A$5001,AJ$3,Base!$B$3:$B$5001,$A$23,Base!$Z$3:$Z$5001,"<>")=0,"",SUMIFS(Base!$Z$3:$Z$5001,Base!$A$3:$A$5001,AJ$3,Base!$B$3:$B$5001,$A$23))) | AK35: =IFERROR(LOOKUP(9.99E+307,F35:AJ35),"")
C36: Falta | D36: =IFERROR(1/(1/INDEX(calculos!$C$55:$K$83,MATCH("Falta",calculos!$A$55:$A$83,0),MATCH($A$23,calculos!$C$54:$K$54,0))),"") | F36: =IF(F$3="","",IF(COUNTIFS(Base!$A$3:$A$5001,F$3,Base!$B$3:$B$5001,$A$23,Base!$AA$3:$AA$5001,"<>")=0,"",SUMIFS(Base!$AA$3:$AA$5001,Base!$A$3:$A$5001,F$3,Base!$B$3:$B$5001,$A$23))) | G36: =IF(G$3="","",IF(COUNTIFS(Base!$A$3:$A$5001,G$3,Base!$B$3:$B$5001,$A$23,Base!$AA$3:$AA$5001,"<>")=0,"",SUMIFS(Base!$AA$3:$AA$5001,Base!$A$3:$A$5001,G$3,Base!$B$3:$B$5001,$A$23))) | H36: =IF(H$3="","",IF(COUNTIFS(Base!$A$3:$A$5001,H$3,Base!$B$3:$B$5001,$A$23,Base!$AA$3:$AA$5001,"<>")=0,"",SUMIFS(Base!$AA$3:$AA$5001,Base!$A$3:$A$5001,H$3,Base!$B$3:$B$5001,$A$23))) | I36: =IF(I$3="","",IF(COUNTIFS(Base!$A$3:$A$5001,I$3,Base!$B$3:$B$5001,$A$23,Base!$AA$3:$AA$5001,"<>")=0,"",SUMIFS(Base!$AA$3:$AA$5001,Base!$A$3:$A$5001,I$3,Base!$B$3:$B$5001,$A$23))) | J36: =IF(J$3="","",IF(COUNTIFS(Base!$A$3:$A$5001,J$3,Base!$B$3:$B$5001,$A$23,Base!$AA$3:$AA$5001,"<>")=0,"",SUMIFS(Base!$AA$3:$AA$5001,Base!$A$3:$A$5001,J$3,Base!$B$3:$B$5001,$A$23))) | K36: =IF(K$3="","",IF(COUNTIFS(Base!$A$3:$A$5001,K$3,Base!$B$3:$B$5001,$A$23,Base!$AA$3:$AA$5001,"<>")=0,"",SUMIFS(Base!$AA$3:$AA$5001,Base!$A$3:$A$5001,K$3,Base!$B$3:$B$5001,$A$23))) | L36: =IF(L$3="","",IF(COUNTIFS(Base!$A$3:$A$5001,L$3,Base!$B$3:$B$5001,$A$23,Base!$AA$3:$AA$5001,"<>")=0,"",SUMIFS(Base!$AA$3:$AA$5001,Base!$A$3:$A$5001,L$3,Base!$B$3:$B$5001,$A$23))) | M36: =IF(M$3="","",IF(COUNTIFS(Base!$A$3:$A$5001,M$3,Base!$B$3:$B$5001,$A$23,Base!$AA$3:$AA$5001,"<>")=0,"",SUMIFS(Base!$AA$3:$AA$5001,Base!$A$3:$A$5001,M$3,Base!$B$3:$B$5001,$A$23))) | ... AJ36: =IF(AJ$3="","",IF(COUNTIFS(Base!$A$3:$A$5001,AJ$3,Base!$B$3:$B$5001,$A$23,Base!$AA$3:$AA$5001,"<>")=0,"",SUMIFS(Base!$AA$3:$AA$5001,Base!$A$3:$A$5001,AJ$3,Base!$B$3:$B$5001,$A$23))) | AK36: =IF(COUNT(F36:AJ36)=0,"",SUM(F36:AJ36))
C37: Folga | D37: =IFERROR(1/(1/INDEX(calculos!$C$55:$K$83,MATCH("Folga",calculos!$A$55:$A$83,0),MATCH($A$23,calculos!$C$54:$K$54,0))),"") | F37: =IF(F$3="","",IF(COUNTIFS(Base!$A$3:$A$5001,F$3,Base!$B$3:$B$5001,$A$23,Base!$AB$3:$AB$5001,"<>")=0,"",SUMIFS(Base!$AB$3:$AB$5001,Base!$A$3:$A$5001,F$3,Base!$B$3:$B$5001,$A$23))) | G37: =IF(G$3="","",IF(COUNTIFS(Base!$A$3:$A$5001,G$3,Base!$B$3:$B$5001,$A$23,Base!$AB$3:$AB$5001,"<>")=0,"",SUMIFS(Base!$AB$3:$AB$5001,Base!$A$3:$A$5001,G$3,Base!$B$3:$B$5001,$A$23))) | H37: =IF(H$3="","",IF(COUNTIFS(Base!$A$3:$A$5001,H$3,Base!$B$3:$B$5001,$A$23,Base!$AB$3:$AB$5001,"<>")=0,"",SUMIFS(Base!$AB$3:$AB$5001,Base!$A$3:$A$5001,H$3,Base!$B$3:$B$5001,$A$23))) | I37: =IF(I$3="","",IF(COUNTIFS(Base!$A$3:$A$5001,I$3,Base!$B$3:$B$5001,$A$23,Base!$AB$3:$AB$5001,"<>")=0,"",SUMIFS(Base!$AB$3:$AB$5001,Base!$A$3:$A$5001,I$3,Base!$B$3:$B$5001,$A$23))) | J37: =IF(J$3="","",IF(COUNTIFS(Base!$A$3:$A$5001,J$3,Base!$B$3:$B$5001,$A$23,Base!$AB$3:$AB$5001,"<>")=0,"",SUMIFS(Base!$AB$3:$AB$5001,Base!$A$3:$A$5001,J$3,Base!$B$3:$B$5001,$A$23))) | K37: =IF(K$3="","",IF(COUNTIFS(Base!$A$3:$A$5001,K$3,Base!$B$3:$B$5001,$A$23,Base!$AB$3:$AB$5001,"<>")=0,"",SUMIFS(Base!$AB$3:$AB$5001,Base!$A$3:$A$5001,K$3,Base!$B$3:$B$5001,$A$23))) | L37: =IF(L$3="","",IF(COUNTIFS(Base!$A$3:$A$5001,L$3,Base!$B$3:$B$5001,$A$23,Base!$AB$3:$AB$5001,"<>")=0,"",SUMIFS(Base!$AB$3:$AB$5001,Base!$A$3:$A$5001,L$3,Base!$B$3:$B$5001,$A$23))) | M37: =IF(M$3="","",IF(COUNTIFS(Base!$A$3:$A$5001,M$3,Base!$B$3:$B$5001,$A$23,Base!$AB$3:$AB$5001,"<>")=0,"",SUMIFS(Base!$AB$3:$AB$5001,Base!$A$3:$A$5001,M$3,Base!$B$3:$B$5001,$A$23))) | ... AJ37: =IF(AJ$3="","",IF(COUNTIFS(Base!$A$3:$A$5001,AJ$3,Base!$B$3:$B$5001,$A$23,Base!$AB$3:$AB$5001,"<>")=0,"",SUMIFS(Base!$AB$3:$AB$5001,Base!$A$3:$A$5001,AJ$3,Base!$B$3:$B$5001,$A$23))) | AK37: =IF(COUNT(F37:AJ37)=0,"",SUM(F37:AJ37))
